Workbook
Name __DdeLink__2326_2541265958: 'Двери Kapelli'!#REF!
Name __DdeLink__294_2844460511: 'Двери Kapelli'!#REF!
Name __DdeLink__960_1832848366: 'Двери Kapelli'!#REF!
Name Print_Area: 'Дерев. гл. двери в проем'!$A$1:$H$44
Name Print_Area: 'Дерев. гл. скр. двери в проем'!$A$1:$H$51

Sheet Смета ЕР (общ) 
F1: Формат объекта | H1: ККО | P1: курс $ | Q1: 85.25
F2: дверной | G2: Адрес объекта: | H2: заполняется конкретный адрес | P2: курс Евро | Q2: 98.85
F3: Плoщадь объекта (м.кв.): | G3: Плащадь объекта: | H3: 500 | P3: Дисконт по тендеру | Q3: 0
F4: Срок проведения работ | G4: Срок проведения работ | H4: Согласно план-графику производства работ | P4: курс Юань | Q4: 12.64
F5: ПОДРЯДЧИК: | G5: ПОДРЯДЧИК: | H5: !!! ЗАПОЛНИТЬ !!!
F6: Юридический адрес: | G6: Юридический адрес: | H6: !!! ЗАПОЛНИТЬ !!!
F7: Электронный адрес: | G7: Электронный адрес: | H7: !!! ЗАПОЛНИТЬ !!!
F8: Контактное лицо (Ф.И.О.) : | G8: Контактное лицо (Ф.И.О.) : | H8: !!! ЗАПОЛНИТЬ !!!
F9: Контактный телефон: | G9: Контактный телефон: | H9: !!! ЗАПОЛНИТЬ !!!
F10: Реквизиты: | G10: Реквизиты: | H10: !!! ЗАПОЛНИТЬ !!!
F11: Сумма по смете: | G11: Сумма по смете: | H11: =N1666 -> 0
A14: Раздел | B14: Подраздел | C14: Подраздел подраздела | D14: Пункт подраздела | E14: Новый номенклатурный номер | F14: № | G14: Наименование работ и затрат | H14: Един. изм. | I14: Кол - во. (объем) | J14: ЕР цена работ, руб.* | K14: ЕР цена материалов и оборудования, руб.* | L14: Цена работ, руб. * | M14: Цена материалов и оборудования, руб. * | N14: Стоимость работ, руб. * | O14: Стоимость материалов и оборудования руб. * | P14: Примечание | R14: ККО/ИНФРАСТРУКТУРА
A15: Р1 | B15: 0 | D15: 0 | E15: =CONCATENATE('Смета ЕР (общ) '!$A15,".",'Смета ЕР (общ) '!$B15,".",'Смета ЕР (общ) '!$D15) -> Р1.0.0 | F15: 1 | G15: Раздел №1. Проектные работы и согласования | I15: =I16 -> 0 | N15: =ROUND(N16,2) -> 0 | O15: =ROUND(O16,2) -> 0
A16: Р1 | B16: 1 | D16: 0 | E16: =CONCATENATE('Смета ЕР (общ) '!$A16,".",'Смета ЕР (общ) '!$B16,".",'Смета ЕР (общ) '!$D16) -> Р1.1.0 | F16: =IF(I16>0,F15+1,F15) -> 1 | G16: 1.1.0 Проектные работы и согласования | I16: =SUM(I17:I108) -> 0 | N16: =SUM(N17:N108) -> 0 | O16: =SUM(O17:O108) -> 0
A17: Р1 | B17: 1 | D17: 1 | E17: =CONCATENATE('Смета ЕР (общ) '!$A17,".",'Смета ЕР (общ) '!$B17,".",'Смета ЕР (общ) '!$D17) -> Р1.1.1 | F17: =IF(I17>0,F16+1,F16) -> 1 | G17: Техническое обследование состояния несущих конструкций помещения с подготовкой рекомендаций по усилению (Техничесекое заключение о конструктиве - "ТЗК") (для помещений от 100 до 450 м.кв) | H17: м2 | J17: ='Проектирование 100-450'!E36*1.05 -> 3675 | K17: 0 | L17: =ROUND(J17-J17*$Q$3,2) -> 3675 | M17: =ROUND(K17-K17*$Q$3,2) -> 0 | N17: =ROUND('Смета ЕР (общ) '!$I17*'Смета ЕР (общ) '!$L17,2) -> 0 | O17: =ROUND('Смета ЕР (общ) '!$I17*'Смета ЕР (общ) '!$M17,2) -> 0
A18: Р1 | B18: 1 | D18: 44 | E18: =CONCATENATE('Смета ЕР (общ) '!$A18,".",'Смета ЕР (общ) '!$B18,".",'Смета ЕР (общ) '!$D18) -> Р1.1.44 | F18: =IF(I18>0,F17+1,F17) -> 1 | G18: Эскизный проект фасада и Колористический паспорт с указанием ведомости отделки и проектным решением со спецификацией элементов (крыльцо, пандус, навесы, колонны и т.д.)(для фасадов от 100 до 450 м.кв) | H18: м2 | J18: ='Проектирование 100-450'!E37*1.05 -> 7822.5 | K18: 0 | L18: =ROUND(J18-J18*$Q$3,2) -> 7822.5 | M18: =ROUND(K18-K18*$Q$3,2) -> 0 | N18: =ROUND('Смета ЕР (общ) '!$I18*'Смета ЕР (общ) '!$L18,2) -> 0 | O18: =ROUND('Смета ЕР (общ) '!$I18*'Смета ЕР (общ) '!$M18,2) -> 0
A19: Р1 | B19: 1 | D19: 2 | E19: =CONCATENATE('Смета ЕР (общ) '!$A19,".",'Смета ЕР (общ) '!$B19,".",'Смета ЕР (общ) '!$D19) -> Р1.1.2 | F19: =IF(I19>0,F18+1,F18) -> 1 | G19: Рабочая документация по усилению/устройству несущих конструкций ("КР"), включая пояснительную записку (для помещений от 100 до 450 м.кв) | H19: м2 | J19: ='Проектирование 100-450'!E18*1.05 -> 135.45 | K19: 0 | L19: =ROUND(J19-J19*$Q$3,2) -> 135.45 | M19: =ROUND(K19-K19*$Q$3,2) -> 0 | N19: =ROUND('Смета ЕР (общ) '!$I19*'Смета ЕР (общ) '!$L19,2) -> 0 | O19: =ROUND('Смета ЕР (общ) '!$I19*'Смета ЕР (общ) '!$M19,2) -> 0
A20: Р1 | B20: 1 | D20: 3 | E20: =CONCATENATE('Смета ЕР (общ) '!$A20,".",'Смета ЕР (общ) '!$B20,".",'Смета ЕР (общ) '!$D20) -> Р1.1.3 | F20: =IF(I20>0,F19+1,F19) -> 1 | G20: Рабочая документация "Архитектурные решения" ("АР"), включая пояснительную записку (для помещений от 100 до 450 м.кв) | H20: м2 | J20: ='Проектирование 100-450'!E19*1.05 -> 389.55 | K20: 0 | L20: =ROUND(J20-J20*$Q$3,2) -> 389.55 | M20: =ROUND(K20-K20*$Q$3,2) -> 0 | N20: =ROUND('Смета ЕР (общ) '!$I20*'Смета ЕР (общ) '!$L20,2) -> 0 | O20: =ROUND('Смета ЕР (общ) '!$I20*'Смета ЕР (общ) '!$M20,2) -> 0
A21: Р1 | B21: 1 | D21: 4 | E21: =CONCATENATE('Смета ЕР (общ) '!$A21,".",'Смета ЕР (общ) '!$B21,".",'Смета ЕР (общ) '!$D21) -> Р1.1.4 | F21: =IF(I21>0,F20+1,F20) -> 1 | G21: Рабочая документация по электроснабжению и электроосвещению ("ЭОМ"), включая пояснительную записку (для помещений от 100 до 450 м.кв) | H21: м2 | J21: ='Проектирование 100-450'!E20*1.05 -> 258.3 | K21: 0 | L21: =ROUND(J21-J21*$Q$3,2) -> 258.3 | M21: =ROUND(K21-K21*$Q$3,2) -> 0 | N21: =ROUND('Смета ЕР (общ) '!$I21*'Смета ЕР (общ) '!$L21,2) -> 0 | O21: =ROUND('Смета ЕР (общ) '!$I21*'Смета ЕР (общ) '!$M21,2) -> 0
A22: Р1 | B22: 1 | D22: 5 | E22: =CONCATENATE('Смета ЕР (общ) '!$A22,".",'Смета ЕР (общ) '!$B22,".",'Смета ЕР (общ) '!$D22) -> Р1.1.5 | F22: =IF(I22>0,F21+1,F21) -> 1 | G22: Рабочая документация Системы вентиляции ("ОВиК-В"), включая пояснительную записку (для помещений от 100 до 450 м.кв) | H22: м2 | J22: ='Проектирование 100-450'!E21*1.05 -> 202.65 | K22: 0 | L22: =ROUND(J22-J22*$Q$3,2) -> 202.65 | M22: =ROUND(K22-K22*$Q$3,2) -> 0 | N22: =ROUND('Смета ЕР (общ) '!$I22*'Смета ЕР (общ) '!$L22,2) -> 0 | O22: =ROUND('Смета ЕР (общ) '!$I22*'Смета ЕР (общ) '!$M22,2) -> 0
A23: Р1 | B23: 1 | D23: 6 | E23: =CONCATENATE('Смета ЕР (общ) '!$A23,".",'Смета ЕР (общ) '!$B23,".",'Смета ЕР (общ) '!$D23) -> Р1.1.6 | F23: =IF(I23>0,F22+1,F22) -> 1 | G23: Рабочая документация Системы кондиционирования ("ОВиК-К"), включая пояснительную записку (для помещений от 100 до 450 м.кв) | H23: м2 | J23: ='Проектирование 100-450'!E22*1.05 -> 159.4845 | K23: 0 | L23: =ROUND(J23-J23*$Q$3,2) -> 159.48 | M23: =ROUND(K23-K23*$Q$3,2) -> 0 | N23: =ROUND('Смета ЕР (общ) '!$I23*'Смета ЕР (общ) '!$L23,2) -> 0 | O23: =ROUND('Смета ЕР (общ) '!$I23*'Смета ЕР (общ) '!$M23,2) -> 0
A24: Р1 | B24: 1 | D24: 7 | E24: =CONCATENATE('Смета ЕР (общ) '!$A24,".",'Смета ЕР (общ) '!$B24,".",'Смета ЕР (общ) '!$D24) -> Р1.1.7 | F24: =IF(I24>0,F23+1,F23) -> 1 | G24: Рабочая документация Системы отопления ("ОВиК-О"), включая Пояснительную записку и Теплотехнический расчет (для помещений от 100 до 450 м.кв) | H24: м2 | J24: ='Проектирование 100-450'!E23*1.05 -> 123.9 | K24: 0 | L24: =ROUND(J24-J24*$Q$3,2) -> 123.9 | M24: =ROUND(K24-K24*$Q$3,2) -> 0 | N24: =ROUND('Смета ЕР (общ) '!$I24*'Смета ЕР (общ) '!$L24,2) -> 0 | O24: =ROUND('Смета ЕР (общ) '!$I24*'Смета ЕР (общ) '!$M24,2) -> 0
A25: Р1 | B25: 1 | D25: 8 | E25: =CONCATENATE('Смета ЕР (общ) '!$A25,".",'Смета ЕР (общ) '!$B25,".",'Смета ЕР (общ) '!$D25) -> Р1.1.8 | F25: =IF(I25>0,F24+1,F24) -> 1 | G25: Рабочая документация Системы водоснабжения и канализации ("ВК"), включая пояснительную записку (для помещений от 100 до 450 м.кв) | H25: м2 | J25: ='Проектирование 100-450'!E24*1.05 -> 130.2 | K25: 0 | L25: =ROUND(J25-J25*$Q$3,2) -> 130.2 | M25: =ROUND(K25-K25*$Q$3,2) -> 0 | N25: =ROUND('Смета ЕР (общ) '!$I25*'Смета ЕР (общ) '!$L25,2) -> 0 | O25: =ROUND('Смета ЕР (общ) '!$I25*'Смета ЕР (общ) '!$M25,2) -> 0
A26: Р1 | B26: 1 | D26: 9 | E26: =CONCATENATE('Смета ЕР (общ) '!$A26,".",'Смета ЕР (общ) '!$B26,".",'Смета ЕР (общ) '!$D26) -> Р1.1.9 | F26: =IF(I26>0,F25+1,F25) -> 1 | G26: Рабочая документация Системы автоматической установки водяного пожаротушения ("АУВПТ"), (спринкерная, дренчерная, модульная система), включая пояснительную записку (для помещений от 100 до 450 м.кв) | H26: м2 | J26: ='Проектирование 100-450'!E25*1.05 -> 91.6755 | K26: 0 | L26: =ROUND(J26-J26*$Q$3,2) -> 91.68 | M26: =ROUND(K26-K26*$Q$3,2) -> 0 | N26: =ROUND('Смета ЕР (общ) '!$I26*'Смета ЕР (общ) '!$L26,2) -> 0 | O26: =ROUND('Смета ЕР (общ) '!$I26*'Смета ЕР (общ) '!$M26,2) -> 0
A27: Р1 | B27: 1 | D27: 43 | E27: =CONCATENATE('Смета ЕР (общ) '!$A27,".",'Смета ЕР (общ) '!$B27,".",'Смета ЕР (общ) '!$D27) -> Р1.1.43 | F27: =IF(I27>0,F26+1,F26) -> 1 | G27: Рабочая документация Системы Внутреннего противопожарного водопровода ("ВПВ"), включая пояснительную записку (для помещений от 100 до 450 м.кв) | H27: м2 | J27: ='Проектирование 100-450'!E26*1.05 -> 91.6755 | K27: 0 | L27: =ROUND(J27-J27*$Q$3,2) -> 91.68 | M27: =ROUND(K27-K27*$Q$3,2) -> 0 | N27: =ROUND('Смета ЕР (общ) '!$I27*'Смета ЕР (общ) '!$L27,2) -> 0 | O27: =ROUND('Смета ЕР (общ) '!$I27*'Смета ЕР (общ) '!$M27,2) -> 0
A28: Р1 | B28: 1 | D28: 10 | E28: =CONCATENATE('Смета ЕР (общ) '!$A28,".",'Смета ЕР (общ) '!$B28,".",'Смета ЕР (общ) '!$D28) -> Р1.1.10 | F28: =IF(I28>0,F27+1,F27) -> 1 | G28: Рабочая документация Системы дымоудаления ("ДУ"), включая пояснительную записку (для помещений от 100 до 450 м.кв) | H28: м2 | J28: ='Проектирование 100-450'!E27*1.05 -> 103.95 | K28: 0 | L28: =ROUND(J28-J28*$Q$3,2) -> 103.95 | M28: =ROUND(K28-K28*$Q$3,2) -> 0 | N28: =ROUND('Смета ЕР (общ) '!$I28*'Смета ЕР (общ) '!$L28,2) -> 0 | O28: =ROUND('Смета ЕР (общ) '!$I28*'Смета ЕР (общ) '!$M28,2) -> 0
A29: Р1 | B29: 1 | D29: 11 | E29: =CONCATENATE('Смета ЕР (общ) '!$A29,".",'Смета ЕР (общ) '!$B29,".",'Смета ЕР (общ) '!$D29) -> Р1.1.11 | F29: =IF(I29>0,F28+1,F28) -> 1 | G29: Рабочая документация "Автоматическая пожарная сигнализация" (АПС) | H29: м2 | J29: ='АПС, СОУЭ, ППА'!F13*1.05*0.1 -> 7.035 | K29: 0 | L29: =ROUND(J29-J29*$Q$3,2) -> 7.04 | M29: =ROUND(K29-K29*$Q$3,2) -> 0 | N29: =ROUND('Смета ЕР (общ) '!$I29*'Смета ЕР (общ) '!$L29,2) -> 0 | O29: =ROUND('Смета ЕР (общ) '!$I29*'Смета ЕР (общ) '!$M29,2) -> 0 | P29: см. лист "АПС, СОУЭ, ППА"
A30: Р1 | B30: 1 | D30: 25 | E30: =CONCATENATE('Смета ЕР (общ) '!$A30,".",'Смета ЕР (общ) '!$B30,".",'Смета ЕР (общ) '!$D30) -> Р1.1.25 | F30: =IF(I30>0,F29+1,F29) -> 1 | G30: Рабочая документация "Система оповещения и управления эвакуацией людей при пожаре" (СОУЭ) | H30: м2 | J30: ='АПС, СОУЭ, ППА'!F14*1.05*0.1 -> 4.095 | K30: 0 | L30: =ROUND(J30-J30*$Q$3,2) -> 4.1 | M30: =ROUND(K30-K30*$Q$3,2) -> 0 | N30: =ROUND('Смета ЕР (общ) '!$I30*'Смета ЕР (общ) '!$L30,2) -> 0 | O30: =ROUND('Смета ЕР (общ) '!$I30*'Смета ЕР (общ) '!$M30,2) -> 0 | P30: см. лист "АПС, СОУЭ, ППА"
A31: Р1 | B31: 1 | D31: 26 | E31: =CONCATENATE('Смета ЕР (общ) '!$A31,".",'Смета ЕР (общ) '!$B31,".",'Смета ЕР (общ) '!$D31) -> Р1.1.26 | F31: =IF(I31>0,F30+1,F30) -> 1 | G31: Рабочая документация "Автоматизация системы внутреннего противопожарного водопровода (ВПВ) | H31: м2 | J31: ='АПС, СОУЭ, ППА'!F16*1.05*0.1 -> 0.84 | K31: 0 | L31: =ROUND(J31-J31*$Q$3,2) -> 0.84 | M31: =ROUND(K31-K31*$Q$3,2) -> 0 | N31: =ROUND('Смета ЕР (общ) '!$I31*'Смета ЕР (общ) '!$L31,2) -> 0 | O31: =ROUND('Смета ЕР (общ) '!$I31*'Смета ЕР (общ) '!$M31,2) -> 0
A32: Р1 | B32: 1 | D32: 29 | E32: =CONCATENATE('Смета ЕР (общ) '!$A32,".",'Смета ЕР (общ) '!$B32,".",'Смета ЕР (общ) '!$D32) -> Р1.1.29 | F32: =IF(I32>0,F31+1,F31) -> 1 | G32: Рабочая документация "Автоматизация системы противодымной вентиляции (ПДВ")" | H32: м2 | J32: ='АПС, СОУЭ, ППА'!F17*1.05*0.1 -> 2.625 | K32: 0 | L32: =ROUND(J32-J32*$Q$3,2) -> 2.63 | M32: =ROUND(K32-K32*$Q$3,2) -> 0 | N32: =ROUND('Смета ЕР (общ) '!$I32*'Смета ЕР (общ) '!$L32,2) -> 0 | O32: =ROUND('Смета ЕР (общ) '!$I32*'Смета ЕР (общ) '!$M32,2) -> 0
A33: Р1 | B33: 1 | D33: 30 | E33: =CONCATENATE('Смета ЕР (общ) '!$A33,".",'Смета ЕР (общ) '!$B33,".",'Смета ЕР (общ) '!$D33) -> Р1.1.30 | F33: =IF(I33>0,F32+1,F32) -> 1 | G33: Рабочая документация "Автоматизация Системы отопления, вентиляции и кондиционирования (ОВиК)" | H33: м2 | J33: ='АПС, СОУЭ, ППА'!F18*1.05*0.1 -> 0.315 | K33: 0 | L33: =ROUND(J33-J33*$Q$3,2) -> 0.32 | M33: =ROUND(K33-K33*$Q$3,2) -> 0 | N33: =ROUND('Смета ЕР (общ) '!$I33*'Смета ЕР (общ) '!$L33,2) -> 0 | O33: =ROUND('Смета ЕР (общ) '!$I33*'Смета ЕР (общ) '!$M33,2) -> 0
A34: Р1 | B34: 1 | D34: 31 | E34: =CONCATENATE('Смета ЕР (общ) '!$A34,".",'Смета ЕР (общ) '!$B34,".",'Смета ЕР (общ) '!$D34) -> Р1.1.31 | F34: =IF(I34>0,F33+1,F33) -> 1 | G34: Рабочая документация "Автоматизация Системы аварийного освещения (АО)" | H34: м2 | J34: ='АПС, СОУЭ, ППА'!F19*1.05*0.1 -> 0.105 | K34: 0 | L34: =ROUND(J34-J34*$Q$3,2) -> 0.11 | M34: =ROUND(K34-K34*$Q$3,2) -> 0 | N34: =ROUND('Смета ЕР (общ) '!$I34*'Смета ЕР (общ) '!$L34,2) -> 0 | O34: =ROUND('Смета ЕР (общ) '!$I34*'Смета ЕР (общ) '!$M34,2) -> 0
A35: Р1 | B35: 1 | D35: 33 | E35: =CONCATENATE('Смета ЕР (общ) '!$A35,".",'Смета ЕР (общ) '!$B35,".",'Смета ЕР (общ) '!$D35) -> Р1.1.33 | F35: =IF(I35>0,F34+1,F34) -> 1 | G35: Рабочая документация "Автоматизации лифтовового хозяйства" | H35: м2 | J35: ='АПС, СОУЭ, ППА'!F20*1.05*0.1 -> 0.105 | K35: 0 | L35: =ROUND(J35-J35*$Q$3,2) -> 0.11 | M35: =ROUND(K35-K35*$Q$3,2) -> 0 | N35: =ROUND('Смета ЕР (общ) '!$I35*'Смета ЕР (общ) '!$L35,2) -> 0 | O35: =ROUND('Смета ЕР (общ) '!$I35*'Смета ЕР (общ) '!$M35,2) -> 0
A36: Р1 | B36: 1 | D36: 36 | E36: =CONCATENATE('Смета ЕР (общ) '!$A36,".",'Смета ЕР (общ) '!$B36,".",'Смета ЕР (общ) '!$D36) -> Р1.1.36 | F36: =IF(I36>0,F35+1,F35) -> 1 | G36: Рабочая документация "Автоматизации Системы контроля управления доступом (СКУД)" | H36: м2 | J36: ='АПС, СОУЭ, ППА'!F21*1.05*0.1 -> 0.105 | K36: 0 | L36: =ROUND(J36-J36*$Q$3,2) -> 0.11 | M36: =ROUND(K36-K36*$Q$3,2) -> 0 | N36: =ROUND('Смета ЕР (общ) '!$I36*'Смета ЕР (общ) '!$L36,2) -> 0 | O36: =ROUND('Смета ЕР (общ) '!$I36*'Смета ЕР (общ) '!$M36,2) -> 0
A37: Р1 | B37: 1 | D37: 37 | E37: =CONCATENATE('Смета ЕР (общ) '!$A37,".",'Смета ЕР (общ) '!$B37,".",'Смета ЕР (общ) '!$D37) -> Р1.1.37 | F37: =IF(I37>0,F36+1,F36) -> 1 | G37: Техническое обследование состояния несущих конструкций помещения с подготовкой рекомендаций по усилению в зоне расположения депозитария, кассового узла и банкоматов (Техничесекое заключение о конструктиве - "ТЗК")(для помещений менее 100 м.кв) | H37: м2 | J37: ='Проектирование до 100'!E35*1.05 -> 3675 | K37: 0 | L37: =ROUND(J37-J37*$Q$3,2) -> 3675 | M37: =ROUND(K37-K37*$Q$3,2) -> 0 | N37: =ROUND('Смета ЕР (общ) '!$I37*'Смета ЕР (общ) '!$L37,2) -> 0 | O37: =ROUND('Смета ЕР (общ) '!$I37*'Смета ЕР (общ) '!$M37,2) -> 0
A38: Р1 | B38: 1 | D38: 45 | E38: =CONCATENATE('Смета ЕР (общ) '!$A38,".",'Смета ЕР (общ) '!$B38,".",'Смета ЕР (общ) '!$D38) -> Р1.1.45 | F38: =IF(I38>0,F37+1,F37) -> 1 | G38: Эскизный проект фасада и колористический паспорт с указанием ведомости отделки и проектным решением со спецификацией элементов (крыльцо, пандус, навесы, колонны и т.д.)(для фасадов менее 100 м.кв) | H38: кв.м.площади фасада | J38: ='Проектирование до 100'!E36*1.05 -> 7822.5 | K38: 0 | L38: =ROUND(J38-J38*$Q$3,2) -> 7822.5 | M38: =ROUND(K38-K38*$Q$3,2) -> 0 | N38: =ROUND('Смета ЕР (общ) '!$I38*'Смета ЕР (общ) '!$L38,2) -> 0 | O38: =ROUND('Смета ЕР (общ) '!$I38*'Смета ЕР (общ) '!$M38,2) -> 0
A39: Р1 | B39: 1 | D39: 46 | E39: =CONCATENATE('Смета ЕР (общ) '!$A39,".",'Смета ЕР (общ) '!$B39,".",'Смета ЕР (общ) '!$D39) -> Р1.1.46 | F39: =IF(I39>0,F38+1,F38) -> 1 | G39: Рабочая документация по усилению/устройству несущих конструкций ("КР"), включая пояснительную записку (для помещений менее 100 м.кв) | H39: компл. | J39: ='Проектирование до 100'!E17*1.05 -> 10500 | K39: 0 | L39: =ROUND(J39-J39*$Q$3,2) -> 10500 | M39: =ROUND(K39-K39*$Q$3,2) -> 0 | N39: =ROUND('Смета ЕР (общ) '!$I39*'Смета ЕР (общ) '!$L39,2) -> 0 | O39: =ROUND('Смета ЕР (общ) '!$I39*'Смета ЕР (общ) '!$M39,2) -> 0
A40: Р1 | B40: 1 | D40: 47 | E40: =CONCATENATE('Смета ЕР (общ) '!$A40,".",'Смета ЕР (общ) '!$B40,".",'Смета ЕР (общ) '!$D40) -> Р1.1.47 | F40: =IF(I40>0,F39+1,F39) -> 1 | G40: Рабочая документация "Архитектурные решения" ("АР"), включая пояснительную записку (для помещений менее 100 м.кв) | H40: компл. | J40: ='Проектирование до 100'!E18*1.05 -> 20737.5 | K40: 0 | L40: =ROUND(J40-J40*$Q$3,2) -> 20737.5 | M40: =ROUND(K40-K40*$Q$3,2) -> 0 | N40: =ROUND('Смета ЕР (общ) '!$I40*'Смета ЕР (общ) '!$L40,2) -> 0 | O40: =ROUND('Смета ЕР (общ) '!$I40*'Смета ЕР (общ) '!$M40,2) -> 0
A41: Р1 | B41: 1 | D41: 48 | E41: =CONCATENATE('Смета ЕР (общ) '!$A41,".",'Смета ЕР (общ) '!$B41,".",'Смета ЕР (общ) '!$D41) -> Р1.1.48 | F41: =IF(I41>0,F40+1,F40) -> 1 | G41: Рабочая документация по электроснабжению и электроосвещению ("ЭОМ"), включая пояснительную записку (для помещений менее 100 м.кв) | H41: компл. | J41: ='Проектирование до 100'!E19*1.05 -> 20737.5 | K41: 0 | L41: =ROUND(J41-J41*$Q$3,2) -> 20737.5 | M41: =ROUND(K41-K41*$Q$3,2) -> 0 | N41: =ROUND('Смета ЕР (общ) '!$I41*'Смета ЕР (общ) '!$L41,2) -> 0 | O41: =ROUND('Смета ЕР (общ) '!$I41*'Смета ЕР (общ) '!$M41,2) -> 0
A42: Р1 | B42: 1 | D42: 49 | E42: =CONCATENATE('Смета ЕР (общ) '!$A42,".",'Смета ЕР (общ) '!$B42,".",'Смета ЕР (общ) '!$D42) -> Р1.1.49 | F42: =IF(I42>0,F41+1,F41) -> 1 | G42: Рабочая документация Системы вентиляции ("ОВиК-В"), включая пояснительную записку (для помещений менее 100 м.кв) | H42: компл. | J42: ='Проектирование до 100'!E20*1.05 -> 15592.5 | K42: 0 | L42: =ROUND(J42-J42*$Q$3,2) -> 15592.5 | M42: =ROUND(K42-K42*$Q$3,2) -> 0 | N42: =ROUND('Смета ЕР (общ) '!$I42*'Смета ЕР (общ) '!$L42,2) -> 0 | O42: =ROUND('Смета ЕР (общ) '!$I42*'Смета ЕР (общ) '!$M42,2) -> 0
...

Sheet ЭУИ
C2: Электроустановочные изделия | D2: Ед.изм. | E2: Цена для подрядчика | F2: Цена для Заказчика
C3: ВЫКЛЮЧАТЕЛЬ ОДНОКЛАВИШНЫЙ, серия - ETIKA, цвет черный Антрацит | D3: шт. | E3: 167.03 | F3: =ROUND(E3*1.05,2)+H8 -> 175.38
C4: ВЫКЛЮЧАТЕЛЬ ДВУХКЛАВИШНЫЙ, серия - ETIKA, цвет черный Антрацит | D4: шт. | E4: 248.09 | F4: =ROUND(E4*1.05,2)+H9 -> 260.49
C5: ПЕРЕКЛЮЧАТЕЛЬ ОДНОКЛАВИШНЫЙ, серия - ETIKA, цвет черный Антрацит | D5: шт. | E5: 253.16 | F5: =ROUND(E5*1.05,2)+H10 -> 346.84333
C6: ПЕРЕКЛЮЧАТЕЛЬ ДВУХКЛАВИШНЫЙ, серия - ETIKA, цвет черный Антрацит | D6: шт. | E6: 468.36 | F6: =ROUND(E6*1.05,2)+H10 -> 572.80333
C7: Рамка 1 пост, цвет - черный | D7: шт. | E7: 69.39 | F7: =ROUND(E7*1.05,2) -> 72.86 | G7: =F7 -> 72.86
C8: Рамка 2 поста, цвет - черный | D8: шт. | E8: 132.61 | F8: =ROUND(E8*1.05,2) -> 139.24 | G8: =F8/2 -> 69.62
C9: Рамка 3 поста, цвет -черный | D9: шт. | E9: 202.03 | F9: =ROUND(E9*1.05,2) -> 212.13 | G9: =F9/3 -> 70.71
C10: Рамка 4 поста, цвет - черный | D10: шт. | E10: 310.6 | F10: =ROUND(E10*1.05,2) -> 326.13 | G10: =SUM(G7:G9)/3 -> 71.063333 | H10: =G10+F17 -> 81.023333
C11: Рамка 5 постов, цвет - черный | D11: шт. | E11: 412.62 | F11: =ROUND(E11*1.05,2) -> 433.25
C12: Розетка 1-местная с заземлением с защитными шторками 16А антрацит ETIKA | D12: шт. | E12: 228.6 | F12: =ROUND(E12*1.05,2)+H10 -> 321.05333
C13: РКС-20-32-П-К Розетка с з/к 2к (на 2 модуля) ПРАЙМЕР красная IEK | D13: шт. | E13: 283.49 | F13: =ROUND(E13*1.05,2)+H10 -> 378.68333
C14: РКС-20-30-П-К Розетка с з/к 2к (на 2 модуля) ПРАЙМЕР белая IEK | D14: шт. | E14: 283.49 | F14: =ROUND(E14*1.05,2)+H10 -> 378.68333
C15: РКС-20-32-П-К Розетка с з/к 2к (на 2 модуля) ПРАЙМЕР красная IEK (для лючка) | D15: шт. | E15: 283.49 | F15: =ROUND(E15*1.05,2) -> 297.66
C16: РКС-20-30-П-К Розетка с з/к 2к (на 2 модуля) ПРАЙМЕР белая IEK (для лючка) | D16: шт. | E16: 283.49 | F16: =ROUND(E16*1.05,2) -> 297.66
C17: Коробка установочная СЗ для твердых стен D=68х45мм GENERICA | D17: шт. | E17: 9.49 | F17: =ROUND(E17*1.05,2) -> 9.96
C18: Штепсельная розетка с заземлением в стену, 2P+E, с з/ш, "Avanti", "Белое облако" (арт. 4400003), с суппоротом и рамкой | D18: шт. | E18: 408.33 | F18: =ROUND(E18*1.05,2)+G26 -> 506.89333
C19: Штепсельная розетка с заземлением в стену, 2P+E, с з/ш, "Avanti", "Красный квадрат" (арт. 4401003), с суппортом и рамкой | D19: шт. | E19: 551.22 | F19: =ROUND(E19*1.05,2)+G26 -> 656.92333
C20: Розетка модульная, 2P+E, с з/ш, "Avanti", "Белое облако", 2 модуля 4400002 | D20: шт. | E20: 195.73 | F20: =ROUND(E20*1.05,2) -> 205.52
C21: Розетка модульная, 2P+E, с з/ш, "Avanti", "Красный квадрат", 2 модуля 4401002 | D21: шт. | E21: 264.24 | F21: =ROUND(E21*1.05,2) -> 277.45
C22: Рамка "Avanti", "Белое облако", 1 пост (2 мод.) 4400902 | D22: шт. | E22: 63.38 | F22: =ROUND(E22*1.05,2) -> 66.55 | G22: =F22 -> 66.55
C23: Рамка "Avanti", "Белое облако", 2 поста (4 мод.) 4400904 | D23: шт. | E23: 140.82 | F23: =ROUND(E23*1.05,2) -> 147.86 | G23: =F23/2 -> 73.93
C24: Рамка "Avanti", "Белое облако", 3 поста (6 мод.) 4400906 | D24: шт. | E24: 183.06 | F24: =ROUND(E24*1.05,2) -> 192.21 | G24: =F24/3 -> 64.07
C25: Рамка "Avanti", "Белое облако", 4 поста (8 мод.) 4400908 | D25: шт. | E25: 309.77 | F25: =ROUND(E25*1.05,2) -> 325.26 | G25: =(SUM(G22:G24))/3 -> 68.183333
C26: Выключатель одноклавишный в стену, "Avanti", "Белое облако" 4400103 | D26: шт. | E26: 422.39 | F26: =ROUND(E26*1.05,2)+G26 -> 521.65333 | G26: =G25+F17 -> 78.143333
C27: Выключатель двухклавишный в стену, "Avanti", "Белое облако" 4400104 | D27: шт. | E27: 563.18 | F27: =ROUND(E27*1.05,2)+G26 -> 669.48333
L32: www.etm.ru
E34: Коммерческое предложение / Спецификация № | F34: 973/30916552 | I34: от | J34: 24.07.2026
D35: АО ''АЛЬФА-БАНК''
A36: Представляем Вашему вниманию цены на продукцию, которая может быть Вам интересна:
A37: Примечание:
A38: N | B38: Код товара | C38: Имя товара | D38: Производитель | E38: Артикул | F38: Кол-во | G38: Ед.изм. | H38: Цена без НДС | I38: Цена с НДС | J38: Сумма без НДС | K38: Сумма с НДС
A39: 1 | B39: 4977704 | C39: Выключатель 1-клавишный 10А безвинтовое крепление антрацит ETIKA | D39: IEK | E39: 672601 | F39: 800 | G39: шт | H39: 136.91 | I39: 167.03 | J39: 109528 | K39: 133624.16
A40: 2 | B40: 5915539 | C40: Выключатель 2-клавишный 10А безвинтовое крепление антрацит ETIKA | D40: IEK | E40: 672602 | F40: 500 | G40: шт | H40: 203.35 | I40: 248.09 | J40: 101675 | K40: 124043.5
A41: 3 | B41: 4981597 | C41: Выключатель 1-клавишный проходной 10А безвинтовое крепление антрацит ETIKA | D41: IEK | E41: 672605 | F41: 300 | G41: шт | H41: 207.51 | I41: 253.16 | J41: 62253 | K41: 75948.66
A42: 4 | B42: 6617473 | C42: Выключатель 2-клавишный проходной 10А безвинтовое крепление антрацит ETIKA | D42: IEK | E42: 672612 | F42: 100 | G42: шт | H42: 383.9 | I42: 468.36 | J42: 38390 | K42: 46835.8
A43: 5 | B43: 5971424 | C43: Рамка 1-местная антрацит ETIKA | D43: IEK | E43: 672581 | F43: 2000 | G43: шт | H43: 56.88 | I43: 69.39 | J43: 113760 | K43: 138787.2
A44: 6 | B44: 4651309 | C44: Рамка 2-местная антрацит ETIKA | D44: IEK | E44: 672582 | F44: 2000 | G44: шт | H44: 108.7 | I44: 132.61 | J44: 217400 | K44: 265228
A45: 7 | B45: 2160796 | C45: Рамка 3-местная антрацит ETIKA | D45: IEK | E45: 672583 | F45: 1000 | G45: шт | H45: 165.6 | I45: 202.03 | J45: 165600 | K45: 202032
A46: 8 | B46: 7834922 | C46: Рамка 4-местная антрацит ETIKA | D46: IEK | E46: 672584 | F46: 1000 | G46: шт | H46: 254.59 | I46: 310.6 | J46: 254590 | K46: 310599.8
...

Sheet Радиаторы
C1: Адрес Склада: | N1: 111672, Москва г, Суздальская ул, дом № 46
C2: Время работы Центрального Офиса:
C3: Время работы Склада: | N3: Пн-Чт 10:30–19:00, Пт 10:30-17:00 (Обмен и Возврат товара с 13 до 17 часов)
C5: Менеджер: | H5: Савелов Андрей | N5: +7 (495) 258-93-88, доб.212 моб. +7 (926) 716-43-58, sam@teplonet.ru | AM5: www.teplonet.ru
C6: Выписал счет: | H6: Савелов Андрей | N6: +7 (495) 258-93-88, доб.212 моб. +7 (926) 716-43-58, sam@teplonet.ru
C12: Филиал "Корпоративный" ПАО "Совкомбанк" г. Москва | U12: БИК | X12: 044525360
U13: Сч. № | X13: 30101810445250000360
C14: Банк получателя
C15: ИНН | E15: 7720712565 | L15: КПП | N15: 772001001 | U15: Сч. № | X15: 40702810500140620906
C16: ООО "ТМ Инвест" | U16: Вид оп. | X16: 01 | AA16: Срок плат.
U17: Наз. пл. | AA17: Очер. плат. | AE17: 5
U18: Код | X18: ЗК2603ТМ000070570007 | AA18: Рез. поле
C19: Получатель
C20: Оплата по заказу клиента №7057
C22: Назначение платежа | AM22: Оплатите, отсканировав код в платежном терминале или передав сотруднику банка
C24: Цена МРЦ
C26: Поставщик: | G26: ООО "ТМ Инвест", ИНН 7720712565, КПП 772001001, 111672, г. Москва, ул. Суздальская, дом № 46, тел.: (495) 545-05-40
C28: Покупатель:
C30: № | E30: Артикул | H30: Товары (работы, услуги) | U30: Количество | Z30: Цена с НДС | AD30: Ставка НДС | AL30: Сумма НДС | AT30: Сумма | BC30: Цена с НДС для Банка
C32: 1 | E32: R-BA-200-10 | H32: Радиатор биметаллический RIFAR BASE 200 10 секц. бок. | U32: 1 | W32: шт | Z32: 9250 | AD32: 22 | AL32: 1668.03 | AT32: 9250 | BC32: =ROUNDUP(Z32*1.05,2) -> 9712.5
C33: 2 | E33: R-BA-350-10 | H33: Радиатор биметаллический RIFAR BASE 350 10 секц. бок. | U33: 1 | W33: шт | Z33: 9460 | AD33: 22 | AL33: 1705.9 | AT33: 9460 | BC33: =ROUNDUP(Z33*1.05,2) -> 9933
C34: 3 | E34: R-BA-500-10 | H34: Радиатор биметаллический RIFAR BASE 500 10 секц. бок. | U34: 1 | W34: шт | Z34: 9660 | AD34: 22 | AL34: 1741.97 | AT34: 9660 | BC34: =ROUNDUP(Z34*1.05,2) -> 10143
C35: 4 | E35: R-EB-300-10 | H35: Радиатор биметаллический RIFAR ECOBUILD 300 10 секц. бок. | U35: 1 | W35: шт | Z35: 9460 | AD35: 22 | AL35: 1705.9 | AT35: 9460 | BC35: =ROUNDUP(Z35*1.05,2) -> 9933
C36: 5 | E36: R-EB-500-10 | H36: Радиатор биметаллический RIFAR ECOBUILD 500 10 секц. бок. | U36: 1 | W36: шт | Z36: 9660 | AD36: 22 | AL36: 1741.97 | AT36: 9660 | BC36: =ROUNDUP(Z36*1.05,2) -> 10143
C37: 6 | E37: R-MN-300-10 | H37: Радиатор биметаллический RIFAR MONOLIT 300 10 секц. бок. | U37: 1 | W37: шт | Z37: 10570 | AD37: 22 | AL37: 1906.07 | AT37: 10570 | BC37: =ROUNDUP(Z37*1.05,2) -> 11098.5
C38: 7 | E38: R-MN-350-10 | H38: Радиатор биметаллический RIFAR MONOLIT 350 10 секц. бок. | U38: 1 | W38: шт | Z38: 10780 | AD38: 22 | AL38: 1943.93 | AT38: 10780 | BC38: =ROUNDUP(Z38*1.05,2) -> 11319
C39: 8 | E39: R-MN-500-10 | H39: Радиатор биметаллический RIFAR MONOLIT 500 10 секц. бок. | U39: 1 | W39: шт | Z39: 10980 | AD39: 22 | AL39: 1980 | AT39: 10980 | BC39: =ROUNDUP(Z39*1.05,2) -> 11529
C40: 9 | E40: R-SU-350-10 | H40: Радиатор биметаллический RIFAR SUPReMO 350 10 секц. бок. | U40: 1 | W40: шт | Z40: 13420 | AD40: 22 | AL40: 2420 | AT40: 13420 | BC40: =ROUNDUP(Z40*1.05,2) -> 14091
C41: 10 | E41: R-SU-500-10 | H41: Радиатор биметаллический RIFAR SUPReMO 500 10 секц. бок. | U41: 1 | W41: шт | Z41: 13620 | AD41: 22 | AL41: 2456.07 | AT41: 13620 | BC41: =ROUNDUP(Z41*1.05,2) -> 14301
C42: 11 | E42: R-SU-800-10 | H42: Радиатор биметаллический RIFAR SUPReMO 800 10 секц. бок. | U42: 1 | W42: шт | Z42: 22370 | AD42: 22 | AL42: 4033.93 | AT42: 22370 | BC42: =ROUNDUP(Z42*1.05,2) -> 23488.5
C43: 12 | E43: TUB 2057-10 | H43: Радиатор трубчатый RIFAR TUBOG 2057 10 секц. бок. | U43: 1 | W43: шт | Z43: 12830.5 | AD43: 22 | AL43: 2313.7 | AT43: 12830.5 | BC43: =ROUNDUP(Z43*1.05,2) -> 13472.03
... C46: 15 | E46: R-BA-200-04-VR | H46: Радиатор биметаллический RIFAR BASE Ventil 200 04 секц. нижн. прав. | U46: 1 | W46: шт | Z46: 5459 | AD46: 22 | AL46: 984.41 | AT46: 5459 | BC46: =ROUNDUP(Z46*1.05,2) -> 5731.95
C47: № | E47: Артикул | H47: Товары (работы, услуги) | U47: Количество | Z47: Цена с НДС | AD47: Ставка НДС | AL47: Сумма НДС | AT47: Сумма | BC47: Цена с НДС для Банка
C49: 16 | E49: R-BA-200-05-VR | H49: Радиатор биметаллический RIFAR BASE Ventil 200 05 секц. нижн. прав. | U49: 2 | W49: шт | Z49: 6384 | AD49: 22 | AL49: 2302.43 | AT49: 12768 | BC49: =ROUNDUP(Z49*1.05,2) -> 6703.2
C50: 17 | E50: R-BA-200-07-VR | H50: Радиатор биметаллический RIFAR BASE Ventil 200 07 секц. нижн. прав. | U50: 1 | W50: шт | Z50: 8234 | AD50: 22 | AL50: 1484.82 | AT50: 8234 | BC50: =ROUNDUP(Z50*1.05,2) -> 8645.7
C51: 18 | E51: R-BA-200-08-VR | H51: Радиатор биметаллический RIFAR BASE Ventil 200 08 секц. нижн. прав. | U51: 1 | W51: шт | Z51: 9159 | AD51: 22 | AL51: 1651.62 | AT51: 9159 | BC51: =ROUNDUP(Z51*1.05,2) -> 9616.95
C52: 19 | E52: R-BA-200-10-VR | H52: Радиатор биметаллический RIFAR BASE Ventil 200 10 секц. нижн. прав. | U52: 1 | W52: шт | Z52: 11009 | AD52: 22 | AL52: 1985.23 | AT52: 11009 | BC52: =ROUNDUP(Z52*1.05,2) -> 11559.45
C53: 20 | E53: R-BA-200-11-VR | H53: Радиатор биметаллический RIFAR BASE Ventil 200 11 секц. нижн. прав. | U53: 1 | W53: шт | Z53: 11934 | AD53: 22 | AL53: 2152.03 | AT53: 11934 | BC53: =ROUNDUP(Z53*1.05,2) -> 12530.7
C54: 21 | E54: R-BA-200-12-VR | H54: Радиатор биметаллический RIFAR BASE Ventil 200 12 секц. нижн. прав. | U54: 1 | W54: шт | Z54: 12859 | AD54: 22 | AL54: 2318.84 | AT54: 12859 | BC54: =ROUNDUP(Z54*1.05,2) -> 13501.95
C55: 22 | E55: R-BA-200-13-VR | H55: Радиатор биметаллический RIFAR BASE Ventil 200 13 секц. нижн. прав. | U55: 1 | W55: шт | Z55: 13784 | AD55: 22 | AL55: 2485.64 | AT55: 13784 | BC55: =ROUNDUP(Z55*1.05,2) -> 14473.2
...

Sheet Стекл двери в алюм. (2)
A1: Наименование компании | B1: ООО "ФАСАДСТРОЙ"
A2: контактная информация | B2: 398050,г.Липецк, ул.Ленина 11/2 , оф.408
A3: эл.почта | B3: svetlanal80@mail.ru
A4: тел | B4: 79155597559 | F4: 46246
A5: Двери входные | B5: Ед. изм. | C5: Цена (руб./ед.) | D5: Цена для Альфа-Банка
A6: однопольный дверной блок (алюминиевый теплый профиль 3 петли, два врезных замка цилиндрического типа, имеющих с внутренней стороны запорные устройства типа «вертушок» (количество ключей не менее 4 шт.) без защелки , ручка из нержавеющей стали типа «труба» со смещением креплений диаметром 32 мм, длиной 1000 мм, цвет «хром». Размер "в свету" 900*2100. однокамерный стеклопакет. | B6: шт. | C6: 55730 | D6: =ROUNDUP(C6*1.05,2) -> 58516.5
A7: полуторапольный дверной блок (алюминиевый теплый профиль 3 петли, два врезных замка цилиндрического типа, имеющих с внутренней стороны запорные устройства типа «вертушок» (количество ключей не менее 4 шт.) без защелки , ручка из нержавеющей стали типа «труба» со смещением креплений диаметром 32 мм, длиной 1000 мм, цвет «хром». Размер "в свету" 1200*2100. однокамерный стеклопакет, | B7: шт. | C7: 83772 | D7: =ROUNDUP(C7*1.05,2) -> 87960.6
A8: двупольноый дверной блок (алюминиевый теплый профиль 3 петли, два врезных замка цилиндрического типа, имеющих с внутренней стороны запорные устройства типа «вертушок» без защелки , ручка из нержавеющей стали типа «труба» со смещением креплений диаметром 32 мм, длиной 1000 мм, цвет «хром»). Размер "в свету" 1800*2100.однокамерный стеклопакет стекла закаленные и/или трипликс 6 мм | B8: шт. | C8: 96100 | D8: =ROUNDUP(C8*1.05,2) -> 100905
A9: Установка дверного доводчика штанга рычажная на входные двери (210 кг) | B9: шт. | C9: 5500 | D9: =ROUNDUP(C9*1.05,2) -> 5775
A10: Двери стеклянные в алюминиевом профиле внутренние
A11: однопольный дверной блок в алюминиевом корпусе. Размер в "свету" 900х2100 мм. Два врезных замка цилиндрического типа, имеющих с внутренней стороны запорные устройства типа «вертушок» (количество ключей не менее 4 шт.). Ручка из нержавеющей стали типа «труба» со смещением креплений диаметром 32 мм, длиной 1000 мм, цвет «хром»). Однокамерный стеклопакет, стекла закаленные 8 мм /или трипликс | B11: шт. | C11: 44790 | D11: =ROUNDUP(C11*1.05,2) -> 47029.5
A12: полуторапольный дверной блок в алюминиевом корпусе.Размер в "свету" 1200х2100 мм . Два врезных замка цилиндрического типа, имеющих с внутренней стороны запорные устройства типа «вертушок» (количество ключей не менее 4 шт.) Ручка из нержавеющей стали типа «труба» со смещением креплений диаметром 32 мм, длиной 1000 мм, цвет «хром»). Однокамерный стеклопакет, стекла закаленные 8 мм /или трипликс | B12: шт. | C12: 65100 | D12: =ROUNDUP(C12*1.05,2) -> 68355
A13: двупольный дверной блок в алюминиевом корпусе.Размер в "свету" 1800х2100 мм . Два врезных замка цилиндрического типа, имеющих с внутренней стороны запорные устройства типа «вертушок» (количество ключей не менее 4 шт.) Ручка из нержавеющей стали типа «труба» со смещением креплений диаметром 32 мм, длиной 1000 мм, цвет «хром»). Однокамерный стеклопакет, стекла закаленные 8 мм /или трипликс | B13: шт. | C13: 75900 | D13: =ROUNDUP(C13*1.05,2) -> 79695

Sheet Проектирование до 100
B2: Диапазон площади проекта, S | C2: кв.м. | D2: 0 < S <100
B3: Количество проектов в данном диапазоне | C3: шт. | D3: =[15]Объекты!C48 -> 17
B4: Общая площадь проектирования в данном диапазоне | C4: кв.м. | D4: =[15]Объекты!B48 -> 890
B5: Средняя площадь проекта | C5: кв.м. | D5: =ROUND(D4/D3,0) -> 52
B6: Средний срок Авторского надзора при РСР | C6: месяц | D6: 1
B7: Доля авторского надзора в стоимости основных проектных работ | D7: 0.3
B8: Стоимость основных проектных работ по КП | C8: руб. | G8: =SUM(G17:G26)*D3 -> 1590435
B9: Стоимость авторского надзора | C9: руб. | G9: =G27*D3 -> 681615
B10: Стоимость опциональных проектных работ по КП | C10: руб. | G10: =G34*D32 -> 76650
B11: ВСЕГО стоимость по КП | C11: руб. | G11: =G8+G9+G10 -> 2348700
B13: ОСНОВНЫЕ ПРОЕКТНЫЕ РАБОТЫ
A14: № | B14: Наименование работ и затрат | C14: Един. изм. | D14: Кол - во. (объем) | E14: Цена работ с АН, руб., в т.ч. НДС | F14: Цена работ без АН, руб., в т.ч. НДС | G14: Стоимость работ, руб., в т.ч. НДС | H14: Стоимость материалов и оборудования руб., в т.ч. НДС | K14: ПОДРЯДЧИК: | L14: ООО "ЛИБГОТ"
B15: Раздел №1. Проектные работы и согласования | D15: =D16 -> 9 | G15: =ROUND(G16,2) -> 133650 | K15: Юридический адрес: | L15: 115114, г. Москва, вн.тер.г. муниципальный округ Замоскворечье, ул. Летниковская, д. 10, стр. 2, помещ. 18/10
B16: Проектные работы и согласования | D16: =SUM(D17:D25) -> 9 | G16: =SUM(G17:G27) -> 133650 | K16: Электронный адрес: | L16: libgotstroy@mail.ru
A17: 1 | B17: Рабочая документация по усилению/устройству несущих конструкций ("КР"), включая пояснительную записку (для помещений менее 100 м.кв) | C17: компл. | D17: 1 | E17: 10000 | F17: =E17*(1-$D$7) -> 7000 | G17: =D17*F17 -> 7000 | K17: Контактное лицо (Ф.И.О.) : | L17: Либгот Андрей Дмитриевич
A18: 2 | B18: Рабочая документация "Архитектурные решения" ("АР"), включая пояснительную записку (для помещений менее 100 м.кв) | C18: компл. | D18: 1 | E18: 19750 | F18: =E18*(1-$D$7) -> 13825 | G18: =D18*F18 -> 13825 | K18: Контактный телефон: | L18: 8-977-330-33-10
A19: 3 | B19: Рабочая документация по электроснабжению и электроосвещению ("ЭОМ"), включая пояснительную записку (для помещений менее 100 м.кв) | C19: компл. | D19: 1 | E19: 19750 | F19: =E19*(1-$D$7) -> 13825 | G19: =D19*F19 -> 13825 | K19: Реквизиты: | L19: ИНН 9705229621, КПП 770501001, ОГРН 1247700560238
A20: 4 | B20: Рабочая документация Системы вентиляции ("ОВиК-В"), включая пояснительную записку (для помещений менее 100 м.кв) | C20: компл. | D20: 1 | E20: 14850 | F20: =E20*(1-$D$7) -> 10395 | G20: =D20*F20 -> 10395
A21: 5 | B21: Рабочая документация Системы кондиционирования ("ОВиК-К"), включая пояснительную записку (для помещений менее 100 м.кв) | C21: компл. | D21: 1 | E21: 9900 | F21: =E21*(1-$D$7) -> 6930 | G21: =D21*F21 -> 6930
A22: 6 | B22: Рабочая документация Системы отопления ("ОВиК-О"), включая Пояснительную записку и Теплотехнический расчет (для помещений менее 100 м.кв) | C22: компл. | D22: 1 | E22: 9900 | F22: =E22*(1-$D$7) -> 6930 | G22: =D22*F22 -> 6930
A23: 7 | B23: Рабочая документация Системы водоснабжения и канализации ("ВК"), включая пояснительную записку (для помещений менее 100 м.кв) | C23: компл. | D23: 1 | E23: 9900 | F23: =E23*(1-$D$7) -> 6930 | G23: =D23*F23 -> 6930
A24: 8 | B24: Рабочая документация Системы автоматической установки водяного пожаротушения ("АУВПТ"), (спринкерная, дренчерная, модульная система), включая пояснительную записку (для помещений менее 100 м.кв) | C24: компл. | D24: 1 | E24: 14850 | F24: =E24*(1-$D$7) -> 10395 | G24: =D24*F24 -> 10395
A25: 9 | B25: Рабочая документация Системы Внутреннего противопожарного водопровода ("ВПВ"), включая пояснительную записку (для помещений менее 100 м.кв) | C25: компл. | D25: 1 | E25: 9900 | F25: =E25*(1-$D$7) -> 6930 | G25: =D25*F25 -> 6930
A26: 10 | B26: Рабочая документация Системы дымоудаления ("ДУ"), включая пояснительную записку (для помещений менее 100 м.кв) | C26: компл. | D26: 1 | E26: 14850 | F26: =E26*(1-$D$7) -> 10395 | G26: =D26*F26 -> 10395
A27: 11 | B27: Авторский надзор (без учета услуги по выездам представителя Подрядчика на Объект) | C27: месяц | D27: =D6 -> 1 | E27: =SUMPRODUCT(D17:D26,E17:E26)*D7/D27 -> 40095 | F27: 0 | G27: =D27*E27 -> 40095
B30: ОПЦИОНАЛЬНЫЕ ПРОЕКТНЫЕ РАБОТЫ
B31: =B5 -> Средняя площадь проекта | C31: кв.м. | D31: =ROUND(D5/10,0) -> 5
B32: =B3 -> Количество проектов в данном диапазоне | C32: шт. | D32: =ROUND(D3/10,0) -> 2
B33: =B4 -> Общая площадь проектирования в данном диапазоне | C33: кв.м. | D33: =D31*D32 -> 10
B34: Проектные работы и согласования | D34: =SUM(D35:D41) -> 10 | G34: =SUM(G35:G36) -> 38325
A35: 1 | B35: Техническое обследование состояния несущих конструкций помещения с подготовкой рекомендаций по усилению в зоне расположения депозитария, кассового узла и банкоматов (Техничесекое заключение о конструктиве - "ТЗК")(для помещений менее 100 м.кв) | C35: кв.м. | D35: =D31 -> 5 | E35: 3500 | F35: =E35*(1-$D$7) -> 2450 | G35: =D35*F35 -> 12250
A36: 2 | B36: Эскизный проект фасада и колористический паспорт с указанием ведомости отделки и проектным решением со спецификацией элементов (крыльцо, пандус, навесы, колонны и т.д.)(для фасадов менее 100 м.кв) | C36: кв.м.площади фасада | D36: =D31 -> 5 | E36: 7450 | F36: =E36*(1-$D$7) -> 5215 | G36: =D36*F36 -> 26075
B40: Примечание: Услуги по выездам представителя Подрядчика на Объект в цену Работ не включены и оплачиваются дополнительно. При необходимости выезда представителя Подрядчика на Объект Заказчик несет расходы по оплате авиабилетов (эконом класс), ж/д билетов (купе, класс обслуживания 2С, 2В) до города и обратно, проживание в гостинице (стандартный номер стоимостью не более 4500 рублей в сутки), трансфер (2000 руб.) на каждого представителя Подрядчика. Возмещение расходов по оплате услуг раннего въезда\ позднего выезда производится согласно отчетным документам в полном объеме (в норму по оплате проживания данные услуги не включены). Необходимость выезда Подрядчика на объект должна быть подтверждена Заказчиком.
B41: Примечание: В течении производства Ремонтно-строительных работ Объекта вести авторский надзор (с присутствием на еженедельных рабочих группах в режиме on/off лайн), в соответствии с положением об авторском надзоре и другими нормативными требованиями в этой области. Вести журнал авторского надзора, своевременно занося в него выявленные при строительстве отступления от ПД, строительных норм и правил, технических условий по производству работ. Проводить работы по внесению всех изменений в проектную документацию всех разделов документации согласно требованиям представителей Технического надзора, Представителей служб Заказчика, авторов дизайн-проекта в течение 3-х рабочих дней.
B42: Примечание: Производство Ремонтно-строительных работ Объекта 1-2 месяца. Выезд на объект по согласованию с Заказчиком.

Sheet Проектирование 100-450
B2: Диапазон площади проекта, S | C2: кв.м. | D2: 100 < S < 450
B3: Количество проектов в данном диапазоне | C3: шт. | D3: =[15]Объекты!C49 -> 59
B4: Общая площадь проектирования в данном диапазоне | C4: кв.м. | D4: =[15]Объекты!B49 -> 14317.4
B5: Средняя площадь проекта | C5: кв.м. | D5: =ROUND(D4/D3,0) -> 243
B6: Средний срок Авторского надзора при РСР | C6: месяц | D6: 2
B7: Доля авторского надзора в стоимости основных проектных работ | D7: 0.3
B8: Стоимость основных проектных работ по КП | C8: руб. | H8: =SUM(H18:H27)*D3 -> 16122774
B9: Стоимость авторского надзора | C9: руб. | H9: =H28*D3 -> 6909760.2
B10: Стоимость опциональных проектных работ по КП | C10: руб. | H10: =H35*D33 -> 1103760
B11: ВСЕГО стоимость по КП | C11: руб. | H11: =H8+H9+H10 -> 24136294
B12: Цена за 1 кв.м. проектирования | C12: руб. за 1 кв.м. | H12: =H11/D4 -> 1685.8015
B14: ОСНОВНЫЕ ПРОЕКТНЫЕ РАБОТЫ
A15: № | B15: Наименование работ и затрат | C15: Един. изм. | D15: Кол - во. (объем) | E15: Цена работ с АН, руб., в т.ч. НДС | F15: Цена работ без АН, руб., в т.ч. НДС | G15: Цена материалов и оборудования, руб., в т.ч. НДС | H15: Стоимость работ, руб., в т.ч. НДС | I15: Стоимость материалов и оборудования руб., в т.ч. НДС | N15: ПОДРЯДЧИК: | O15: ООО "ЛИБГОТ"
B16: Раздел №1. Проектные работы и согласования | D16: =D17 -> 2187 | H16: =ROUND(H17,2) -> 390381.93 | N16: Юридический адрес: | O16: 115114, г. Москва, вн.тер.г. муниципальный округ Замоскворечье, ул. Летниковская, д. 10, стр. 2, помещ. 18/10
B17: Проектные работы и согласования | D17: =SUM(D18:D26) -> 2187 | H17: =SUM(H18:H28) -> 390381.93 | N17: Электронный адрес: | O17: libgotstroy@mail.ru
A18: 1 | B18: Рабочая документация по усилению/устройству несущих конструкций ("КР"), включая пояснительную записку (для помещений от 100 до 450 м.кв) | C18: кв.м.площади офиса | D18: =$D$5 -> 243 | E18: 129 | F18: =E18*(1-$D$7) -> 90.3 | G18: =ROUND(#REF!-#REF!*$Q$17,2) -> #REF! | H18: =D18*F18 -> 21942.9 | N18: Контактное лицо (Ф.И.О.) : | O18: Либгот Андрей Дмитриевич
A19: 2 | B19: Рабочая документация "Архитектурные решения" ("АР"), включая пояснительную записку (для помещений от 100 до 450 м.кв) | C19: кв.м.площади офиса | D19: =$D$5 -> 243 | E19: 371 | F19: =E19*(1-$D$7) -> 259.7 | G19: =ROUND(#REF!-#REF!*$Q$17,2) -> #REF! | H19: =D19*F19 -> 63107.1 | N19: Контактный телефон: | O19: 8-977-330-33-10
A20: 3 | B20: Рабочая документация по электроснабжению и электроосвещению ("ЭОМ"), включая пояснительную записку (для помещений от 100 до 450 м.кв) | C20: кв.м.площади офиса | D20: =$D$5 -> 243 | E20: 246 | F20: =E20*(1-$D$7) -> 172.2 | G20: =ROUND(#REF!-#REF!*$Q$17,2) -> #REF! | H20: =D20*F20 -> 41844.6 | N20: Реквизиты: | O20: ИНН 9705229621, КПП 770501001, ОГРН 1247700560238
A21: 4 | B21: Рабочая документация Системы вентиляции ("ОВиК-В"), включая пояснительную записку (для помещений от 100 до 450 м.кв) | C21: кв.м.площади офиса | D21: =$D$5 -> 243 | E21: 193 | F21: =E21*(1-$D$7) -> 135.1 | G21: =ROUND(#REF!-#REF!*$Q$17,2) -> #REF! | H21: =D21*F21 -> 32829.3
A22: 5 | B22: Рабочая документация Системы кондиционирования ("ОВиК-К"), включая пояснительную записку (для помещений от 100 до 450 м.кв) | C22: кв.м.площади офиса | D22: =$D$5 -> 243 | E22: 151.89 | F22: =E22*(1-$D$7) -> 106.323 | G22: =ROUND(#REF!-#REF!*$Q$17,2) -> #REF! | H22: =D22*F22 -> 25836.489
A23: 6 | B23: Рабочая документация Системы отопления ("ОВиК-О"), включая Пояснительную записку и Теплотехнический расчет (для помещений от 100 до 450 м.кв) | C23: кв.м.площади офиса | D23: =$D$5 -> 243 | E23: 118 | F23: =E23*(1-$D$7) -> 82.6 | G23: =ROUND(#REF!-#REF!*$Q$17,2) -> #REF! | H23: =D23*F23 -> 20071.8
A24: 7 | B24: Рабочая документация Системы водоснабжения и канализации ("ВК"), включая пояснительную записку (для помещений от 100 до 450 м.кв) | C24: кв.м.площади офиса | D24: =$D$5 -> 243 | E24: 124 | F24: =E24*(1-$D$7) -> 86.8 | G24: =ROUND(#REF!-#REF!*$Q$17,2) -> #REF! | H24: =D24*F24 -> 21092.4
A25: 8 | B25: Рабочая документация Системы автоматической установки водяного пожаротушения ("АУВПТ"), (спринкерная, дренчерная, модульная система), включая пояснительную записку (для помещений от 100 до 450 м.кв) | C25: кв.м.площади офиса | D25: =$D$5 -> 243 | E25: 87.31 | F25: =E25*(1-$D$7) -> 61.117 | G25: =ROUND(#REF!-#REF!*$Q$17,2) -> #REF! | H25: =D25*F25 -> 14851.431
A26: 9 | B26: Рабочая документация Системы Внутреннего противопожарного водопровода ("ВПВ"), включая пояснительную записку (для помещений от 100 до 450 м.кв) | C26: кв.м.площади офиса | D26: =$D$5 -> 243 | E26: 87.31 | F26: =E26*(1-$D$7) -> 61.117 | G26: =ROUND(#REF!-#REF!*$Q$17,2) -> #REF! | H26: =D26*F26 -> 14851.431
A27: 10 | B27: Рабочая документация Системы дымоудаления ("ДУ"), включая пояснительную записку (для помещений от 100 до 450 м.кв) | C27: кв.м.площади офиса | D27: =$D$5 -> 243 | E27: 99 | F27: =E27*(1-$D$7) -> 69.3 | G27: =ROUND(#REF!-#REF!*$Q$17,2) -> #REF! | H27: =D27*F27 -> 16839.9
A28: 11 | B28: Авторский надзор (без учета услуги по выездам представителя Подрядчика на Объект) | C28: месяц | D28: =D6 -> 2 | E28: =SUMPRODUCT(D18:D27,E18:E27)*D7/D28 -> 58557.29 | G28: =ROUND(#REF!-#REF!*$Q$17,2) -> #REF! | H28: =D28*E28 -> 117114.58
B31: ОПЦИОНАЛЬНЫЕ ПРОЕКТНЫЕ РАБОТЫ
B32: =B5 -> Средняя площадь проекта | C32: кв.м. | D32: =ROUND(D5/10,0) -> 24
B33: =B3 -> Количество проектов в данном диапазоне | C33: шт. | D33: =ROUND(D3/10,0) -> 6
B34: =B4 -> Общая площадь проектирования в данном диапазоне | C34: кв.м. | D34: =D32*D33 -> 144
B35: Проектные работы и согласования | D35: =SUM(D36:D42) -> 48 | H35: =SUM(H36:H37) -> 183960
A36: 1 | B36: Техническое обследование состояния несущих конструкций помещения с подготовкой рекомендаций по усилению (Техничесекое заключение о конструктиве - "ТЗК") (для помещений от 100 до 450 м.кв) | C36: кв.м. | D36: =D32 -> 24 | E36: 3500 | F36: =E36*(1-$D$7) -> 2450 | G36: =ROUND(#REF!-#REF!*$Q$17,2) -> #REF! | H36: =D36*F36 -> 58800
A37: 2 | B37: Эскизный проект фасада и Колористический паспорт с указанием ведомости отделки и проектным решением со спецификацией элементов (крыльцо, пандус, навесы, колонны и т.д.)(для фасадов от 100 до 450 м.кв) | C37: кв.м.площади фасада | D37: =D32 -> 24 | E37: 7450 | F37: =E37*(1-$D$7) -> 5215 | G37: =ROUND(#REF!-#REF!*$Q$17,2) -> #REF! | H37: =D37*F37 -> 125160
B41: Примечание: Услуги по выездам представителя Подрядчика на Объект в цену Работ не включены и оплачиваются дополнительно. При необходимости выезда представителя Подрядчика на Объект Заказчик несет расходы по оплате авиабилетов (эконом класс), ж/д билетов (купе, класс обслуживания 2С, 2В) до города и обратно, проживание в гостинице (стандартный номер стоимостью не более 4500 рублей в сутки), трансфер (2000 руб.) на каждого представителя Подрядчика. Возмещение расходов по оплате услуг раннего въезда\ позднего выезда производится согласно отчетным документам в полном объеме (в норму по оплате проживания данные услуги не включены). Необходимость выезда Подрядчика на объект должна быть подтверждена Заказчиком.
B42: Примечание: В течении производства Ремонтно-строительных работ Объекта вести авторский надзор (с присутствием на еженедельных рабочих группах в режиме on/off лайн), в соответствии с положением об авторском надзоре и другими нормативными требованиями в этой области. Вести журнал авторского надзора, своевременно занося в него выявленные при строительстве отступления от ПД, строительных норм и правил, технических условий по производству работ. Проводить работы по внесению всех изменений в проектную документацию всех разделов документации согласно требованиям представителей Технического надзора, Представителей служб Заказчика, авторов дизайн-проекта в течение 3-х рабочих дней.
B43: Примечание: Производство Ремонтно-строительных работ Объекта 2-3 месяца. Выезд на объект по согласованию с Заказчиком.

Sheet Список и контакты поставщиков
A1: ККО
A2: Инфраструктура
B3: Материал | C3: Производитель | D3: ФИО | E3: Телефон | F3: Электронная почта | G3: Наличие меморандума | H3: Срок окончания
B4: Керамогранит | C4: Kerama-Marazzi | D4: Александр Зуев | E4: +7 (926) 376-55-56 | F4: a.zuev@grestyle.ru | G4: да | H4: 45290
D5: Алексей Лукашов | E5: +7 (926) 376-53-70 | F5: a.lukashov@grestyle.ru
B6: Кондиционеры | C6: «Haier» | D6: Владимир Власенко | E6: 8 (926) 466-81-78 | F6: vladimir.vlasenko@haierrussia.ru | G6: да | H6: 45352
D7: Песин Андрей Олегович | E7: 8 (919) 991-27-22 | F7: andrey.pesin@haierrussia.ru
D8: Дмитриев Е.В. | E8: +7(916) 922-22-20 | F8: Evgeniy.Dmitriev@haierrussia.ru
C9: MDV («Дженерал-Трейд»)/ Mitsubishi Heavy | D9: Карпов Александр | E9: 8 (977) 477-19-97 | F9: akarpov@jac-company.com
D10: Комарова Наталья | F10: nkomarova@jac-company.com
C11: Daikin | D11: Ведущий специалист Куценко Екатерина Васильевна | E11: 7-495-73-73-73-3 (доб. 1786) | F11: Kutsenko@daichi.ru
D12: Заместитель генерального директора по работе с ключевыми клиентами Минаев Андрей Евгеньевич | E12: 7-495-73-73-73-3 (доб. 1702) | F12: Aminaev@daichi.ru
B13: Трансформируемая стеклянная перегородка | C13: ООО "Ктисис" | D13: Дубовицкая Ольга Юрьевна | E13: 8 913 774 32 31 | F13: rperegorodki@yandex.ru | G13: да | H13: 45291
B14: Вентиляция | C14: Globalvent | D14: Алейник Алена | E14: 8 985 270 67 65 | F14: aleinik.alena@gmail.com | G14: да | H14: 45291
C15: VTS | D15: Хусяинов Марат | E15: 8 926 281 00 51 | F15: Marat.Khusainov@vtsrussia.ru | G15: нет | H15: временно не ставим
B16: Бризер | C16: ТИОН | E16: 8 (800) 500-6029
D17: Васильева Наталья | E17: 8 913 915 18 85 | G17: нет | H17: договоренности по цене | I17: (находится в головном офисе в г. Новосибирск +4 часа от Москвы) .
B18: Проектирование | C18: ООО "Ронко" | D18: Романенко Евгений | E18: 8 916 833 86 48 | F18: romanenko@roncogroup.ru | G18: нет | H18: договоренности по цене
C19: ООО "ЛИБГОТ" | D19: Либгот Андрей Дмитриевич | E19: 8-977-330-33-10 | F19: libgotstroy@mail.ru
C20: ООО «ИНТЕЛЛЕКТ-СТРОЙПРОЕКТ» | D20: Шумова Алла Алексеевна. | E20: +7 (903) 587-10-40 | F20: archont15@yandex.ru | G20: нет | H20: договоренности по цене
B21: Лайтбоксы | C21: ООО «ЛЕД ДИЗАЙН» (ТД ПРОФЛЕД) | D21: Тишкова Алие Энверовна | E21: Моб.: 8-963-634-89-88 | F21: E-mail: tae@prof-led.ru | G21: да | H21: 45428
B22: Светильники | C22: ООО "ЭТМ" | D22: Шитов Михаил | E22: 8 (926) 208-37-90 | F22: shitov_ma@etm.ru, | G22: да | H22: 45427
B23: Сантехника, | C23: ООО "Дом мечты" | D23: Шихов Сергей | E23: 8 925 088 35 55 | F23: 17935@mail.ru | G23: нет | H23: договоренности по цене. Проводился выбор. Параллельный импорт. Оперативная замена с согласия ДУС.
B24: Керамическая плитка стены СУ (основной поставщик) | C24: ООО "Отделкино" | D24: Руев Сергей Викторович | E24: 8 920 859 42 13 | F24: ruev@otdelkino.ru | G24: да | H24: 45352
B25: Керамическая плитка стены СУ (резерв) | C25: ООО «Промлес» | D25: Коваленко Галина | E25: +7 (926) 820-03-26, | F25: kovalenko_gn@mosplitka.ru. | G25: да | H25: 45046
B26: Двери Kapelli | C26: Фабрика Kapelli (г. Ростов-на-Дону) | D26: Журавлёва Елена | E26: (863) 261-89-82 доб. 172., моб. 8950-843-15-45 | G26: да | H26: 45368 | I26: периодически корректируют по КП
B27: Щиты | C27: ООО "АВВ-электрощит" | D27: Александр Семенихин | E27: тел.: 8(495)152-25-52 моб. тел.: 8(966)666-24-92 | F27: aleksandr.s@abb-electro.ru www.abb-electro.ru | G27: да | H27: 45374
B28: ПВХ | C28: ООО "Опус-контаркт" | D28: Карнелия | E28: Моб. +7 (965) 209-57-09 , | F28: ksimonova@opuscontract.ru
B29: Тепловые завесы | C29: ООО "Тепломаш-Центр" | D29: Полунин Валерий Викторович | E29: 8(499)504-04-24, 8(916)850-11-40 | F29: polunin@teplomash.ru | G29: да | H29: 45291
B30: Радиаторы REFAR | C30: ООО "ТМ Инвест" | D30: Савелов Андрей | E30: +7 (495) 258-93-88, доб.212 моб. +7 (926) 716-43-58 | F30: sam@teplonet.ru | G30: да | H30: срок вышел нужен новый тендер
B31: Бронеизделия (лотки, панели, передаточный узел, бронедвери) и ПП двери | C31: ООО "СПЕЦ Прожект групп" | D31: Семихин Алексей Николаевич | E31: 8(904) 037-44-57 | F31: 4457@apit-kovrov.ru | G31: да | H31: отказ, идет конкурс
B32: Формат МИКРО (коробочное решение электрика), ЭУИ | C32: ООО "ТД "Электромонтаж" (ЭТМ) | D32: Шафигулин Рузил Рустемович | E32: 7 (926) 528-89-50 +7 (495) 668-70-10 (доб. 360) | F32: shafigulin_rr@etm.ru | G32: да | H32: 45449
D33: Шитов Михаил Александрович | E33: 7(926)208-37-90 | F33: shitov_ma@etm.ru
B34: ЭУИ | C34: ООО "Русский свет" | D34: Дмитрий Варданян | E34: +7 (495) 981-49-21, +7 (962) 985-51-88 | F34: mpp3@skm.russvet.ru | G34: да | H34: 45117
B35: Потолки грильято | C35: ООО "Профиль С" | E35: 8 495 221 31 31 доб. 104 , 8 985 300 35 87 | F35: potolki@griliato.ru | G35: да | H35: 45274 | I35: не используют
B36: Стеклянные двери в алюминиевом корпусе | C36: ООО "ФАСАДСТРОЙ" | D36: Светлана | E36: 79155597559 | F36: svetlanal80@mail.ru | G36: да | H36: срок вышел нужен новый тендер
B37: Бескаркасные двери и перегородки | C37: ООО "Вертикальный транспорт" | D37: Дегтярев С.Д. | E37: +7(903)-622-74-45. | F37: degtyarev.s.str@gmail.com
B38: Стеклянные двери и перегородки инфраструктура | C38: ООО "Вертикальный транспорт" | D38: Дегтярев С.Д. | E38: +7(903)-622-74-45. | F38: degtyarev.s.str@gmail.com
B39: Деревянные двери инфраструктура | C39: ООО "Вертикальный транспорт" | D39: Дегтярев С.Д. | E39: +7(903)-622-74-45. | F39: degtyarev.s.str@gmail.com
B40: Светильники инфраструктура | C40: ООО "Рефлекта" | E40: +7 (499) 755 95 87 | F40: info@reflectalight.ru
...

Sheet АПС, СОУЭ, ППА
A1: Формат объекта | C1: Инфраструктура
A2: Адрес объекта: | B2: Адрес объекта: | C2: г. Москва, ул. Каланчевская, д. 29, стр. 2
A3: Плoщадь объекта (м.кв.): | B3: Плащадь объекта: | C3: =B37 -> 0
A4: Срок проведения работ | B4: Срок проведения работ
A5: ПОДРЯДЧИК: | B5: ПОДРЯДЧИК:
A6: Юридический адрес: | B6: Юридический адрес:
A7: Электронный адрес: | B7: Электронный адрес:
A8: Контактное лицо (Ф.И.О.) : | B8: Контактное лицо (Ф.И.О.) :
A9: Контактный телефон: | B9: Контактный телефон:
A10: Реквизиты: | B10: Реквизиты:
A11: Сумма по смете: | B11: Сумма по смете: | C11: =D38 -> 0
A12: Поз № | B12: Наименование помещений | D12: Ед.изм. | E12: Объем | F12: Цена за 1 кв.м. руб. с НДС руб.
A13: 1 | B13: Рабочая документация "Автоматическая пожарная сигнализация" (АПС) | D13: кв.м площади офиса | E13: 1 | F13: 67
A14: 2 | B14: Рабочая документация "Система оповещения и управления эвакуацией людей при пожаре" (СОУЭ) | D14: кв.м площади офиса | E14: 1 | F14: 39
A15: 3 | B15: Рабочая документация "Противопожарная автоматика (ППА), включая: | D15: кв.м площади офиса | E15: 1 | F15: =SUM(F16:F21) -> 39
A16: 3.1 | B16: Автоматизация системы внутреннего противопожарного водопровода (ВПВ) | D16: кв.м площади офиса | E16: 1 | F16: 8
A17: 3.2 | B17: Автоматизация системы противодымной вентиляции (ПДВ) | D17: кв.м площади офиса | E17: 1 | F17: 25
A18: 3.3 | B18: Автоматизация Системы отопления, вентиляции и кондиционирования (ОВиК) | D18: кв.м площади офиса | E18: 1 | F18: 3
A19: 3.4 | B19: Автоматизация Системы аварийного освещения (АО) | D19: кв.м площади офиса | E19: 1 | F19: 1
A20: 3.5 | B20: Автоматизации лифтовового хозяйства | D20: кв.м площади офиса | E20: 1 | F20: 1
A21: 3.6 | B21: Автоматизации Системы контроля управления доступом (СКУД) | D21: кв.м площади офиса | E21: 1 | F21: 1
A22: 4 | B22: Сметная документация на АПС, СОУЭ и ППА | D22: кв.м площади офиса | E22: 1 | F22: 5
B23: Базовая цена проектирования за 1 кв.м. | D23: кв.м площади офиса | E23: 1 | F23: =SUM(F13:F15)+F22 -> 150

Sheet Освещение Рефлекта
B2: Russia, Moscow region, 143902
B3: Balashikha, Sovetskaya str, 36, build.13
B4: tel/fax: +7 (495) 740-55-69
B5: E-mail: info@reflectalight.ru
A8: Спецификация № 194 /_01_07_2025_
A11: * - на предзаказе длины и прочие размеры согласовываются отдельно с конструктором +/- см
A14: Вид | B14: Тип | C14: Наименование | D14: Артикул | E14: Размеры, мм | F14: Цена, вкл. НДС, ₽ | G14: Цена, вкл. НДС, ₽ с ГП | H14: Сумма, ₽ | I14: Производитель | J14: Готовность к отгрузке | K14: Примечания
B15: L1 | C15: Rota D1000 MP ECO 42W-4000K CRI 90 Susp WHI - Светильник | D15: 2206905_ WHI | E15: D1000, H107 | F15: 32428.62 | G15: =F15*1.05 -> 34050.051 | H15: =F15*G15 -> 1.1041962e+09 | I15: REFLECTA
B16: L1 | C16: Rota D1000 MP ECO 42W-4000K CRI 90 Susp BLK - Светильник | D16: 2206905_ BLK | E16: D1000, H107 | F16: 32428.62 | G16: =F16*1.05 -> 34050.051 | H16: =F16*G16 -> 1.1041962e+09 | I16: REFLECTA
B17: L1A | C17: Rota D1000 MP ECO 42W-4000K CRI 90 Susp WHI Emerg- Светильник | D17: 2206905_ WHI Emg | E17: D1000, H107 | F17: 37564.695 | G17: =F17*1.05 -> 39442.93 | H17: =F17*G17 -> 1.4816616e+09 | I17: REFLECTA
B18: L1A | C18: Rota D1000 MP ECO 42W-4000K CRI 90 Susp BLK Emerg- Светильник | D18: 2206905_ BLK Emg | E18: D1000, H107 | F18: 37564.695 | G18: =F18*1.05 -> 39442.93 | H18: =F18*G18 -> 1.4816616e+09 | I18: REFLECTA
B19: L1.1 | C19: Rota D1000 MP ECO 54W-4000K CRI 90 L24 270mA Susp WHI - Светильник | D19: 2206911_ WHI | E19: D1000, H107 | F19: 33572.07 | G19: =F19*1.05 -> 35250.674 | H19: =F19*G19 -> 1.1834381e+09 | I19: REFLECTA
B20: L1.1 | C20: Rota D1000 MP ECO 54W-4000K CRI 90 L24 270mA Susp BLK - Светильник | D20: 2206911_ BLK | E20: D1000, H107 | F20: 33572.07 | G20: =F20*1.05 -> 35250.674 | H20: =F20*G20 -> 1.1834381e+09 | I20: REFLECTA
B21: L1.1A | C21: Rota D1000 MP ECO 54W-4000K CRI 90 L24 270mA Susp WHI Emerg- Светильник | D21: 2206911_ WHI Emerg | E21: D1000, H107 | F21: 38708.145 | G21: =F21*1.05 -> 40643.552 | H21: =F21*G21 -> 1.5732365e+09 | I21: REFLECTA
B22: L1.1A | C22: Rota D1000 MP ECO 54W-4000K CRI 90 L24 270mA Susp BLK Emerg- Светильник | D22: 2206911_ BLK Emg | E22: D1000, H107 | F22: 38708.145 | G22: =F22*1.05 -> 40643.552 | H22: =F22*G22 -> 1.5732365e+09 | I22: REFLECTA
B23: L1.2 | C23: Rota D1000 MP ECO 28W-4000K CRI 90 270mA Susp WHI - Светильник | D23: 2208013_ WHI | E23: D1000, H107 | F23: 32428.62 | G23: =F23*1.05 -> 34050.051 | H23: =F23*G23 -> 1.1041962e+09 | I23: REFLECTA
B24: L1.2 | C24: Rota D1000 MP ECO 28W-4000K CRI 90 270mA Susp BLK - Светильник | D24: 2208013_ BLK | E24: D1000, H107 | F24: 32428.62 | G24: =F24*1.05 -> 34050.051 | H24: =F24*G24 -> 1.1041962e+09 | I24: REFLECTA
B25: L1.2 | C25: Rota D1000 MP ECO 77W-4000K CRI 90 L24 Susp WHI - Светильник | D25: 2400467_ WHI | E25: D1000, H107 | F25: 33572.07 | G25: =F25*1.05 -> 35250.674 | H25: =F25*G25 -> 1.1834381e+09 | I25: REFLECTA
B26: L1.2 | C26: Rota D1000 MP ECO 77W-4000K CRI 90 L24 Susp BLK - Светильник | D26: 2400467_ BLK | E26: D1000, H107 | F26: 33572.07 | G26: =F26*1.05 -> 35250.674 | H26: =F26*G26 -> 1.1834381e+09 | I26: REFLECTA
... B75: C2.1 A | C75: MICA System D330 27W-4000K CRI 90 MP ECO BLK Emerg - Светильник | D75: 2206251 BLK Emg | E75: D330 | F75: 22532.58 | G75: =F75*1.05 -> 23659.209 | H75: =F75*G75 -> 5.3310302e+08 | I75: REFLECTA
B76: С2.1 | C76: MICA System Base Kit, ROW Susp BLK, L=XXXXmm - База | D76: 2100369_XXXX BLK | E76: 1000 | F76: 5958.225 | G76: =F76*1.05 -> 6256.1363 | H76: =F76*G76 -> 37275467 | I76: REFLECTA
B77: L4 | C77: Calida MP ECO 16W/mt-4000K CRI 90 R-8620 Line_2500 ROW Susp BLK | D77: 2204401_2500x60_ BLK | E77: 2500 | F77: 42521.22 | G77: =F77*1.05 -> 44647.281 | H77: =F77*G77 -> 1.8984569e+09 | I77: REFLECTA
C78: Calida MP ECO 16W/mt-4000K CRI 90 R-2850 Line_3575 ROW Susp BLK | D78: 2204401_3575x60_ BLK | E78: 3575 | F78: 60805.08 | G78: =F78*1.05 -> 63845.334 | H78: =F78*G78 -> 3.8821206e+09 | I78: REFLECTA
C79: Calida MP ECO 16W/mt-4000K CRI 90 R-8620 Line_5764 ROW Susp BLK | D79: 2204401_5764x60_ BLK | E79: 5764 | F79: 98037.135 | G79: =F79*1.05 -> 102938.99 | H79: =F79*G79 -> 1.0091844e+10 | I79: REFLECTA
B80: L4 | C80: Calida MP ECO 16W/mt-4000K CRI 90 R-XXX Line_XXXX ROW Susp WHI | D80: 2204401_XXXXx60_ WHI | E80: 1000 | F80: 17008.425 | G80: =F80*1.05 -> 17858.846 | H80: =F80*G80 -> 3.0375085e+08 | I80: REFLECTA
B81: L4 | C81: Calida MP ECO 16W/mt-4000K CRI 90 R-XXX Line_XXXX ROW Susp BLK | D81: 2204401_XXXXx60_ BLK | E81: 1000 | F81: 17008.425 | G81: =F81*1.05 -> 17858.846 | H81: =F81*G81 -> 3.0375085e+08 | I81: REFLECTA
B82: C15 | C82: Quark ON HE MP D30 8W-4000K CRI 90 H630 Ceil BLK - Светильник (драйвер выносной) | D82: 2202647 BLK | E82: D30, H630 | F82: 5465.1765 | G82: =F82*1.05 -> 5738.4353 | H82: =F82*G82 -> 31361562 | I82: REFLECTA
B83: C15.1 | C83: Quark ON HE MP D30 8W-4000K CRI 90 H420 Ceil BLK - Светильник (драйвер выносной) | D83: 2202635_ BLK | E83: D30, H420 | F83: 5063.121 | G83: =F83*1.05 -> 5316.2771 | H83: =F83*G83 -> 26916954 | I83: REFLECTA
B84: L3 | C84: Quark AIR HE D30 Lens 10` 2W-4000K CRI 90 H200 Susp BLK - Светильник | D84: 2503487 BLK | E84: D30, H200 | F84: 5013.687 | G84: =F84*1.05 -> 5264.3714 | H84: =F84*G84 -> 26393910 | I84: REFLECTA | J84: 4-6 недель
B85: L4 | C85: Quark AIR HE D30 Lens 10` 2W-4000K CRI 90 H300 Susp - Светильник | D85: 2503488 | E85: D30, H300 | F85: 5286.204 | G85: =F85*1.05 -> 5550.5142 | H85: =F85*G85 -> 29341150 | I85: REFLECTA
B86: L1 | C86: Quark AIR HE D30 Lens 10` 2W-4000K CRI 90 H500 Susp BLK - Светильник | D86: 2503489 BLK | E86: D30, H500 | F86: 5817.777 | G86: =F86*1.05 -> 6108.6659 | H86: =F86*G86 -> 35538856 | I86: REFLECTA | J86: 4-6 недель
