Workbook

Sheet СВОД_АНКЕТА СООТВЕТСТВИЯ
A2: № | B2: Требования к участнику
C3: Спектрум-Холдинг | D3: Ди Би Си Констракшн | E3: Николиерс Управление Строительством | F3: КОР ЭКС ПИ | G3: Комонвелс Партнершип | H3: Восход | I3: НФ Проперти Менеджмент | J3: СР. ДЕВЕЛОПМЕНТ | K3: Инжиниринговая компания «Элемент» | L3: ИЭС Инжиниринг и Консалтинг | M3: Инжиниринговая корпорация «ИРБИС» | N3: АКРОН Девелопмент | O3: ПМК | P3: РИТМ Проект (JLL) | Q3: Эс Эй Риччи ПМ | R3: Стройконтроль
A4: 1 | B4: Дата создания компании | C4: 2002 | D4: 2011 | E4: 2023 | F4: ='CORE XP_АС'!C10 -> С 08.11.2005 по 10.01.2007 - ООО "Эн Джи Холдинг" С 11.01.2007 по 11.04.2022 - ООО "Си Би Ричард Эллис", 2022-по настоящее время - ООО "КОР ЭКС ПИ" | G4: =CMWР_АС!C10 -> 27.12.2004 - ООО "Кушман энд Вэйкфилд". С 28 июня 2022 - ООО "Комонвелс" | H4: =Восход_АС!C10 -> 2019 | I4: =NFrank_АС!D10 -> 2013 г. (ООО "Найт Фрэнк ПИЭМ"), 2022 г. (ООО "НФ Проперти Менеджмент") | J4: ='СР Девелопиент_АС'!C10 -> ДА | K4: 2014 | L4: 2004 | M4: =Ирбис_АС!D10 -> 1993 | N4: 2009 | O4: 2001 | P4: 2022, до 2022 входило в компанию ООО "Джонс Лэнг ЛаСаль", в данный момент входит в группу компаний ООО "Ай Би Си РиалЭстейт" | Q4: ='Эс Эй Риччи ПМ_АС'!C10 -> 2012 | R4: =Стройконтроль_АС!C10 -> ДА
A5: 2 | B5: Опыт управления аналогичными проектами по объему и сложности работ в Москве и/или СПб. | C5: ='СПЕКТРУМ ХОЛДИНГ_АС'!C11 -> ДА | D5: =DBC_АС!C11 -> ДА | E5: =Nikoliers_АС!C11 -> ДА | F5: ='CORE XP_АС'!C11 -> ДА | G5: =CMWР_АС!C11 -> ДА | H5: =Восход_АС!C11 -> ДА | I5: =NFrank_АС!C11 -> ДА | J5: ='СР Девелопиент_АС'!C11 -> ДА | K5: ='ИК Элемент_АС'!C11 -> ДА | L5: ДА | M5: =Ирбис_АС!C11 -> ДА | N5: =АКРОН_АС!C15 -> ДА | O5: ДА | P5: ='РИТМ ПРОЕКТ_АС'!C11 -> ДА | Q5: ='Эс Эй Риччи ПМ_АС'!C11 -> ДА | R5: =Стройконтроль_АС!C11 -> ДА
A6: 3 | B6: Готовность предоставить Резюме на каждого члена команды проекта | C6: ='СПЕКТРУМ ХОЛДИНГ_АС'!C12 -> ДА | D6: =DBC_АС!C12 -> ДА | E6: =Nikoliers_АС!C12 -> ДА | F6: ='CORE XP_АС'!C12 -> ДА | G6: =CMWР_АС!C12 -> ДА | H6: =Восход_АС!C12 -> ДА | I6: =NFrank_АС!C12 -> ДА | J6: ='СР Девелопиент_АС'!C12 -> ДА | K6: ='ИК Элемент_АС'!C12 -> ДА | L6: ДА | M6: =Ирбис_АС!C12 -> ДА | N6: =АКРОН_АС!C16 -> ДА | O6: ДА | P6: ='РИТМ ПРОЕКТ_АС'!C12 -> ДА | Q6: ='Эс Эй Риччи ПМ_АС'!C12 -> ДА | R6: =Стройконтроль_АС!C12 -> ДА
A7: 4 | B7: Готовность выделить на проект не менее 10 членов команды соответствующего профиля | C7: ='СПЕКТРУМ ХОЛДИНГ_АС'!C13 -> ДА | D7: =DBC_АС!C13 -> ДА | E7: =Nikoliers_АС!C13 -> ДА | F7: ='CORE XP_АС'!C13 -> ДА | G7: =CMWР_АС!C13 -> ДА | H7: =Восход_АС!C13 -> ДА | I7: =NFrank_АС!C13 -> ДА | J7: ='СР Девелопиент_АС'!C13 -> ДА | K7: ='ИК Элемент_АС'!C13 -> ДА | L7: ДА | M7: =Ирбис_АС!C13 -> ДА | N7: =АКРОН_АС!C17 -> ДА | O7: ДА | P7: ='РИТМ ПРОЕКТ_АС'!C13 -> ДА | Q7: ='Эс Эй Риччи ПМ_АС'!C13 -> ДА | R7: =Стройконтроль_АС!C13 -> ДА
A8: 5 | B8: Отсутствие проблемной налоговой и/или кредитной задолженности. | C8: ='СПЕКТРУМ ХОЛДИНГ_АС'!C14 -> ДА | D8: =DBC_АС!C14 -> ДА | E8: =Nikoliers_АС!C14 -> ДА | F8: ='CORE XP_АС'!C14 -> ДА | G8: =CMWР_АС!C14 -> ДА | H8: =Восход_АС!C14 -> ДА | I8: =NFrank_АС!C14 -> ДА | J8: ='СР Девелопиент_АС'!C14 -> ДА | K8: ='ИК Элемент_АС'!C14 -> ДА | L8: ДА | M8: =Ирбис_АС!C14 -> ДА | N8: =АКРОН_АС!C18 -> ДА | O8: ДА | P8: ='РИТМ ПРОЕКТ_АС'!C14 -> ДА | Q8: ='Эс Эй Риччи ПМ_АС'!C14 -> ДА | R8: =Стройконтроль_АС!C14 -> ДА
A9: 6 | B9: Отсутствие судебных споров в качестве ответчика. | C9: ='СПЕКТРУМ ХОЛДИНГ_АС'!C15 -> ДА | D9: =DBC_АС!C15 -> НЕТ | E9: =Nikoliers_АС!C15 -> ДА | F9: ='CORE XP_АС'!C15 -> ДА | G9: =CMWР_АС!C15 -> ДА | H9: =Восход_АС!C15 -> НЕТ | I9: =NFrank_АС!C15 -> ДА | J9: ='СР Девелопиент_АС'!C15 -> ДА | K9: ='ИК Элемент_АС'!C15 -> НЕТ | L9: ДА | M9: =Ирбис_АС!C15 -> ДА | N9: =АКРОН_АС!C19 -> ДА | O9: ДА | P9: ='РИТМ ПРОЕКТ_АС'!C15 -> НЕТ | Q9: ='Эс Эй Риччи ПМ_АС'!C15 -> ДА | R9: =Стройконтроль_АС!C15 -> ДА
A10: 6.1. | B10: коментарий к п.6 Анкеты | D10: 1 судебный спор на текущий момент с поставщиком. В справке подробно прилагается. | H10: Дело № А43-27419/2015. Несмотря на то, что ООО "Восход" было включено заявителем в состав ответчиков по спору об оспаривании сделок в рамках дела о банкротстве ООО "Консорциум", данное лицо, как было установлено вступившими в силу | K10: н/д | P10: Судебный спор (первая инстанция): истец- ООО «Титон», основание – взыскание задолженности.

Sheet СВОД_АНКЕТА (ДОП. ДАННЫЕ)
C2: Спектрум-Холдинг | I2: Ди Би Си Констракшн | O2: Николиерс Управление Строительством | U2: КОР ЭКС ПИ | AA2: Комонвелс Партнершип | AG2: Восход | AM2: НФ Проперти Менеджмент | AS2: Инжиниринговая компания «Элемент» | AY2: ИЭС Инжиниринг и Консалтинг | BE2: Инжиниринговая корпорация «ИРБИС» | BK2: АКРОН Девелопмент | BQ2: ПМК | BW2: РИТМ Проект (JLL) | CC2: Эс Эй Риччи ПМ | CI2: Стройконтроль
A3: № | B3: Требования к участнику | C3: 2019 | D3: 2020 | E3: 2021 | F3: 2022 | G3: 2023 | H3: 2024 | I3: 2019 | J3: 2020 | K3: 2021 | L3: 2022 | M3: 2023 | N3: 2024 | O3: 2019 | P3: 2020 | Q3: 2021 | R3: 2022 | S3: 2023 | T3: 2024 | U3: 2019 | V3: 2020 | W3: 2021 | X3: 2022 | Y3: 2023 | Z3: 2024 | AA3: 2019 | AB3: 2020 | AC3: 2021 | AD3: 2022 | AE3: 2023 | AF3: 2024 | AG3: 2019 | AH3: 2020 | AI3: 2021 | AJ3: 2022 | AK3: 2023 | AL3: 2024 | AM3: 2019 | AN3: 2020 | AO3: 2021 | AP3: 2022 | AQ3: 2023 | AR3: 2024 | AS3: 2019 | AT3: 2020 | AU3: 2021 | AV3: 2022 | AW3: 2023 | AX3: 2024 | AY3: 2019 | AZ3: 2020 | BA3: 2021 | BB3: 2022 | BC3: 2023 | BD3: 2024 | BE3: 2019 | BF3: 2020 | BG3: 2021 | BH3: 2022 | BI3: 2023 | BJ3: 2024 | BK3: 2019 | BL3: 2020 | BM3: 2021 | BN3: 2022 | BO3: 2023 | BP3: 2024 | BQ3: 2019 | BR3: 2020 | BS3: 2021 | BT3: 2022 | BU3: 2023 | BV3: 2024 | BW3: 2019 | BX3: 2020 | BY3: 2021 | BZ3: 2022 | CA3: 2023 | CB3: 2024 | CC3: 2019 | CD3: 2020 | CE3: 2021 | CF3: 2022 | CG3: 2023 | CH3: 2024 | CI3: 2019 | CJ3: 2020 | CK3: 2021 | CL3: 2022 | CM3: 2023 | CN3: 2024
A4: 1 | B4: Годовой оборот компании (юр. лицо участника тендера) не менее 500 млн руб. | C4: ='СПЕКТРУМ ХОЛДИНГ_ДД'!C10 -> 1375.55 | D4: ='СПЕКТРУМ ХОЛДИНГ_ДД'!D10 -> 1652.03 | E4: ='СПЕКТРУМ ХОЛДИНГ_ДД'!E10 -> 2331.07 | F4: ='СПЕКТРУМ ХОЛДИНГ_ДД'!F10 -> 3956 | G4: ='СПЕКТРУМ ХОЛДИНГ_ДД'!G10 -> 4219.19 | H4: ='СПЕКТРУМ ХОЛДИНГ_ДД'!H10 -> 7517.66 | I4: =DBC_ДД!C10 -> 247.418 | J4: =DBC_ДД!D10 -> 406.151 | K4: =DBC_ДД!E10 -> 551.939 | L4: =DBC_ДД!F10 -> 624.656 | M4: =DBC_ДД!G10 -> 709.269 | N4: =DBC_ДД!H10 -> 3599.786 | O4: =Nikoliers_ДД!C10 -> нет | P4: =Nikoliers_ДД!D10 -> нет | Q4: =Nikoliers_ДД!E10 -> нет | R4: =Nikoliers_ДД!F10 -> нет | S4: =Nikoliers_ДД!G10 -> нет | T4: =Nikoliers_ДД!H10 -> 57807 | U4: ='CORE XP_ДД'!C10 -> 2297378 | V4: ='CORE XP_ДД'!D10 -> 1384592 | W4: ='CORE XP_ДД'!E10 -> 1689445 | X4: ='CORE XP_ДД'!F10 -> 1636303 | Y4: ='CORE XP_ДД'!G10 -> 1865216 | Z4: ='CORE XP_ДД'!H10 -> 2515282 | AA4: =CMWР_ДД!C10 -> 2029548000 | AB4: =CMWР_ДД!D10 -> 1674788000 | AC4: =CMWР_ДД!E10 -> 2307303000 | AD4: =CMWР_ДД!F10 -> 1833589000 | AE4: =CMWР_ДД!G10 -> 1988761000 | AF4: =CMWР_ДД!H10 -> 1871577000 | AG4: =Восход_ДД!C10 -> 0 | AH4: =Восход_ДД!D10 -> 42500 | AI4: =Восход_ДД!E10 -> 802293 | AJ4: =Восход_ДД!F10 -> 652037 | AK4: =Восход_ДД!G10 -> 734606 | AL4: =Восход_ДД!H10 -> 450053 | AM4: =NFrank_ДД!C10 -> 221.562 | AN4: =NFrank_ДД!D10 -> 297.519 | AO4: =NFrank_ДД!E10 -> 445.126 | AP4: =NFrank_ДД!F10 -> 612.062 | AQ4: =NFrank_ДД!G10 -> 884.979 | AR4: =NFrank_ДД!H10 -> 1176.124 | AS4: ='ИК Элемент_ДД'!C10 -> 94079000 | AT4: ='ИК Элемент_ДД'!D10 -> 265408000 | AU4: ='ИК Элемент_ДД'!E10 -> 258506000 | AV4: ='ИК Элемент_ДД'!F10 -> 469899000 | AW4: ='ИК Элемент_ДД'!G10 -> 591413000 | AX4: ='ИК Элемент_ДД'!H10 -> 976243000 | AY4: 215.83 | AZ4: 156.88 | BA4: 262.86 | BB4: 427.81 | BC4: 612.92 | BD4: 865.58 | BE4: =Ирбис_ДД!C10 -> 77.27 | BF4: =Ирбис_ДД!D10 -> 94.93 | BG4: =Ирбис_ДД!E10 -> 165.05 | BH4: =Ирбис_ДД!F10 -> 258.66 | BI4: =Ирбис_ДД!G10 -> 304.22 | BJ4: =Ирбис_ДД!H10 -> 396.34 | BK4: =АКРОН_ДД!C16 -> 18.228 | BL4: =АКРОН_ДД!D16 -> 68.112 | BM4: =АКРОН_ДД!E16 -> 68.4 | BN4: =АКРОН_ДД!F16 -> 48.6 | BO4: =АКРОН_ДД!G16 -> 117.75 | BP4: =АКРОН_ДД!H16 -> 299.09 | BQ4: Н/Д | BR4: Н/Д | BS4: Н/Д | BT4: Н/Д | BU4: Н/Д | BV4: Н/Д | BW4: ='РИТМ ПРОЕКТ_ДД'!C10 -> 130.83 | BX4: ='РИТМ ПРОЕКТ_ДД'!D10 -> 160.83 | BY4: ='РИТМ ПРОЕКТ_ДД'!E10 -> 150.65 | BZ4: ='РИТМ ПРОЕКТ_ДД'!F10 -> 59.99 | CA4: ='РИТМ ПРОЕКТ_ДД'!G10 -> 62.23 | CB4: ='РИТМ ПРОЕКТ_ДД'!H10 -> 67.57 | CC4: ='Эс Эй Риччи ПМ_ДД'!C10 -> 27113174 | CD4: ='Эс Эй Риччи ПМ_ДД'!D10 -> 46839920 | CE4: ='Эс Эй Риччи ПМ_ДД'!E10 -> 49934413 | CF4: ='Эс Эй Риччи ПМ_ДД'!F10 -> 30847020 | CG4: ='Эс Эй Риччи ПМ_ДД'!G10 -> 50203018 | CH4: ='Эс Эй Риччи ПМ_ДД'!H10 -> 65412051 | CI4: Х | CJ4: Х | CK4: Х | CL4: Х | CM4: 70 | CN4: 153
A5: 2 | B5: Годовой оборот Группы компаний (если юр. лицо участника тендера входит в группу компаний), млн руб. | C5: ='СПЕКТРУМ ХОЛДИНГ_ДД'!C11 -> 1655.3 | D5: ='СПЕКТРУМ ХОЛДИНГ_ДД'!D11 -> 1884.69 | E5: ='СПЕКТРУМ ХОЛДИНГ_ДД'!E11 -> 2561.34 | F5: ='СПЕКТРУМ ХОЛДИНГ_ДД'!F11 -> 4235.15 | G5: ='СПЕКТРУМ ХОЛДИНГ_ДД'!G11 -> 4647.93 | H5: ='СПЕКТРУМ ХОЛДИНГ_ДД'!H11 -> 7884.32 | I5: Х | J5: Х | K5: Х | L5: Х | M5: Х | N5: Х | O5: =Nikoliers_ДД!C11 -> 1611074 | P5: =Nikoliers_ДД!D11 -> 1632230 | Q5: =Nikoliers_ДД!E11 -> 1427034 | R5: =Nikoliers_ДД!F11 -> 1417502 | S5: =Nikoliers_ДД!G11 -> 1620219 | T5: =Nikoliers_ДД!H11 -> 2345936 | U5: ='CORE XP_ДД'!C11 -> нет | V5: ='CORE XP_ДД'!D11 -> нет | W5: ='CORE XP_ДД'!E11 -> нет | X5: ='CORE XP_ДД'!F11 -> нет | Y5: ='CORE XP_ДД'!G11 -> нет | Z5: ='CORE XP_ДД'!H11 -> нет | AA5: Х | AB5: Х | AC5: Х | AD5: Х | AE5: Х | AF5: Х | AG5: Х | AH5: Х | AI5: Х | AJ5: Х | AK5: Х | AL5: Х | AM5: =NFrank_ДД!C11 -> 1095.032 | AN5: =NFrank_ДД!D11 -> 1322.259 | AO5: =NFrank_ДД!E11 -> 2158.726 | AP5: =NFrank_ДД!F11 -> 2026.612 | AQ5: =NFrank_ДД!G11 -> 3252.639 | AR5: =NFrank_ДД!H11 -> 4161.594 | AS5: Х | AT5: Х | AU5: Х | AV5: Х | AW5: Х | AX5: Х | AY5: Х | AZ5: Х | BA5: Х | BB5: Х | BC5: Х | BD5: Х | BE5: =Ирбис_ДД!C11 -> 155.79 | BF5: =Ирбис_ДД!D11 -> 175.17 | BG5: =Ирбис_ДД!E11 -> 285.16 | BH5: =Ирбис_ДД!F11 -> 389.86 | BI5: =Ирбис_ДД!G11 -> 425.32 | BJ5: =Ирбис_ДД!H11 -> 608.86 | BK5: =АКРОН_ДД!C17 -> 18.228 | BL5: =АКРОН_ДД!D17 -> 68.112 | BM5: =АКРОН_ДД!E17 -> 68.4 | BN5: =АКРОН_ДД!F17 -> 48.6 | BO5: =АКРОН_ДД!G17 -> 117.75 | BP5: =АКРОН_ДД!H17 -> 299.09 | BQ5: Н/Д | BR5: Н/Д | BS5: Н/Д | BT5: Н/Д | BU5: Н/Д | BV5: Н/Д | BW5: ='РИТМ ПРОЕКТ_ДД'!C11 -> 972.622 | BX5: ='РИТМ ПРОЕКТ_ДД'!D11 -> 1093.958 | BY5: ='РИТМ ПРОЕКТ_ДД'!E11 -> 1258.227 | BZ5: ='РИТМ ПРОЕКТ_ДД'!F11 -> 645.569 | CA5: ='РИТМ ПРОЕКТ_ДД'!G11 -> 1043.329 | CB5: ='РИТМ ПРОЕКТ_ДД'!H11 -> 1040.746 | CC5: Х | CD5: Х | CE5: Х | CF5: Х | CG5: Х | CH5: Х | CI5: Х | CJ5: Х | CK5: Х | CL5: Х | CM5: Х | CN5: Х
A6: 3 | B6: Доля выручки от управления проектами (алогичными по объему и сложности работ) по отношению к общей выручке Участника за год (в абсолютном (млн. руб.) и относительном (%) выражении) | C6: ='СПЕКТРУМ ХОЛДИНГ_ДД'!C12 -> 397.12 | D6: ='СПЕКТРУМ ХОЛДИНГ_ДД'!D12 -> 356,66 | E6: ='СПЕКТРУМ ХОЛДИНГ_ДД'!E12 -> 547,01 | F6: ='СПЕКТРУМ ХОЛДИНГ_ДД'!F12 -> 660,88 | G6: ='СПЕКТРУМ ХОЛДИНГ_ДД'!G12 -> 890,05 | H6: ='СПЕКТРУМ ХОЛДИНГ_ДД'!H12 -> 1203,26 | I6: =DBC_ДД!C12 -> 247.418 | J6: =DBC_ДД!D12 -> 406.151 | K6: =DBC_ДД!E12 -> 551.939 | L6: =DBC_ДД!F12 -> 624.656 | M6: =DBC_ДД!G12 -> 570.41 | N6: =DBC_ДД!H12 -> 956.04 | O6: =Nikoliers_ДД!C12 -> будет направлено позднее | U6: ='CORE XP_ДД'!C12 -> 187174/8,15% | V6: ='CORE XP_ДД'!D12 -> 162021/11,70% | W6: ='CORE XP_ДД'!E12 -> 201021/11,90% | X6: ='CORE XP_ДД'!F12 -> 237113/14,49% | Y6: ='CORE XP_ДД'!G12 -> 206651/11,08% | Z6: ='CORE XP_ДД'!H12 -> 346835/13,79% | AA6: =CMWР_ДД!C12 -> 0.07 | AB6: =CMWР_ДД!D12 -> 0.07 | AC6: =CMWР_ДД!E12 -> 0.08 | AD6: =CMWР_ДД!F12 -> 0.08 | AE6: =CMWР_ДД!G12 -> 0.07 | AF6: =CMWР_ДД!H12 -> 0.1 | AG6: Н/Д | AH6: Н/Д | AI6: Н/Д | AJ6: Н/Д | AK6: Н/Д | AL6: Н/Д | AM6: =NFrank_ДД!C12 -> 29,55/13,3% | AN6: =NFrank_ДД!D12 -> 50,56/17% | AO6: =NFrank_ДД!E12 -> 105,49/23,7% | AP6: =NFrank_ДД!F12 -> 110,56/18,06% | AQ6: =NFrank_ДД!G12 -> 196,63/22,22% | AR6: =NFrank_ДД!H12 -> 388,68/33,05% | AS6: ='ИК Элемент_ДД'!C12 -> 0,0% | AT6: ='ИК Элемент_ДД'!D12 -> 61 043 840, 23% | AU6: ='ИК Элемент_ДД'!E12 -> 93 062 160, 36% | AV6: ='ИК Элемент_ДД'!F12 -> 159 765 660, 34% | AW6: ='ИК Элемент_ДД'!G12 -> 230 651 070, 39% | AX6: ='ИК Элемент_ДД'!H12 -> 410 022 060, 42% | AY6: 57,63 / 27% | AZ6: 31,15 / 20% | BA6: 14,67 / 6% | BB6: 43,53 / 10% | BC6: 29,61 / 5% | BD6: 247,64 / 29% | BE6: =Ирбис_ДД!C12 -> 37,44/48% | BF6: =Ирбис_ДД!D12 -> 71,5/75% | BG6: =Ирбис_ДД!E12 -> 117,97/71% | BH6: =Ирбис_ДД!F12 -> 135,26/58% | BI6: =Ирбис_ДД!G12 -> 128,22/42% | BJ6: =Ирбис_ДД!H12 -> 240,75/60% | BK6: =АКРОН_ДД!C18 -> 18,228 (100%) | BL6: =АКРОН_ДД!D18 -> 68,112 (100%) | BM6: =АКРОН_ДД!E18 -> 68,4 (100%) | BN6: =АКРОН_ДД!F18 -> 48,6 (100%) | BO6: =АКРОН_ДД!G18 -> 68 (58%) | BP6: =АКРОН_ДД!H18 -> 88 (30%) | BQ6: Н/Д | BR6: Н/Д | BS6: Н/Д | BT6: Н/Д | BU6: Н/Д | BV6: Н/Д | BW6: ='РИТМ ПРОЕКТ_ДД'!C12 -> 78,49/60% | BX6: ='РИТМ ПРОЕКТ_ДД'!D12 -> 80,42/50% | BY6: ='РИТМ ПРОЕКТ_ДД'!E12 -> 106,96/71% | BZ6: ='РИТМ ПРОЕКТ_ДД'!F12 -> 29,99/50% | CA6: ='РИТМ ПРОЕКТ_ДД'!G12 -> 42,32/68% | CB6: ='РИТМ ПРОЕКТ_ДД'!H12 -> 39,19/58% | CC6: ='Эс Эй Риччи ПМ_ДД'!C12 -> компания специализируется на организации, координации и контроле работ по проектированию и строительству (услуги технического заказика, строительный контроль) | CD6: ='Эс Эй Риччи ПМ_ДД'!D12 -> компания специализируется на организации, координации и контроле работ по проектированию и строительству (услуги технического заказика, строительный контроль) | CE6: ='Эс Эй Риччи ПМ_ДД'!E12 -> компания специализируется на организации, координации и контроле работ по проектированию и строительству (услуги технического заказика, строительный контроль) | CF6: ='Эс Эй Риччи ПМ_ДД'!F12 -> компания специализируется на организации, координации и контроле работ по проектированию и строительству (услуги технического заказика, строительный контроль) | CG6: ='Эс Эй Риччи ПМ_ДД'!G12 -> компания специализируется на организации, координации и контроле работ по проектированию и строительству (услуги технического заказика, строительный контроль) | CH6: ='Эс Эй Риччи ПМ_ДД'!H12 -> компания специализируется на организации, координации и контроле работ по проектированию и строительству (услуги технического заказика, строительный контроль) | CI6: Х | CJ6: Х | CK6: Х | CL6: Х | CM6: =Стройконтроль_ДД!G12 -> 98,67/67% | CN6: =Стройконтроль_ДД!H12 -> 115,48/73%
A7: 5 | B7: Проекты компании за последние 5 лет с аналогичным составом и объемом работ (обязательно указать какие работы велись на объекте, какой была роль Участника) | C7: ='СПЕКТРУМ ХОЛДИНГ_ДД'!C13 -> Приложена "2. Справка о перечне и объемах выполнения основных Проектов" | D7: ='СПЕКТРУМ ХОЛДИНГ_ДД'!D13 -> Приложена "2. Справка о перечне и объемах выполнения основных Проектов" | E7: ='СПЕКТРУМ ХОЛДИНГ_ДД'!E13 -> Приложена "2. Справка о перечне и объемах выполнения основных Проектов" | F7: ='СПЕКТРУМ ХОЛДИНГ_ДД'!F13 -> Приложена "2. Справка о перечне и объемах выполнения основных Проектов" | G7: ='СПЕКТРУМ ХОЛДИНГ_ДД'!G13 -> Приложена "2. Справка о перечне и объемах выполнения основных Проектов" | H7: ='СПЕКТРУМ ХОЛДИНГ_ДД'!H13 -> Приложена "2. Справка о перечне и объемах выполнения основных Проектов" | I7: =DBC_ДД!C13 -> СТРЦ "МЕГА Теплый стан" / Управление проектом, Технический заказчик, Строительный контроль, Москва, 400 000 м2. | J7: =DBC_ДД!D13 -> Аэровокзальный комплекс Аэропорта "Геленджик" / Управление проектом, Технический заказчик, Строительный контроль, г. Геленджик, 16 700 м2. | K7: =DBC_ДД!E13 -> ТРЦ "Винный Город" / Управление проектом, Технический заказчик, Строительный контроль, г. Геленджик, 22 000 м2. | L7: =DBC_ДД!F13 -> Офис JetBrains / Строительный контроль, г. Санкт-Петербург, 37 700 м2. | M7: =DBC_ДД!G13 -> Мультифункциональный комплекс «Мир в огне» / Управление проектом, Технический заказчик, Строительный контроль, г. Верхняя Пышма, 42 500 м2. | N7: =DBC_ДД!H13 -> Многофункциональный центр "Охта"/ Строительный контроль, г. Санкт-Петербург, 165 000 м3. | O7: =Nikoliers_ДД!C13 -> Референц лист в приложении к анкете | U7: ='CORE XP_ДД'!C13 -> 1.Револют, г.Спб, 2000 кв.м, Услуги по управлению проектом внутренней отделки помещений. 2.Хоневелл ,г.Мск, управление проектом внутренней отделки, Консультант 3.Озон, г. Мск, офис, Строительный контроль за полным комплексом строительно-монтажных работ по ремонту, в том числе капитальному 4.INNIO, г.Мск, 2 271,4 кв.м , Генеральный подрядчик 5.Porshe Russland , г.Мск, 7500 кв., управление проектом реконструкции 6.AstraZeneca , г.Мск, 2509 кв. м, Управление проектом внутренней отделки | V7: ='CORE XP_ДД'!D13 -> 1.Офис Такеда, г.Мск, 4 800 кв.м, Услуги по управлению проектом переоборудования и косметического ремонта помещений, 2.Офис Альфа-Банк, г.Екатеренбург, 10 546,10 кв.м, Консультант , 3. Hasbro , г. Мск, 1000 кв.м, управление проектом внутренней отделки, 4. АО "ОДК", г.Мск, 6 369кв.м, Технический заказчик, 5.Росбанк, гМск, управление проектом внутренней отделки, | W7: ='CORE XP_ДД'!E13 -> 1. офис Action Development, г.Мск, 23 917 кв.м, управление проектом внутренней отделки, 2.офис IQVIA, г.Мск, 1500 кв ., управление проектом внутренней отделки, 3. Офис Deutsche Bank, г.Мск, 2197,68 кв. м, услуги по техническому аудиту, 4. Офис British Petroleum Russia, г.Мск, 1 720 кв. м, Строительный контроль 5.Офис Viartis , г.Мск, 1113 кв.м | X7: ='CORE XP_ДД'!F13 -> 1.офис Velkom, г.Истра, мск.обл, 21 406 кв.м, Технический заказчик, 2.офис Яндекс.Такси, г.Мск, 6 600 кв.м, Технический заказчик, 3.офис Райффайзенбанк, г.Мск, 34 000 кв.м, Консультант , 4. офис Porsche Russland , г.Мск, 8 610 кв.м, Технический заказчик | Y7: ='CORE XP_ДД'!G13 -> 1. АО «Райффайзенбанк», (Мск, 6 000 кв.м, Технический заказчик, Строительный контроль) 2.Административный офис ПАО «МТС» (Мск, 35 852 кв.м, Технический заказчик) 3. ИТМС(BAT), г.Мск, 4 430 кв.м, услуги по управлению проектом внутренней отделки, | Z7: ='CORE XP_ДД'!H13 -> 1.Офисное помещение ООО "Грэйс Пропертис"(KEPT), (Мск, 10 423 кв.м, Технический заказчик) 2.Офис ООО "Каргилл", (Мск, 1 506 кв.м, технический заказчик) , 3.офис Итерсерч Солюшнс(Яндекс) ,(г.Мск, 3 600 кв.м, Технический заказчик ), 4.Центр подготовки национальной сборной команды по футболу, Российский футбольный союз, г.Мск, Технический заказчик 30 000 кв.м, | AA7: =CMWР_ДД!C13 -> Корпоративный университет НЛМК / строительство (Липецк, 11 000 м2, Тех.Заказчик/Строительный контроль) | AB7: =CMWР_ДД!D13 -> Московский офис компании ОТЭКО / внутренняя отделка помещений (Москва, 9 000 м2, Тех.Заказчик/Строительный контроль) | AC7: =CMWР_ДД!E13 -> Центральный офис компании Nestle по региону СНГ / внутренняя отделка помещений (Москва, 10 000 м2, Тех.Заказчик/Строительный контроль) | AD7: =CMWР_ДД!F13 -> Бизнес-центр ООО ЭКТО, Москва, 18 000 м2, Технический заказчик, стройконтроль) | AE7: =CMWР_ДД!G13 -> ТЦ на Новой Риге ООО ЭКТО/ Московская область, р-н Красногорский, 16 000-22 000 м2 Технический заказчик, стройконтроль) | AG7: =Восход_ДД!C13 -> 1. Жилой комплекс элитного класса, строительство Armani Casa Moscow Residences г. Москва, пер. Старомонетный, 19 (10 400м2, Заказчик-Девелопер) | AH7: =Восход_ДД!D13 -> 1. Жилой комплекс элитного класса, строительство Armani Casa Moscow Residences г. Москва, пер. Старомонетный, 19 (10 400м2, Заказчик-Девелопер) | AI7: =Восход_ДД!E13 -> 1. Жилой комплекс элитного класса, строительство Armani Casa Moscow Residences г. Москва, пер. Старомонетный, 19 (10 400м2, Заказчик-Девелопер) 2. Brusov г. Москва, пер. Брюсов, 2 (8 700м2, Заказчик-Девелопер); | AJ7: =Восход_ДД!F13 -> 1. Жилой комплекс элитного класса, строительство Armani Casa Moscow Residences г. Москва, пер. Старомонетный, 19 (10 400м2, Заказчик-Девелопер) 2. Brusov г. Москва, пер. Брюсов, 2 (8 700м2, Заказчик-Девелопер); 3. AHEAD г. Москва, ул. Василисы Кожиной, 25 (25 000м2, заказчик-девелопер) 4. Cheval Court г. Санкт-Петербург, пл. Конюшенная, 2 (7 400 м2, заказчик-девелопер), | AK7: =Восход_ДД!G13 -> 1. Жилой комплекс элитного класса, строительство Armani Casa Moscow Residences г. Москва, пер. Старомонетный, 19 (10 400м2, Заказчик-Девелопер) 2. Brusov г. Москва, пер. Брюсов, 2 (8 700м2, Заказчик-Девелопер); 3. AHEAD г. Москва, ул. Василисы Кожиной, 25 (25 000м2, заказчик-девелопер) 4. Cheval Court г. Санкт-Петербург, пл. Конюшенная, 2 (7 400 м2, заказчик-девелопер), 5. Nobu Restaurant, Hotel& Residences ОАЭ, Рас-Аль-Хайм (80 000м2); | AL7: =Восход_ДД!H13 -> 1. Жилой комплекс элитного класса, строительство Armani Casa Moscow Residences г. Москва, пер. Старомонетный, 19 (10 400м2, Заказчик-Девелопер) 2. Brusov г. Москва, пер. Брюсов, 2 (8 700м2, Заказчик-Девелопер); 3. AHEAD г. Москва, ул. Василисы Кожиной, 25 (25 000м2, заказчик-девелопер) 4. Cheval Court г. Санкт-Петербург, пл. Конюшенная, 2 (7 400 м2, заказчик-девелопер), 5. Nobu Restaurant, Hotel& Residences ОАЭ, Рас-Аль-Хайм (80 000м2); 6. Центральный Телеграф г. Москва, ул. Тверская, 7 (76 500м2,FEE-DEVELOPER). | AM7: =NFrank_ДД!C13 -> 1. Научно-производственный комплекс «КРУНИТ» / строительство (Мск, 16 000 м2, Строительный контроль) | AN7: =NFrank_ДД!D13 -> 1. Офисные помещения для компании «Альфа-Банк» / отделка офисных помещений (Мск, 3 770 м2, строительный контроль) | AO7: =NFrank_ДД!E13 -> 1. Офисные помещения ПАО «СПБ Биржа» (управление проектом отделки, Мск, 4200 м2) 2. Офисные помещения для компании «Альфа-Банк» (Мск, 3 770 м2, строительный контроль) | AP7: =NFrank_ДД!F13 -> 1. МФК «ЛАХТА ЦЕНТР» (фаза 1) / отделка офисных помещений (Спб, 66 700 м2, строительный контроль) 2. Офисные помещения для компании «Альфа-Банк» / отделка офисных помещений (Екб, 10 550 м2, строительный контроль) 3. Офисные помещения для компании «Альфа-Банк» / отделка офисных помещений (Барнаул, 5 230 м2, строительный контроль) 4. Офисные помещения для компании «Альфа-Банк» / отделка офисных помещений (Ульяновск, 6 000 м2, строительный контроль) | AQ7: =NFrank_ДД!G13 -> 1. Торгово-развлекательный комплекс «Одинцовопарк» / строительство (Московская обл., 32 500 м2, Технический заказчик) 2. Медиацентр "СПАС" / строительство (Мск, 9 400 м2, Технический заказчик) 3. Дом Зингер/ реновация помещений штаб-квартиры компании (Спб, 2 600 м2, управление проектом, строительный контроль) 4. Производственные помещения для биофарм.компании/новое кап.строительство (МО, 18 000 м2) | AR7: =NFrank_ДД!H13 -> 1. Номерной фонд класса «люкс» в гостинице с МФК / строительство (Мск, 33 000 м2, тех. заказчик) 2. Административные помещения для АО «Альфа-Банк» / отделка офисных помещений (Мск, 21 100 м2, строительный контроль) 3. ЖК «G3 Театральный»/ новое кап.строительство (МО, 85 000 м2, строительный контроль | AS7: ='ИК Элемент_ДД'!C13 -> 0 | AT7: ='ИК Элемент_ДД'!D13 -> 1. Услуги Технического эксперта при проведении строительно-монтажных работ по объекту: "Развитие инфраструктуры железнодорожного транспорта общего пользования на станции Людиново-1 Московской железной дороги" 2. Услуги по осуществлению строительного контроля объекта капитального строительства, в помещениях, расположенных по адресу: г. Москва, ул. Большая Молчановка, д. 21А, подвальный, 1, 2, 3 этажи, ООО СТЗ,7 000 м2 3. Услуги Технического эксперта при проведении строительно-монтажных работ по объекту: "Соединительный железнодорожный путь необщего пользования от станции Людиново-1 Московской железной дороги до границы Площадки ОЭЗ ППТ "Калуга". | AU7: ='ИК Элемент_ДД'!E13 -> 1. Функции технического заказчика при проведении проектных и изыскательских работ на объекте, расположенном по адресу: г. Москва, вн. мун. о. Чертанов Южное, ш. Варшавское, влад. 150Б/1, ФудХолл, 3500 м2 2. Услуги по осуществлению строительного контроля объекта капитального строительства: Общедоступная взлетно-посадочная полоса и площадка для вертолетов с общественным терминалом, инфраструктурными зданиями и сооружениями, расположенная по адресу: Республика Крым, с. Уромное, ООО "СБ Девелопмент", 14 000 м2. 3. Услуги по проведению строительного контроля за строительством/ремонтом газопроводов высокого давления и нефтепродуктопроводов, Российская Федерация, Московская область, городской округ Солнечногорск, рабочий посёлок Ржавки, микрорайон № 2, строение 20, вблизи МТРК «Зеленопарк», АШАН. 4. Оказание услуг по строительному контролю при капитальном ремонте объектов подведомственных Москомспорту Учреждений, направленных на развитие объектов спортивной инфраструктуры, 36 объектов споривного назначения, 38 800 м2. | AV7: ='ИК Элемент_ДД'!F13 -> 1. Услуги по выполнению функций технического заказчика по проектированию и капитальному ремонту Объекта: помещения общей площадью 19 668,4 кв. м в зданиях по адресу: г. Москва, ул. Знаменка, д. 7, стр. 3, д. 9, стр. 3, Бизнес-центр. 2. Осуществление функций Технического заказчика, направленные на исполнение Заказчиком функций Технического заказчика на объекте "Гостиничный комплекс «Radisson Blu Resort & Congress Center, Sochi», 43 186 кв.м, 508 номеров. 3. Работы по осуществлению функций технического заказчика и строительного контроля в отношении объекта: «Автоматизированный складской комплекс для хранения мороженой рыбопродукции и морепродуктов», по адресу: Мурманская обл., МО с.п. Междуречье Кольского р-на, с. Минькино, 6000 м2. 4. Услуги строительного контроля за строительством объектов капитального строительства «Черногорский горно-обогатительный комбинат (ГОК). Очередь I. Вскрытие и отработка запасов Черногорского месторождения», Площадь застройки: 282 000 м2. 5. Осуществление строительного контроля за выполнением Подрядчиком отделочных работ на объекте: «Жилой комплекс с дошкольными образовательными учреждениями, школой, надземными паркингами, инженерными сетями и объектами инженерной инфраструктуры, по адресу: г. Москва, НАО, п. Московский, дер. Картмазово уч.16/1, 165 778,8 м2. 6. функций технического заказчика на период выполнения проектно-изыскательских работ и разработать Проектную и Рабочую документацию по Объекту: «Реконструкция АТТК Тойота, расположенного по адресу: г. Москва, с/п Сосенское, 2 887 м2. | AW7: ='ИК Элемент_ДД'!G13 -> 1. Функции строительного контроля технического заказчика Объекта " Деревянные частные виллы-шале с Термальным центром, расположенные на территории Всесезонного курорта «Манжерок», 15 511 м2. 2. Функции строительного контроля за выполнением Проектных работ и строительно-монтажных работ по переоборудованию Объекта и переустройству инженерных систем Объекта "Ситуационного центра SCS, расположенные в здании ПАО Сбербанк, Москва, 2040 м2. 3. Оказание услуг по строительному контролю при выполнении работ на подведомственных Москомспорту Учреждениях, направленных на развитие объектов спортивной инфраструктуры, 39 500 м2. 4. Функции строительного контроля и технического заказчика при реконструкции Объекта: «Городской детский парк имени Щорса» , г. Луганск, 3,5 Га. 5. Осуществление строительного контроля за выполнением строительно-монтажных работ на объекте «Реконструкция объектов морского терминала «Сероглазка» в административных границах Петропавловск-Камчатского морского порта», мощностью 25 тысяч тонн единовременного хранения и пропускной способностью для рефрижераторных грузов – свыше 300 тысяч тонн в год. 6. Управление проектом и выполнение функций технического заказчика и строительного контроля по проекту: «Многофункциональный гостиничный кмоплекс", г. Владивосток, ул. Державина, д. 17», 14 900 м2. 7. Управление проектом и выполнение функций технического заказчика и строительного контроля по проекту:«Многофункциональный гостиничный кмоплекс", г. Калининград, 12 797 м2. 8. Управление проектом и выполнение функций технического заказчика и строительного контроля по проекту:«Многофункциональный гостиничный кмоплекс", г. Кемерово, 17 558 м2. | AX7: ='ИК Элемент_ДД'!H13 -> 1. Услуги по осуществлению функций технического заказчика при проектировании объета ПАО НПО "Наука": Испытательный комплекс 2, Владимирская область, 5187,0 м² 2. Оказание услуг по строительному контролю при выполнение строительно-монтажных работ в недостроенном Жилом комплексе «Сказочный лес», расположенном по адресу: г. Москва, Лосиноостровская ул., вл45к1, 1 корпус - 35535 кв.м.; 2 корпус - 35 674 кв.м.; 3 корпус - 33 307 кв.м.; 4 корпус - 33 653 кв.м., ДДОУ - 2 902 кв.м. 3. Функции технического заказчика и проведение строительного контроля при Реализации первого и второго этапа строительства первой очереди Проекта "Комплексный туристический проект «Новый Шерегеш», 446 номеров, Кемеровская область, 51 000 м2. 4. Услуги по строительному контролю за выполнением работ, в рамках реализации проекта: «Горнодобывающее и перерабатывающее предприятие на базе золоторудного месторождения Хангалас, 5 100 м2. 5. Функции Технического заказчика в части экологического сопровождения Объектов ООПТ «Воробьевы горы», 2 500 м2. 6. Управление проектом и выполнение функций технического заказчика по проекту: «Многофункциональный комплекс, по адресу: Кабардино-Балкарская Республика, Эльбрусский р-н, 39 000 м2. 7.Услуги по осуществлению функций Технического заказчика и строительного контроля строительства ЦОД, Пермь, Площадка включает 2 объекта: 1) здание бывшего цеха (износ 72%) площадью 1471 м2.; 2) земельный участок площадью 1,7 Га. 8. Услуги строительного контроля по организации приемки Объектов и МОП с выполненной Отделкой, комплекс зданий гостиничного типа «Студенческий квартал», включающий в себя 9 корпусов (№№ 1-9) по адресу: г. Москва, Территория инновационного центра «Сколково», 13 212 м2. | AY7: Р172. Предоставление услуг Консультанта по Управлению Проектом (PMC) по обустройству Парусового, Северо-Парусового и Семаковского месторождений», а также разработка ТЭО вариантов обустройства месторождений | AZ7: Р172. Предоставление услуг Консультанта по Управлению Проектом (PMC) по обустройству Парусового, Северо-Парусового и Семаковского месторождений», а также разработка ТЭО вариантов обустройства месторождений | BA7: Р172. Предоставление услуг Консультанта по Управлению Проектом (PMC) по обустройству Парусового, Северо-Парусового и Семаковского месторождений», а также разработка ТЭО вариантов обустройства месторождений | BB7: Р172. Предоставление услуг Консультанта по Управлению Проектом (PMC) по обустройству Парусового, Северо-Парусового и Семаковского месторождений», а также разработка ТЭО вариантов обустройства месторождений.14092. Выполнение услуг консультанта по управлению проектом (PMC) на строительство газохимического комплекса в Ненецком автономном округе РФ | BC7: 14092. Выполнение услуг консультанта по управлению проектом (PMC) на строительство газохимического комплекса в Ненецком автономном округе РФ.А0029 Консультационные услуги по управлению проектом (услуги РМС) от лица Заказчика при строительстве «Находкинского Завода минеральных удобрений» проекта по производству метанола мощностью 5400 тонн в сутки (1,8 млн. тонн в год) в Козьмино, Дальний Восток России | BD7: А0029 Консультационные услуги по управлению проектом (услуги РМС) от лица Заказчика при строительстве «Находкинского Завода минеральных удобрений» проекта по производству метанола мощностью 5400 тонн в сутки (1,8 млн. тонн в год) в Козьмино, Дальний Восток России | BE7: =Ирбис_ДД!C13 -> Референс лист прилагается | BK7: =АКРОН_ДД!C19 -> 1. Функция финтехэксперта (Проект БЦ Poklonka Place 143 тыс м2); 2. Функция стройконтроль (Проект ЖК Мильфей 65 тыс м2) | BL7: =АКРОН_ДД!D19 -> 1. Функция Техзаказчика и строительный контроль. Реконструкция и модернизация внутренних инженерных систем, кап ремонт фасада, комплекс общестроительных работ (БЦ Poklonka Place 143 тыс м2) | BM7: =АКРОН_ДД!E19 -> 1. Функция Техзаказчика и строительный контроль. Реконструкция и модернизация внутренних инженерных систем, кап ремонт фасада, комплекс общестроительных работ (БЦ Poklonka Place 143 тыс м2) | BN7: =АКРОН_ДД!F19 -> 1. Функция Техзаказчика и строительный контроль. Реконструкция и модернизация внутренних инженерных систем, кап ремонт фасада, комплекс общестроительных работ (БЦ Poklonka Place 143 тыс м2) | BO7: =АКРОН_ДД!G19 -> 1. Функция Техзаказчика и строительный контроль. Реконструкция и модернизация внутренних инженерных систем (БЦ Poklonka Place 143 тыс м2) 2. Выполнение функции Технического заказчика нового строительства корпуса (Poklonka II 40 тыс м2) разработка архитектурной концепции, согласование ТЭП, внесение изменений ПЗЗ, заключение договора на Генпроектирование. | BP7: =АКРОН_ДД!H19 -> 1. Функция Техзаказчика и строительный контроль. Реконструкция и модернизация внутренних инженерных систем (БЦ Poklonka Place 143 тыс м2); 2. Выполнение функции Технического заказчика нового строительства корпуса (Poklonka II 40 тыс м2) разработка архитектурной концепции, согласование ТЭП, внесение изменений ПЗЗ, заключение договора на Генпроектирование; 3. Функция Технического заказчика предстроительный этап, формирование ТЭО и Бизнес Плана Проекта Гостиничного комплекса 5* Крым (ЗУ 7 га, ТЭП 25 000 м2) | BQ7: Н/Д | BR7: Н/Д | BS7: Н/Д | BT7: Н/Д | BU7: Н/Д | BV7: Н/Д | BW7: ='РИТМ ПРОЕКТ_ДД'!C13 -> 1.Строительство и отделка здания Гольф клуба / сироительство (МО 6 500 м2, Тех Заказчик, Строительный контроль) 2. «ARTPLAY» Центр дизайна / реконструкция (СПБ 44 763 м2, Тех Заказчик, Строительный контроль) 3. Заводы по производству автомобильных комплектующих / строительство (Тольятти 14 500 м2, Тех Заказчик, Строительный контроль) | BX7: ='РИТМ ПРОЕКТ_ДД'!D13 -> 1. Строительство и отделка здания Гольф клуба / сироительство (МО 6 500 м2, Тех Заказчик, Строительный контроль) 2. «ARTPLAY» Центр дизайна / реконструкция (СПБ 44 763 м2, Тех Заказчик, Строительный контроль) 3. Заводы по производству автомобильных комплектующих / строительство (Тольятти 14 500 м2, Тех Заказчик, Строительный контроль) 4. Многофункциональный комплекс TALAN TOWERS, строительство / (Астана 120 000 м2, Тех консультант)Астана, Казахстан | BY7: ='РИТМ ПРОЕКТ_ДД'!E13 -> 1. «Партнерский центр ООО «Феникс Контакт Рус»» / строительство (МО 22 458 м2, Тех Заказчик, Строительный контроль) 2. Офисы, R&D центры компании Huawei / отделка (Мск, Минск, Новосибирск ... 88 500 м2, Тех Заказчик, Строительный контроль) 3. Строительство и оснащение складского комплекса / строительство (Н. Новгород, Самара, Мск. 51 000 м2 Тех Заказчик, Строительный контроль) | BZ7: ='РИТМ ПРОЕКТ_ДД'!F13 -> 1. «Партнерский центр ООО «Феникс Контакт Рус»» / строительство (МО 22 458 м2, Тех Заказчик, Строительный контроль) 2. Офисы, R&D центры компании Huawei / отделка (Мск, Минск, Новосибирск ... 88 500 м2, Тех Заказчик, Строительный контроль) 3. Строительство и оснащение складского комплекса / строительство (Н. Новгород, Самара, Мск. 51 000 м2 Тех Заказчик, Строительный контроль) | CA7: ='РИТМ ПРОЕКТ_ДД'!G13 -> 1. Федеральный Распределительный центр / строительство (МО 109 000 м2, Тех Заказчик, Строительный контроль) 2. Офисы, R&D центры компании Huawei / отделка (Мск, СПБ 88 500 м2, Тех Заказчик, Строительный контроль) | CB7: ='РИТМ ПРОЕКТ_ДД'!H13 -> 1. Федеральный Распределительный центр / строительство (МО 109 000 м2, Тех Заказчик, Строительный контроль) 2. Офисы, R&D центры компании Huawei / отделка (Мск, СПБ 88 500 м2, Тех Заказчик, Строительный контроль) 3. Офис компании Яндекс / отделка (Ереван, 6000 м2, Тех Заказчик, Строительный контроль) | CC7: ='Эс Эй Риччи ПМ_ДД'!C13 -> ПОЛНЫЙ ПЕРЕЧЕНЬ ПРОЕКТОВ ПРЕДСТАВЛЕН В ОТДЕЛЬНОЙ СПРАВКЕ 1.Банк Зенит (Москва, комплексное управление проектированием, строительством и обустройством, строительный контроль, управление переездом, 11 000 кв. м); 2. ПАО «Банк ВТБ» (ООО «Ланит –Интеграция» Москва, Башня Евразия, Управление проектированием и строительством, 70 000 кв.м.) | CD7: ='Эс Эй Риччи ПМ_ДД'!D13 -> ПОЛНЫЙ ПЕРЕЧЕНЬ ПРОЕКТОВ ПРЕДСТАВЛЕН В ОТДЕЛЬНОЙ СПРАВКЕ ПАО «Банк ВТБ» (ООО «Ланит –Интеграция» Башня Восток, Москва, Управление проектированием и строительством, 8000 кв.м.) | CE7: ='Эс Эй Риччи ПМ_ДД'!E13 -> ПОЛНЫЙ ПЕРЕЧЕНЬ ПРОЕКТОВ ПРЕДСТАВЛЕН В ОТДЕЛЬНОЙ СПРАВКЕ СитиМобил (Москва, комплексное управление проектированием, строительством и обустройством, строительный контроль, управление переездом, 9 655 кв. м | CF7: ='Эс Эй Риччи ПМ_ДД'!F13 -> ПОЛНЫЙ ПЕРЕЧЕНЬ ПРОЕКТОВ ПРЕДСТАВЛЕН В ОТДЕЛЬНОЙ СПРАВКЕ WinLine (ООО "Нацилнальный коневодческий союз, Москва, Комплексное управление проектированием,строительством и обустройством, строительный контроль, 2300 кв.м | CG7: ='Эс Эй Риччи ПМ_ДД'!G13 -> ПОЛНЫЙ ПЕРЕЧЕНЬ ПРОЕКТОВ ПРЕДСТАВЛЕН В ОТДЕЛЬНОЙ СПРАВКЕ Деметра Холдинг (Москва, комплексное управление проектированием,строительством и обустройством, строительный контроль, 8630 кв.м, | CH7: ='Эс Эй Риччи ПМ_ДД'!H13 -> ПОЛНЫЙ ПЕРЕЧЕНЬ ПРОЕКТОВ ПРЕДСТАВЛЕН В ОТДЕЛЬНОЙ СПРАВКЕ 1. Газпром (ООО "Ланит Интеграция", Лахта-Центр, г. Санкт-Петербург 59 000 кв. м.- управление проектом); 2.ТС Интеграция (Москва, Комплексное управление проектированием, строительством и обустройством, строительный контроль, оптимизация стоимости, 9 000 кв. м) 3. УК Уральская сталь (Москва, Разработка стратегии организации рабочего пространства, комплексное управление проектированием, строительством и обустройством, строительный контроль, управление переездом, 3678 кв.м .) 4. Газпромбанк (г. Москва, Озерковская наб. дом 24,1-5 этажи, Комплексное управление проектированием,строительством и обустройством, строительный контроль, 6565 кв.м.) | CI7: Х | CJ7: Х | CK7: Х | CL7: Х | CM7: =Стройконтроль_ДД!G13 -> 1. Объект образования ( 17 790,0 м2, Тех.Заказчик, Строительный контроль) 2. Объект образования (18 974,2 м2) Тех. Заказчик, Строительный контроль) | CN7: =Стройконтроль_ДД!H13 -> 1. Объект образования (166 708,57 м3) Тех.Заказчик, Строительный контроль) 2. Объект образования (78 922 м3) Тех.Заказчик, Строительный контроль) 3. Объект образования (77 842,0 м3) Тех.Заказчик, Строительный контроль)
C31: =C4*1000000 -> 1375550000 | D31: =D4*1000000 -> 1652030000 | E31: =E4*1000000 -> 2331070000 | F31: =F4*1000000 -> 3956000000 | G31: =G4*1000000 -> 4.21919e+09 | H31: =H4*1000000 -> 7517660000 | I31: =I4*1000000 -> 247418000 | J31: =J4*1000000 -> 406151000 | ... N31: =N4*1000000 -> 3599786000 | O31: 0 | P31: 0 | Q31: 0 | R31: 0 | S31: 0 | T31: =T4*1000000 -> 57807000000 | U31: =+U4*1000 -> 2297378000 | V31: =+V4*1000 -> 1384592000 | W31: =+W4*1000 -> 1689445000 | X31: =+X4*1000 -> 1636303000 | Y31: =+Y4*1000 -> 1865216000 | Z31: =+Z4*1000 -> 2515282000 | AA31: =AA4 -> 2029548000 | AB31: =AB4 -> 1674788000 | AC31: =AC4 -> 2307303000 | AD31: =AD4 -> 1833589000 | AE31: =AE4 -> 1988761000 | AF31: =AF4 -> 1871577000 | AG31: =AG4*1000 -> 0 | AH31: =AH4*1000 -> 42500000 | AI31: =AI4*1000 -> 802293000 | AJ31: =AJ4*1000 -> 652037000 | AK31: =AK4*1000 -> 734606000 | AL31: =AL4*1000 -> 450053000 | AM31: =AM4*1000000 -> 221562000 | AN31: =AN4*1000000 -> 297519000 | AO31: =AO4*1000000 -> 445126000 | AP31: =AP4*1000000 -> 612062000 | AQ31: =AQ4*1000000 -> 884979000 | AR31: =AR4*1000000 -> 1176124000 | AS31: =AS4 -> 94079000 | AT31: =AT4 -> 265408000 | AU31: =AU4 -> 258506000 | AV31: =AV4 -> 469899000 | AW31: =AW4 -> 591413000 | AX31: =AX4 -> 976243000 | AY31: =AY4*1000000 -> 215830000 | AZ31: =AZ4*1000000 -> 156880000 | BA31: =BA4*1000000 -> 262860000 | BB31: =BB4*1000000 -> 427810000 | BC31: =BC4*1000000 -> 612920000 | BD31: =BD4*1000000 -> 865580000 | BE31: =BE4*1000000 -> 77270000 | BF31: =BF4*1000000 -> 94930000 | ... CB31: =CB4*1000000 -> 67570000 | CC31: =CC4 -> 27113174 | CD31: =CD4 -> 46839920 | CE31: =CE4 -> 49934413 | CF31: =CF4 -> 30847020 | CG31: =CG4 -> 50203018 | CH31: =CH4 -> 65412051 | CI31: 0 | CJ31: 0 | CK31: 0 | CL31: 0 | CM31: =CM4*1000000 -> 70000000 | CN31: =CN4*1000000 -> 153000000
C32: =SUM(C31:H31) -> 21051500000 | I32: =SUM(I31:N31) -> 6139219000 | O32: =SUM(O31:T31) -> 57807000000 | U32: =SUM(U31:Z31) -> 11388216000 | AA32: =SUM(AA31:AF31) -> 11705566000 | AG32: =SUM(AG31:AL31) -> 2681489000 | AM32: =SUM(AM31:AR31) -> 3637372000 | AS32: =SUM(AS31:AX31) -> 2655548000 | AY32: =SUM(AY31:BD31) -> 2541880000 | BE32: =SUM(BE31:BJ31) -> 1296470000 | BK32: =SUM(BK31:BP31) -> 620180000 | BW32: =SUM(BW31:CB31) -> 632100000 | CC32: =SUM(CC31:CH31) -> 2.703496e+08 | CI32: =SUM(CI31:CN31) -> 223000000
B38: Участник | C38: ИТОГО | D38: 2024 | E38: 2023 | F38: 2022 | G38: 2021 | H38: 2020 | I38: 2019
B39: Спектрум-Холдинг | C39: =SUM(D39:I39) -> 21051.5 | D39: 7517.66 | E39: 4219.19 | F39: 3956 | G39: 2331.07 | H39: 1652.03 | I39: 1375.55 | J39: 21 млрд
B40: Ди Би Си Констракшн | C40: =SUM(D40:I40) -> 6139.219 | D40: 3599.786 | E40: 709.269 | F40: 624.656 | G40: 551.939 | H40: 406.151 | I40: 247.418 | J40: 6 млрд
B41: Николиерс Управление Строительством | C41: =SUM(D41:I41) -> 57807 | D41: 57807 | E41: нет | F41: нет | G41: нет | H41: нет | I41: нет | J41: 57 млрд
B42: КОР ЭКС ПИ | C42: =SUM(D42:I42) -> 11388216 | D42: 2515282 | E42: 1865216 | F42: 1636303 | G42: 1689445 | H42: 1384592 | I42: 2297378 | J42: 11 млрд
B43: Комонвелс Партнершип | C43: =SUM(D43:I43) -> 11705566000 | D43: 1871577000 | E43: 1988761000 | F43: 1833589000 | G43: 2307303000 | H43: 1674788000 | I43: 2029548000 | J43: 11 млрд | BQ43: 70 | BR43: 153
B44: Восход | C44: =SUM(D44:I44) -> 2681489 | D44: 450053 | E44: 734606 | F44: 652037 | G44: 802293 | H44: 42500 | I44: 0 | J44: 2 млрд
B45: НФ Проперти Менеджмент | C45: =SUM(D45:I45) -> 3637.372 | D45: 1176.124 | E45: 884.979 | F45: 612.062 | G45: 445.126 | H45: 297.519 | I45: 221.562 | J45: 3 млрд
B46: Инжиниринговая компания «Элемент» | C46: =SUM(D46:I46) -> 2655548000 | D46: 976243000 | E46: 591413000 | F46: 469899000 | G46: 258506000 | H46: 265408000 | I46: 94079000 | J46: 2 млрд
B47: ИЭС Инжиниринг и Консалтинг | C47: =SUM(D47:I47) -> 2541.88 | D47: 865.58 | E47: 612.92 | F47: 427.81 | G47: 262.86 | H47: 156.88 | I47: 215.83 | J47: 2 млрд
B48: Инжиниринговая корпорация «ИРБИС» | C48: =SUM(D48:I48) -> 1296.47 | D48: 396.34 | E48: 304.22 | F48: 258.66 | G48: 165.05 | H48: 94.93 | I48: 77.27 | J48: 1 млрд
B49: АКРОН Девелопмент | C49: =SUM(D49:I49) -> 620.18 | D49: 299.09 | E49: 117.75 | F49: 48.6 | G49: 68.4 | H49: 68.112 | I49: 18.228 | J49: 0 млрд
B50: ПМК | C50: =SUM(D50:I50) -> 0 | D50: Н/Д | E50: Н/Д | F50: Н/Д | G50: Н/Д | H50: Н/Д | I50: Н/Д | J50: 0 млрд
B51: РИТМ Проект (JLL) | C51: =SUM(D51:I51) -> 632.1 | D51: 67.57 | E51: 62.23 | F51: 59.99 | G51: 150.65 | H51: 160.83 | I51: 130.83 | J51: 0 млрд
B52: Эс Эй Риччи ПМ | C52: =SUM(D52:I52) -> 2.703496e+08 | D52: 65412051 | E52: 50203018 | F52: 30847020 | G52: 49934413 | H52: 46839920 | I52: 27113174 | J52: 0 млрд
B53: Стройконтроль | C53: =SUM(D53:I53) -> 223 | D53: 153 | E53: 70 | F53: Х | G53: Х | H53: Х | I53: Х | J53: 0 млрд

Sheet СПЕКТРУМ ХОЛДИНГ_АС
A1: ЗАКУПОЧНАЯ ПРОЦЕДУРА | C1: Предварительный квалификационный отбор (ПКО) по выбору Управляющей компании/ Технического заказчика для управления проектом по реконструкции комплекса офисных зданий: г. Москва, адресу ул. Маши Порываевой, 34
A2: Полное юридическое наименование участника | C2: Общество с ограниченной ответственностью «Спектрум-Холдинг»
A3: ИНН участника | C3: 7708196924
A4: Форма налогообложения участника, % НДС | C4: 20
A5: Контактное лицо | C5: Наталия Винниченко Менеджер по развитию бизнеса
A6: Телефон | C6: T: +7 (495) 981-6888 | M: +7(926)717-07-94
A7: Электронная почта | C7: E: vinnichenko@spgr.ru
A8: ЗАПОЛНЯТЬ ТОЛЬКО ЖЕЛТЫЕ ЯЧЕЙКИ!
A9: № | B9: Требования к участнику | C9: Соответствие требованиям (ответ поставщика) | D9: Примечание к заполнению / Комментарий поставщика (если необходимо) | F9: Образец заполнения
A10: 1 | B10: Дата создания компании | C10: ДА | D10: 13 мая 2002 года | F10: 2015
A11: 2 | B11: Опыт управления аналогичными проектами по объему и сложности работ в Москве и/или СПб. | C11: ДА | D11: Приложена 2. Справка о перечне и объемах выполнения основных Проектов | F11: да
A12: 3 | B12: Готовность предоставить Резюме на каждого члена команды проекта | C12: ДА | D12: Подтвердить (Резюме на команду готовы предоставить по дополнительному запросу). Пока предоставили штатное расписание и количество сотрудников НОПРИЗ и НОСТРОЙ | F12: да
A13: 4 | B13: Готовность выделить на проект не менее 10 членов команды соответствующего профиля | C13: ДА | D13: Подтвердить | F13: да
A14: 5 | B14: Отсутствие проблемной налоговой и/или кредитной задолженности. | C14: ДА | D14: Приложение информационное письмо об отсутствии кредитов и спрвка ИФНС | F14: да
A15: 6 | B15: Отсутствие судебных споров в качестве ответчика. | C15: ДА | D15: Приложена справка Судебные споры СХ на 04.07.2025. | F15: да

Sheet СПЕКТРУМ ХОЛДИНГ_ДД
A1: ЗАКУПОЧНАЯ ПРОЦЕДУРА | C1: Предварительный квалификационный отбор (ПКО) по выбору Управляющей компании/ Технического заказчика для управления проектом по реконструкции комплекса офисных зданий: г. Москва, адресу ул. Маши Порываевой, 34
A2: Полное юридическое наименование участника | C2: Общество с ограниченной ответственностью «Спектрум-Холдинг»
A3: ИНН участника | C3: 7708196924
A4: Форма налогообложения участника, % НДС | C4: 20
A5: Контактное лицо | C5: Наталия Винниченко Менеджер по развитию бизнеса
A6: Телефон | C6: T: +7 (495) 981-6888 | M: +7(926)717-07-94
A7: Электронная почта | C7: E: vinnichenko@spgr.ru
A8: ЗАПОЛНЯТЬ ТОЛЬКО ЖЕЛТЫЕ ЯЧЕЙКИ!
A9: № | B9: Требования к участнику | C9: 2019 | D9: 2020 | E9: 2021 | F9: 2022 | G9: 2023 | H9: 2024 | I9: Образец заполнения
A10: 1 | B10: Годовой оборот компании (юр. лицо участника тендера) не менее 500 млн руб. | C10: 1375.55 | D10: 1652.03 | E10: 2331.07 | F10: 3956 | G10: 4219.19 | H10: 7517.66 | I10: 545.25
A11: 2 | B11: Годовой оборот Группы компаний (если юр. лицо участника тендера входит в группу компаний), млн руб. | C11: 1655.3 | D11: 1884.69 | E11: 2561.34 | F11: 4235.15 | G11: 4647.93 | H11: 7884.32 | I11: 5647.1
A12: 3 | B12: Доля выручки от управления проектами (алогичными по объему и сложности работ) по отношению к общей выручке Участника за год (в абсолютном (млн. руб.) и относительном (%) выражении) | C12: 397.12 | D12: 356,66 | E12: 547,01 | F12: 660,88 | G12: 890,05 | H12: 1203,26 | I12: 125,34 / 22%
A13: 5 | B13: Проекты компании за последние 5 лет с аналогичным составом и объемом работ (обязательно указать какие работы велись на объекте, какой была роль Участника) | C13: Приложена "2. Справка о перечне и объемах выполнения основных Проектов" | D13: Приложена "2. Справка о перечне и объемах выполнения основных Проектов" | E13: Приложена "2. Справка о перечне и объемах выполнения основных Проектов" | F13: Приложена "2. Справка о перечне и объемах выполнения основных Проектов" | G13: Приложена "2. Справка о перечне и объемах выполнения основных Проектов" | H13: Приложена "2. Справка о перечне и объемах выполнения основных Проектов" | I13: 1. Образовательный комплекс "Рога и копыта" / строительство (Мск, 45 350 м2, Тех. Заказчик, Строительный контроль) 2. Здание Музея невозможных наук/ реставрацяи и ревитализация (Спб, 28 500 м2, Управляющая компания) …

Sheet DBC_АС
A1: ЗАКУПОЧНАЯ ПРОЦЕДУРА | C1: Предварительный квалификационный отбор (ПКО) по выбору Управляющей компании/ Технического заказчика для управления проектом по реконструкции комплекса офисных зданий: г. Москва, адресу ул. Маши Порываевой, 34
A2: Полное юридическое наименование участника | C2: Общество с ограниченной ответсвенность "Ди Би Си Констракшн"
A3: ИНН участника | C3: 7734663357
A4: Форма налогообложения участника, % НДС | C4: Общая система налогообложения, 20%
A5: Контактное лицо | C5: Харитонов Владимир Дмитриевич
A6: Телефон | C6: 8(963)628-94-25
A7: Электронная почта | C7: Vladimir.Haritonov@dbc.ru
A8: ЗАПОЛНЯТЬ ТОЛЬКО ЖЕЛТЫЕ ЯЧЕЙКИ!
A9: № | B9: Требования к участнику | C9: Соответствие требованиям (ответ поставщика) | D9: Примечание к заполнению / Комментарий поставщика (если необходимо)
A10: 1 | B10: Дата создания компании | C10: ДА | D10: 2011 г.
A11: 2 | B11: Опыт управления аналогичными проектами по объему и сложности работ в Москве и/или СПб. | C11: ДА | D11: -
A12: 3 | B12: Готовность предоставить Резюме на каждого члена команды проекта | C12: ДА | D12: Прилагается
A13: 4 | B13: Готовность выделить на проект не менее 10 членов команды соответствующего профиля | C13: ДА | D13: Подтверждаем
A14: 5 | B14: Отсутствие проблемной налоговой и/или кредитной задолженности. | C14: ДА | D14: Отсуствует
A15: 6 | B15: Отсутствие судебных споров в качестве ответчика. | C15: НЕТ | D15: 1 судебный спор на текущий момент с поставщиком. В справке подробно прилагается.

Sheet DBC_ДД
A1: ЗАКУПОЧНАЯ ПРОЦЕДУРА | C1: Предварительный квалификационный отбор (ПКО) по выбору Управляющей компании/ Технического заказчика для управления проектом по реконструкции комплекса офисных зданий: г. Москва, адресу ул. Маши Порываевой, 34
A2: Полное юридическое наименование участника | C2: Общество с ограниченной ответсвенность "Ди Би Си Констракшн"
A3: ИНН участника | C3: 7734663357
A4: Форма налогообложения участника, % НДС | C4: Общая система налогообложения, 20%
A5: Контактное лицо | C5: Харитонов Владимир Дмитриевич
A6: Телефон | C6: 8(963)628-94-25
A7: Электронная почта | C7: Vladimir.Haritonov@dbc.ru
A8: ЗАПОЛНЯТЬ ТОЛЬКО ЖЕЛТЫЕ ЯЧЕЙКИ!
A9: № | B9: Требования к участнику | C9: 2019 | D9: 2020 | E9: 2021 | F9: 2022 | G9: 2023 | H9: 2024
A10: 1 | B10: Годовой оборот компании (юр. лицо участника тендера) не менее 500 млн руб. | C10: 247.418 | D10: 406.151 | E10: 551.939 | F10: 624.656 | G10: 709.269 | H10: 3599.786
A11: 2 | B11: Годовой оборот Группы компаний (если юр. лицо участника тендера входит в группу компаний), млн руб.
A12: 3 | B12: Доля выручки от управления проектами (алогичными по объему и сложности работ) по отношению к общей выручке Участника за год (в абсолютном (млн. руб.) и относительном (%) выражении) | C12: 247.418 | D12: 406.151 | E12: 551.939 | F12: 624.656 | G12: 570.41 | H12: 956.04
A13: 5 | B13: Проекты компании за последние 5 лет с аналогичным составом и объемом работ (обязательно указать какие работы велись на объекте, какой была роль Участника) | C13: СТРЦ "МЕГА Теплый стан" / Управление проектом, Технический заказчик, Строительный контроль, Москва, 400 000 м2. | D13: Аэровокзальный комплекс Аэропорта "Геленджик" / Управление проектом, Технический заказчик, Строительный контроль, г. Геленджик, 16 700 м2. | E13: ТРЦ "Винный Город" / Управление проектом, Технический заказчик, Строительный контроль, г. Геленджик, 22 000 м2. | F13: Офис JetBrains / Строительный контроль, г. Санкт-Петербург, 37 700 м2. | G13: Мультифункциональный комплекс «Мир в огне» / Управление проектом, Технический заказчик, Строительный контроль, г. Верхняя Пышма, 42 500 м2. | H13: Многофункциональный центр "Охта"/ Строительный контроль, г. Санкт-Петербург, 165 000 м3.

Sheet Nikoliers_АС
A1: ЗАКУПОЧНАЯ ПРОЦЕДУРА | C1: Предварительный квалификационный отбор (ПКО) по выбору Управляющей компании/ Технического заказчика для управления проектом по реконструкции комплекса офисных зданий: г. Москва, адресу ул. Маши Порываевой, 34
A2: Полное юридическое наименование участника | C2: ООО "Николиерс Управление Строительством"
A3: ИНН участника | C3: 9703145119
A4: Форма налогообложения участника, % НДС | C4: НДС
A5: Контактное лицо | C5: Эрген Виктория_Специалист по работе с тендерами
A6: Телефон | C6: 89165844345
A7: Электронная почта | C7: victoria.ergen@nikoliers.ru
A8: ЗАПОЛНЯТЬ ТОЛЬКО ЖЕЛТЫЕ ЯЧЕЙКИ!
A9: № | B9: Требования к участнику | C9: Соответствие требованиям (ответ поставщика) | D9: Примечание к заполнению / Комментарий поставщика (если необходимо) | F9: Образец заполнения
A10: 1 | B10: Дата создания компании | C10: ДА | D10: 45056 | F10: 2015
A11: 2 | B11: Опыт управления аналогичными проектами по объему и сложности работ в Москве и/или СПб. | C11: ДА | D11: Подтвердить | F11: да
A12: 3 | B12: Готовность предоставить Резюме на каждого члена команды проекта | C12: ДА | D12: Подтвердить (Резюме на команду приложить отдельным файлом, форма заполнения - свободная) | F12: да
A13: 4 | B13: Готовность выделить на проект не менее 10 членов команды соответствующего профиля | C13: ДА | D13: Подтвердить | F13: да
A14: 5 | B14: Отсутствие проблемной налоговой и/или кредитной задолженности. | C14: ДА | D14: Подтвердить | F14: да
A15: 6 | B15: Отсутствие судебных споров в качестве ответчика. | C15: ДА | D15: Подтвердить | F15: да

Sheet Nikoliers_ДД
A1: ЗАКУПОЧНАЯ ПРОЦЕДУРА | C1: Предварительный квалификационный отбор (ПКО) по выбору Управляющей компании/ Технического заказчика для управления проектом по реконструкции комплекса офисных зданий: г. Москва, адресу ул. Маши Порываевой, 34
A2: Полное юридическое наименование участника | C2: ООО "Николиерс Управление Строительством"
A3: ИНН участника | C3: 9703145119
A4: Форма налогообложения участника, % НДС | C4: НДС
A5: Контактное лицо | C5: Эрген Виктория_Специалист по работе с тендерами
A6: Телефон | C6: 89165844345
A7: Электронная почта | C7: victoria.ergen@nikoliers.ru
A8: ЗАПОЛНЯТЬ ТОЛЬКО ЖЕЛТЫЕ ЯЧЕЙКИ!
A9: № | B9: Требования к участнику | C9: 2019 | D9: 2020 | E9: 2021 | F9: 2022 | G9: 2023 | H9: 2024 | I9: Образец заполнения
A10: 1 | B10: Годовой оборот компании (юр. лицо участника тендера) не менее 500 млн руб. | C10: нет | D10: нет | E10: нет | F10: нет | G10: нет | H10: 57807 | I10: 545.25
A11: 2 | B11: Годовой оборот Группы компаний (если юр. лицо участника тендера входит в группу компаний), млн руб. | C11: 1611074 | D11: 1632230 | E11: 1427034 | F11: 1417502 | G11: 1620219 | H11: 2345936 | I11: 5647.1
A12: 3 | B12: Доля выручки от управления проектами (алогичными по объему и сложности работ) по отношению к общей выручке Участника за год (в абсолютном (млн. руб.) и относительном (%) выражении) | C12: будет направлено позднее | I12: 125,34 / 22%
A13: 5 | B13: Проекты компании за последние 5 лет с аналогичным составом и объемом работ (обязательно указать какие работы велись на объекте, какой была роль Участника) | C13: Референц лист в приложении к анкете | I13: 1. Образовательный комплекс "Рога и копыта" / строительство (Мск, 45 350 м2, Тех. Заказчик, Строительный контроль) 2. Здание Музея невозможных наук/ реставрацяи и ревитализация (Спб, 28 500 м2, Управляющая компания) …

Sheet CORE XP_АС
A1: ЗАКУПОЧНАЯ ПРОЦЕДУРА | C1: Предварительный квалификационный отбор (ПКО) по выбору Управляющей компании/ Технического заказчика для управления проектом по реконструкции комплекса офисных зданий: г. Москва, адресу ул. Маши Порываевой, 34
A2: Полное юридическое наименование участника | C2: Общество с ограниченной ответственностью «КОР ЭКС ПИ»
A3: ИНН участника | C3: 7714624720
A4: Форма налогообложения участника, % НДС | C4: Общая система налогооблажения, 20% НДС
A5: Контактное лицо | C5: Каплун Михаил Всеволодович
A6: Телефон | C6: 7 495 258 39 90
A7: Электронная почта | C7: michael.kaplun@core-xp.ru
A8: ЗАПОЛНЯТЬ ТОЛЬКО ЖЕЛТЫЕ ЯЧЕЙКИ!
A9: № | B9: Требования к участнику | C9: Соответствие требованиям (ответ поставщика) | D9: Примечание к заполнению / Комментарий поставщика (если необходимо) | F9: Образец заполнения
A10: 1 | B10: Дата создания компании | C10: С 08.11.2005 по 10.01.2007 - ООО "Эн Джи Холдинг" С 11.01.2007 по 11.04.2022 - ООО "Си Би Ричард Эллис", 2022-по настоящее время - ООО "КОР ЭКС ПИ" | D10: Указать дату создания компании, если входит в группу компаний или была переименована- указать! | F10: 2015
A11: 2 | B11: Опыт управления аналогичными проектами по объему и сложности работ в Москве и/или СПб. | C11: ДА | D11: Подтвердить | F11: да
A12: 3 | B12: Готовность предоставить Резюме на каждого члена команды проекта | C12: ДА | D12: Подтвердить (Резюме на команду приложить отдельным файлом, форма заполнения - свободная) | F12: да
A13: 4 | B13: Готовность выделить на проект не менее 10 членов команды соответствующего профиля | C13: ДА | D13: Подтвердить | F13: да
A14: 5 | B14: Отсутствие проблемной налоговой и/или кредитной задолженности. | C14: ДА | D14: Подтвердить | F14: да
A15: 6 | B15: Отсутствие судебных споров в качестве ответчика. | C15: ДА | D15: Подтвердить | F15: да

Sheet CORE XP_ДД
A1: ЗАКУПОЧНАЯ ПРОЦЕДУРА | C1: Предварительный квалификационный отбор (ПКО) по выбору Управляющей компании/ Технического заказчика для управления проектом по реконструкции комплекса офисных зданий: г. Москва, адресу ул. Маши Порываевой, 34
A2: Полное юридическое наименование участника | C2: Общество с ограниченной ответственностью «КОР ЭКС ПИ»
A3: ИНН участника | C3: 7714624720
A4: Форма налогообложения участника, % НДС | C4: Общая система налогооблажения, 20% НДС
A5: Контактное лицо | C5: Каплун Михаил Всеволодович
A6: Телефон | C6: 7 495 258 39 90
A7: Электронная почта | C7: michael.kaplun@core-xp.ru
A8: ЗАПОЛНЯТЬ ТОЛЬКО ЖЕЛТЫЕ ЯЧЕЙКИ!
A9: № | B9: Требования к участнику | C9: 2019 | D9: 2020 | E9: 2021 | F9: 2022 | G9: 2023 | H9: 2024 | I9: Образец заполнения
A10: 1 | B10: Годовой оборот компании (юр. лицо участника тендера) не менее 500 млн руб. | C10: 2297378 | D10: 1384592 | E10: 1689445 | F10: 1636303 | G10: 1865216 | H10: 2515282 | I10: 545.25
A11: 2 | B11: Годовой оборот Группы компаний (если юр. лицо участника тендера входит в группу компаний), млн руб. | C11: нет | D11: нет | E11: нет | F11: нет | G11: нет | H11: нет | I11: 5647.1
A12: 3 | B12: Доля выручки от управления проектами (алогичными по объему и сложности работ) по отношению к общей выручке Участника за год (в абсолютном (млн. руб.) и относительном (%) выражении) | C12: 187174/8,15% | D12: 162021/11,70% | E12: 201021/11,90% | F12: 237113/14,49% | G12: 206651/11,08% | H12: 346835/13,79% | I12: 125,34 / 22%
A13: 5 | B13: Проекты компании за последние 5 лет с аналогичным составом и объемом работ (обязательно указать какие работы велись на объекте, какой была роль Участника) | C13: 1.Револют, г.Спб, 2000 кв.м, Услуги по управлению проектом внутренней отделки помещений. 2.Хоневелл ,г.Мск, управление проектом внутренней отделки, Консультант 3.Озон, г. Мск, офис, Строительный контроль за полным комплексом строительно-монтажных работ по ремонту, в том числе капитальному 4.INNIO, г.Мск, 2 271,4 кв.м , Генеральный подрядчик 5.Porshe Russland , г.Мск, 7500 кв., управление проектом реконструкции 6.AstraZeneca , г.Мск, 2509 кв. м, Управление проектом внутренней отделки | D13: 1.Офис Такеда, г.Мск, 4 800 кв.м, Услуги по управлению проектом переоборудования и косметического ремонта помещений, 2.Офис Альфа-Банк, г.Екатеренбург, 10 546,10 кв.м, Консультант , 3. Hasbro , г. Мск, 1000 кв.м, управление проектом внутренней отделки, 4. АО "ОДК", г.Мск, 6 369кв.м, Технический заказчик, 5.Росбанк, гМск, управление проектом внутренней отделки, | E13: 1. офис Action Development, г.Мск, 23 917 кв.м, управление проектом внутренней отделки, 2.офис IQVIA, г.Мск, 1500 кв ., управление проектом внутренней отделки, 3. Офис Deutsche Bank, г.Мск, 2197,68 кв. м, услуги по техническому аудиту, 4. Офис British Petroleum Russia, г.Мск, 1 720 кв. м, Строительный контроль 5.Офис Viartis , г.Мск, 1113 кв.м | F13: 1.офис Velkom, г.Истра, мск.обл, 21 406 кв.м, Технический заказчик, 2.офис Яндекс.Такси, г.Мск, 6 600 кв.м, Технический заказчик, 3.офис Райффайзенбанк, г.Мск, 34 000 кв.м, Консультант , 4. офис Porsche Russland , г.Мск, 8 610 кв.м, Технический заказчик | G13: 1. АО «Райффайзенбанк», (Мск, 6 000 кв.м, Технический заказчик, Строительный контроль) 2.Административный офис ПАО «МТС» (Мск, 35 852 кв.м, Технический заказчик) 3. ИТМС(BAT), г.Мск, 4 430 кв.м, услуги по управлению проектом внутренней отделки, | H13: 1.Офисное помещение ООО "Грэйс Пропертис"(KEPT), (Мск, 10 423 кв.м, Технический заказчик) 2.Офис ООО "Каргилл", (Мск, 1 506 кв.м, технический заказчик) , 3.офис Итерсерч Солюшнс(Яндекс) ,(г.Мск, 3 600 кв.м, Технический заказчик ), 4.Центр подготовки национальной сборной команды по футболу, Российский футбольный союз, г.Мск, Технический заказчик 30 000 кв.м, | I13: 1. Образовательный комплекс "Рога и копыта" / строительство (Мск, 45 350 м2, Тех. Заказчик, Строительный контроль) 2. Здание Музея невозможных наук/ реставрацяи и ревитализация (Спб, 28 500 м2, Управляющая компания) …

Sheet CMWР_АС
