Workbook

Sheet Смета ЕР (общ) 
F1: Формат объекта | P1: курс $ | Q1: 81
F2: дверной | G2: Адрес объекта: | H2: г. Москва, ул. Маши Порываевой, д. 34 | P2: курс Евро | Q2: 95
F3: Плoщадь объекта (м.кв.): | G3: Плащадь объекта: | H3: - | P3: Дисконт по тендеру | Q3: 0
F4: Срок проведения работ | G4: Срок проведения работ | H4: Согласно план-графику производства работ | P4: курс Юань | Q4: 10.94
F5: ПОДРЯДЧИК: | G5: ПОДРЯДЧИК:
F6: Юридический адрес: | G6: Юридический адрес:
F7: Электронный адрес: | G7: Электронный адрес:
F8: Контактное лицо (Ф.И.О.) : | G8: Контактное лицо (Ф.И.О.) :
F9: Контактный телефон: | G9: Контактный телефон:
F10: Реквизиты: | G10: Реквизиты:
F11: Сумма по смете: | G11: Сумма по смете: | H11: =N1708 -> 0
A14: Раздел | B14: Подраздел | C14: Подраздел подраздела | D14: Пункт подраздела | E14: Новый номенклатурный номер | F14: № | G14: Наименование работ и затрат | H14: Един. изм. | I14: Кол - во. (объем) | J14: ЕР цена работ, руб.* | K14: ЕР цена материалов и оборудования, руб.* | L14: Цена работ, руб. * | M14: Цена материалов и оборудования, руб. * | N14: Стоимость работ, руб. * | O14: Стоимость материалов и оборудования руб. * | P14: Примечание | T14: Кол - во. (объем)
A15: Р1 | B15: 0 | D15: 0 | E15: =CONCATENATE('Смета ЕР (общ) '!$A15,".",'Смета ЕР (общ) '!$B15,".",'Смета ЕР (общ) '!$D15) -> Р1.0.0 | F15: 1 | G15: Раздел №1. Проектные работы и согласования | N15: =ROUND(N16,2) -> 0 | O15: =ROUND(O16,2) -> 0 | T15: 1498
A16: Р1 | B16: 1 | D16: 0 | E16: =CONCATENATE('Смета ЕР (общ) '!$A16,".",'Смета ЕР (общ) '!$B16,".",'Смета ЕР (общ) '!$D16) -> Р1.1.0 | F16: =IF(I16>0,F15+1,F15) -> 1 | G16: 1.1.0 Проектные работы и согласования | N16: =SUM(N17:N108) -> 0 | O16: =SUM(O17:O108) -> 0 | T16: 1498
A17: Р1 | B17: 1 | D17: 1 | E17: =CONCATENATE('Смета ЕР (общ) '!$A17,".",'Смета ЕР (общ) '!$B17,".",'Смета ЕР (общ) '!$D17) -> Р1.1.1 | F17: =IF(I17>0,F16+1,F16) -> 1 | G17: Техническое обследование состояния несущих конструкций помещения с подготовкой рекомендаций по усилению (Техничесекое заключение о конструктиве - "ТЗК") (для помещений от 100 до 450 м.кв) | H17: м2 | J17: ='[14]Проектирование 100-450'!E36*1.05 -> 3675 | K17: 0 | L17: =ROUND(J17-J17*$Q$3,2) -> 3675 | M17: =ROUND(K17-K17*$Q$3,2) -> 0 | N17: =ROUND('Смета ЕР (общ) '!$I17*'Смета ЕР (общ) '!$L17,2) -> 0 | O17: =ROUND('Смета ЕР (общ) '!$I17*'Смета ЕР (общ) '!$M17,2) -> 0
A18: Р1 | B18: 1 | D18: 44 | E18: =CONCATENATE('Смета ЕР (общ) '!$A18,".",'Смета ЕР (общ) '!$B18,".",'Смета ЕР (общ) '!$D18) -> Р1.1.44 | F18: =IF(I18>0,F17+1,F17) -> 1 | G18: Эскизный проект фасада и Колористический паспорт с указанием ведомости отделки и проектным решением со спецификацией элементов (крыльцо, пандус, навесы, колонны и т.д.)(для фасадов от 100 до 450 м.кв) | H18: м2 | J18: ='[14]Проектирование 100-450'!E37*1.05 -> 7822.5 | K18: 0 | L18: =ROUND(J18-J18*$Q$3,2) -> 7822.5 | M18: =ROUND(K18-K18*$Q$3,2) -> 0 | N18: =ROUND('Смета ЕР (общ) '!$I18*'Смета ЕР (общ) '!$L18,2) -> 0 | O18: =ROUND('Смета ЕР (общ) '!$I18*'Смета ЕР (общ) '!$M18,2) -> 0
A19: Р1 | B19: 1 | D19: 2 | E19: =CONCATENATE('Смета ЕР (общ) '!$A19,".",'Смета ЕР (общ) '!$B19,".",'Смета ЕР (общ) '!$D19) -> Р1.1.2 | F19: =IF(I19>0,F18+1,F18) -> 1 | G19: Рабочая документация по усилению/устройству несущих конструкций ("КР"), включая пояснительную записку (для помещений от 100 до 450 м.кв) | H19: м2 | J19: ='[14]Проектирование 100-450'!E18*1.05 -> 135.45 | K19: 0 | L19: =ROUND(J19-J19*$Q$3,2) -> 135.45 | M19: =ROUND(K19-K19*$Q$3,2) -> 0 | N19: =ROUND('Смета ЕР (общ) '!$I19*'Смета ЕР (общ) '!$L19,2) -> 0 | O19: =ROUND('Смета ЕР (общ) '!$I19*'Смета ЕР (общ) '!$M19,2) -> 0
A20: Р1 | B20: 1 | D20: 3 | E20: =CONCATENATE('Смета ЕР (общ) '!$A20,".",'Смета ЕР (общ) '!$B20,".",'Смета ЕР (общ) '!$D20) -> Р1.1.3 | F20: =IF(I20>0,F19+1,F19) -> 1 | G20: Рабочая документация "Архитектурные решения" ("АР"), включая пояснительную записку (для помещений от 100 до 450 м.кв) | H20: м2 | J20: ='[14]Проектирование 100-450'!E19*1.05 -> 389.55 | K20: 0 | L20: =ROUND(J20-J20*$Q$3,2) -> 389.55 | M20: =ROUND(K20-K20*$Q$3,2) -> 0 | N20: =ROUND('Смета ЕР (общ) '!$I20*'Смета ЕР (общ) '!$L20,2) -> 0 | O20: =ROUND('Смета ЕР (общ) '!$I20*'Смета ЕР (общ) '!$M20,2) -> 0 | T20: 214
A21: Р1 | B21: 1 | D21: 4 | E21: =CONCATENATE('Смета ЕР (общ) '!$A21,".",'Смета ЕР (общ) '!$B21,".",'Смета ЕР (общ) '!$D21) -> Р1.1.4 | F21: =IF(I21>0,F20+1,F20) -> 1 | G21: Рабочая документация по электроснабжению и электроосвещению ("ЭОМ"), включая пояснительную записку (для помещений от 100 до 450 м.кв) | H21: м2 | J21: ='[14]Проектирование 100-450'!E20*1.05 -> 258.3 | K21: 0 | L21: =ROUND(J21-J21*$Q$3,2) -> 258.3 | M21: =ROUND(K21-K21*$Q$3,2) -> 0 | N21: =ROUND('Смета ЕР (общ) '!$I21*'Смета ЕР (общ) '!$L21,2) -> 0 | O21: =ROUND('Смета ЕР (общ) '!$I21*'Смета ЕР (общ) '!$M21,2) -> 0 | T21: 214
A22: Р1 | B22: 1 | D22: 5 | E22: =CONCATENATE('Смета ЕР (общ) '!$A22,".",'Смета ЕР (общ) '!$B22,".",'Смета ЕР (общ) '!$D22) -> Р1.1.5 | F22: =IF(I22>0,F21+1,F21) -> 1 | G22: Рабочая документация Системы вентиляции ("ОВиК-В"), включая пояснительную записку (для помещений от 100 до 450 м.кв) | H22: м2 | J22: ='[14]Проектирование 100-450'!E21*1.05 -> 202.65 | K22: 0 | L22: =ROUND(J22-J22*$Q$3,2) -> 202.65 | M22: =ROUND(K22-K22*$Q$3,2) -> 0 | N22: =ROUND('Смета ЕР (общ) '!$I22*'Смета ЕР (общ) '!$L22,2) -> 0 | O22: =ROUND('Смета ЕР (общ) '!$I22*'Смета ЕР (общ) '!$M22,2) -> 0 | T22: 214
A23: Р1 | B23: 1 | D23: 6 | E23: =CONCATENATE('Смета ЕР (общ) '!$A23,".",'Смета ЕР (общ) '!$B23,".",'Смета ЕР (общ) '!$D23) -> Р1.1.6 | F23: =IF(I23>0,F22+1,F22) -> 1 | G23: Рабочая документация Системы кондиционирования ("ОВиК-К"), включая пояснительную записку (для помещений от 100 до 450 м.кв) | H23: м2 | J23: ='[14]Проектирование 100-450'!E22*1.05 -> 159.4845 | K23: 0 | L23: =ROUND(J23-J23*$Q$3,2) -> 159.48 | M23: =ROUND(K23-K23*$Q$3,2) -> 0 | N23: =ROUND('Смета ЕР (общ) '!$I23*'Смета ЕР (общ) '!$L23,2) -> 0 | O23: =ROUND('Смета ЕР (общ) '!$I23*'Смета ЕР (общ) '!$M23,2) -> 0 | T23: 214
A24: Р1 | B24: 1 | D24: 7 | E24: =CONCATENATE('Смета ЕР (общ) '!$A24,".",'Смета ЕР (общ) '!$B24,".",'Смета ЕР (общ) '!$D24) -> Р1.1.7 | F24: =IF(I24>0,F23+1,F23) -> 1 | G24: Рабочая документация Системы отопления ("ОВиК-О"), включая Пояснительную записку и Теплотехнический расчет (для помещений от 100 до 450 м.кв) | H24: м2 | J24: ='[14]Проектирование 100-450'!E23*1.05 -> 123.9 | K24: 0 | L24: =ROUND(J24-J24*$Q$3,2) -> 123.9 | M24: =ROUND(K24-K24*$Q$3,2) -> 0 | N24: =ROUND('Смета ЕР (общ) '!$I24*'Смета ЕР (общ) '!$L24,2) -> 0 | O24: =ROUND('Смета ЕР (общ) '!$I24*'Смета ЕР (общ) '!$M24,2) -> 0 | T24: 214
A25: Р1 | B25: 1 | D25: 8 | E25: =CONCATENATE('Смета ЕР (общ) '!$A25,".",'Смета ЕР (общ) '!$B25,".",'Смета ЕР (общ) '!$D25) -> Р1.1.8 | F25: =IF(I25>0,F24+1,F24) -> 1 | G25: Рабочая документация Системы водоснабжения и канализации ("ВК"), включая пояснительную записку (для помещений от 100 до 450 м.кв) | H25: м2 | J25: ='[14]Проектирование 100-450'!E24*1.05 -> 130.2 | K25: 0 | L25: =ROUND(J25-J25*$Q$3,2) -> 130.2 | M25: =ROUND(K25-K25*$Q$3,2) -> 0 | N25: =ROUND('Смета ЕР (общ) '!$I25*'Смета ЕР (общ) '!$L25,2) -> 0 | O25: =ROUND('Смета ЕР (общ) '!$I25*'Смета ЕР (общ) '!$M25,2) -> 0 | T25: 214
A26: Р1 | B26: 1 | D26: 9 | E26: =CONCATENATE('Смета ЕР (общ) '!$A26,".",'Смета ЕР (общ) '!$B26,".",'Смета ЕР (общ) '!$D26) -> Р1.1.9 | F26: =IF(I26>0,F25+1,F25) -> 1 | G26: Рабочая документация Системы автоматической установки водяного пожаротушения ("АУВПТ"), (спринкерная, дренчерная, модульная система), включая пояснительную записку (для помещений от 100 до 450 м.кв) | H26: м2 | J26: ='[14]Проектирование 100-450'!E25*1.05 -> 91.6755 | K26: 0 | L26: =ROUND(J26-J26*$Q$3,2) -> 91.68 | M26: =ROUND(K26-K26*$Q$3,2) -> 0 | N26: =ROUND('Смета ЕР (общ) '!$I26*'Смета ЕР (общ) '!$L26,2) -> 0 | O26: =ROUND('Смета ЕР (общ) '!$I26*'Смета ЕР (общ) '!$M26,2) -> 0
A27: Р1 | B27: 1 | D27: 43 | E27: =CONCATENATE('Смета ЕР (общ) '!$A27,".",'Смета ЕР (общ) '!$B27,".",'Смета ЕР (общ) '!$D27) -> Р1.1.43 | F27: =IF(I27>0,F26+1,F26) -> 1 | G27: Рабочая документация Системы Внутреннего противопожарного водопровода ("ВПВ"), включая пояснительную записку (для помещений от 100 до 450 м.кв) | H27: м2 | J27: ='[14]Проектирование 100-450'!E26*1.05 -> 91.6755 | K27: 0 | L27: =ROUND(J27-J27*$Q$3,2) -> 91.68 | M27: =ROUND(K27-K27*$Q$3,2) -> 0 | N27: =ROUND('Смета ЕР (общ) '!$I27*'Смета ЕР (общ) '!$L27,2) -> 0 | O27: =ROUND('Смета ЕР (общ) '!$I27*'Смета ЕР (общ) '!$M27,2) -> 0
A28: Р1 | B28: 1 | D28: 10 | E28: =CONCATENATE('Смета ЕР (общ) '!$A28,".",'Смета ЕР (общ) '!$B28,".",'Смета ЕР (общ) '!$D28) -> Р1.1.10 | F28: =IF(I28>0,F27+1,F27) -> 1 | G28: Рабочая документация Системы дымоудаления ("ДУ"), включая пояснительную записку (для помещений от 100 до 450 м.кв) | H28: м2 | J28: ='[14]Проектирование 100-450'!E27*1.05 -> 103.95 | K28: 0 | L28: =ROUND(J28-J28*$Q$3,2) -> 103.95 | M28: =ROUND(K28-K28*$Q$3,2) -> 0 | N28: =ROUND('Смета ЕР (общ) '!$I28*'Смета ЕР (общ) '!$L28,2) -> 0 | O28: =ROUND('Смета ЕР (общ) '!$I28*'Смета ЕР (общ) '!$M28,2) -> 0
A29: Р1 | B29: 1 | D29: 11 | E29: =CONCATENATE('Смета ЕР (общ) '!$A29,".",'Смета ЕР (общ) '!$B29,".",'Смета ЕР (общ) '!$D29) -> Р1.1.11 | F29: =IF(I29>0,F28+1,F28) -> 1 | G29: Рабочая документация "Автоматическая пожарная сигнализация" (АПС) | H29: м2 | J29: ='[14]АПС, СОУЭ, ППА'!F13*1.05*0.1 -> 7.035 | K29: 0 | L29: =ROUND(J29-J29*$Q$3,2) -> 7.04 | M29: =ROUND(K29-K29*$Q$3,2) -> 0 | N29: =ROUND('Смета ЕР (общ) '!$I29*'Смета ЕР (общ) '!$L29,2) -> 0 | O29: =ROUND('Смета ЕР (общ) '!$I29*'Смета ЕР (общ) '!$M29,2) -> 0
A30: Р1 | B30: 1 | D30: 25 | E30: =CONCATENATE('Смета ЕР (общ) '!$A30,".",'Смета ЕР (общ) '!$B30,".",'Смета ЕР (общ) '!$D30) -> Р1.1.25 | F30: =IF(I30>0,F29+1,F29) -> 1 | G30: Рабочая документация "Система оповещения и управления эвакуацией людей при пожаре" (СОУЭ) | H30: м2 | J30: ='[14]АПС, СОУЭ, ППА'!F14*1.05*0.1 -> 4.095 | K30: 0 | L30: =ROUND(J30-J30*$Q$3,2) -> 4.1 | M30: =ROUND(K30-K30*$Q$3,2) -> 0 | N30: =ROUND('Смета ЕР (общ) '!$I30*'Смета ЕР (общ) '!$L30,2) -> 0 | O30: =ROUND('Смета ЕР (общ) '!$I30*'Смета ЕР (общ) '!$M30,2) -> 0
A31: Р1 | B31: 1 | D31: 26 | E31: =CONCATENATE('Смета ЕР (общ) '!$A31,".",'Смета ЕР (общ) '!$B31,".",'Смета ЕР (общ) '!$D31) -> Р1.1.26 | F31: =IF(I31>0,F30+1,F30) -> 1 | G31: Рабочая документация "Автоматизация системы внутреннего противопожарного водопровода (ВПВ) | H31: м2 | J31: ='[14]АПС, СОУЭ, ППА'!F16*1.05*0.1 -> 0.84 | K31: 0 | L31: =ROUND(J31-J31*$Q$3,2) -> 0.84 | M31: =ROUND(K31-K31*$Q$3,2) -> 0 | N31: =ROUND('Смета ЕР (общ) '!$I31*'Смета ЕР (общ) '!$L31,2) -> 0 | O31: =ROUND('Смета ЕР (общ) '!$I31*'Смета ЕР (общ) '!$M31,2) -> 0
A32: Р1 | B32: 1 | D32: 29 | E32: =CONCATENATE('Смета ЕР (общ) '!$A32,".",'Смета ЕР (общ) '!$B32,".",'Смета ЕР (общ) '!$D32) -> Р1.1.29 | F32: =IF(I32>0,F31+1,F31) -> 1 | G32: Рабочая документация "Автоматизация системы противодымной вентиляции (ПДВ")" | H32: м2 | J32: ='[14]АПС, СОУЭ, ППА'!F17*1.05*0.1 -> 2.625 | K32: 0 | L32: =ROUND(J32-J32*$Q$3,2) -> 2.63 | M32: =ROUND(K32-K32*$Q$3,2) -> 0 | N32: =ROUND('Смета ЕР (общ) '!$I32*'Смета ЕР (общ) '!$L32,2) -> 0 | O32: =ROUND('Смета ЕР (общ) '!$I32*'Смета ЕР (общ) '!$M32,2) -> 0
A33: Р1 | B33: 1 | D33: 30 | E33: =CONCATENATE('Смета ЕР (общ) '!$A33,".",'Смета ЕР (общ) '!$B33,".",'Смета ЕР (общ) '!$D33) -> Р1.1.30 | F33: =IF(I33>0,F32+1,F32) -> 1 | G33: Рабочая документация "Автоматизация Системы отопления, вентиляции и кондиционирования (ОВиК)" | H33: м2 | J33: ='[14]АПС, СОУЭ, ППА'!F18*1.05*0.1 -> 0.315 | K33: 0 | L33: =ROUND(J33-J33*$Q$3,2) -> 0.32 | M33: =ROUND(K33-K33*$Q$3,2) -> 0 | N33: =ROUND('Смета ЕР (общ) '!$I33*'Смета ЕР (общ) '!$L33,2) -> 0 | O33: =ROUND('Смета ЕР (общ) '!$I33*'Смета ЕР (общ) '!$M33,2) -> 0
A34: Р1 | B34: 1 | D34: 31 | E34: =CONCATENATE('Смета ЕР (общ) '!$A34,".",'Смета ЕР (общ) '!$B34,".",'Смета ЕР (общ) '!$D34) -> Р1.1.31 | F34: =IF(I34>0,F33+1,F33) -> 1 | G34: Рабочая документация "Автоматизация Системы аварийного освещения (АО)" | H34: м2 | J34: ='[14]АПС, СОУЭ, ППА'!F19*1.05*0.1 -> 0.105 | K34: 0 | L34: =ROUND(J34-J34*$Q$3,2) -> 0.11 | M34: =ROUND(K34-K34*$Q$3,2) -> 0 | N34: =ROUND('Смета ЕР (общ) '!$I34*'Смета ЕР (общ) '!$L34,2) -> 0 | O34: =ROUND('Смета ЕР (общ) '!$I34*'Смета ЕР (общ) '!$M34,2) -> 0
A35: Р1 | B35: 1 | D35: 33 | E35: =CONCATENATE('Смета ЕР (общ) '!$A35,".",'Смета ЕР (общ) '!$B35,".",'Смета ЕР (общ) '!$D35) -> Р1.1.33 | F35: =IF(I35>0,F34+1,F34) -> 1 | G35: Рабочая документация "Автоматизации лифтовового хозяйства" | H35: м2 | J35: ='[14]АПС, СОУЭ, ППА'!F20*1.05*0.1 -> 0.105 | K35: 0 | L35: =ROUND(J35-J35*$Q$3,2) -> 0.11 | M35: =ROUND(K35-K35*$Q$3,2) -> 0 | N35: =ROUND('Смета ЕР (общ) '!$I35*'Смета ЕР (общ) '!$L35,2) -> 0 | O35: =ROUND('Смета ЕР (общ) '!$I35*'Смета ЕР (общ) '!$M35,2) -> 0
A36: Р1 | B36: 1 | D36: 36 | E36: =CONCATENATE('Смета ЕР (общ) '!$A36,".",'Смета ЕР (общ) '!$B36,".",'Смета ЕР (общ) '!$D36) -> Р1.1.36 | F36: =IF(I36>0,F35+1,F35) -> 1 | G36: Рабочая документация "Автоматизации Системы контроля управления доступом (СКУД)" | H36: м2 | J36: ='[14]АПС, СОУЭ, ППА'!F21*1.05*0.1 -> 0.105 | K36: 0 | L36: =ROUND(J36-J36*$Q$3,2) -> 0.11 | M36: =ROUND(K36-K36*$Q$3,2) -> 0 | N36: =ROUND('Смета ЕР (общ) '!$I36*'Смета ЕР (общ) '!$L36,2) -> 0 | O36: =ROUND('Смета ЕР (общ) '!$I36*'Смета ЕР (общ) '!$M36,2) -> 0
A37: Р1 | B37: 1 | D37: 37 | E37: =CONCATENATE('Смета ЕР (общ) '!$A37,".",'Смета ЕР (общ) '!$B37,".",'Смета ЕР (общ) '!$D37) -> Р1.1.37 | F37: =IF(I37>0,F36+1,F36) -> 1 | G37: Техническое обследование состояния несущих конструкций помещения с подготовкой рекомендаций по усилению в зоне расположения депозитария, кассового узла и банкоматов (Техничесекое заключение о конструктиве - "ТЗК")(для помещений менее 100 м.кв) | H37: м2 | J37: ='[14]Проектирование до 100'!E35*1.05 -> 3675 | K37: 0 | L37: =ROUND(J37-J37*$Q$3,2) -> 3675 | M37: =ROUND(K37-K37*$Q$3,2) -> 0 | N37: =ROUND('Смета ЕР (общ) '!$I37*'Смета ЕР (общ) '!$L37,2) -> 0 | O37: =ROUND('Смета ЕР (общ) '!$I37*'Смета ЕР (общ) '!$M37,2) -> 0
A38: Р1 | B38: 1 | D38: 45 | E38: =CONCATENATE('Смета ЕР (общ) '!$A38,".",'Смета ЕР (общ) '!$B38,".",'Смета ЕР (общ) '!$D38) -> Р1.1.45 | F38: =IF(I38>0,F37+1,F37) -> 1 | G38: Эскизный проект фасада и колористический паспорт с указанием ведомости отделки и проектным решением со спецификацией элементов (крыльцо, пандус, навесы, колонны и т.д.)(для фасадов менее 100 м.кв) | H38: кв.м.площади фасада | J38: ='[14]Проектирование до 100'!E36*1.05 -> 7822.5 | K38: 0 | L38: =ROUND(J38-J38*$Q$3,2) -> 7822.5 | M38: =ROUND(K38-K38*$Q$3,2) -> 0 | N38: =ROUND('Смета ЕР (общ) '!$I38*'Смета ЕР (общ) '!$L38,2) -> 0 | O38: =ROUND('Смета ЕР (общ) '!$I38*'Смета ЕР (общ) '!$M38,2) -> 0
A39: Р1 | B39: 1 | D39: 46 | E39: =CONCATENATE('Смета ЕР (общ) '!$A39,".",'Смета ЕР (общ) '!$B39,".",'Смета ЕР (общ) '!$D39) -> Р1.1.46 | F39: =IF(I39>0,F38+1,F38) -> 1 | G39: Рабочая документация по усилению/устройству несущих конструкций ("КР"), включая пояснительную записку (для помещений менее 100 м.кв) | H39: компл. | J39: ='[14]Проектирование до 100'!E17*1.05 -> 10500 | K39: 0 | L39: =ROUND(J39-J39*$Q$3,2) -> 10500 | M39: =ROUND(K39-K39*$Q$3,2) -> 0 | N39: =ROUND('Смета ЕР (общ) '!$I39*'Смета ЕР (общ) '!$L39,2) -> 0 | O39: =ROUND('Смета ЕР (общ) '!$I39*'Смета ЕР (общ) '!$M39,2) -> 0
A40: Р1 | B40: 1 | D40: 47 | E40: =CONCATENATE('Смета ЕР (общ) '!$A40,".",'Смета ЕР (общ) '!$B40,".",'Смета ЕР (общ) '!$D40) -> Р1.1.47 | F40: =IF(I40>0,F39+1,F39) -> 1 | G40: Рабочая документация "Архитектурные решения" ("АР"), включая пояснительную записку (для помещений менее 100 м.кв) | H40: компл. | J40: ='[14]Проектирование до 100'!E18*1.05 -> 20737.5 | K40: 0 | L40: =ROUND(J40-J40*$Q$3,2) -> 20737.5 | M40: =ROUND(K40-K40*$Q$3,2) -> 0 | N40: =ROUND('Смета ЕР (общ) '!$I40*'Смета ЕР (общ) '!$L40,2) -> 0 | O40: =ROUND('Смета ЕР (общ) '!$I40*'Смета ЕР (общ) '!$M40,2) -> 0
A41: Р1 | B41: 1 | D41: 48 | E41: =CONCATENATE('Смета ЕР (общ) '!$A41,".",'Смета ЕР (общ) '!$B41,".",'Смета ЕР (общ) '!$D41) -> Р1.1.48 | F41: =IF(I41>0,F40+1,F40) -> 1 | G41: Рабочая документация по электроснабжению и электроосвещению ("ЭОМ"), включая пояснительную записку (для помещений менее 100 м.кв) | H41: компл. | J41: ='[14]Проектирование до 100'!E19*1.05 -> 20737.5 | K41: 0 | L41: =ROUND(J41-J41*$Q$3,2) -> 20737.5 | M41: =ROUND(K41-K41*$Q$3,2) -> 0 | N41: =ROUND('Смета ЕР (общ) '!$I41*'Смета ЕР (общ) '!$L41,2) -> 0 | O41: =ROUND('Смета ЕР (общ) '!$I41*'Смета ЕР (общ) '!$M41,2) -> 0
A42: Р1 | B42: 1 | D42: 49 | E42: =CONCATENATE('Смета ЕР (общ) '!$A42,".",'Смета ЕР (общ) '!$B42,".",'Смета ЕР (общ) '!$D42) -> Р1.1.49 | F42: =IF(I42>0,F41+1,F41) -> 1 | G42: Рабочая документация Системы вентиляции ("ОВиК-В"), включая пояснительную записку (для помещений менее 100 м.кв) | H42: компл. | J42: ='[14]Проектирование до 100'!E20*1.05 -> 15592.5 | K42: 0 | L42: =ROUND(J42-J42*$Q$3,2) -> 15592.5 | M42: =ROUND(K42-K42*$Q$3,2) -> 0 | N42: =ROUND('Смета ЕР (общ) '!$I42*'Смета ЕР (общ) '!$L42,2) -> 0 | O42: =ROUND('Смета ЕР (общ) '!$I42*'Смета ЕР (общ) '!$M42,2) -> 0
...
