Workbook

Sheet Смета 1-й этаж
G4: Формат объекта | I4: Инфраструктура | O4: курс $ | P4: 70
G5: Адрес объекта: | H5: Адрес объекта: | S5: Выбрать значение из списка | AP5: не считать электрику
G6: Плoщадь объекта (м.кв.): | H6: Плащадь объекта: | R6: Электрическая мощность объекта | S6: не считать электрику | AP6: до 33 кВт включ., автомат до 63А включ.
G7: Срок проведения работ | H7: Срок проведения работ | AP7: от 33 кВт до 40 кВт включ., автомат от 63А до 80А включ.
G8: ПОДРЯДЧИК: | H8: ПОДРЯДЧИК: | AP8: от 40 кВт до 60 кВт включ., автомат от 80А до 125А включ.
G9: Юридический адрес: | H9: Юридический адрес: | S9: Выбрать значение из списка | AP9: нет
G10: Электронный адрес: | H10: Электронный адрес: | R10: Наличие на объекте АВР | S10: от 40 кВт до 60 кВт включ., автомат от 80А до 125А включ. | AP10: до 33 кВт включ., автомат до 63А включ.
G11: Контактное лицо (Ф.И.О.) : | H11: Контактное лицо (Ф.И.О.) : | AP11: от 33 кВт до 40 кВт включ., автомат от 63А до 80А включ.
G12: Контактный телефон: | H12: Контактный телефон: | S12: Выбрать значение из списка | AP12: от 40 кВт до 60 кВт включ., автомат от 80А до 125А включ.
G13: Реквизиты: | H13: Реквизиты: | R13: Наличие на объекте ИБП | S13: да | AP13: да
G14: Сумма по смете: | H14: Сумма по смете: | AP14: нет
A16: Новый номенклатурный номер | B16: Номер строки | C16: Раздел | D16: Подраздел | E16: Пункт подраздела | F16: Новый номенклатурный номер | G16: № | H16: Наименование работ и затрат | I16: Един. изм. | J16: Кол - во. (объем) | K16: Цена работ, руб., в т.ч. НДС | L16: Цена материалов и оборудования, руб., в т.ч. НДС | M16: Стоимость работ, руб., в т.ч. НДС | N16: Стоимость материалов и оборудования руб., в т.ч. НДС | O16: Уточнение УОС | P16: Уточнение для ПЭУ | S16: Перед отправкой смету фильтровать по Кол-у | AQ16: "Специальные" работы | AR16: Стоимость "специальных" рпбот
A17: =CONCATENATE('Смета 1-й этаж'!$C17,".",'Смета 1-й этаж'!$D17,".",'Смета 1-й этаж'!$E17) -> Р1.0.0 | B17: 1 | C17: Р1 | D17: 0 | E17: 0 | F17: =CONCATENATE('Смета 1-й этаж'!$C17,".",'Смета 1-й этаж'!$D17,".",'Смета 1-й этаж'!$E17) -> Р1.0.0 | G17: 1 | H17: Раздел №1. Проектные работы и согласования | J17: =J18 -> 0 | M17: =ROUND(M18,2) -> 0 | N17: =ROUND(N18,2) -> 0
A18: =CONCATENATE('Смета 1-й этаж'!$C18,".",'Смета 1-й этаж'!$D18,".",'Смета 1-й этаж'!$E18) -> Р1.1.0 | B18: 2 | C18: Р1 | D18: 1 | E18: 0 | F18: =CONCATENATE('Смета 1-й этаж'!$C18,".",'Смета 1-й этаж'!$D18,".",'Смета 1-й этаж'!$E18) -> Р1.1.0 | G18: 2 | H18: Проектные работы и согласования | J18: =SUM(J19:J51) -> 0 | M18: =SUM(M19:M55) -> 0 | N18: =SUM(N19:N55) -> 0 | P18: новый подраздел
A19: =CONCATENATE('Смета 1-й этаж'!$C19,".",'Смета 1-й этаж'!$D19,".",'Смета 1-й этаж'!$E19) -> Р1.0.1 | B19: 3 | C19: Р1 | D19: 0 | E19: 1 | F19: =CONCATENATE('Смета 1-й этаж'!$C19,".",'Смета 1-й этаж'!$D19,".",'Смета 1-й этаж'!$E19) -> Р1.0.1 | G19: =IF(J19>0,G18+1,G18) -> 2 | H19: Техническое обследование состояния несущих конструкций помещения с подготовкой рекомендаций по усилению (Техничесекое заключение о конструктиве - "ТЗК") | I19: кв.м.площади офиса | K19: 350 | M19: =ROUND('Смета 1-й этаж'!$J19*'Смета 1-й этаж'!$K19,2) -> 0 | N19: =ROUND('Смета 1-й этаж'!$J19*'Смета 1-й этаж'!$L19,2) -> 0
C20: Р1 | D20: 0 | E20: 40 | F20: =CONCATENATE('Смета 1-й этаж'!$C20,".",'Смета 1-й этаж'!$D20,".",'Смета 1-й этаж'!$E20) -> Р1.0.40 | G20: =IF(J20>0,G19+1,G19) -> 2 | H20: Техническое обследование состояния несущих конструкций помещения с подготовкой рекомендаций по усилению в зоне расположения депозитария, кассового узла и банкоматов (Техничесекое заключение о конструктиве - "ТЗК") | I20: шт | K20: 65000 | L20: 0 | M20: =ROUND('Смета 1-й этаж'!$J20*'Смета 1-й этаж'!$K20,2) -> 0 | N20: =ROUND('Смета 1-й этаж'!$J20*'Смета 1-й этаж'!$L20,2) -> 0 | P20: новая позиция
A21: =CONCATENATE('Смета 1-й этаж'!$C21,".",'Смета 1-й этаж'!$D21,".",'Смета 1-й этаж'!$E21) -> Р1.0.2 | B21: 4 | C21: Р1 | D21: 0 | E21: 2 | F21: =CONCATENATE('Смета 1-й этаж'!$C21,".",'Смета 1-й этаж'!$D21,".",'Смета 1-й этаж'!$E21) -> Р1.0.2 | G21: =IF(J21>0,G20+1,G20) -> 2 | H21: Рабочая документация по усилению/устройству несущих конструкций ("КР"), включая пояснительную записку | I21: кв.м.площади офиса | K21: 70.5 | M21: =ROUND('Смета 1-й этаж'!$J21*'Смета 1-й этаж'!$K21,2) -> 0 | N21: =ROUND('Смета 1-й этаж'!$J21*'Смета 1-й этаж'!$L21,2) -> 0
A22: =CONCATENATE('Смета 1-й этаж'!$C22,".",'Смета 1-й этаж'!$D22,".",'Смета 1-й этаж'!$E22) -> Р1.0.3 | B22: 5 | C22: Р1 | D22: 0 | E22: 3 | F22: =CONCATENATE('Смета 1-й этаж'!$C22,".",'Смета 1-й этаж'!$D22,".",'Смета 1-й этаж'!$E22) -> Р1.0.3 | G22: =IF(J22>0,G21+1,G21) -> 2 | H22: Рабочая документация "Архитектурные решения" ("АР"), включая пояснительную записку | I22: кв.м.площади офиса | K22: 240 | M22: =ROUND('Смета 1-й этаж'!$J22*'Смета 1-й этаж'!$K22,2) -> 0 | N22: =ROUND('Смета 1-й этаж'!$J22*'Смета 1-й этаж'!$L22,2) -> 0 | AQ22: 57388084
A23: =CONCATENATE('Смета 1-й этаж'!$C23,".",'Смета 1-й этаж'!$D23,".",'Смета 1-й этаж'!$E23) -> Р1.0.4 | B23: 6 | C23: Р1 | D23: 0 | E23: 4 | F23: =CONCATENATE('Смета 1-й этаж'!$C23,".",'Смета 1-й этаж'!$D23,".",'Смета 1-й этаж'!$E23) -> Р1.0.4 | G23: =IF(J23>0,G22+1,G22) -> 2 | H23: Рабочая документация по электроснабжению и электроосвещению ("ЭОМ"), включая пояснительную записку | I23: кв.м.площади офиса | K23: 201.6 | M23: =ROUND('Смета 1-й этаж'!$J23*'Смета 1-й этаж'!$K23,2) -> 0 | N23: =ROUND('Смета 1-й этаж'!$J23*'Смета 1-й этаж'!$L23,2) -> 0 | AQ23: 26471538
A24: =CONCATENATE('Смета 1-й этаж'!$C24,".",'Смета 1-й этаж'!$D24,".",'Смета 1-й этаж'!$E24) -> Р1.0.5 | B24: 7 | C24: Р1 | D24: 0 | E24: 5 | F24: =CONCATENATE('Смета 1-й этаж'!$C24,".",'Смета 1-й этаж'!$D24,".",'Смета 1-й этаж'!$E24) -> Р1.0.5 | G24: =IF(J24>0,G23+1,G23) -> 2 | H24: Рабочая документация Системы вентиляции ("ОВиК-В"), включая пояснительную записку | I24: кв.м.площади офиса | K24: 86.4 | M24: =ROUND('Смета 1-й этаж'!$J24*'Смета 1-й этаж'!$K24,2) -> 0 | N24: =ROUND('Смета 1-й этаж'!$J24*'Смета 1-й этаж'!$L24,2) -> 0 | AQ24: =SUBTOTAL(9,AQ22:AQ23) -> 83859622
A25: =CONCATENATE('Смета 1-й этаж'!$C25,".",'Смета 1-й этаж'!$D25,".",'Смета 1-й этаж'!$E25) -> Р1.0.6 | B25: 8 | C25: Р1 | D25: 0 | E25: 6 | F25: =CONCATENATE('Смета 1-й этаж'!$C25,".",'Смета 1-й этаж'!$D25,".",'Смета 1-й этаж'!$E25) -> Р1.0.6 | G25: =IF(J25>0,G24+1,G24) -> 2 | H25: Рабочая документация Системы кондиционирования ("ОВиК-К"), включая пояснительную записку | I25: кв.м.площади офиса | K25: 79.2 | M25: =ROUND('Смета 1-й этаж'!$J25*'Смета 1-й этаж'!$K25,2) -> 0 | N25: =ROUND('Смета 1-й этаж'!$J25*'Смета 1-й этаж'!$L25,2) -> 0 | AQ25: 82281575
A26: =CONCATENATE('Смета 1-й этаж'!$C26,".",'Смета 1-й этаж'!$D26,".",'Смета 1-й этаж'!$E26) -> Р1.0.7 | B26: 9 | C26: Р1 | D26: 0 | E26: 7 | F26: =CONCATENATE('Смета 1-й этаж'!$C26,".",'Смета 1-й этаж'!$D26,".",'Смета 1-й этаж'!$E26) -> Р1.0.7 | G26: =IF(J26>0,G25+1,G25) -> 2 | H26: Рабочая документация Системы отопления ("ОВиК-О"), включая Пояснительную записку и Теплотехнический расчет | I26: кв.м.площади офиса | K26: 64.8 | M26: =ROUND('Смета 1-й этаж'!$J26*'Смета 1-й этаж'!$K26,2) -> 0 | N26: =ROUND('Смета 1-й этаж'!$J26*'Смета 1-й этаж'!$L26,2) -> 0 | AQ26: =AQ24-AQ25 -> 1578046.9
A27: =CONCATENATE('Смета 1-й этаж'!$C27,".",'Смета 1-й этаж'!$D27,".",'Смета 1-й этаж'!$E27) -> Р1.0.8 | B27: 10 | C27: Р1 | D27: 0 | E27: 8 | F27: =CONCATENATE('Смета 1-й этаж'!$C27,".",'Смета 1-й этаж'!$D27,".",'Смета 1-й этаж'!$E27) -> Р1.0.8 | G27: =IF(J27>0,G26+1,G26) -> 2 | H27: Рабочая документация Системы водоснабжения и канализации ("ВК"), включая пояснительную записку | I27: кв.м.площади офиса | K27: 100.8 | M27: =ROUND('Смета 1-й этаж'!$J27*'Смета 1-й этаж'!$K27,2) -> 0 | N27: =ROUND('Смета 1-й этаж'!$J27*'Смета 1-й этаж'!$L27,2) -> 0
A28: =CONCATENATE('Смета 1-й этаж'!$C28,".",'Смета 1-й этаж'!$D28,".",'Смета 1-й этаж'!$E28) -> Р1.0.9 | B28: 11 | C28: Р1 | D28: 0 | E28: 9 | F28: =CONCATENATE('Смета 1-й этаж'!$C28,".",'Смета 1-й этаж'!$D28,".",'Смета 1-й этаж'!$E28) -> Р1.0.9 | G28: =IF(J28>0,G27+1,G27) -> 2 | H28: Эскизный проект фасада и колористический паспорт с указанием ведомости отделки и проектным решением со спецификацией элементов (крыльцо, пандус, навесы, колонны и т.д.) | I28: кв.м.площади офиса | K28: 69.25 | M28: =ROUND('Смета 1-й этаж'!$J28*'Смета 1-й этаж'!$K28,2) -> 0 | N28: =ROUND('Смета 1-й этаж'!$J28*'Смета 1-й этаж'!$L28,2) -> 0
A29: =CONCATENATE('Смета 1-й этаж'!$C29,".",'Смета 1-й этаж'!$D29,".",'Смета 1-й этаж'!$E29) -> Р1.0.10 | B29: 12 | C29: Р1 | D29: 0 | E29: 10 | F29: =CONCATENATE('Смета 1-й этаж'!$C29,".",'Смета 1-й этаж'!$D29,".",'Смета 1-й этаж'!$E29) -> Р1.0.10 | G29: =IF(J29>0,G28+1,G28) -> 2 | H29: Рабочая документация Системы автматической установки водяного пожаротушения ("АУВПТ"), (сплинкерная, дренчерная, модульная система), включая пояснительную записку | I29: кв.м.площади офиса | K29: 100.8 | M29: =ROUND('Смета 1-й этаж'!$J29*'Смета 1-й этаж'!$K29,2) -> 0 | N29: =ROUND('Смета 1-й этаж'!$J29*'Смета 1-й этаж'!$L29,2) -> 0
B30: 38 | C30: Р2 | D30: 0 | E30: 43 | F30: =CONCATENATE('Смета 1-й этаж'!$C30,".",'Смета 1-й этаж'!$D30,".",'Смета 1-й этаж'!$E30) -> Р2.0.43 | G30: =IF(J30>0,G29+1,G29) -> 2 | H30: Испытания системы внутреннего противопожарного водопровода аккредитованной организацией (ВПВ и АУПТ). | I30: компл. | K30: 7500 | M30: =ROUND('Смета 1-й этаж'!$J30*'Смета 1-й этаж'!$K30,2) -> 0 | N30: =ROUND('Смета 1-й этаж'!$J30*'Смета 1-й этаж'!$L30,2) -> 0 | P30: новая позиция
A31: =CONCATENATE('Смета 1-й этаж'!$C31,".",'Смета 1-й этаж'!$D31,".",'Смета 1-й этаж'!$E31) -> Р1.0.11 | B31: 13 | C31: Р1 | D31: 0 | E31: 11 | F31: =CONCATENATE('Смета 1-й этаж'!$C31,".",'Смета 1-й этаж'!$D31,".",'Смета 1-й этаж'!$E31) -> Р1.0.11 | G31: =IF(J31>0,G30+1,G30) -> 2 | H31: Рабочая документация Системы Внутреннего противопожарного водопровода ("ВПВ"), включая пояснительную записку | I31: кв.м.площади офиса | K31: 43.2 | M31: =ROUND('Смета 1-й этаж'!$J31*'Смета 1-й этаж'!$K31,2) -> 0 | N31: =ROUND('Смета 1-й этаж'!$J31*'Смета 1-й этаж'!$L31,2) -> 0
A32: =CONCATENATE('Смета 1-й этаж'!$C32,".",'Смета 1-й этаж'!$D32,".",'Смета 1-й этаж'!$E32) -> Р1.0.12 | B32: 14 | C32: Р1 | D32: 0 | E32: 12 | F32: =CONCATENATE('Смета 1-й этаж'!$C32,".",'Смета 1-й этаж'!$D32,".",'Смета 1-й этаж'!$E32) -> Р1.0.12 | G32: =IF(J32>0,G31+1,G31) -> 2 | H32: Стоимость согласования проекта перепланировки/реставрации объекта культурного наследия в соответствии с нормативными актами г.______________. | I32: кв.м.площади офиса | K32: 0 | L32: 0 | M32: =ROUND('Смета 1-й этаж'!$J32*'Смета 1-й этаж'!$K32,2) -> 0 | N32: =ROUND('Смета 1-й этаж'!$J32*'Смета 1-й этаж'!$L32,2) -> 0
A33: =CONCATENATE('Смета 1-й этаж'!$C33,".",'Смета 1-й этаж'!$D33,".",'Смета 1-й этаж'!$E33) -> Р1.0.13 | B33: 15 | C33: Р1 | D33: 0 | E33: 13 | F33: =CONCATENATE('Смета 1-й этаж'!$C33,".",'Смета 1-й этаж'!$D33,".",'Смета 1-й этаж'!$E33) -> Р1.0.13 | G33: =IF(J33>0,G32+1,G32) -> 2 | H33: Стоимость согласования проекта перепланировки/реконструкции объекта в соответствии с нормативными актами г.Москва. | I33: кв.м.площади офиса | K33: 150 | M33: =ROUND('Смета 1-й этаж'!$J33*'Смета 1-й этаж'!$K33,2) -> 0 | N33: =ROUND('Смета 1-й этаж'!$J33*'Смета 1-й этаж'!$L33,2) -> 0
A34: =CONCATENATE('Смета 1-й этаж'!$C34,".",'Смета 1-й этаж'!$D34,".",'Смета 1-й этаж'!$E34) -> Р1.0.14 | B34: 16 | C34: Р1 | D34: 0 | E34: 14 | F34: =CONCATENATE('Смета 1-й этаж'!$C34,".",'Смета 1-й этаж'!$D34,".",'Смета 1-й этаж'!$E34) -> Р1.0.14 | G34: =IF(J34>0,G33+1,G33) -> 2 | H34: Получение паспорта БТИ (в черных линиях) | I34: кв.м.площади офиса | K34: 171.924 | M34: =ROUND('Смета 1-й этаж'!$J34*'Смета 1-й этаж'!$K34,2) -> 0 | N34: =ROUND('Смета 1-й этаж'!$J34*'Смета 1-й этаж'!$L34,2) -> 0
A35: =CONCATENATE('Смета 1-й этаж'!$C35,".",'Смета 1-й этаж'!$D35,".",'Смета 1-й этаж'!$E35) -> Р1.0.15 | B35: 17 | C35: Р1 | D35: 0 | E35: 15 | F35: =CONCATENATE('Смета 1-й этаж'!$C35,".",'Смета 1-й этаж'!$D35,".",'Смета 1-й этаж'!$E35) -> Р1.0.15 | G35: =IF(J35>0,G34+1,G34) -> 2 | H35: Сертификация помещения для совершения операций с ценностями, хранение ценностей по (2) классу вломостойкости и (3) классу пулестойкости | I35: кв.м.площади офиса | K35: 60.48 | L35: 0 | M35: =ROUND('Смета 1-й этаж'!$J35*'Смета 1-й этаж'!$K35,2) -> 0 | N35: =ROUND('Смета 1-й этаж'!$J35*'Смета 1-й этаж'!$L35,2) -> 0
A36: =CONCATENATE('Смета 1-й этаж'!$C36,".",'Смета 1-й этаж'!$D36,".",'Смета 1-й этаж'!$E36) -> Р1.0.16 | B36: 18 | C36: Р1 | D36: 0 | E36: 16 | F36: =CONCATENATE('Смета 1-й этаж'!$C36,".",'Смета 1-й этаж'!$D36,".",'Смета 1-й этаж'!$E36) -> Р1.0.16 | G36: =IF(J36>0,G35+1,G35) -> 2 | H36: Сертификация помещения для совершения операций с ценностями, хранение ценностей по 3 классу вломостойкости и 3 классу пулестойкости | I36: кв.м.площади офиса | K36: 108.48 | L36: 0 | M36: =ROUND('Смета 1-й этаж'!$J36*'Смета 1-й этаж'!$K36,2) -> 0 | N36: =ROUND('Смета 1-й этаж'!$J36*'Смета 1-й этаж'!$L36,2) -> 0
A37: =CONCATENATE('Смета 1-й этаж'!$C37,".",'Смета 1-й этаж'!$D37,".",'Смета 1-й этаж'!$E37) -> Р1.0.17 | B37: 19 | C37: Р1 | D37: 0 | E37: 17 | F37: =CONCATENATE('Смета 1-й этаж'!$C37,".",'Смета 1-й этаж'!$D37,".",'Смета 1-й этаж'!$E37) -> Р1.0.17 | G37: =IF(J37>0,G36+1,G36) -> 2 | H37: Сертификация помещения для совершения операций с ценностями, хранение ценностей по (5) классу вломостойкости | I37: кв.м.площади офиса | K37: 62.52 | L37: 0 | M37: =ROUND('Смета 1-й этаж'!$J37*'Смета 1-й этаж'!$K37,2) -> 0 | N37: =ROUND('Смета 1-й этаж'!$J37*'Смета 1-й этаж'!$L37,2) -> 0
A38: =CONCATENATE('Смета 1-й этаж'!$C38,".",'Смета 1-й этаж'!$D38,".",'Смета 1-й этаж'!$E38) -> Р1.0.18 | B38: 20 | C38: Р1 | D38: 0 | E38: 18 | F38: =CONCATENATE('Смета 1-й этаж'!$C38,".",'Смета 1-й этаж'!$D38,".",'Смета 1-й этаж'!$E38) -> Р1.0.18 | G38: =IF(J38>0,G37+1,G37) -> 2 | H38: Технический отчет электролаборатории | I38: кв.м.площади офиса | K38: 83.428138 | M38: =ROUND('Смета 1-й этаж'!$J38*'Смета 1-й этаж'!$K38,2) -> 0 | N38: =ROUND('Смета 1-й этаж'!$J38*'Смета 1-й этаж'!$L38,2) -> 0
A39: =CONCATENATE('Смета 1-й этаж'!$C39,".",'Смета 1-й этаж'!$D39,".",'Смета 1-й этаж'!$E39) -> Р1.0.19 | B39: 21 | C39: Р1 | D39: 0 | E39: 19 | F39: =CONCATENATE('Смета 1-й этаж'!$C39,".",'Смета 1-й этаж'!$D39,".",'Смета 1-й этаж'!$E39) -> Р1.0.19 | G39: =IF(J39>0,G38+1,G38) -> 2 | H39: Стоимость согласования проекта изменения фасада согласно нормативных и законодательных актов г. ___________ и РФ. | I39: кв.м.площади офиса | K39: 131.15 | L39: 0 | M39: =ROUND('Смета 1-й этаж'!$J39*'Смета 1-й этаж'!$K39,2) -> 0 | N39: =ROUND('Смета 1-й этаж'!$J39*'Смета 1-й этаж'!$L39,2) -> 0
A40: =CONCATENATE('Смета 1-й этаж'!$C40,".",'Смета 1-й этаж'!$D40,".",'Смета 1-й этаж'!$E40) -> Р1.0.20 | B40: 22 | C40: Р1 | D40: 0 | E40: 20 | F40: =CONCATENATE('Смета 1-й этаж'!$C40,".",'Смета 1-й этаж'!$D40,".",'Смета 1-й этаж'!$E40) -> Р1.0.20 | G40: =IF(J40>0,G39+1,G39) -> 2 | H40: Разработка дизайн-проекта интерьера | I40: кв.м.площади офиса | K40: 0 | L40: 0 | M40: =ROUND('Смета 1-й этаж'!$J40*'Смета 1-й этаж'!$K40,2) -> 0 | N40: =ROUND('Смета 1-й этаж'!$J40*'Смета 1-й этаж'!$L40,2) -> 0
A41: =CONCATENATE('Смета 1-й этаж'!$C41,".",'Смета 1-й этаж'!$D41,".",'Смета 1-й этаж'!$E41) -> Р1.0.21 | B41: 23 | C41: Р1 | D41: 0 | E41: 21 | F41: =CONCATENATE('Смета 1-й этаж'!$C41,".",'Смета 1-й этаж'!$D41,".",'Смета 1-й этаж'!$E41) -> Р1.0.21 | G41: =IF(J41>0,G40+1,G40) -> 2 | H41: Экспертиза и согласование проекта ЭОМ в Ростехнадзоре | I41: кв.м.площади офиса | K41: 73.65 | L41: 0 | M41: =ROUND('Смета 1-й этаж'!$J41*'Смета 1-й этаж'!$K41,2) -> 0 | N41: =ROUND('Смета 1-й этаж'!$J41*'Смета 1-й этаж'!$L41,2) -> 0
A42: =CONCATENATE('Смета 1-й этаж'!$C42,".",'Смета 1-й этаж'!$D42,".",'Смета 1-й этаж'!$E42) -> Р1.0.22 | B42: 24 | C42: Р1 | D42: 0 | E42: 22 | F42: =CONCATENATE('Смета 1-й этаж'!$C42,".",'Смета 1-й этаж'!$D42,".",'Смета 1-й этаж'!$E42) -> Р1.0.22 | G42: =IF(J42>0,G41+1,G41) -> 2 | H42: Проект системы водоотведения | I42: кв.м.площади офиса | K42: 0 | L42: 0 | M42: =ROUND('Смета 1-й этаж'!$J42*'Смета 1-й этаж'!$K42,2) -> 0 | N42: =ROUND('Смета 1-й этаж'!$J42*'Смета 1-й этаж'!$L42,2) -> 0
A43: =CONCATENATE('Смета 1-й этаж'!$C43,".",'Смета 1-й этаж'!$D43,".",'Смета 1-й этаж'!$E43) -> Р1.0.23 | B43: 25 | C43: Р1 | D43: 0 | E43: 23 | F43: =CONCATENATE('Смета 1-й этаж'!$C43,".",'Смета 1-й этаж'!$D43,".",'Смета 1-й этаж'!$E43) -> Р1.0.23 | G43: =IF(J43>0,G42+1,G42) -> 2 | H43: Рабочая документация Системы ливневой канализации | I43: кв.м.площади офиса | K43: 0 | L43: 0 | M43: =ROUND('Смета 1-й этаж'!$J43*'Смета 1-й этаж'!$K43,2) -> 0 | N43: =ROUND('Смета 1-й этаж'!$J43*'Смета 1-й этаж'!$L43,2) -> 0
A44: =CONCATENATE('Смета 1-й этаж'!$C44,".",'Смета 1-й этаж'!$D44,".",'Смета 1-й этаж'!$E44) -> Р1.0.24 | B44: 26 | C44: Р1 | D44: 0 | E44: 24 | F44: =CONCATENATE('Смета 1-й этаж'!$C44,".",'Смета 1-й этаж'!$D44,".",'Смета 1-й этаж'!$E44) -> Р1.0.24 | G44: =IF(J44>0,G43+1,G43) -> 2 | H44: Получение Технических условий (при необходимости) | I44: кв.м.площади офиса | K44: 0 | L44: 0 | M44: =ROUND('Смета 1-й этаж'!$J44*'Смета 1-й этаж'!$K44,2) -> 0 | N44: =ROUND('Смета 1-й этаж'!$J44*'Смета 1-й этаж'!$L44,2) -> 0
...

Sheet Для калькулятора
H2: Общие расценки, зависят от площади офиса. Все значения должны округляться до целых чисел | O2: Коэффициенты зависимости от площади
A4: Р9.0.168 | B4: 801 | C4: Р9 | D4: 0 | E4: 168 | F4: Р9.0.168 | G4: 2 | H4: Светильник эвакуационный с аккумуляторной батареей | I4: шт | K4: 488.86 | L4: 1494.42 | M4: 0 | N4: 0 | O4: 0.025 | P4: 1 шт на 40 м кв площади офиса
A5: Р9.0.171 | B5: 804 | C5: Р9 | D5: 0 | E5: 171 | F5: Р9.0.171 | G5: 2 | H5: Гофрированная ПВХ труба ∅ 20 | I5: м.п. | K5: 68.91 | L5: 18.78 | M5: 0 | N5: 0 | O5: 15.39 | P5: 1 м.п. на 0,065 м кв площади офиса
A6: Р9.0.172 | B6: 805 | C6: Р9 | D6: 0 | E6: 172 | F6: Р9.0.172 | G6: 2 | H6: Гофрированная ПВХ труба ∅ 16 | I6: м.п. | K6: 68.91 | L6: 13.92 | M6: 0 | N6: 0 | O6: 28.57 | P6: 1 м.п. на 0,035 м кв площади офиса
A7: Р9.0.176 | B7: 810 | C7: Р9 | D7: 0 | E7: 176 | F7: Р9.0.176 | G7: 2 | H7: Кабель-канал 105х50 мм. | I7: м.п. | K7: 101.23 | L7: 336.01 | M7: 0 | N7: 0 | O7: 0.066 | P7: 1 м.п. на 15 м кв площади офиса
A8: Р9.0.177 | B8: 811 | C8: Р9 | D8: 0 | E8: 177 | F8: Р9.0.177 | G8: 2 | H8: Лоток металлический перфорированный с фасонными частями, крепежом 200*50 | I8: м.п. | K8: 174.99 | L8: 351.64 | M8: 0 | N8: 0 | O8: 0.1 | P8: 1 м.п. на 10 м кв площади офиса
A9: Р9.0.178 | B9: 812 | C9: Р9 | D9: 0 | E9: 178 | F9: Р9.0.178 | G9: 2 | H9: Зажим 773-302 безвинтовой 6х (0,75-2,5) кв. мм для меди и алюминия (Wago) | I9: шт | K9: 8.66 | L9: 15.39 | M9: 0 | N9: 0 | O9: 1 | P9: 1 шт на 1 м кв площади офиса
A10: Р9.0.179 | B10: 813 | C10: Р9 | D10: 0 | E10: 179 | F10: Р9.0.179 | G10: 2 | H10: Зажим 773-302 безвинтовой 2х (0,75-2,5) кв. мм для меди и алюминия (Wago) | I10: шт | K10: 4.74 | L10: 7.56 | M10: 0 | N10: 0 | O10: 1 | P10: 1 шт на 1 м кв площади офиса
A11: Р9.0.206 | B11: 840 | C11: Р9 | D11: 0 | E11: 206 | F11: Р9.0.206 | G11: 2 | H11: Светильник с люминесцентными лампами встраиваемый PRBLUX -600х600(касса) | I11: шт | K11: 486.25 | L11: 2772.5 | M11: 0 | N11: 0 | O11: 2 шт на офис | P11: 2 шт на офис
A12: Р9.0.207 | B12: 841 | C12: Р9 | D12: 0 | E12: 207 | F12: Р9.0.207 | G12: 2 | H12: Светильник противопожарный с люминесцентными лампами встраиваемый стекло матовое 600х600(серверная) | I12: шт | K12: 410.87 | L12: 4301.26 | M12: 0 | N12: 0 | O12: 2 шт на офис | P12: 2 шт на офис
A13: Р9.0.210 | B13: 844 | C13: Р9 | D13: 0 | E13: 210 | F13: Р9.0.210 | G13: 2 | H13: Пуско-наладочные работы | I13: к-т | K13: 10598.55 | L13: 1118.63 | M13: 0 | N13: 0 | O13: 1 шт на офис | P13: 1 шт на офис
A14: Р9.0.211 | B14: 845 | C14: Р9 | D14: 0 | E14: 211 | F14: Р9.0.211 | G14: 2 | H14: Расходные и крепежные материалы | I14: к-т | K14: 0 | L14: 13608.89 | M14: 0 | N14: 0 | O14: 1 шт на офис | P14: 1 шт на офис
A15: Р9.0.214 | B15: 848 | C15: Р9 | D15: 0 | E15: 214 | F15: Р9.0.214 | G15: 2 | H15: Блок аварийного питания INTERLUX ES-1 ( 6-58Ц) | I15: шт | K15: 184.87 | L15: 3256.59 | M15: 0 | N15: 0 | O15: 0.05 | P15: 1 шт на 20 м кв площади офиса
A16: Р9.0.217 | B16: 851 | C16: Р9 | D16: 0 | E16: 217 | F16: Р9.0.217 | G16: 2 | H16: Распред коробка legrand | I16: шт | K16: 88.48 | L16: 204.67 | M16: 0 | N16: 0 | O16: 0.5 | P16: 1 шт на 2 м кв площади офиса
A17: Р9.0.219 | B17: 854 | C17: Р9 | D17: 0 | E17: 219 | F17: Р9.0.219 | G17: 2 | H17: Установка светильника 94 836 NDL-P1-10W-840-WH-LED (аналог R80 100Вт) Navigator 4607136948365 | I17: шт | K17: 590 | L17: 900 | M17: 0 | N17: 0 | O17: 0.2 | P17: 1 шт на 5 м кв площади офиса
A18: Р9.0.246 | B18: 876 | C18: Р9 | D18: 0 | E18: 246 | F18: Р9.0.246 | G18: 2 | H18: Обработка проходов кабелей через перегородки огнезой с 2 сторон | I18: шт | K18: 150 | L18: 350 | M18: 0 | N18: 0 | O18: 0.066 | P18: 1 шт на 15 м кв площади офиса
A19: Р9.0.261 | B19: 853 | C19: Р9 | D19: 0 | E19: 261 | F19: Р9.0.261 | G19: 2 | H19: Светильник светодиодный 18 Вт, Navigator 71 761 NLP-R1-18W-R220-840-WH-LED | I19: шт | K19: 600 | L19: 1350 | M19: 0 | N19: 0 | O19: 0.29 | P19: 1 шт на 3,5 м кв площади офиса
A20: Р9.0.262 | B20: 855 | C20: Р9 | D20: 0 | E20: 262 | F20: Р9.0.262 | G20: 2 | H20: Светильник светодиодный 5 Вт IP44, Navigator 71 366 NDL-P2-5W-830-CH-LED | I20: шт | K20: 500 | L20: 800 | M20: 0 | N20: 0 | O20: 0.033 | P20: 1 шт на 30 м кв площади офиса
A21: Р9.0.231 | B21: 867 | C21: Р9 | D21: 0 | E21: 231 | F21: Р9.0.231 | G21: 2 | H21: Кабель ППГнг(А)-HF 3х2,5 | I21: м.п. | K21: 36.28 | L21: 57.73 | M21: 0 | N21: 0 | O21: 5,5 если площадь офиса больше 300 м кв | P21: 1 м.п. на 0,18 м кв площади офиса
A22: Р9.0.232 | B22: 868 | C22: Р9 | D22: 0 | E22: 232 | F22: Р9.0.232 | G22: 2 | H22: Кабель ППГнг(А)-HF 3x1,5 | I22: м.п. | K22: 36.28 | L22: 41.51 | M22: 0 | N22: 0 | O22: 3,8 если площадь офиса больше 300 м кв | P22: 1 м.п. на 0,26 м кв площади офиса
A23: Р9.0.228 | B23: 864 | C23: Р9 | D23: 0 | E23: 228 | F23: Р9.0.228 | G23: 2 | H23: Кабель ППГнг(А)-HF 5х2,5 | I23: м.п. | K23: 94.04 | L23: 92.48 | M23: 0 | N23: 0 | O23: 0,066 если площадь офиса больше 300 м кв | P23: 1 м.п. на 15 м кв площади офиса
A24: Р9.0.226 | B24: 862 | C24: Р9 | D24: 0 | E24: 226 | F24: Р9.0.226 | G24: 2 | H24: Кабель ППГнг(А)-HF 5х6 | I24: м.п. | K24: 94.04 | L24: 199.29 | M24: 0 | N24: 0 | O24: 0,025 если площадь офиса больше 300 м кв | P24: 1 м.п. на 40 м кв площади офиса
A25: Р9.0.182 | B25: 816 | C25: Р9 | D25: 0 | E25: 182 | F25: Р9.0.182 | G25: 2 | H25: Кабель ВВГнг-LS 5х6 | I25: м.п. | K25: 94.04 | L25: 194.81 | M25: 0 | N25: 0 | O25: 0,025 если площадь офиса меньше 300 м кв | P25: 1 м.п. на 40 м кв площади офиса
A26: Р9.0.184 | B26: 818 | C26: Р9 | D26: 0 | E26: 184 | F26: Р9.0.184 | G26: 2 | H26: Кабель ВВГнг-LS 5х2,5 | I26: м.п. | K26: 117.69 | L26: 85.02 | M26: 0 | N26: 0 | O26: 0,066 если площадь офиса меньше 300 м кв | P26: 1 м.п. на 15 м кв площади офиса
A27: Р9.0.188 | B27: 822 | C27: Р9 | D27: 0 | E27: 188 | F27: Р9.0.188 | G27: 2 | H27: Кабель ВВГнг-LS 3х2,5 | I27: м.п. | K27: 36.28 | L27: 41.85 | M27: 0 | N27: 0 | O27: 5,5 если площадь офиса меньше 300 м кв | P27: 1 м.п. на 0,18 м кв площади офиса
A28: Р9.0.189 | B28: 823 | C28: Р9 | D28: 0 | E28: 189 | F28: Р9.0.189 | G28: 2 | H28: Кабель ВВГнг-LS 3х1,5 | I28: м.п. | K28: 36.28 | L28: 33.05 | M28: 0 | N28: 0 | O28: 3,8 если площадь офиса меньше 300 м кв | P28: 1 м.п. на 0,26 м кв площади офиса
A29: Р9.0.263 | B29: 870 | C29: Р9 | D29: 0 | E29: 263 | F29: Р9.0.263 | G29: 2 | H29: Кабель ППГнг(А)-FRHF 3х1,5 | I29: м.п. | K29: 36.28 | L29: 66.27 | M29: 0 | N29: 0 | O29: 0.5 | P29: 1 м.п. на 2 м кв площади офиса
A30: Р9.0.195 | B30: 829 | C30: Р9 | D30: 0 | E30: 195 | F30: Р9.0.195 | G30: 2 | H30: Провод ПВ1 1х6 (красный/голубой/желтый/зеленый/желто-зеленый) | I30: м.п. | K30: 30.38 | L30: 35.74 | M30: 0 | N30: 0 | O30: 0.05 | P30: 1 м.п. на 20 м кв площади офиса
A31: Р9.0.196 | B31: 830 | C31: Р9 | D31: 0 | E31: 196 | F31: Р9.0.196 | G31: 2 | H31: Провод ПВ1 1х2,5 (красный/голубой/желтый/зеленый/желто-зеленый) | I31: м.п. | K31: 31.57 | L31: 22.81 | M31: 0 | N31: 0 | O31: 0.1 | P31: 1 м.п. на 10 м кв площади офиса
H35: Нижеследующие расценки разделены на три блока. Выбор блока будет зависеть от электрической мощности выделенной на объект и вводного автомата. К каждому из 3-х блоков возможно ПО два добавления (дабавления разные и зависят от номера блока): в ячейке должен быть вопрос "На объекте будет АВР?" и два варианта ответа да или нет. При ответе да добавляются несколько позиций. В другой ячейке должен быть вопрос "На объекте будет ИБП?" и два варианта ответа да или нет. При ответе да добавляется одна позиция.
H37: Если электрическая мощность меньше, либо равна 33 кВт или вводной автомат меньше либо равен 63А, то 1 блок. IF P<=33 and I<=63 THEN "блок 1"
A39: Р9.0.3 | B39: 627 | C39: Р9 | D39: 0 | E39: 3 | F39: Р9.0.3 | G39: 2 | H39: Щит 72 модулей, IP43, ABB или Legrand, с замком в комплекте с DIN-рейками, перемычками, шинами РЕ и N | I39: шт | J39: 1 | K39: 3289.97 | L39: 14122.98 | M39: 0 | N39: 0
A40: Р9.0.6 | B40: 625 | C40: Р9 | D40: 0 | E40: 6 | F40: Р9.0.6 | G40: 2 | H40: Щит 48 модулей, IP43, ABB или Legrand, с замком в комплекте с DIN-рейками, перемычками, шинами РЕ и N | I40: шт | J40: 3 | K40: 2726.23 | L40: 12171.03 | M40: 0 | N40: 0
A41: Р9.0.7 | B41: 624 | C41: Р9 | D41: 0 | E41: 7 | F41: Р9.0.7 | G41: 2 | H41: Щит 36 модулей, IP43, ABB или Legrand, с замком в комплекте с DIN-рейками, перемычками, шинами РЕ и N | I41: шт | J41: 1 | K41: 2508.08 | L41: 10421.19 | M41: 0 | N41: 0
A42: Р9.0.250 | B42: 622 | C42: Р9 | D42: 0 | E42: 250 | F42: Р9.0.250 | G42: 2 | H42: Щит 12 модулей, IP43, ABB или Legrand, с замком в комплекте с DIN-рейками, перемычками, шинами РЕ и N | I42: шт | J42: 1 | K42: 1800 | L42: 2674 | M42: 0 | N42: 0
A43: Р9.0.245 | B43: 630 | C43: Р9 | D43: 0 | E43: 245 | F43: Р9.0.245 | G43: 2 | H43: Щит ППУ 8-12 мод IP 65 красный металлический | I43: шт | J43: 1 | K43: 1500 | L43: 14600 | M43: 0 | N43: 0
A44: Р9.0.9 | B44: 638 | C44: Р9 | D44: 0 | E44: 9 | F44: Р9.0.9 | G44: 2 | H44: Счетчик электроэнергии, Меркурий 231 АТ 01 (двухтарифный, 3-х фазный, 63А) | I44: шт | J44: 1 | K44: 1856.03 | L44: 3917.46 | M44: 0 | N44: 0
A45: Р9.0.265 | B45: 728 | C45: Р9 | D45: 0 | E45: 265 | F45: Р9.0.265 | G45: 2 | H45: Автомат.выкл-ль АВВ 3-полюсный S203 C63А | I45: шт | J45: 1 | K45: 343.33 | L45: 2100 | M45: 0 | N45: 0
A46: Р9.0.95 | B46: 726 | C46: Р9 | D46: 0 | E46: 95 | F46: Р9.0.95 | G46: 2 | H46: Автомат.выкл-ль АВВ 3-полюсный S203 C40А | I46: шт | J46: 1 | K46: 343.33 | L46: 2094.97 | M46: 0 | N46: 0
A47: Р9.0.94 | B47: 725 | C47: Р9 | D47: 0 | E47: 94 | F47: Р9.0.94 | G47: 2 | H47: Автомат.выкл-ль АВВ 3-полюсный S203 C32А | I47: шт | J47: 4 | K47: 343.33 | L47: 1918.87 | M47: 0 | N47: 0
...

Sheet Кондиционеры
B1: Тип | C1: Инвертор | D1: Мощность охлаждения, кВт | E1: Шум, не более, Дб | F1: Макс. длина трубопровода, м | G1: Кол-во внутр. блоков | H1: Доп. требования | I1: ООО "Хайер Электрикал Эпплаенсис РУС" | L1: Дженерал-Трейд (АЯК) - оборудование MDV (GD Midea)
I2: Модель | J2: Цена для Подрядчика Альфа-Банка с НДС, в USD | K2: Цена для Альфа-Банка с НДС, в USD | L2: Модель | M2: Цена для Подрядчика Альфа-Банка с НДС, в USD | N2: Цена для Альфа-Банка с НДС, в USD
A5: 1 | B5: Настенный 7 | C5: нет | D5: 2,0 - 2,3 | E5: 40 | H5: включая пульт | I5: HSU-07HT103/R2/HSU-07HUN203/R2 | J5: 157 | K5: =J5*1.1 -> 172.7 | L5: MDSF-07HRN1/MDOF-07HN1 | M5: 175.78 | N5: =M5*1.1 -> 193.358
A6: 2 | B6: Настенный 9 | C6: нет | D6: 2,5 - 2,8 | E6: 40 | H6: включая пульт | I6: HSU-09HT203/R2/HSU-09HUN103/R2 | J6: 168 | K6: =J6*1.1 -> 184.8 | L6: MDSF-09HRN1/MDOF-09HN1 | M6: 183.3 | N6: =M6*1.1 -> 201.63
A7: 3 | B7: Настенный 12 | C7: нет | D7: 3,2 - 3,6 | E7: 42 | H7: включая пульт | I7: HSU-12HT203/R2/HSU-12HUN103/R2 | J7: 216 | K7: =J7*1.1 -> 237.6 | L7: MDSF-12HRN1/MDOF-12HN1 | M7: 244.87 | N7: =M7*1.1 -> 269.357 | O7: =N7*70 -> 18854.99
A8: 4 | B8: Настенный 18 | C8: нет | D8: 4,8 - 5,4 | E8: 45 | H8: включая пульт | I8: HSU-18HT203/R2/HSU-18HUN103/R2 | J8: 330 | K8: =J8*1.1 -> 363 | L8: MDSF-18HRN1/MDOF-18HN1 | M8: 374.12 | N8: =M8*1.1 -> 411.532 | O8: =N8*70 -> 28807.24
A9: 5 | B9: Настенный 24 | C9: нет | D9: 6,1 - 7,1 | E9: 49 | H9: включая пульт | I9: HSU-24HT203/R2/HSU-24HUN103/R2 | J9: 438 | K9: =J9*1.1 -> 481.8 | L9: MDSF-24HRN1/MDOF-24HN1 | M9: 490.68 | N9: =M9*1.1 -> 539.748
A10: 6 | B10: Кассетный 12 | C10: нет | D10: 3,3 - 3,7 | E10: 38 | H10: включая пульт | I10: AB18CS1ERA(S)/1U18DS1EAA/PB-700IB | J10: 543 | K10: =J10*1.1 -> 597.3 | L10: MDCA3-12HN1/MDOU-12HN1/T-MBQ4-03B4 | M10: 547.68 | N10: =M10*1.1 -> 602.448
A11: 7 | B11: Кассетный 18 | C11: нет | D11: 4,6 - 5,4 | E11: 49 | H11: включая пульт | I11: AB18CS1ERA(S)/1U18DS1EAA/PB-700IB | J11: 543 | K11: =J11*1.1 -> 597.3 | L11: MDCA3-18HN1/MDOU-18HN1/T-MBQ4-03B4 | M11: 623.04 | N11: =M11*1.1 -> 685.344
A12: 8 | B12: Кассетный 24 | C12: нет | D12: 6,8 - 7,5 | E12: 48 | H12: включая пульт | I12: AB24ES1ERA(S)/1U24FS1EAA/PB-950JB | J12: 737 | K12: =J12*1.1 -> 810.7 | L12: MDCD-24HRN1/MDOU-24HN1/T-MBQ-02C1 | M12: 779.52 | N12: =M12*1.1 -> 857.472
A13: 9 | B13: Кассетный 30 | C13: нет | D13: 7,1 - 8,5 | E13: 50 | H13: включая пульт | I13: AB24ES1ERA(S)/1U24FS1EAA/PB-950JB | J13: 737 | K13: =J13*1.1 -> 810.7 | L13: MDCD-24HRN1/MDOU-24HN1/T-MBQ-02C1 | M13: 779.52 | N13: =M13*1.1 -> 857.472
A14: 10 | B14: Кассетный 36 | C14: нет | D14: 9,7 - 11 | E14: 53 | H14: включая пульт | I14: AB36ES1ERA(S)/1U36SS1EAB/PB-950JB | J14: 863 | K14: =J14*1.1 -> 949.3 | L14: MDCD-36HRN1/MDOU-36HN1-L/LT-MBQ-02C1 | M14: 1162.08 | N14: =M14*1.1 -> 1278.288
A15: 11 | B15: Кассетный 48 | C15: нет | D15: 13,5 - 14,1 | E15: 52 | H15: включая пульт | I15: AB48ES1ERA(S)/1U48LS1EAB(S)/PB-P50JB | J15: 1046 | K15: =J15*1.1 -> 1150.6 | L15: MDCD-48HRN1/MDOU-48HN1-L/LT-MBQ-02C1 | M15: 1291.2 | N15: =M15*1.1 -> 1420.32
A16: 12 | B16: Кассетный 54 | C16: нет | D16: 14,3 - 16,2 | E16: 52 | H16: включая пульт | I16: AB60CS1ERA(S)/1U60IS1EAB(S)/PB-1340IB | J16: 1215 | K16: =J16*1.1 -> 1336.5 | L16: MDCD-60HRN1/MDOU-60HN1-L/LT-MBQ-02C1 | M16: 1427.52 | N16: =M16*1.1 -> 1570.272
A17: 13 | B17: Напольно - потолочный 18 | C17: нет | D17: 5,0 - 5,5 | E17: 46 | H17: включая пульт | I17: AC18CS1ERA(S)/1U18DS1EAA | J17: 553 | K17: =J17*1.1 -> 608.3 | L17: MDUE-18HRN1/MDOU-18HN1 | M17: 582.24 | N17: =M17*1.1 -> 640.464
A18: 14 | B18: Напольно - потолочный 24 | C18: нет | D18: 6,5 - 7,7 | E18: 52 | H18: включая пульт | I18: AC24CS1ERA(S)/1U24FS1EAA | J18: 744 | K18: =J18*1.1 -> 818.4 | L18: MDUE-24HRN1/MDOU-24HN1 | M18: 775.68 | N18: =M18*1.1 -> 853.248
A19: 15 | B19: Напольно - потолочный 36 | C19: нет | D19: 10,0 - 11,5 | E19: 54 | H19: включая пульт | I19: AC36ES1ERA(S)/1U36SS1EAB | J19: 896 | K19: =J19*1.1 -> 985.6 | L19: MDUE-36HRN1/MDOU-36HN1 | M19: 1158.24 | N19: =M19*1.1 -> 1274.064
A20: 16 | B20: Напольно - потолочный 48 | C20: нет | D20: 13,4 - 14,2 | E20: 55 | H20: включая пульт | I20: AC48FS1ERA(S)/1U48LS1EAB(S) | J20: 1005 | K20: =J20*1.1 -> 1105.5 | L20: MDUE-48HRN1/MDOU-48HN1 | M20: 1294.08 | N20: =M20*1.1 -> 1423.488
... A27: 23 | B27: Настенный 7 | C27: да | D27: 2,0 - 2,3 | E27: 40 | H27: включая пульт | I27: AS07TH3HRA/1U07MR4ERA | J27: 254 | K27: =J27*1.1 -> 279.4 | L27: MDSA-07HRFN1 | M27: 330.88 | N27: =M27*1.1 -> 363.968
A28: 24 | B28: Настенный 9 | C28: да | D28: 2,5 - 2,8 | E28: 40 | H28: включая пульт | I28: AS09TH3HRA/1U09MR4ERA | J28: 264 | K28: =J28*1.1 -> 290.4 | L28: MDSA-09HRFN1 | M28: 347.8 | N28: =M28*1.1 -> 382.58 | O28: =N28*66.56 -> 25464.525
A29: 25 | B29: Настенный 12 | C29: да | D29: 3,2 - 3,6 | E29: 42 | H29: включая пульт | I29: AS12TB3HRA/1U12MR4ERA | J29: 299 | K29: =J29*1.1 -> 328.9 | L29: MDSA-12HRFN1 | M29: 397.15 | N29: =M29*1.1 -> 436.865 | O29: =N29*70 -> 30580.55
A30: 26 | B30: Настенный 18 | C30: да | D30: 4,8 - 5,4 | E30: 45 | H30: включая пульт | I30: AS18TD2HRA/1U18EE8ERA | J30: 446 | K30: =J30*1.1 -> 490.6 | L30: MDSA-18HRFN1 | M30: 622.28 | N30: =M30*1.1 -> 684.508 | O30: =N30*70 -> 47915.56
A31: 27 | B31: Настенный 24 | C31: да | D31: 6,1 - 7,1 | E31: 49 | H31: включая пульт | I31: AS24TD2HRA/1U24RE8ERA | J31: 577 | K31: =J31*1.1 -> 634.7 | L31: MDSA-24HRFN1 | M31: 765.63 | N31: =M31*1.1 -> 842.193
A32: 28 | B32: Кассетный 12 | C32: да | D32: 3,3 - 3,7 | E32: 38 | H32: включая пульт | I32: AB12CS1ERA(S)/1U12BS3ERA/PB-700IB | J32: 586 | K32: =J32*1.1 -> 644.6 | L32: MDCA3-18HRDN1 | M32: 722.86 | N32: =M32*1.1 -> 795.146
A33: 29 | B33: Кассетный 18 | C33: да | D33: 4,6 - 5,4 | E33: 49 | H33: включая пульт | I33: AB18CS1ERA(S)/1U18FS2ERA(S)/PB-700IB | J33: 761 | K33: =J33*1.1 -> 837.1 | L33: MDCA3-18HRDN1 | M33: 722.86 | N33: =M33*1.1 -> 795.146
A34: 30 | B34: Кассетный 24 | C34: да | D34: 6,8 - 7,5 | E34: 48 | H34: включая пульт | I34: AB24ES1ERA(S)/1U24GS1ERA/PB-950JB | J34: 962 | K34: =J34*1.1 -> 1058.2 | L34: MDCD-24HRDN1 | M34: 928.25 | N34: =M34*1.1 -> 1021.075
A35: 31 | B35: Кассетный 30 | C35: да | D35: 7,1 - 8,5 | E35: 50 | H35: включая пульт | I35: AB24ES1ERA(S)/1U24GS1ERA/PB-950JB | J35: 962 | K35: =J35*1.1 -> 1058.2 | L35: MDCD-24HRDN1 | M35: 928.25 | N35: =M35*1.1 -> 1021.075
A36: 32 | B36: Кассетный 36 | C36: да | D36: 9,7 - 11 | E36: 53 | H36: включая пульт | I36: AB36ES1ERA(S)/1U36HS1ERA(S)/PB-950JB | J36: 1433 | K36: =J36*1.1 -> 1576.3 | L36: MDCD-36HRDN1 | M36: 1475.33 | N36: =M36*1.1 -> 1622.863
A37: 33 | B37: Кассетный 48 | C37: да | D37: 13,5 - 14,1 | E37: 52 | H37: включая пульт | I37: AB48ES1ERA(S)/1U48LS1ERB(S)/PB-950JB | J37: 1762 | K37: =J37*1.1 -> 1938.2 | L37: MDCD-48HRDN1 | M37: 1624.32 | N37: =M37*1.1 -> 1786.752
A38: 34 | B38: Кассетный 54 | C38: да | D38: 14,3 - 16,2 | E38: 52 | H38: включая пульт | I38: AB60CS1ERA(S)/1U60IS1ERB(S)/PB-1340IB | J38: 2067 | K38: =J38*1.1 -> 2273.7 | L38: MDCD-60HRDN1 | M38: 1886.58 | N38: =M38*1.1 -> 2075.238
A39: 35 | B39: Напольно - потолочный 18 | C39: да | D39: 5,0 - 5,5 | E39: 46 | H39: включая пульт | I39: AC18CS1ERA(S)/1U18FS2ERA(S) | J39: 765 | K39: =J39*1.1 -> 841.5 | L39: MDUE-18HRDN1 | M39: 713.93 | N39: =M39*1.1 -> 785.323
A40: 36 | B40: Напольно - потолочный 24 | C40: да | D40: 6,5 - 7,7 | E40: 52 | H40: включая пульт | I40: AC24CS1ERA(S)/1U24GS1ERA | J40: 944 | K40: =J40*1.1 -> 1038.4 | L40: MDUE-24HRDN1 | M40: 713.93 | N40: =M40*1.1 -> 785.323
A41: 37 | B41: Напольно - потолочный 36 | C41: да | D41: 10,0 - 11,5 | E41: 54 | H41: включая пульт | I41: AC36ES1ERA(S)/1U36HS1ERA(S) | J41: 1458 | K41: =J41*1.1 -> 1603.8 | L41: MDUE-36HRDN1 | M41: 1458.41 | N41: =M41*1.1 -> 1604.251
A42: 38 | B42: Напольно - потолочный 48 | C42: да | D42: 13,4 - 14,2 | E42: 55 | H42: включая пульт | I42: AC48FS1ERA(S)/1U48LS1ERB(S) | J42: 1722 | K42: =J42*1.1 -> 1894.2 | L42: MDUE-48HRDN1 | M42: 1629.02 | N42: =M42*1.1 -> 1791.922
... A48: 44 | B48: Канальный 60 | C48: да | D48: 15,0 - 16,2 | E48: 53 | H48: включая пульт и раздаточный пленум | I48: AD60HS1ERA(S)/1U60IS1ERB(S) | J48: 2125 | K48: =J48*1.1 -> 2337.5 | L48: MDTB-60HWDN1 | M48: 1848.98 | N48: =M48*1.1 -> 2033.878
A49: 45 | B49: Мульти-сплит внешн. блок | C49: да | D49: 4,7 - 5,3 | E49: 57 | F49: 20 - 40 | G49: 2 | H49: включая пульт | I49: 2U18FS2ERA(S) | J49: 470 | K49: =J49*1.1 -> 517 | L49: MD2O-14HFN1 outdoor | M49: 626.98 | N49: =M49*1.1 -> 689.678
A50: 46 | B50: Мульти-сплит внешн. блок | C50: да | D50: 5,4 - 7,1 | E50: 62 | F50: 30 - 60 | G50: 2 | H50: включая пульт | I50: 3U19FS1ERA(N) | J50: 722 | K50: =J50*1.1 -> 794.2 | L50: MD3O-21HFN1 outdoor | M50: 744.48 | N50: =M50*1.1 -> 818.928
A51: 47 | B51: Мульти-сплит внешн. блок | C51: да | D51: 7,2 - 8,3 | E51: 65 | F51: 45 - 80 | G51: 3 - 4 | H51: включая пульт | I51: 4U26HS1ERA | J51: 966 | K51: =J51*1.1 -> 1062.6 | L51: MD4O-28HFN1 outdoor | M51: 811.22 | N51: =M51*1.1 -> 892.342
A52: 48 | B52: Мульти-сплит внешн. блок | C52: да | D52: 9,0 - 11,7 | E52: 67 | F52: 60 - 85 | G52: 4 - 5 | H52: включая пульт | I52: 4U30HS1ERA | J52: 1082 | K52: =J52*1.1 -> 1190.2 | L52: MD4O-36HFN1 outdoor | M52: 1445.25 | N52: =M52*1.1 -> 1589.775
A53: 49 | B53: Мульти-сплит внешн. блок | C53: да | D53: 10,7 - 14,7 | E53: 67 | F53: 60 - 135 | G53: 4 - 8 | H53: включая пульт | I53: 5U34HS1ERA | J53: 1279 | K53: =J53*1.1 -> 1406.9 | L53: MD5O-42HFN1 outdoor | M53: 1487.55 | N53: =M53*1.1 -> 1636.305
...

Sheet Контакты кондиционеры
A1: Уполномоченным лицом от «Haier» является:
A2: Руководитель филиала Фомичев С.Ю.
A3: E-mail: info@haierrussia.ru
A4: тел.: +7(495) 782-10-20
A5: Для заказа оборудования:
A6: Менеджер проектов направления систем кондиционирования
A7: Вячеслав Оданец
A8: тел.: +7(495) 782-10-20 доб.129
A9: моб.: +7(926) 920-53-77
A10: E-mail: V.odanets@haierrussia.ru
A12: Уполномоченным лицом от «Дженерал-Трейд»/Аяк является:
A13: Директор по развитию Гасин Михаил Юрьевич
... A33: Тарская Кристина

Sheet ККО
A1: Раздел | B1: Подраздел | C1: Пункт подраздела | D1: Новый номенклатурный номер | E1: Наименование работ и затрат | F1: СРЕДНЯЯ Стоимость работ, руб. | G1: СРЕДНЯЯ Стоимость материалов и оборудования руб. | H1: СРЕДНЯЯ стоимость ВСЕГО, руб. | I1: Стоимость работ, руб. | J1: Стоимость материалов и оборудования руб. | K1: ВСЕГО стоимость ВСЕГО, руб. | L1: Отклонение, %
A2: Р1 | B2: 0 | C2: 0 | D2: Р1.0.0 | E2: Раздел №1. Проектные работы и согласования | F2: 1595.7959 | G2: 0 | H2: 1595.7959 | I2: =IF('Смета 1-й этаж'!$I$4="ККО",'Смета 1-й этаж'!$M$17/'Смета 1-й этаж'!$I$6,0) -> 0 | J2: =IF('Смета 1-й этаж'!$I$4="ККО",'Смета 1-й этаж'!$N$17/'Смета 1-й этаж'!$I$6,0) -> 0 | K2: =I2+J2 -> 0 | L2: =K2/H2-1 -> -1
A3: Р2 | B3: 0 | C3: 0 | D3: Р2.0.0 | E3: Раздел №2. Демонтажные работы. | F3: 1504.7928 | G3: 229.02445 | H3: 1733.8173 | I3: =IF('Смета 1-й этаж'!$I$4="ККО",'Смета 1-й этаж'!$M$57/'Смета 1-й этаж'!$I$6,0) -> 0 | J3: =IF('Смета 1-й этаж'!$I$4="ККО",'Смета 1-й этаж'!$N$57/'Смета 1-й этаж'!$I$6,0) -> 0 | K3: =I3+J3 -> 0 | L3: =K3/H3-1 -> -1
A4: Р3 | B4: 0 | C4: 0 | D4: Р3.0.0 | E4: Раздел №3. Внутренние строительные работы | F4: 5234.746 | G4: 10264.199 | H4: 15498.945 | I4: =IF('Смета 1-й этаж'!$I$4="ККО",'Смета 1-й этаж'!$M$196/'Смета 1-й этаж'!$I$6,0) -> 0 | J4: =IF('Смета 1-й этаж'!$I$4="ККО",'Смета 1-й этаж'!$N$196/'Смета 1-й этаж'!$I$6,0) -> 0 | K4: =I4+J4 -> 0 | L4: =K4/H4-1 -> -1
A5: Р4 | B5: 0 | C5: 0 | D5: Р4.0.0 | E5: Раздел №4. Наружные строительные работы | F5: 211.01514 | G5: 485.45572 | H5: 696.47086 | I5: =IF('Смета 1-й этаж'!$I$4="ККО",'Смета 1-й этаж'!$M$472/'Смета 1-й этаж'!$I$6,0) -> 0 | J5: =IF('Смета 1-й этаж'!$I$4="ККО",'Смета 1-й этаж'!$N$472/'Смета 1-й этаж'!$I$6,0) -> 0 | K5: =I5+J5 -> 0 | L5: =K5/H5-1 -> -1
A6: Р5 | B6: 0 | C6: 0 | D6: Р5.0.0 | E6: Раздел №5. Водоснабжение и Канализация | F6: 193.04775 | G6: 592.60376 | H6: 785.65151 | I6: =IF('Смета 1-й этаж'!$I$4="ККО",'Смета 1-й этаж'!$M$534/'Смета 1-й этаж'!$I$6,0) -> 0 | J6: =IF('Смета 1-й этаж'!$I$4="ККО",'Смета 1-й этаж'!$N$534/'Смета 1-й этаж'!$I$6,0) -> 0 | K6: =I6+J6 -> 0 | L6: =K6/H6-1 -> -1
A7: Р6 | B7: 0 | C7: 0 | D7: Р6.0.0 | E7: Раздел №6. Отопление | F7: 418.52736 | G7: 447.62296 | H7: 866.15032 | I7: =IF('Смета 1-й этаж'!$I$4="ККО",'Смета 1-й этаж'!$M$628/'Смета 1-й этаж'!$I$6,0) -> 0 | J7: =IF('Смета 1-й этаж'!$I$4="ККО",'Смета 1-й этаж'!$N$628/'Смета 1-й этаж'!$I$6,0) -> 0 | K7: =I7+J7 -> 0 | L7: =K7/H7-1 -> -1
A8: Р7 | B8: 0 | C8: 0 | D8: Р7.0.0 | E8: Раздел №7. Вентиляция | F8: 440.67248 | G8: 2966.1666 | H8: 3406.8391 | I8: =IF('Смета 1-й этаж'!$I$4="ККО",'Смета 1-й этаж'!$M$686/'Смета 1-й этаж'!$I$6,0) -> 0 | J8: =IF('Смета 1-й этаж'!$I$4="ККО",'Смета 1-й этаж'!$N$686/'Смета 1-й этаж'!$I$6,0) -> 0 | K8: =I8+J8 -> 0 | L8: =K8/H8-1 -> -1
A9: Р8 | B9: 0 | C9: 0 | D9: Р8.0.0 | E9: Раздел №8. Кондиционирование | F9: 615.20973 | G9: 2979.6748 | H9: 3594.8845 | I9: =IF('Смета 1-й этаж'!$I$4="ККО",'Смета 1-й этаж'!M$712/'Смета 1-й этаж'!$I$6,0) -> 0 | J9: =IF('Смета 1-й этаж'!$I$4="ККО",'Смета 1-й этаж'!$N$712/'Смета 1-й этаж'!$I$6,0) -> 0 | K9: =I9+J9 -> 0 | L9: =K9/H9-1 -> -1
A10: Р9 | B10: 0 | C10: 0 | D10: Р9.0.0 | E10: Раздел №9. Электротехнические работы | F10: 1401.4891 | G10: 3655.3367 | H10: 5056.8258 | I10: =IF('Смета 1-й этаж'!$I$4="ККО",'Смета 1-й этаж'!$M$759/'Смета 1-й этаж'!$I$6,0) -> 0 | J10: =IF('Смета 1-й этаж'!$I$4="ККО",'Смета 1-й этаж'!$N$759/'Смета 1-й этаж'!$I$6,0) -> 0 | K10: =I10+J10 -> 0 | L10: =K10/H10-1 -> -1
A11: Р10 | B11: 0 | C11: 0 | D11: Р10.0.0 | E11: Раздел №10. Адаптация объекта для МГН | I11: =IF('Смета 1-й этаж'!$I$4="ККО",'Смета 1-й этаж'!$M$1181/'Смета 1-й этаж'!$I$6,0) -> 0 | J11: =IF('Смета 1-й этаж'!$I$4="ККО",'Смета 1-й этаж'!$N$1181/'Смета 1-й этаж'!$I$6,0) -> 0 | K11: =I11+J11 -> 0 | L11: =K11/H11-1 -> #DIV/0!
E12: Транспортно-накладные расходы (% от стоимости работ и материалов): | F12: 598.41783 | G12: 0 | H12: 598.41783 | I12: =IF('Смета 1-й этаж'!$I$4="ККО",'Смета 1-й этаж'!$M$1212/'Смета 1-й этаж'!$I$6,0) -> 0 | J12: 0 | K12: =I12+J12 -> 0 | L12: =K12/H12-1 -> -1
A13: Итог | B13: 0 | E13: ИТОГО РАЗДЕЛ | F13: =SUM(F2:F12) -> 12213.714 | G13: =SUM(G2:G12) -> 21620.084 | H13: =SUM(H2:H12) -> 33833.798 | I13: =SUM(I2:I12) -> 0 | J13: =SUM(J2:J12) -> 0 | K13: =SUM(K2:K12) -> 0 | L13: =K13/H13-1 -> -1
D16: Работы, выходящие по стоимости из "среднего" проекта
J17: Стоитмость (руб.) | K17: Цена 1 кв.м. (руб.) | N17: Заполняется перечень и стоимость работ, выходящих за рамки "типоывой" площадки. В таблице пример таких работ (могут быть другие)
D18: 1 | E18: Конструктивные работы | J18: ='Смета 1-й этаж'!AR197+'Смета 1-й этаж'!AR357+'Смета 1-й этаж'!AR440 -> 0 | K18: =J18/'Смета 1-й этаж'!$I$6 -> #DIV/0!
D19: 2 | E19: Устройство новых входных групп или запасных выходов (изменение фасадов) | J19: ='Смета 1-й этаж'!AR264 -> 0 | K19: =J19/'Смета 1-й этаж'!$I$6 -> #DIV/0!
D20: 3 | E20: Ремонт фасадов | J20: ='Смета 1-й этаж'!AR486 -> 0 | K20: =J20/'Смета 1-й этаж'!$I$6 -> #DIV/0!
D21: 4 | E21: Ремонт кровли | J21: ='Смета 1-й этаж'!AR473 -> 0 | K21: =J21/'Смета 1-й этаж'!$I$6 -> #DIV/0!
D22: 5 | E22: Противопожарные мероприятия | J22: ='Смета 1-й этаж'!AR606+'Смета 1-й этаж'!AR624+'Смета 1-й этаж'!AR707 -> 0 | K22: =J22/'Смета 1-й этаж'!$I$6 -> #DIV/0!
D23: 6 | E23: Устройство, ремонт лифтов | K23: =J23/'Смета 1-й этаж'!$I$6 -> #DIV/0!
D24: 7 | E24: Диспетчеризация и управление инженерными системами: | K24: =J24/'Смета 1-й этаж'!$I$6 -> #DIV/0!
D25: 8 | E25: Благоустроство территории | J25: ='Смета 1-й этаж'!AR515 -> 0 | K25: =J25/'Смета 1-й этаж'!$I$6 -> #DIV/0!
D26: 9 | E26: Ввод и Резервирование электроснабжения: | K26: =J26/'Смета 1-й этаж'!$I$6 -> #DIV/0!
D27: 10 | E27: Внешние сети | K27: =J27/'Смета 1-й этаж'!$I$6 -> #DIV/0!
D28: 11 | E28: Стеклянные перегородки (больше обычного) | K28: =J28/'Смета 1-й этаж'!$I$6 -> #DIV/0!
D29: 12 | E29: Вентиляция (больше обычного) | K29: =J29/'Смета 1-й этаж'!$I$6 -> #DIV/0!
D30: 13 | E30: Кондиционирование (больше обычного) | K30: =J30/'Смета 1-й этаж'!$I$6 -> #DIV/0!
D31: 14 | K31: =J31/'Смета 1-й этаж'!$I$6 -> #DIV/0!
D32: 15 | K32: =J32/'Смета 1-й этаж'!$I$6 -> #DIV/0!
D33: 16 | K33: =J33/'Смета 1-й этаж'!$I$6 -> #DIV/0!
E34: Итого стоимость "специальных" работ | J34: =SUM(J18:J33) -> 0 | K34: =SUM(K18:K33) -> #DIV/0!
E35: Цена 1 кв м стоимости РСР без учета "специальных" работ | K35: =K13-K34 -> #DIV/0!

Sheet Инфраструктура
A1: Раздел | B1: Подраздел | C1: Пункт подраздела | D1: Новый номенклатурный номер | E1: Наименование работ и затрат | F1: СРЕДНЯЯ Стоимость работ, руб. | G1: СРЕДНЯЯ Стоимость материалов и оборудования руб. | H1: СРЕДНЯЯ стоимость ВСЕГО, руб. | I1: Стоимость работ, руб. | J1: Стоимость материалов и оборудования руб. | K1: ВСЕГО стоимость ВСЕГО, руб. | L1: Отклонение, %
A2: Р1 | B2: 0 | C2: 0 | D2: Р1.0.0 | E2: Раздел №1. Проектные работы и согласования | F2: 1079.0166 | G2: 0 | H2: 1079.0166 | I2: =IF('Смета 1-й этаж'!$I$4="Инфраструктура",'Смета 1-й этаж'!$M$17/'Смета 1-й этаж'!$I$6,0) -> #DIV/0! | J2: =IF('Смета 1-й этаж'!$I$4="Инфраструктура",'Смета 1-й этаж'!$N$17/'Смета 1-й этаж'!$I$6,0) -> #DIV/0! | K2: =I2+J2 -> #DIV/0! | L2: =K2/H2-1 -> #DIV/0!
A3: Р2 | B3: 0 | C3: 0 | D3: Р2.0.0 | E3: Раздел №2. Демонтажные работы. | F3: 1716.883 | G3: 105.7182 | H3: 1822.6012 | I3: =IF('Смета 1-й этаж'!$I$4="Инфраструктура",'Смета 1-й этаж'!$M$57/'Смета 1-й этаж'!$I$6,0) -> #DIV/0! | J3: =IF('Смета 1-й этаж'!$I$4="Инфраструктура",'Смета 1-й этаж'!$N$57/'Смета 1-й этаж'!$I$6,0) -> #DIV/0! | K3: =I3+J3 -> #DIV/0! | L3: =K3/H3-1 -> #DIV/0!
A4: Р3 | B4: 0 | C4: 0 | D4: Р3.0.0 | E4: Раздел №3. Внутренние строительные работы | F4: 6370.3388 | G4: 12428.826 | H4: 18799.165 | I4: =IF('Смета 1-й этаж'!$I$4="Инфраструктура",'Смета 1-й этаж'!$M$196/'Смета 1-й этаж'!$I$6,0) -> #DIV/0! | J4: =IF('Смета 1-й этаж'!$I$4="Инфраструктура",'Смета 1-й этаж'!$N$196/'Смета 1-й этаж'!$I$6,0) -> #DIV/0! | K4: =I4+J4 -> #DIV/0! | L4: =K4/H4-1 -> #DIV/0!
A5: Р4 | B5: 0 | C5: 0 | D5: Р4.0.0 | E5: Раздел №4. Наружные строительные работы | F5: 223.81675 | G5: 759.68777 | H5: 983.50452 | I5: =IF('Смета 1-й этаж'!$I$4="Инфраструктура",'Смета 1-й этаж'!$M$472/'Смета 1-й этаж'!$I$6,0) -> #DIV/0! | J5: =IF('Смета 1-й этаж'!$I$4="Инфраструктура",'Смета 1-й этаж'!$N$472/'Смета 1-й этаж'!$I$6,0) -> #DIV/0! | K5: =I5+J5 -> #DIV/0! | L5: =K5/H5-1 -> #DIV/0!
A6: Р5 | B6: 0 | C6: 0 | D6: Р5.0.0 | E6: Раздел №5. Водоснабжение и Канализация | F6: 191.78339 | G6: 369.50799 | H6: 561.29139 | I6: =IF('Смета 1-й этаж'!$I$4="Инфраструктура",'Смета 1-й этаж'!$M$534/'Смета 1-й этаж'!$I$6,0) -> #DIV/0! | J6: =IF('Смета 1-й этаж'!$I$4="Инфраструктура",'Смета 1-й этаж'!$N$534/'Смета 1-й этаж'!$I$6,0) -> #DIV/0! | K6: =I6+J6 -> #DIV/0! | L6: =K6/H6-1 -> #DIV/0!
A7: Р6 | B7: 0 | C7: 0 | D7: Р6.0.0 | E7: Раздел №6. Отопление | F7: 196.81226 | G7: 249.92222 | H7: 446.73448 | I7: =IF('Смета 1-й этаж'!$I$4="Инфраструктура",'Смета 1-й этаж'!$M$628/'Смета 1-й этаж'!$I$6,0) -> #DIV/0! | J7: =IF('Смета 1-й этаж'!$I$4="Инфраструктура",'Смета 1-й этаж'!$N$628/'Смета 1-й этаж'!$I$6,0) -> #DIV/0! | K7: =I7+J7 -> #DIV/0! | L7: =K7/H7-1 -> #DIV/0!
A8: Р7 | B8: 0 | C8: 0 | D8: Р7.0.0 | E8: Раздел №7. Вентиляция | F8: 657.15384 | G8: 3376.1791 | H8: 4033.3329 | I8: =IF('Смета 1-й этаж'!$I$4="Инфраструктура",'Смета 1-й этаж'!$M$686/'Смета 1-й этаж'!$I$6,0) -> #DIV/0! | J8: =IF('Смета 1-й этаж'!$I$4="Инфраструктура",'Смета 1-й этаж'!$N$686/'Смета 1-й этаж'!$I$6,0) -> #DIV/0! | K8: =I8+J8 -> #DIV/0! | L8: =K8/H8-1 -> #DIV/0!
A9: Р8 | B9: 0 | C9: 0 | D9: Р8.0.0 | E9: Раздел №8. Кондиционирование | F9: 570.71637 | G9: 2786.6431 | H9: 3357.3595 | I9: =IF('Смета 1-й этаж'!$I$4="Инфраструктура",'Смета 1-й этаж'!M$712/'Смета 1-й этаж'!$I$6,0) -> #DIV/0! | J9: =IF('Смета 1-й этаж'!$I$4="Инфраструктура",'Смета 1-й этаж'!$N$712/'Смета 1-й этаж'!$I$6,0) -> #DIV/0! | K9: =I9+J9 -> #DIV/0! | L9: =K9/H9-1 -> #DIV/0!
A10: Р9 | B10: 0 | C10: 0 | D10: Р9.0.0 | E10: Раздел №9. Электротехнические работы | F10: 1497.0422 | G10: 3569.412 | H10: 5066.4542 | I10: =IF('Смета 1-й этаж'!$I$4="Инфраструктура",'Смета 1-й этаж'!$M$759/'Смета 1-й этаж'!$I$6,0) -> #DIV/0! | J10: =IF('Смета 1-й этаж'!$I$4="Инфраструктура",'Смета 1-й этаж'!$N$759/'Смета 1-й этаж'!$I$6,0) -> #DIV/0! | K10: =I10+J10 -> #DIV/0! | L10: =K10/H10-1 -> #DIV/0!
A11: Р10 | B11: 0 | C11: 0 | D11: Р10.0.0 | E11: Раздел №10. Адаптация объекта для МГН | I11: =IF('Смета 1-й этаж'!$I$4="Инфраструктура",'Смета 1-й этаж'!$M$1181/'Смета 1-й этаж'!$I$6,0) -> #DIV/0! | J11: =IF('Смета 1-й этаж'!$I$4="Инфраструктура",'Смета 1-й этаж'!$N$1181/'Смета 1-й этаж'!$I$6,0) -> #DIV/0! | K11: =I11+J11 -> #DIV/0! | L11: =K11/H11-1 -> #DIV/0!
E12: Транспортно-накладные расходы (% от стоимости работ и материалов): | F12: 628.48145 | G12: 0 | H12: 628.48145 | I12: =IF('Смета 1-й этаж'!$I$4="Инфраструктура",'Смета 1-й этаж'!$M$1212/'Смета 1-й этаж'!$I$6,0) -> #DIV/0! | J12: 0 | K12: =I12+J12 -> #DIV/0! | L12: =K12/H12-1 -> #DIV/0!
A13: Итог | B13: 0 | E13: ИТОГО РАЗДЕЛ | F13: =SUM(F2:F12) -> 13132.045 | G13: =SUM(G2:G12) -> 23645.896 | H13: =SUM(H2:H12) -> 36777.941 | I13: =SUM(I2:I12) -> #DIV/0! | J13: =SUM(J2:J12) -> #DIV/0! | K13: =SUM(K2:K12) -> #DIV/0! | L13: =K13/H13-1 -> #DIV/0!

Sheet Список
A1: ККО
A2: Инфраструктура

Sheet свод_исходн
A3: Названия строк | B3: Стоимость работ | C3: Стоимость материалов и оборудования | D3: Итого
A4: Смета_FIFA_Добролюбова | B4: 8242224 | C4: 14557776 | D4: =B4+C4 -> 22800000
A5: Смета_FIFA_Житная | B5: 6023712.9 | C5: 12720312 | D5: =B5+C5 -> 18744025
A6: Смета_FIFA_Проектируемый проезд | B6: 2180901 | C6: 5719099 | D6: =B6+C6 -> 7900000
A7: Смета_Братиславский_5 | B7: 2013600.8 | C7: 4434529.2 | D7: =B7+C7 -> 6448130
A8: Смета_Братиславский_6 | B8: 1360056.9 | C8: 2991813 | D8: =B8+C8 -> 4351869.9
A9: Смета_Володарский | B9: 6922260.7 | C9: 11484249 | D9: =B9+C9 -> 18406510
A10: Смета_Кемерово_Кузбасс | B10: 3325304.8 | C10: 6422661.7 | D10: =B10+C10 -> 9747966.5
A11: Смета_КЦ_МОПР | B11: 7996659.6 | C11: 16238497 | D11: =B11+C11 -> 24235157
A12: Смета_Людмила | B12: 3061831.9 | C12: 6229060.3 | D12: =B12+C12 -> 9290892.1
A13: Смета_Саратовский_Соборная | B13: 5473685 | C13: 8815485.1 | D13: =B13+C13 -> 14289170
A14: Смета_Саратовский_Чернышевского | B14: 3415508 | C14: 5995321.9 | D14: =B14+C14 -> 9410829.9
A15: Смета_Сокольники | B15: 4293844.8 | C15: 7017814.1 | D15: =B15+C15 -> 11311659
... A17: Смета_Ярославский_Чайковского | B17: 939732.31 | C17: 1414657.2 | D17: =B17+C17 -> 2354389.5
A18: Общий итог | B18: 62289122 | C18: 1.1611259e+08 | D18: =SUM(D4:D17) -> 1.7840171e+08
