Workbook
Name S_общая: Параметры!$B$19
Name S_поверхность: Параметры!$B$23
Name S_пол: Параметры!$B$20
Name S_потолок: Параметры!$B$22
Name S_проёмы: Параметры!$B$24
Name S_стены: Параметры!$B$21
Name S_фасад: Параметры!$B$25
Name Адрес: Параметры!$B$6
Name ДатаЦен: Параметры!$B$8
Name ДисконтТендер: Параметры!$B$31
Name КодыРабот: Работы!$A$2:$A$6000
Name КонтЛицо: Параметры!$B$14
Name КонтТел: Параметры!$B$15
Name КурсEUR: Параметры!$B$36
Name КурсUSD: Параметры!$B$35
Name мат_VRF_ВНУТ: OFFSET(Материалы!$A$1,MATCH("VRF.ВНУТ",Материалы!$G:$G,0)-1,0,COUNTIF(Материалы!$G:$G,"VRF.ВНУТ"),1)
Name мат_VRF_НАР: OFFSET(Материалы!$A$1,MATCH("VRF.НАР",Материалы!$G:$G,0)-1,0,COUNTIF(Материалы!$G:$G,"VRF.НАР"),1)
Name мат_БРОНЯ: OFFSET(Материалы!$A$1,MATCH("БРОНЯ",Материалы!$G:$G,0)-1,0,COUNTIF(Материалы!$G:$G,"БРОНЯ"),1)
Name мат_ДВ: OFFSET(Материалы!$A$1,MATCH("ДВ",Материалы!$G:$G,0)-1,0,COUNTIF(Материалы!$G:$G,"ДВ"),1)
Name мат_ДВ_АЛ: OFFSET(Материалы!$A$1,MATCH("ДВ.АЛ",Материалы!$G:$G,0)-1,0,COUNTIF(Материалы!$G:$G,"ДВ.АЛ"),1)
Name мат_ДВ_ДЕР: OFFSET(Материалы!$A$1,MATCH("ДВ.ДЕР",Материалы!$G:$G,0)-1,0,COUNTIF(Материалы!$G:$G,"ДВ.ДЕР"),1)
Name мат_ДВ_СТ: OFFSET(Материалы!$A$1,MATCH("ДВ.СТ",Материалы!$G:$G,0)-1,0,COUNTIF(Материалы!$G:$G,"ДВ.СТ"),1)
Name мат_ЗАВЕСА: OFFSET(Материалы!$A$1,MATCH("ЗАВЕСА",Материалы!$G:$G,0)-1,0,COUNTIF(Материалы!$G:$G,"ЗАВЕСА"),1)
Name мат_ЛЮЧОК: OFFSET(Материалы!$A$1,MATCH("ЛЮЧОК",Материалы!$G:$G,0)-1,0,COUNTIF(Материалы!$G:$G,"ЛЮЧОК"),1)
Name мат_ПВУ: OFFSET(Материалы!$A$1,MATCH("ПВУ",Материалы!$G:$G,0)-1,0,COUNTIF(Материалы!$G:$G,"ПВУ"),1)
Name мат_ПЕРЕГ_СТ: OFFSET(Материалы!$A$1,MATCH("ПЕРЕГ.СТ",Материалы!$G:$G,0)-1,0,COUNTIF(Материалы!$G:$G,"ПЕРЕГ.СТ"),1)
Name мат_ПЕРЕГ_ТР: OFFSET(Материалы!$A$1,MATCH("ПЕРЕГ.ТР",Материалы!$G:$G,0)-1,0,COUNTIF(Материалы!$G:$G,"ПЕРЕГ.ТР"),1)
Name мат_ПОЛ_КГ: OFFSET(Материалы!$A$1,MATCH("ПОЛ.КГ",Материалы!$G:$G,0)-1,0,COUNTIF(Материалы!$G:$G,"ПОЛ.КГ"),1)
Name мат_ПОЛ_МОД: OFFSET(Материалы!$A$1,MATCH("ПОЛ.МОД",Материалы!$G:$G,0)-1,0,COUNTIF(Материалы!$G:$G,"ПОЛ.МОД"),1)
Name мат_ПОТОЛОК: OFFSET(Материалы!$A$1,MATCH("ПОТОЛОК",Материалы!$G:$G,0)-1,0,COUNTIF(Материалы!$G:$G,"ПОТОЛОК"),1)
Name мат_РАД: OFFSET(Материалы!$A$1,MATCH("РАД",Материалы!$G:$G,0)-1,0,COUNTIF(Материалы!$G:$G,"РАД"),1)
Name мат_РАД_КОМПЛ: OFFSET(Материалы!$A$1,MATCH("РАД.КОМПЛ",Материалы!$G:$G,0)-1,0,COUNTIF(Материалы!$G:$G,"РАД.КОМПЛ"),1)
Name мат_СВЕТ: OFFSET(Материалы!$A$1,MATCH("СВЕТ",Материалы!$G:$G,0)-1,0,COUNTIF(Материалы!$G:$G,"СВЕТ"),1)
Name мат_СВЕТ_АВАР: OFFSET(Материалы!$A$1,MATCH("СВЕТ.АВАР",Материалы!$G:$G,0)-1,0,COUNTIF(Материалы!$G:$G,"СВЕТ.АВАР"),1)
Name мат_СПЛИТ: OFFSET(Материалы!$A$1,MATCH("СПЛИТ",Материалы!$G:$G,0)-1,0,COUNTIF(Материалы!$G:$G,"СПЛИТ"),1)
Name мат_СТЕН_ПЛ: OFFSET(Материалы!$A$1,MATCH("СТЕН.ПЛ",Материалы!$G:$G,0)-1,0,COUNTIF(Материалы!$G:$G,"СТЕН.ПЛ"),1)
Name мат_СТП_РАК: OFFSET(Материалы!$A$1,MATCH("СТП.РАК",Материалы!$G:$G,0)-1,0,COUNTIF(Материалы!$G:$G,"СТП.РАК"),1)
Name мат_СТП_СМЕС: OFFSET(Материалы!$A$1,MATCH("СТП.СМЕС",Материалы!$G:$G,0)-1,0,COUNTIF(Материалы!$G:$G,"СТП.СМЕС"),1)
Name мат_СТП_УНИТ: OFFSET(Материалы!$A$1,MATCH("СТП.УНИТ",Материалы!$G:$G,0)-1,0,COUNTIF(Материалы!$G:$G,"СТП.УНИТ"),1)
Name мат_ФАЛЬШПОЛ: OFFSET(Материалы!$A$1,MATCH("ФАЛЬШПОЛ",Материалы!$G:$G,0)-1,0,COUNTIF(Материалы!$G:$G,"ФАЛЬШПОЛ"),1)
Name мат_ЭУИ_ВЫКЛ: OFFSET(Материалы!$A$1,MATCH("ЭУИ.ВЫКЛ",Материалы!$G:$G,0)-1,0,COUNTIF(Материалы!$G:$G,"ЭУИ.ВЫКЛ"),1)
Name мат_ЭУИ_РОЗ: OFFSET(Материалы!$A$1,MATCH("ЭУИ.РОЗ",Материалы!$G:$G,0)-1,0,COUNTIF(Материалы!$G:$G,"ЭУИ.РОЗ"),1)
Name мат_ЭЩ: OFFSET(Материалы!$A$1,MATCH("ЭЩ",Материалы!$G:$G,0)-1,0,COUNTIF(Материалы!$G:$G,"ЭЩ"),1)
Name Периметр_пола: Параметры!$B$26
Name Подрядчик: Параметры!$B$11
Name ПроцРезерв: Параметры!$B$34
Name ПроцТакелаж: Параметры!$B$33
Name ПроцТранспорт: Параметры!$B$32
Name РежимЦены: Параметры!$B$29
Name Реквизиты: Параметры!$B$16
Name Срок: Параметры!$B$7
Name СтавкаНДС: Параметры!$B$30
Name ФорматОбъекта: Параметры!$B$5
Name ЭлАдрес: Параметры!$B$13
Name ЮрАдрес: Параметры!$B$12

Sheet О шаблоне
A1: Смета объекта — единый файл (Excel 2019+)
A3: ТРИ ПРАВИЛА
A4: 1. «Конструктор» — вводишь по нужным строкам: Объём · Код_материала · Вкл. (да/нет).
A5: Подсказка «Драйвер» говорит, откуда объём (S_пол, S_стены, спецификация, замер…).
A6: Список материала — только по группе этой работы. «Гр_ОK» краснеет, если выбран не тот.
A7: 2. «Смета» — готовый документ. После ввода объёмов: встать на таблицу расшифровки →
A8: Данные → «Применить повторно» (Ctrl+Alt+L). Позиции появятся, итоги встанут под ними.
A9: 3. Цены и работы менять — на жёлтых листах «Работы» / «Материалы» в этом же файле.
A10: После ДОБАВЛЕНИЯ материалов — отсортировать лист «Материалы» по колонке «Группа_материалов»
A11: (выделить таблицу → Данные → Сортировка). Иначе список материала по группе будет неполным.
A13: ЛИСТЫ:
A14: Параметры — объект, подрядчик, площади, НДС, %% транспорта/такелажа/резерва, курсы (жёлтые ячейки).
... A24: Сформировано: 2026-08-31. Работ: 911. Материалов: 1218. Буфер Конструктора: 1211. Версия: 1.0 (единый файл).

Sheet Параметры
A1: ПАРАМЕТРЫ ОБЪЕКТА
A3: Параметр | B3: Значение | C3: Пояснение
A4: Объект
A5: Формат объекта | B5: ККО | C5: ККО / Инфраструктура
A6: Адрес объекта
A7: Срок проведения работ | B7: Согласно план-графику производства работ
A8: Дата цен | B8: 46265 | C8: на какую дату актуальны цены КП
A10: Подрядчик
A11: ПОДРЯДЧИК (наименование)
A12: Юридический адрес
A13: Электронный адрес
A14: Контактное лицо (Ф.И.О.)
A15: Контактный телефон
A16: Реквизиты
A18: Площади, м²
A19: S_общая (площадь объекта) | B19: 0 | C19: для ТЭП и проектных расценок
A20: S_пол | B20: 0 | C20: драйвер S_пол
A21: S_стены | B21: 0 | C21: драйвер S_стены (развёртка)
A22: S_потолок | B22: 0 | C22: драйвер S_потолок
A23: S_поверхность | B23: 0 | C23: драйвер S_поверхность
A24: S_проёмы | B24: 0 | C24: драйвер S_проёмы
A25: S_фасад | B25: 0 | C25: драйвер S_фасад
A26: Периметр_пола, м.п. | B26: 0 | C26: драйвер Периметр_пола
A28: Финансы
A29: Режим цены | B29: с НДС в цене | C29: «с НДС в цене» — НДС извлекается; «без НДС» — начисляется сверху
A30: Ставка НДС, % | B30: 20 | C30: 5 / 7 / 20
A31: Дисконт по тендеру, доля | B31: 0 | C31: 0,05 = минус 5% к ЕР
A32: Транспортные, % от стоимости материалов | B32: 3
A33: Такелаж / верт. транспорт, % от (работы+материалы) | B33: 0 | C33: режим ТЦ/БЦ, ночные работы
A34: Резерв на непредвиденные, % от (работы+материалы) | B34: 0 | C34: 0 = не применять
A35: Курс USD | B35: 81 | C35: для валютных материалов
A36: Курс EUR | B36: 95

Sheet Конструктор
A1: Раздел | B1: Подраздел | C1: Код_работы | D1: Наименование работы | E1: Ед | F1: Группа_мат | G1: Драйвер | H1: Объём | I1: Код_материала | J1: Наименование материала | K1: Гр_ОK | L1: Цена работ, ₽ | M1: Цена мат, ₽ | N1: Стоим. работ, ₽ | O1: Стоим. мат, ₽ | P1: Всего, ₽ | Q1: Тип | R1: Вкл. | S1: Примечание | T1: _ранг
A2: =IFERROR(INDEX(Работы!$D$2:$D$6000,MATCH($C2,Работы!$A$2:$A$6000,0)),"") -> Р1 | B2: =IFERROR(INDEX(Работы!$F$2:$F$6000,MATCH($C2,Работы!$A$2:$A$6000,0)),"") -> 1 | C2: =IFERROR(INDEX(Работы!$A$2:$A$6000,1),"") -> РАБ.Р1.1.001 | D2: =IFERROR(INDEX(Работы!$B$2:$B$6000,MATCH($C2,Работы!$A$2:$A$6000,0)),"") -> Техническое обследование состояния несущих конструкций помещения с подготовкой рекомендаций по усилению (Техничесекое заключение о конструктиве - "ТЗК") (для помещений от 100 до 45… | E2: =IFERROR(INDEX(Работы!$C$2:$C$6000,MATCH($C2,Работы!$A$2:$A$6000,0)),"") -> м2 | F2: =IFERROR(INDEX(Работы!$G$2:$G$6000,MATCH($C2,Работы!$A$2:$A$6000,0)),"") -> 0 | G2: =IFERROR(INDEX(Работы!$K$2:$K$6000,MATCH($C2,Работы!$A$2:$A$6000,0)),"") -> S_общая | J2: =IFERROR(INDEX(Материалы!$B$2:$B$9000,MATCH($I2,Материалы!$A$2:$A$9000,0)),"") | K2: =IF($I2="","",IF($F2=IFERROR(INDEX(Материалы!$G$2:$G$9000,MATCH($I2,Материалы!$A$2:$A$9000,0)),""),"OK","!! не та группа")) | L2: =IFERROR(INDEX(Работы!$H$2:$H$6000,MATCH($C2,Работы!$A$2:$A$6000,0))*(1-ДисконтТендер),0) -> 3675 | M2: =IF($I2="",0,IFERROR(INDEX(Материалы!$I$2:$I$9000,MATCH($I2,Материалы!$A$2:$A$9000,0))*IF(INDEX(Материалы!$J$2:$J$9000,MATCH($I2,Материалы!$A$2:$A$9000,0))="USD",КурсUSD,IF(INDEX(Материалы!$J$2:$J$9000,MATCH($I2,Материалы!$A$2:$A$9000,0))="EUR",КурсEUR,1))*INDEX(Материалы!$K$2:$K$9000,MATCH($I2,Материалы!$A$2:$A$9000,0))*(1+IFERROR(INDEX(Работы!$I$2:$I$6000,MATCH($C2,Работы!$A$2:$A$6000,0))/100,0))*(1-ДисконтТендер),0)) -> 0 | N2: =IF(AND($R2="да",$H2<>""),ROUND($H2*$L2,2),0) -> 0 | O2: =IF(AND($R2="да",$H2<>""),ROUND($H2*$M2,2),0) -> 0 | P2: =$N2+$O2 -> 0 | Q2: =IFERROR(INDEX(Работы!$J$2:$J$6000,MATCH($C2,Работы!$A$2:$A$6000,0)),"") -> нетиповая | R2: да | T2: =IF(AND($P2>0,$R2="да"),MAX($T$1:$T1)+1,"")
A3: =IFERROR(INDEX(Работы!$D$2:$D$6000,MATCH($C3,Работы!$A$2:$A$6000,0)),"") -> Р1 | B3: =IFERROR(INDEX(Работы!$F$2:$F$6000,MATCH($C3,Работы!$A$2:$A$6000,0)),"") -> 1 | C3: =IFERROR(INDEX(Работы!$A$2:$A$6000,2),"") -> РАБ.Р1.1.002 | D3: =IFERROR(INDEX(Работы!$B$2:$B$6000,MATCH($C3,Работы!$A$2:$A$6000,0)),"") -> Эскизный проект фасада и Колористический паспорт с указанием ведомости отделки и проектным решением со спецификацией элементов (крыльцо, пандус, навесы, колонны и т.д.)(для фасадов… | E3: =IFERROR(INDEX(Работы!$C$2:$C$6000,MATCH($C3,Работы!$A$2:$A$6000,0)),"") -> м2 | F3: =IFERROR(INDEX(Работы!$G$2:$G$6000,MATCH($C3,Работы!$A$2:$A$6000,0)),"") -> 0 | G3: =IFERROR(INDEX(Работы!$K$2:$K$6000,MATCH($C3,Работы!$A$2:$A$6000,0)),"") -> S_общая | J3: =IFERROR(INDEX(Материалы!$B$2:$B$9000,MATCH($I3,Материалы!$A$2:$A$9000,0)),"") | K3: =IF($I3="","",IF($F3=IFERROR(INDEX(Материалы!$G$2:$G$9000,MATCH($I3,Материалы!$A$2:$A$9000,0)),""),"OK","!! не та группа")) | L3: =IFERROR(INDEX(Работы!$H$2:$H$6000,MATCH($C3,Работы!$A$2:$A$6000,0))*(1-ДисконтТендер),0) -> 7822.5 | M3: =IF($I3="",0,IFERROR(INDEX(Материалы!$I$2:$I$9000,MATCH($I3,Материалы!$A$2:$A$9000,0))*IF(INDEX(Материалы!$J$2:$J$9000,MATCH($I3,Материалы!$A$2:$A$9000,0))="USD",КурсUSD,IF(INDEX(Материалы!$J$2:$J$9000,MATCH($I3,Материалы!$A$2:$A$9000,0))="EUR",КурсEUR,1))*INDEX(Материалы!$K$2:$K$9000,MATCH($I3,Материалы!$A$2:$A$9000,0))*(1+IFERROR(INDEX(Работы!$I$2:$I$6000,MATCH($C3,Работы!$A$2:$A$6000,0))/100,0))*(1-ДисконтТендер),0)) -> 0 | N3: =IF(AND($R3="да",$H3<>""),ROUND($H3*$L3,2),0) -> 0 | O3: =IF(AND($R3="да",$H3<>""),ROUND($H3*$M3,2),0) -> 0 | P3: =$N3+$O3 -> 0 | Q3: =IFERROR(INDEX(Работы!$J$2:$J$6000,MATCH($C3,Работы!$A$2:$A$6000,0)),"") -> нетиповая | R3: да | T3: =IF(AND($P3>0,$R3="да"),MAX($T$1:$T2)+1,"")
A4: =IFERROR(INDEX(Работы!$D$2:$D$6000,MATCH($C4,Работы!$A$2:$A$6000,0)),"") -> Р1 | B4: =IFERROR(INDEX(Работы!$F$2:$F$6000,MATCH($C4,Работы!$A$2:$A$6000,0)),"") -> 1 | C4: =IFERROR(INDEX(Работы!$A$2:$A$6000,3),"") -> РАБ.Р1.1.003 | D4: =IFERROR(INDEX(Работы!$B$2:$B$6000,MATCH($C4,Работы!$A$2:$A$6000,0)),"") -> Рабочая документация по усилению/устройству несущих конструкций ("КР"), включая пояснительную записку (для помещений от 100 до 450 м.кв) | E4: =IFERROR(INDEX(Работы!$C$2:$C$6000,MATCH($C4,Работы!$A$2:$A$6000,0)),"") -> м2 | F4: =IFERROR(INDEX(Работы!$G$2:$G$6000,MATCH($C4,Работы!$A$2:$A$6000,0)),"") -> 0 | G4: =IFERROR(INDEX(Работы!$K$2:$K$6000,MATCH($C4,Работы!$A$2:$A$6000,0)),"") -> S_общая | J4: =IFERROR(INDEX(Материалы!$B$2:$B$9000,MATCH($I4,Материалы!$A$2:$A$9000,0)),"") | K4: =IF($I4="","",IF($F4=IFERROR(INDEX(Материалы!$G$2:$G$9000,MATCH($I4,Материалы!$A$2:$A$9000,0)),""),"OK","!! не та группа")) | L4: =IFERROR(INDEX(Работы!$H$2:$H$6000,MATCH($C4,Работы!$A$2:$A$6000,0))*(1-ДисконтТендер),0) -> 135.45 | M4: =IF($I4="",0,IFERROR(INDEX(Материалы!$I$2:$I$9000,MATCH($I4,Материалы!$A$2:$A$9000,0))*IF(INDEX(Материалы!$J$2:$J$9000,MATCH($I4,Материалы!$A$2:$A$9000,0))="USD",КурсUSD,IF(INDEX(Материалы!$J$2:$J$9000,MATCH($I4,Материалы!$A$2:$A$9000,0))="EUR",КурсEUR,1))*INDEX(Материалы!$K$2:$K$9000,MATCH($I4,Материалы!$A$2:$A$9000,0))*(1+IFERROR(INDEX(Работы!$I$2:$I$6000,MATCH($C4,Работы!$A$2:$A$6000,0))/100,0))*(1-ДисконтТендер),0)) -> 0 | N4: =IF(AND($R4="да",$H4<>""),ROUND($H4*$L4,2),0) -> 0 | O4: =IF(AND($R4="да",$H4<>""),ROUND($H4*$M4,2),0) -> 0 | P4: =$N4+$O4 -> 0 | Q4: =IFERROR(INDEX(Работы!$J$2:$J$6000,MATCH($C4,Работы!$A$2:$A$6000,0)),"") -> нетиповая | R4: да | T4: =IF(AND($P4>0,$R4="да"),MAX($T$1:$T3)+1,"")
A5: =IFERROR(INDEX(Работы!$D$2:$D$6000,MATCH($C5,Работы!$A$2:$A$6000,0)),"") -> Р1 | B5: =IFERROR(INDEX(Работы!$F$2:$F$6000,MATCH($C5,Работы!$A$2:$A$6000,0)),"") -> 1 | C5: =IFERROR(INDEX(Работы!$A$2:$A$6000,4),"") -> РАБ.Р1.1.004 | D5: =IFERROR(INDEX(Работы!$B$2:$B$6000,MATCH($C5,Работы!$A$2:$A$6000,0)),"") -> Рабочая документация "Архитектурные решения" ("АР"), включая пояснительную записку (для помещений от 100 до 450 м.кв) | E5: =IFERROR(INDEX(Работы!$C$2:$C$6000,MATCH($C5,Работы!$A$2:$A$6000,0)),"") -> м2 | F5: =IFERROR(INDEX(Работы!$G$2:$G$6000,MATCH($C5,Работы!$A$2:$A$6000,0)),"") -> 0 | G5: =IFERROR(INDEX(Работы!$K$2:$K$6000,MATCH($C5,Работы!$A$2:$A$6000,0)),"") -> S_общая | J5: =IFERROR(INDEX(Материалы!$B$2:$B$9000,MATCH($I5,Материалы!$A$2:$A$9000,0)),"") | K5: =IF($I5="","",IF($F5=IFERROR(INDEX(Материалы!$G$2:$G$9000,MATCH($I5,Материалы!$A$2:$A$9000,0)),""),"OK","!! не та группа")) | L5: =IFERROR(INDEX(Работы!$H$2:$H$6000,MATCH($C5,Работы!$A$2:$A$6000,0))*(1-ДисконтТендер),0) -> 389.55 | M5: =IF($I5="",0,IFERROR(INDEX(Материалы!$I$2:$I$9000,MATCH($I5,Материалы!$A$2:$A$9000,0))*IF(INDEX(Материалы!$J$2:$J$9000,MATCH($I5,Материалы!$A$2:$A$9000,0))="USD",КурсUSD,IF(INDEX(Материалы!$J$2:$J$9000,MATCH($I5,Материалы!$A$2:$A$9000,0))="EUR",КурсEUR,1))*INDEX(Материалы!$K$2:$K$9000,MATCH($I5,Материалы!$A$2:$A$9000,0))*(1+IFERROR(INDEX(Работы!$I$2:$I$6000,MATCH($C5,Работы!$A$2:$A$6000,0))/100,0))*(1-ДисконтТендер),0)) -> 0 | N5: =IF(AND($R5="да",$H5<>""),ROUND($H5*$L5,2),0) -> 0 | O5: =IF(AND($R5="да",$H5<>""),ROUND($H5*$M5,2),0) -> 0 | P5: =$N5+$O5 -> 0 | Q5: =IFERROR(INDEX(Работы!$J$2:$J$6000,MATCH($C5,Работы!$A$2:$A$6000,0)),"") -> типовая | R5: да | T5: =IF(AND($P5>0,$R5="да"),MAX($T$1:$T4)+1,"")
A6: =IFERROR(INDEX(Работы!$D$2:$D$6000,MATCH($C6,Работы!$A$2:$A$6000,0)),"") -> Р1 | B6: =IFERROR(INDEX(Работы!$F$2:$F$6000,MATCH($C6,Работы!$A$2:$A$6000,0)),"") -> 1 | C6: =IFERROR(INDEX(Работы!$A$2:$A$6000,5),"") -> РАБ.Р1.1.005 | D6: =IFERROR(INDEX(Работы!$B$2:$B$6000,MATCH($C6,Работы!$A$2:$A$6000,0)),"") -> Рабочая документация по электроснабжению и электроосвещению ("ЭОМ"), включая пояснительную записку (для помещений от 100 до 450 м.кв) | E6: =IFERROR(INDEX(Работы!$C$2:$C$6000,MATCH($C6,Работы!$A$2:$A$6000,0)),"") -> м2 | F6: =IFERROR(INDEX(Работы!$G$2:$G$6000,MATCH($C6,Работы!$A$2:$A$6000,0)),"") -> 0 | G6: =IFERROR(INDEX(Работы!$K$2:$K$6000,MATCH($C6,Работы!$A$2:$A$6000,0)),"") -> S_общая | J6: =IFERROR(INDEX(Материалы!$B$2:$B$9000,MATCH($I6,Материалы!$A$2:$A$9000,0)),"") | K6: =IF($I6="","",IF($F6=IFERROR(INDEX(Материалы!$G$2:$G$9000,MATCH($I6,Материалы!$A$2:$A$9000,0)),""),"OK","!! не та группа")) | L6: =IFERROR(INDEX(Работы!$H$2:$H$6000,MATCH($C6,Работы!$A$2:$A$6000,0))*(1-ДисконтТендер),0) -> 258.3 | M6: =IF($I6="",0,IFERROR(INDEX(Материалы!$I$2:$I$9000,MATCH($I6,Материалы!$A$2:$A$9000,0))*IF(INDEX(Материалы!$J$2:$J$9000,MATCH($I6,Материалы!$A$2:$A$9000,0))="USD",КурсUSD,IF(INDEX(Материалы!$J$2:$J$9000,MATCH($I6,Материалы!$A$2:$A$9000,0))="EUR",КурсEUR,1))*INDEX(Материалы!$K$2:$K$9000,MATCH($I6,Материалы!$A$2:$A$9000,0))*(1+IFERROR(INDEX(Работы!$I$2:$I$6000,MATCH($C6,Работы!$A$2:$A$6000,0))/100,0))*(1-ДисконтТендер),0)) -> 0 | N6: =IF(AND($R6="да",$H6<>""),ROUND($H6*$L6,2),0) -> 0 | O6: =IF(AND($R6="да",$H6<>""),ROUND($H6*$M6,2),0) -> 0 | P6: =$N6+$O6 -> 0 | Q6: =IFERROR(INDEX(Работы!$J$2:$J$6000,MATCH($C6,Работы!$A$2:$A$6000,0)),"") -> типовая | R6: да | T6: =IF(AND($P6>0,$R6="да"),MAX($T$1:$T5)+1,"")
A7: =IFERROR(INDEX(Работы!$D$2:$D$6000,MATCH($C7,Работы!$A$2:$A$6000,0)),"") -> Р1 | B7: =IFERROR(INDEX(Работы!$F$2:$F$6000,MATCH($C7,Работы!$A$2:$A$6000,0)),"") -> 1 | C7: =IFERROR(INDEX(Работы!$A$2:$A$6000,6),"") -> РАБ.Р1.1.006 | D7: =IFERROR(INDEX(Работы!$B$2:$B$6000,MATCH($C7,Работы!$A$2:$A$6000,0)),"") -> Рабочая документация Системы вентиляции ("ОВиК-В"), включая пояснительную записку (для помещений от 100 до 450 м.кв) | E7: =IFERROR(INDEX(Работы!$C$2:$C$6000,MATCH($C7,Работы!$A$2:$A$6000,0)),"") -> м2 | F7: =IFERROR(INDEX(Работы!$G$2:$G$6000,MATCH($C7,Работы!$A$2:$A$6000,0)),"") -> 0 | G7: =IFERROR(INDEX(Работы!$K$2:$K$6000,MATCH($C7,Работы!$A$2:$A$6000,0)),"") -> S_общая | J7: =IFERROR(INDEX(Материалы!$B$2:$B$9000,MATCH($I7,Материалы!$A$2:$A$9000,0)),"") | K7: =IF($I7="","",IF($F7=IFERROR(INDEX(Материалы!$G$2:$G$9000,MATCH($I7,Материалы!$A$2:$A$9000,0)),""),"OK","!! не та группа")) | L7: =IFERROR(INDEX(Работы!$H$2:$H$6000,MATCH($C7,Работы!$A$2:$A$6000,0))*(1-ДисконтТендер),0) -> 202.65 | M7: =IF($I7="",0,IFERROR(INDEX(Материалы!$I$2:$I$9000,MATCH($I7,Материалы!$A$2:$A$9000,0))*IF(INDEX(Материалы!$J$2:$J$9000,MATCH($I7,Материалы!$A$2:$A$9000,0))="USD",КурсUSD,IF(INDEX(Материалы!$J$2:$J$9000,MATCH($I7,Материалы!$A$2:$A$9000,0))="EUR",КурсEUR,1))*INDEX(Материалы!$K$2:$K$9000,MATCH($I7,Материалы!$A$2:$A$9000,0))*(1+IFERROR(INDEX(Работы!$I$2:$I$6000,MATCH($C7,Работы!$A$2:$A$6000,0))/100,0))*(1-ДисконтТендер),0)) -> 0 | N7: =IF(AND($R7="да",$H7<>""),ROUND($H7*$L7,2),0) -> 0 | O7: =IF(AND($R7="да",$H7<>""),ROUND($H7*$M7,2),0) -> 0 | P7: =$N7+$O7 -> 0 | Q7: =IFERROR(INDEX(Работы!$J$2:$J$6000,MATCH($C7,Работы!$A$2:$A$6000,0)),"") -> типовая | R7: да | T7: =IF(AND($P7>0,$R7="да"),MAX($T$1:$T6)+1,"")
A8: =IFERROR(INDEX(Работы!$D$2:$D$6000,MATCH($C8,Работы!$A$2:$A$6000,0)),"") -> Р1 | B8: =IFERROR(INDEX(Работы!$F$2:$F$6000,MATCH($C8,Работы!$A$2:$A$6000,0)),"") -> 1 | C8: =IFERROR(INDEX(Работы!$A$2:$A$6000,7),"") -> РАБ.Р1.1.007 | D8: =IFERROR(INDEX(Работы!$B$2:$B$6000,MATCH($C8,Работы!$A$2:$A$6000,0)),"") -> Рабочая документация Системы кондиционирования ("ОВиК-К"), включая пояснительную записку (для помещений от 100 до 450 м.кв) | E8: =IFERROR(INDEX(Работы!$C$2:$C$6000,MATCH($C8,Работы!$A$2:$A$6000,0)),"") -> м2 | F8: =IFERROR(INDEX(Работы!$G$2:$G$6000,MATCH($C8,Работы!$A$2:$A$6000,0)),"") -> 0 | G8: =IFERROR(INDEX(Работы!$K$2:$K$6000,MATCH($C8,Работы!$A$2:$A$6000,0)),"") -> S_общая | J8: =IFERROR(INDEX(Материалы!$B$2:$B$9000,MATCH($I8,Материалы!$A$2:$A$9000,0)),"") | K8: =IF($I8="","",IF($F8=IFERROR(INDEX(Материалы!$G$2:$G$9000,MATCH($I8,Материалы!$A$2:$A$9000,0)),""),"OK","!! не та группа")) | L8: =IFERROR(INDEX(Работы!$H$2:$H$6000,MATCH($C8,Работы!$A$2:$A$6000,0))*(1-ДисконтТендер),0) -> 159.48 | M8: =IF($I8="",0,IFERROR(INDEX(Материалы!$I$2:$I$9000,MATCH($I8,Материалы!$A$2:$A$9000,0))*IF(INDEX(Материалы!$J$2:$J$9000,MATCH($I8,Материалы!$A$2:$A$9000,0))="USD",КурсUSD,IF(INDEX(Материалы!$J$2:$J$9000,MATCH($I8,Материалы!$A$2:$A$9000,0))="EUR",КурсEUR,1))*INDEX(Материалы!$K$2:$K$9000,MATCH($I8,Материалы!$A$2:$A$9000,0))*(1+IFERROR(INDEX(Работы!$I$2:$I$6000,MATCH($C8,Работы!$A$2:$A$6000,0))/100,0))*(1-ДисконтТендер),0)) -> 0 | N8: =IF(AND($R8="да",$H8<>""),ROUND($H8*$L8,2),0) -> 0 | O8: =IF(AND($R8="да",$H8<>""),ROUND($H8*$M8,2),0) -> 0 | P8: =$N8+$O8 -> 0 | Q8: =IFERROR(INDEX(Работы!$J$2:$J$6000,MATCH($C8,Работы!$A$2:$A$6000,0)),"") -> типовая | R8: да | T8: =IF(AND($P8>0,$R8="да"),MAX($T$1:$T7)+1,"")
A9: =IFERROR(INDEX(Работы!$D$2:$D$6000,MATCH($C9,Работы!$A$2:$A$6000,0)),"") -> Р1 | B9: =IFERROR(INDEX(Работы!$F$2:$F$6000,MATCH($C9,Работы!$A$2:$A$6000,0)),"") -> 1 | C9: =IFERROR(INDEX(Работы!$A$2:$A$6000,8),"") -> РАБ.Р1.1.008 | D9: =IFERROR(INDEX(Работы!$B$2:$B$6000,MATCH($C9,Работы!$A$2:$A$6000,0)),"") -> Рабочая документация Системы отопления ("ОВиК-О"), включая Пояснительную записку и Теплотехнический расчет (для помещений от 100 до 450 м.кв) | E9: =IFERROR(INDEX(Работы!$C$2:$C$6000,MATCH($C9,Работы!$A$2:$A$6000,0)),"") -> м2 | F9: =IFERROR(INDEX(Работы!$G$2:$G$6000,MATCH($C9,Работы!$A$2:$A$6000,0)),"") -> 0 | G9: =IFERROR(INDEX(Работы!$K$2:$K$6000,MATCH($C9,Работы!$A$2:$A$6000,0)),"") -> S_общая | J9: =IFERROR(INDEX(Материалы!$B$2:$B$9000,MATCH($I9,Материалы!$A$2:$A$9000,0)),"") | K9: =IF($I9="","",IF($F9=IFERROR(INDEX(Материалы!$G$2:$G$9000,MATCH($I9,Материалы!$A$2:$A$9000,0)),""),"OK","!! не та группа")) | L9: =IFERROR(INDEX(Работы!$H$2:$H$6000,MATCH($C9,Работы!$A$2:$A$6000,0))*(1-ДисконтТендер),0) -> 123.9 | M9: =IF($I9="",0,IFERROR(INDEX(Материалы!$I$2:$I$9000,MATCH($I9,Материалы!$A$2:$A$9000,0))*IF(INDEX(Материалы!$J$2:$J$9000,MATCH($I9,Материалы!$A$2:$A$9000,0))="USD",КурсUSD,IF(INDEX(Материалы!$J$2:$J$9000,MATCH($I9,Материалы!$A$2:$A$9000,0))="EUR",КурсEUR,1))*INDEX(Материалы!$K$2:$K$9000,MATCH($I9,Материалы!$A$2:$A$9000,0))*(1+IFERROR(INDEX(Работы!$I$2:$I$6000,MATCH($C9,Работы!$A$2:$A$6000,0))/100,0))*(1-ДисконтТендер),0)) -> 0 | N9: =IF(AND($R9="да",$H9<>""),ROUND($H9*$L9,2),0) -> 0 | O9: =IF(AND($R9="да",$H9<>""),ROUND($H9*$M9,2),0) -> 0 | P9: =$N9+$O9 -> 0 | Q9: =IFERROR(INDEX(Работы!$J$2:$J$6000,MATCH($C9,Работы!$A$2:$A$6000,0)),"") -> типовая | R9: да | T9: =IF(AND($P9>0,$R9="да"),MAX($T$1:$T8)+1,"")
A10: =IFERROR(INDEX(Работы!$D$2:$D$6000,MATCH($C10,Работы!$A$2:$A$6000,0)),"") -> Р1 | B10: =IFERROR(INDEX(Работы!$F$2:$F$6000,MATCH($C10,Работы!$A$2:$A$6000,0)),"") -> 1 | C10: =IFERROR(INDEX(Работы!$A$2:$A$6000,9),"") -> РАБ.Р1.1.009 | D10: =IFERROR(INDEX(Работы!$B$2:$B$6000,MATCH($C10,Работы!$A$2:$A$6000,0)),"") -> Рабочая документация Системы водоснабжения и канализации ("ВК"), включая пояснительную записку (для помещений от 100 до 450 м.кв) | E10: =IFERROR(INDEX(Работы!$C$2:$C$6000,MATCH($C10,Работы!$A$2:$A$6000,0)),"") -> м2 | F10: =IFERROR(INDEX(Работы!$G$2:$G$6000,MATCH($C10,Работы!$A$2:$A$6000,0)),"") -> 0 | G10: =IFERROR(INDEX(Работы!$K$2:$K$6000,MATCH($C10,Работы!$A$2:$A$6000,0)),"") -> S_общая | J10: =IFERROR(INDEX(Материалы!$B$2:$B$9000,MATCH($I10,Материалы!$A$2:$A$9000,0)),"") | K10: =IF($I10="","",IF($F10=IFERROR(INDEX(Материалы!$G$2:$G$9000,MATCH($I10,Материалы!$A$2:$A$9000,0)),""),"OK","!! не та группа")) | L10: =IFERROR(INDEX(Работы!$H$2:$H$6000,MATCH($C10,Работы!$A$2:$A$6000,0))*(1-ДисконтТендер),0) -> 130.2 | M10: =IF($I10="",0,IFERROR(INDEX(Материалы!$I$2:$I$9000,MATCH($I10,Материалы!$A$2:$A$9000,0))*IF(INDEX(Материалы!$J$2:$J$9000,MATCH($I10,Материалы!$A$2:$A$9000,0))="USD",КурсUSD,IF(INDEX(Материалы!$J$2:$J$9000,MATCH($I10,Материалы!$A$2:$A$9000,0))="EUR",КурсEUR,1))*INDEX(Материалы!$K$2:$K$9000,MATCH($I10,Материалы!$A$2:$A$9000,0))*(1+IFERROR(INDEX(Работы!$I$2:$I$6000,MATCH($C10,Работы!$A$2:$A$6000,0))/100,0))*(1-ДисконтТендер),0)) -> 0 | N10: =IF(AND($R10="да",$H10<>""),ROUND($H10*$L10,2),0) -> 0 | O10: =IF(AND($R10="да",$H10<>""),ROUND($H10*$M10,2),0) -> 0 | P10: =$N10+$O10 -> 0 | Q10: =IFERROR(INDEX(Работы!$J$2:$J$6000,MATCH($C10,Работы!$A$2:$A$6000,0)),"") -> типовая | R10: да | T10: =IF(AND($P10>0,$R10="да"),MAX($T$1:$T9)+1,"")
A11: =IFERROR(INDEX(Работы!$D$2:$D$6000,MATCH($C11,Работы!$A$2:$A$6000,0)),"") -> Р1 | B11: =IFERROR(INDEX(Работы!$F$2:$F$6000,MATCH($C11,Работы!$A$2:$A$6000,0)),"") -> 1 | C11: =IFERROR(INDEX(Работы!$A$2:$A$6000,10),"") -> РАБ.Р1.1.010 | D11: =IFERROR(INDEX(Работы!$B$2:$B$6000,MATCH($C11,Работы!$A$2:$A$6000,0)),"") -> Рабочая документация Системы автоматической установки водяного пожаротушения ("АУВПТ"), (спринкерная, дренчерная, модульная система), включая пояснительную записку (для помещений о… | E11: =IFERROR(INDEX(Работы!$C$2:$C$6000,MATCH($C11,Работы!$A$2:$A$6000,0)),"") -> м2 | F11: =IFERROR(INDEX(Работы!$G$2:$G$6000,MATCH($C11,Работы!$A$2:$A$6000,0)),"") -> 0 | G11: =IFERROR(INDEX(Работы!$K$2:$K$6000,MATCH($C11,Работы!$A$2:$A$6000,0)),"") -> S_общая | J11: =IFERROR(INDEX(Материалы!$B$2:$B$9000,MATCH($I11,Материалы!$A$2:$A$9000,0)),"") | K11: =IF($I11="","",IF($F11=IFERROR(INDEX(Материалы!$G$2:$G$9000,MATCH($I11,Материалы!$A$2:$A$9000,0)),""),"OK","!! не та группа")) | L11: =IFERROR(INDEX(Работы!$H$2:$H$6000,MATCH($C11,Работы!$A$2:$A$6000,0))*(1-ДисконтТендер),0) -> 91.68 | M11: =IF($I11="",0,IFERROR(INDEX(Материалы!$I$2:$I$9000,MATCH($I11,Материалы!$A$2:$A$9000,0))*IF(INDEX(Материалы!$J$2:$J$9000,MATCH($I11,Материалы!$A$2:$A$9000,0))="USD",КурсUSD,IF(INDEX(Материалы!$J$2:$J$9000,MATCH($I11,Материалы!$A$2:$A$9000,0))="EUR",КурсEUR,1))*INDEX(Материалы!$K$2:$K$9000,MATCH($I11,Материалы!$A$2:$A$9000,0))*(1+IFERROR(INDEX(Работы!$I$2:$I$6000,MATCH($C11,Работы!$A$2:$A$6000,0))/100,0))*(1-ДисконтТендер),0)) -> 0 | N11: =IF(AND($R11="да",$H11<>""),ROUND($H11*$L11,2),0) -> 0 | O11: =IF(AND($R11="да",$H11<>""),ROUND($H11*$M11,2),0) -> 0 | P11: =$N11+$O11 -> 0 | Q11: =IFERROR(INDEX(Работы!$J$2:$J$6000,MATCH($C11,Работы!$A$2:$A$6000,0)),"") -> типовая | R11: да | T11: =IF(AND($P11>0,$R11="да"),MAX($T$1:$T10)+1,"")
A12: =IFERROR(INDEX(Работы!$D$2:$D$6000,MATCH($C12,Работы!$A$2:$A$6000,0)),"") -> Р1 | B12: =IFERROR(INDEX(Работы!$F$2:$F$6000,MATCH($C12,Работы!$A$2:$A$6000,0)),"") -> 1 | C12: =IFERROR(INDEX(Работы!$A$2:$A$6000,11),"") -> РАБ.Р1.1.011 | D12: =IFERROR(INDEX(Работы!$B$2:$B$6000,MATCH($C12,Работы!$A$2:$A$6000,0)),"") -> Рабочая документация Системы Внутреннего противопожарного водопровода ("ВПВ"), включая пояснительную записку (для помещений от 100 до 450 м.кв) | E12: =IFERROR(INDEX(Работы!$C$2:$C$6000,MATCH($C12,Работы!$A$2:$A$6000,0)),"") -> м2 | F12: =IFERROR(INDEX(Работы!$G$2:$G$6000,MATCH($C12,Работы!$A$2:$A$6000,0)),"") -> 0 | G12: =IFERROR(INDEX(Работы!$K$2:$K$6000,MATCH($C12,Работы!$A$2:$A$6000,0)),"") -> S_общая | J12: =IFERROR(INDEX(Материалы!$B$2:$B$9000,MATCH($I12,Материалы!$A$2:$A$9000,0)),"") | K12: =IF($I12="","",IF($F12=IFERROR(INDEX(Материалы!$G$2:$G$9000,MATCH($I12,Материалы!$A$2:$A$9000,0)),""),"OK","!! не та группа")) | L12: =IFERROR(INDEX(Работы!$H$2:$H$6000,MATCH($C12,Работы!$A$2:$A$6000,0))*(1-ДисконтТендер),0) -> 91.68 | M12: =IF($I12="",0,IFERROR(INDEX(Материалы!$I$2:$I$9000,MATCH($I12,Материалы!$A$2:$A$9000,0))*IF(INDEX(Материалы!$J$2:$J$9000,MATCH($I12,Материалы!$A$2:$A$9000,0))="USD",КурсUSD,IF(INDEX(Материалы!$J$2:$J$9000,MATCH($I12,Материалы!$A$2:$A$9000,0))="EUR",КурсEUR,1))*INDEX(Материалы!$K$2:$K$9000,MATCH($I12,Материалы!$A$2:$A$9000,0))*(1+IFERROR(INDEX(Работы!$I$2:$I$6000,MATCH($C12,Работы!$A$2:$A$6000,0))/100,0))*(1-ДисконтТендер),0)) -> 0 | N12: =IF(AND($R12="да",$H12<>""),ROUND($H12*$L12,2),0) -> 0 | O12: =IF(AND($R12="да",$H12<>""),ROUND($H12*$M12,2),0) -> 0 | P12: =$N12+$O12 -> 0 | Q12: =IFERROR(INDEX(Работы!$J$2:$J$6000,MATCH($C12,Работы!$A$2:$A$6000,0)),"") -> типовая | R12: да | T12: =IF(AND($P12>0,$R12="да"),MAX($T$1:$T11)+1,"")
A13: =IFERROR(INDEX(Работы!$D$2:$D$6000,MATCH($C13,Работы!$A$2:$A$6000,0)),"") -> Р1 | B13: =IFERROR(INDEX(Работы!$F$2:$F$6000,MATCH($C13,Работы!$A$2:$A$6000,0)),"") -> 1 | C13: =IFERROR(INDEX(Работы!$A$2:$A$6000,12),"") -> РАБ.Р1.1.012 | D13: =IFERROR(INDEX(Работы!$B$2:$B$6000,MATCH($C13,Работы!$A$2:$A$6000,0)),"") -> Рабочая документация Системы дымоудаления ("ДУ"), включая пояснительную записку (для помещений от 100 до 450 м.кв) | E13: =IFERROR(INDEX(Работы!$C$2:$C$6000,MATCH($C13,Работы!$A$2:$A$6000,0)),"") -> м2 | F13: =IFERROR(INDEX(Работы!$G$2:$G$6000,MATCH($C13,Работы!$A$2:$A$6000,0)),"") -> 0 | G13: =IFERROR(INDEX(Работы!$K$2:$K$6000,MATCH($C13,Работы!$A$2:$A$6000,0)),"") -> S_общая | J13: =IFERROR(INDEX(Материалы!$B$2:$B$9000,MATCH($I13,Материалы!$A$2:$A$9000,0)),"") | K13: =IF($I13="","",IF($F13=IFERROR(INDEX(Материалы!$G$2:$G$9000,MATCH($I13,Материалы!$A$2:$A$9000,0)),""),"OK","!! не та группа")) | L13: =IFERROR(INDEX(Работы!$H$2:$H$6000,MATCH($C13,Работы!$A$2:$A$6000,0))*(1-ДисконтТендер),0) -> 103.95 | M13: =IF($I13="",0,IFERROR(INDEX(Материалы!$I$2:$I$9000,MATCH($I13,Материалы!$A$2:$A$9000,0))*IF(INDEX(Материалы!$J$2:$J$9000,MATCH($I13,Материалы!$A$2:$A$9000,0))="USD",КурсUSD,IF(INDEX(Материалы!$J$2:$J$9000,MATCH($I13,Материалы!$A$2:$A$9000,0))="EUR",КурсEUR,1))*INDEX(Материалы!$K$2:$K$9000,MATCH($I13,Материалы!$A$2:$A$9000,0))*(1+IFERROR(INDEX(Работы!$I$2:$I$6000,MATCH($C13,Работы!$A$2:$A$6000,0))/100,0))*(1-ДисконтТендер),0)) -> 0 | N13: =IF(AND($R13="да",$H13<>""),ROUND($H13*$L13,2),0) -> 0 | O13: =IF(AND($R13="да",$H13<>""),ROUND($H13*$M13,2),0) -> 0 | P13: =$N13+$O13 -> 0 | Q13: =IFERROR(INDEX(Работы!$J$2:$J$6000,MATCH($C13,Работы!$A$2:$A$6000,0)),"") -> типовая | R13: да | T13: =IF(AND($P13>0,$R13="да"),MAX($T$1:$T12)+1,"")
A14: =IFERROR(INDEX(Работы!$D$2:$D$6000,MATCH($C14,Работы!$A$2:$A$6000,0)),"") -> Р1 | B14: =IFERROR(INDEX(Работы!$F$2:$F$6000,MATCH($C14,Работы!$A$2:$A$6000,0)),"") -> 1 | C14: =IFERROR(INDEX(Работы!$A$2:$A$6000,13),"") -> РАБ.Р1.1.013 | D14: =IFERROR(INDEX(Работы!$B$2:$B$6000,MATCH($C14,Работы!$A$2:$A$6000,0)),"") -> Рабочая документация "Автоматическая пожарная сигнализация" (АПС) | E14: =IFERROR(INDEX(Работы!$C$2:$C$6000,MATCH($C14,Работы!$A$2:$A$6000,0)),"") -> м2 | F14: =IFERROR(INDEX(Работы!$G$2:$G$6000,MATCH($C14,Работы!$A$2:$A$6000,0)),"") -> 0 | G14: =IFERROR(INDEX(Работы!$K$2:$K$6000,MATCH($C14,Работы!$A$2:$A$6000,0)),"") -> S_общая | J14: =IFERROR(INDEX(Материалы!$B$2:$B$9000,MATCH($I14,Материалы!$A$2:$A$9000,0)),"") | K14: =IF($I14="","",IF($F14=IFERROR(INDEX(Материалы!$G$2:$G$9000,MATCH($I14,Материалы!$A$2:$A$9000,0)),""),"OK","!! не та группа")) | L14: =IFERROR(INDEX(Работы!$H$2:$H$6000,MATCH($C14,Работы!$A$2:$A$6000,0))*(1-ДисконтТендер),0) -> 7.04 | M14: =IF($I14="",0,IFERROR(INDEX(Материалы!$I$2:$I$9000,MATCH($I14,Материалы!$A$2:$A$9000,0))*IF(INDEX(Материалы!$J$2:$J$9000,MATCH($I14,Материалы!$A$2:$A$9000,0))="USD",КурсUSD,IF(INDEX(Материалы!$J$2:$J$9000,MATCH($I14,Материалы!$A$2:$A$9000,0))="EUR",КурсEUR,1))*INDEX(Материалы!$K$2:$K$9000,MATCH($I14,Материалы!$A$2:$A$9000,0))*(1+IFERROR(INDEX(Работы!$I$2:$I$6000,MATCH($C14,Работы!$A$2:$A$6000,0))/100,0))*(1-ДисконтТендер),0)) -> 0 | N14: =IF(AND($R14="да",$H14<>""),ROUND($H14*$L14,2),0) -> 0 | O14: =IF(AND($R14="да",$H14<>""),ROUND($H14*$M14,2),0) -> 0 | P14: =$N14+$O14 -> 0 | Q14: =IFERROR(INDEX(Работы!$J$2:$J$6000,MATCH($C14,Работы!$A$2:$A$6000,0)),"") -> типовая | R14: да | T14: =IF(AND($P14>0,$R14="да"),MAX($T$1:$T13)+1,"")
A15: =IFERROR(INDEX(Работы!$D$2:$D$6000,MATCH($C15,Работы!$A$2:$A$6000,0)),"") -> Р1 | B15: =IFERROR(INDEX(Работы!$F$2:$F$6000,MATCH($C15,Работы!$A$2:$A$6000,0)),"") -> 1 | C15: =IFERROR(INDEX(Работы!$A$2:$A$6000,14),"") -> РАБ.Р1.1.014 | D15: =IFERROR(INDEX(Работы!$B$2:$B$6000,MATCH($C15,Работы!$A$2:$A$6000,0)),"") -> Рабочая документация "Система оповещения и управления эвакуацией людей при пожаре" (СОУЭ) | E15: =IFERROR(INDEX(Работы!$C$2:$C$6000,MATCH($C15,Работы!$A$2:$A$6000,0)),"") -> м2 | F15: =IFERROR(INDEX(Работы!$G$2:$G$6000,MATCH($C15,Работы!$A$2:$A$6000,0)),"") -> 0 | G15: =IFERROR(INDEX(Работы!$K$2:$K$6000,MATCH($C15,Работы!$A$2:$A$6000,0)),"") -> S_общая | J15: =IFERROR(INDEX(Материалы!$B$2:$B$9000,MATCH($I15,Материалы!$A$2:$A$9000,0)),"") | K15: =IF($I15="","",IF($F15=IFERROR(INDEX(Материалы!$G$2:$G$9000,MATCH($I15,Материалы!$A$2:$A$9000,0)),""),"OK","!! не та группа")) | L15: =IFERROR(INDEX(Работы!$H$2:$H$6000,MATCH($C15,Работы!$A$2:$A$6000,0))*(1-ДисконтТендер),0) -> 4.1 | M15: =IF($I15="",0,IFERROR(INDEX(Материалы!$I$2:$I$9000,MATCH($I15,Материалы!$A$2:$A$9000,0))*IF(INDEX(Материалы!$J$2:$J$9000,MATCH($I15,Материалы!$A$2:$A$9000,0))="USD",КурсUSD,IF(INDEX(Материалы!$J$2:$J$9000,MATCH($I15,Материалы!$A$2:$A$9000,0))="EUR",КурсEUR,1))*INDEX(Материалы!$K$2:$K$9000,MATCH($I15,Материалы!$A$2:$A$9000,0))*(1+IFERROR(INDEX(Работы!$I$2:$I$6000,MATCH($C15,Работы!$A$2:$A$6000,0))/100,0))*(1-ДисконтТендер),0)) -> 0 | N15: =IF(AND($R15="да",$H15<>""),ROUND($H15*$L15,2),0) -> 0 | O15: =IF(AND($R15="да",$H15<>""),ROUND($H15*$M15,2),0) -> 0 | P15: =$N15+$O15 -> 0 | Q15: =IFERROR(INDEX(Работы!$J$2:$J$6000,MATCH($C15,Работы!$A$2:$A$6000,0)),"") -> типовая | R15: да | T15: =IF(AND($P15>0,$R15="да"),MAX($T$1:$T14)+1,"")
A16: =IFERROR(INDEX(Работы!$D$2:$D$6000,MATCH($C16,Работы!$A$2:$A$6000,0)),"") -> Р1 | B16: =IFERROR(INDEX(Работы!$F$2:$F$6000,MATCH($C16,Работы!$A$2:$A$6000,0)),"") -> 1 | C16: =IFERROR(INDEX(Работы!$A$2:$A$6000,15),"") -> РАБ.Р1.1.015 | D16: =IFERROR(INDEX(Работы!$B$2:$B$6000,MATCH($C16,Работы!$A$2:$A$6000,0)),"") -> Рабочая документация "Автоматизация системы внутреннего противопожарного водопровода (ВПВ) | E16: =IFERROR(INDEX(Работы!$C$2:$C$6000,MATCH($C16,Работы!$A$2:$A$6000,0)),"") -> м2 | F16: =IFERROR(INDEX(Работы!$G$2:$G$6000,MATCH($C16,Работы!$A$2:$A$6000,0)),"") -> 0 | G16: =IFERROR(INDEX(Работы!$K$2:$K$6000,MATCH($C16,Работы!$A$2:$A$6000,0)),"") -> S_общая | J16: =IFERROR(INDEX(Материалы!$B$2:$B$9000,MATCH($I16,Материалы!$A$2:$A$9000,0)),"") | K16: =IF($I16="","",IF($F16=IFERROR(INDEX(Материалы!$G$2:$G$9000,MATCH($I16,Материалы!$A$2:$A$9000,0)),""),"OK","!! не та группа")) | L16: =IFERROR(INDEX(Работы!$H$2:$H$6000,MATCH($C16,Работы!$A$2:$A$6000,0))*(1-ДисконтТендер),0) -> 0.84 | M16: =IF($I16="",0,IFERROR(INDEX(Материалы!$I$2:$I$9000,MATCH($I16,Материалы!$A$2:$A$9000,0))*IF(INDEX(Материалы!$J$2:$J$9000,MATCH($I16,Материалы!$A$2:$A$9000,0))="USD",КурсUSD,IF(INDEX(Материалы!$J$2:$J$9000,MATCH($I16,Материалы!$A$2:$A$9000,0))="EUR",КурсEUR,1))*INDEX(Материалы!$K$2:$K$9000,MATCH($I16,Материалы!$A$2:$A$9000,0))*(1+IFERROR(INDEX(Работы!$I$2:$I$6000,MATCH($C16,Работы!$A$2:$A$6000,0))/100,0))*(1-ДисконтТендер),0)) -> 0 | N16: =IF(AND($R16="да",$H16<>""),ROUND($H16*$L16,2),0) -> 0 | O16: =IF(AND($R16="да",$H16<>""),ROUND($H16*$M16,2),0) -> 0 | P16: =$N16+$O16 -> 0 | Q16: =IFERROR(INDEX(Работы!$J$2:$J$6000,MATCH($C16,Работы!$A$2:$A$6000,0)),"") -> типовая | R16: да | T16: =IF(AND($P16>0,$R16="да"),MAX($T$1:$T15)+1,"")
A17: =IFERROR(INDEX(Работы!$D$2:$D$6000,MATCH($C17,Работы!$A$2:$A$6000,0)),"") -> Р1 | B17: =IFERROR(INDEX(Работы!$F$2:$F$6000,MATCH($C17,Работы!$A$2:$A$6000,0)),"") -> 1 | C17: =IFERROR(INDEX(Работы!$A$2:$A$6000,16),"") -> РАБ.Р1.1.016 | D17: =IFERROR(INDEX(Работы!$B$2:$B$6000,MATCH($C17,Работы!$A$2:$A$6000,0)),"") -> Рабочая документация "Автоматизация системы противодымной вентиляции (ПДВ")" | E17: =IFERROR(INDEX(Работы!$C$2:$C$6000,MATCH($C17,Работы!$A$2:$A$6000,0)),"") -> м2 | F17: =IFERROR(INDEX(Работы!$G$2:$G$6000,MATCH($C17,Работы!$A$2:$A$6000,0)),"") -> 0 | G17: =IFERROR(INDEX(Работы!$K$2:$K$6000,MATCH($C17,Работы!$A$2:$A$6000,0)),"") -> S_общая | J17: =IFERROR(INDEX(Материалы!$B$2:$B$9000,MATCH($I17,Материалы!$A$2:$A$9000,0)),"") | K17: =IF($I17="","",IF($F17=IFERROR(INDEX(Материалы!$G$2:$G$9000,MATCH($I17,Материалы!$A$2:$A$9000,0)),""),"OK","!! не та группа")) | L17: =IFERROR(INDEX(Работы!$H$2:$H$6000,MATCH($C17,Работы!$A$2:$A$6000,0))*(1-ДисконтТендер),0) -> 2.62 | M17: =IF($I17="",0,IFERROR(INDEX(Материалы!$I$2:$I$9000,MATCH($I17,Материалы!$A$2:$A$9000,0))*IF(INDEX(Материалы!$J$2:$J$9000,MATCH($I17,Материалы!$A$2:$A$9000,0))="USD",КурсUSD,IF(INDEX(Материалы!$J$2:$J$9000,MATCH($I17,Материалы!$A$2:$A$9000,0))="EUR",КурсEUR,1))*INDEX(Материалы!$K$2:$K$9000,MATCH($I17,Материалы!$A$2:$A$9000,0))*(1+IFERROR(INDEX(Работы!$I$2:$I$6000,MATCH($C17,Работы!$A$2:$A$6000,0))/100,0))*(1-ДисконтТендер),0)) -> 0 | N17: =IF(AND($R17="да",$H17<>""),ROUND($H17*$L17,2),0) -> 0 | O17: =IF(AND($R17="да",$H17<>""),ROUND($H17*$M17,2),0) -> 0 | P17: =$N17+$O17 -> 0 | Q17: =IFERROR(INDEX(Работы!$J$2:$J$6000,MATCH($C17,Работы!$A$2:$A$6000,0)),"") -> типовая | R17: да | T17: =IF(AND($P17>0,$R17="да"),MAX($T$1:$T16)+1,"")
A18: =IFERROR(INDEX(Работы!$D$2:$D$6000,MATCH($C18,Работы!$A$2:$A$6000,0)),"") -> Р1 | B18: =IFERROR(INDEX(Работы!$F$2:$F$6000,MATCH($C18,Работы!$A$2:$A$6000,0)),"") -> 1 | C18: =IFERROR(INDEX(Работы!$A$2:$A$6000,17),"") -> РАБ.Р1.1.017 | D18: =IFERROR(INDEX(Работы!$B$2:$B$6000,MATCH($C18,Работы!$A$2:$A$6000,0)),"") -> Рабочая документация "Автоматизация Системы отопления, вентиляции и кондиционирования (ОВиК)" | E18: =IFERROR(INDEX(Работы!$C$2:$C$6000,MATCH($C18,Работы!$A$2:$A$6000,0)),"") -> м2 | F18: =IFERROR(INDEX(Работы!$G$2:$G$6000,MATCH($C18,Работы!$A$2:$A$6000,0)),"") -> 0 | G18: =IFERROR(INDEX(Работы!$K$2:$K$6000,MATCH($C18,Работы!$A$2:$A$6000,0)),"") -> S_общая | J18: =IFERROR(INDEX(Материалы!$B$2:$B$9000,MATCH($I18,Материалы!$A$2:$A$9000,0)),"") | K18: =IF($I18="","",IF($F18=IFERROR(INDEX(Материалы!$G$2:$G$9000,MATCH($I18,Материалы!$A$2:$A$9000,0)),""),"OK","!! не та группа")) | L18: =IFERROR(INDEX(Работы!$H$2:$H$6000,MATCH($C18,Работы!$A$2:$A$6000,0))*(1-ДисконтТендер),0) -> 0.32 | M18: =IF($I18="",0,IFERROR(INDEX(Материалы!$I$2:$I$9000,MATCH($I18,Материалы!$A$2:$A$9000,0))*IF(INDEX(Материалы!$J$2:$J$9000,MATCH($I18,Материалы!$A$2:$A$9000,0))="USD",КурсUSD,IF(INDEX(Материалы!$J$2:$J$9000,MATCH($I18,Материалы!$A$2:$A$9000,0))="EUR",КурсEUR,1))*INDEX(Материалы!$K$2:$K$9000,MATCH($I18,Материалы!$A$2:$A$9000,0))*(1+IFERROR(INDEX(Работы!$I$2:$I$6000,MATCH($C18,Работы!$A$2:$A$6000,0))/100,0))*(1-ДисконтТендер),0)) -> 0 | N18: =IF(AND($R18="да",$H18<>""),ROUND($H18*$L18,2),0) -> 0 | O18: =IF(AND($R18="да",$H18<>""),ROUND($H18*$M18,2),0) -> 0 | P18: =$N18+$O18 -> 0 | Q18: =IFERROR(INDEX(Работы!$J$2:$J$6000,MATCH($C18,Работы!$A$2:$A$6000,0)),"") -> типовая | R18: да | T18: =IF(AND($P18>0,$R18="да"),MAX($T$1:$T17)+1,"")
A19: =IFERROR(INDEX(Работы!$D$2:$D$6000,MATCH($C19,Работы!$A$2:$A$6000,0)),"") -> Р1 | B19: =IFERROR(INDEX(Работы!$F$2:$F$6000,MATCH($C19,Работы!$A$2:$A$6000,0)),"") -> 1 | C19: =IFERROR(INDEX(Работы!$A$2:$A$6000,18),"") -> РАБ.Р1.1.018 | D19: =IFERROR(INDEX(Работы!$B$2:$B$6000,MATCH($C19,Работы!$A$2:$A$6000,0)),"") -> Рабочая документация "Автоматизация Системы аварийного освещения (АО)" | E19: =IFERROR(INDEX(Работы!$C$2:$C$6000,MATCH($C19,Работы!$A$2:$A$6000,0)),"") -> м2 | F19: =IFERROR(INDEX(Работы!$G$2:$G$6000,MATCH($C19,Работы!$A$2:$A$6000,0)),"") -> 0 | G19: =IFERROR(INDEX(Работы!$K$2:$K$6000,MATCH($C19,Работы!$A$2:$A$6000,0)),"") -> S_общая | J19: =IFERROR(INDEX(Материалы!$B$2:$B$9000,MATCH($I19,Материалы!$A$2:$A$9000,0)),"") | K19: =IF($I19="","",IF($F19=IFERROR(INDEX(Материалы!$G$2:$G$9000,MATCH($I19,Материалы!$A$2:$A$9000,0)),""),"OK","!! не та группа")) | L19: =IFERROR(INDEX(Работы!$H$2:$H$6000,MATCH($C19,Работы!$A$2:$A$6000,0))*(1-ДисконтТендер),0) -> 0.11 | M19: =IF($I19="",0,IFERROR(INDEX(Материалы!$I$2:$I$9000,MATCH($I19,Материалы!$A$2:$A$9000,0))*IF(INDEX(Материалы!$J$2:$J$9000,MATCH($I19,Материалы!$A$2:$A$9000,0))="USD",КурсUSD,IF(INDEX(Материалы!$J$2:$J$9000,MATCH($I19,Материалы!$A$2:$A$9000,0))="EUR",КурсEUR,1))*INDEX(Материалы!$K$2:$K$9000,MATCH($I19,Материалы!$A$2:$A$9000,0))*(1+IFERROR(INDEX(Работы!$I$2:$I$6000,MATCH($C19,Работы!$A$2:$A$6000,0))/100,0))*(1-ДисконтТендер),0)) -> 0 | N19: =IF(AND($R19="да",$H19<>""),ROUND($H19*$L19,2),0) -> 0 | O19: =IF(AND($R19="да",$H19<>""),ROUND($H19*$M19,2),0) -> 0 | P19: =$N19+$O19 -> 0 | Q19: =IFERROR(INDEX(Работы!$J$2:$J$6000,MATCH($C19,Работы!$A$2:$A$6000,0)),"") -> типовая | R19: да | T19: =IF(AND($P19>0,$R19="да"),MAX($T$1:$T18)+1,"")
A20: =IFERROR(INDEX(Работы!$D$2:$D$6000,MATCH($C20,Работы!$A$2:$A$6000,0)),"") -> Р1 | B20: =IFERROR(INDEX(Работы!$F$2:$F$6000,MATCH($C20,Работы!$A$2:$A$6000,0)),"") -> 1 | C20: =IFERROR(INDEX(Работы!$A$2:$A$6000,19),"") -> РАБ.Р1.1.019 | D20: =IFERROR(INDEX(Работы!$B$2:$B$6000,MATCH($C20,Работы!$A$2:$A$6000,0)),"") -> Рабочая документация "Автоматизации лифтовового хозяйства" | E20: =IFERROR(INDEX(Работы!$C$2:$C$6000,MATCH($C20,Работы!$A$2:$A$6000,0)),"") -> м2 | F20: =IFERROR(INDEX(Работы!$G$2:$G$6000,MATCH($C20,Работы!$A$2:$A$6000,0)),"") -> 0 | G20: =IFERROR(INDEX(Работы!$K$2:$K$6000,MATCH($C20,Работы!$A$2:$A$6000,0)),"") -> S_общая | J20: =IFERROR(INDEX(Материалы!$B$2:$B$9000,MATCH($I20,Материалы!$A$2:$A$9000,0)),"") | K20: =IF($I20="","",IF($F20=IFERROR(INDEX(Материалы!$G$2:$G$9000,MATCH($I20,Материалы!$A$2:$A$9000,0)),""),"OK","!! не та группа")) | L20: =IFERROR(INDEX(Работы!$H$2:$H$6000,MATCH($C20,Работы!$A$2:$A$6000,0))*(1-ДисконтТендер),0) -> 0.11 | M20: =IF($I20="",0,IFERROR(INDEX(Материалы!$I$2:$I$9000,MATCH($I20,Материалы!$A$2:$A$9000,0))*IF(INDEX(Материалы!$J$2:$J$9000,MATCH($I20,Материалы!$A$2:$A$9000,0))="USD",КурсUSD,IF(INDEX(Материалы!$J$2:$J$9000,MATCH($I20,Материалы!$A$2:$A$9000,0))="EUR",КурсEUR,1))*INDEX(Материалы!$K$2:$K$9000,MATCH($I20,Материалы!$A$2:$A$9000,0))*(1+IFERROR(INDEX(Работы!$I$2:$I$6000,MATCH($C20,Работы!$A$2:$A$6000,0))/100,0))*(1-ДисконтТендер),0)) -> 0 | N20: =IF(AND($R20="да",$H20<>""),ROUND($H20*$L20,2),0) -> 0 | O20: =IF(AND($R20="да",$H20<>""),ROUND($H20*$M20,2),0) -> 0 | P20: =$N20+$O20 -> 0 | Q20: =IFERROR(INDEX(Работы!$J$2:$J$6000,MATCH($C20,Работы!$A$2:$A$6000,0)),"") -> нетиповая | R20: да | T20: =IF(AND($P20>0,$R20="да"),MAX($T$1:$T19)+1,"")
A21: =IFERROR(INDEX(Работы!$D$2:$D$6000,MATCH($C21,Работы!$A$2:$A$6000,0)),"") -> Р1 | B21: =IFERROR(INDEX(Работы!$F$2:$F$6000,MATCH($C21,Работы!$A$2:$A$6000,0)),"") -> 1 | C21: =IFERROR(INDEX(Работы!$A$2:$A$6000,20),"") -> РАБ.Р1.1.020 | D21: =IFERROR(INDEX(Работы!$B$2:$B$6000,MATCH($C21,Работы!$A$2:$A$6000,0)),"") -> Рабочая документация "Автоматизации Системы контроля управления доступом (СКУД)" | E21: =IFERROR(INDEX(Работы!$C$2:$C$6000,MATCH($C21,Работы!$A$2:$A$6000,0)),"") -> м2 | F21: =IFERROR(INDEX(Работы!$G$2:$G$6000,MATCH($C21,Работы!$A$2:$A$6000,0)),"") -> 0 | G21: =IFERROR(INDEX(Работы!$K$2:$K$6000,MATCH($C21,Работы!$A$2:$A$6000,0)),"") -> S_общая | J21: =IFERROR(INDEX(Материалы!$B$2:$B$9000,MATCH($I21,Материалы!$A$2:$A$9000,0)),"") | K21: =IF($I21="","",IF($F21=IFERROR(INDEX(Материалы!$G$2:$G$9000,MATCH($I21,Материалы!$A$2:$A$9000,0)),""),"OK","!! не та группа")) | L21: =IFERROR(INDEX(Работы!$H$2:$H$6000,MATCH($C21,Работы!$A$2:$A$6000,0))*(1-ДисконтТендер),0) -> 0.11 | M21: =IF($I21="",0,IFERROR(INDEX(Материалы!$I$2:$I$9000,MATCH($I21,Материалы!$A$2:$A$9000,0))*IF(INDEX(Материалы!$J$2:$J$9000,MATCH($I21,Материалы!$A$2:$A$9000,0))="USD",КурсUSD,IF(INDEX(Материалы!$J$2:$J$9000,MATCH($I21,Материалы!$A$2:$A$9000,0))="EUR",КурсEUR,1))*INDEX(Материалы!$K$2:$K$9000,MATCH($I21,Материалы!$A$2:$A$9000,0))*(1+IFERROR(INDEX(Работы!$I$2:$I$6000,MATCH($C21,Работы!$A$2:$A$6000,0))/100,0))*(1-ДисконтТендер),0)) -> 0 | N21: =IF(AND($R21="да",$H21<>""),ROUND($H21*$L21,2),0) -> 0 | O21: =IF(AND($R21="да",$H21<>""),ROUND($H21*$M21,2),0) -> 0 | P21: =$N21+$O21 -> 0 | Q21: =IFERROR(INDEX(Работы!$J$2:$J$6000,MATCH($C21,Работы!$A$2:$A$6000,0)),"") -> типовая | R21: да | T21: =IF(AND($P21>0,$R21="да"),MAX($T$1:$T20)+1,"")
A22: =IFERROR(INDEX(Работы!$D$2:$D$6000,MATCH($C22,Работы!$A$2:$A$6000,0)),"") -> Р1 | B22: =IFERROR(INDEX(Работы!$F$2:$F$6000,MATCH($C22,Работы!$A$2:$A$6000,0)),"") -> 1 | C22: =IFERROR(INDEX(Работы!$A$2:$A$6000,21),"") -> РАБ.Р1.1.021 | D22: =IFERROR(INDEX(Работы!$B$2:$B$6000,MATCH($C22,Работы!$A$2:$A$6000,0)),"") -> Техническое обследование состояния несущих конструкций помещения с подготовкой рекомендаций по усилению в зоне расположения депозитария, кассового узла и банкоматов (Техничесекое з… | E22: =IFERROR(INDEX(Работы!$C$2:$C$6000,MATCH($C22,Работы!$A$2:$A$6000,0)),"") -> м2 | F22: =IFERROR(INDEX(Работы!$G$2:$G$6000,MATCH($C22,Работы!$A$2:$A$6000,0)),"") -> 0 | G22: =IFERROR(INDEX(Работы!$K$2:$K$6000,MATCH($C22,Работы!$A$2:$A$6000,0)),"") -> S_общая | J22: =IFERROR(INDEX(Материалы!$B$2:$B$9000,MATCH($I22,Материалы!$A$2:$A$9000,0)),"") | K22: =IF($I22="","",IF($F22=IFERROR(INDEX(Материалы!$G$2:$G$9000,MATCH($I22,Материалы!$A$2:$A$9000,0)),""),"OK","!! не та группа")) | L22: =IFERROR(INDEX(Работы!$H$2:$H$6000,MATCH($C22,Работы!$A$2:$A$6000,0))*(1-ДисконтТендер),0) -> 3675 | M22: =IF($I22="",0,IFERROR(INDEX(Материалы!$I$2:$I$9000,MATCH($I22,Материалы!$A$2:$A$9000,0))*IF(INDEX(Материалы!$J$2:$J$9000,MATCH($I22,Материалы!$A$2:$A$9000,0))="USD",КурсUSD,IF(INDEX(Материалы!$J$2:$J$9000,MATCH($I22,Материалы!$A$2:$A$9000,0))="EUR",КурсEUR,1))*INDEX(Материалы!$K$2:$K$9000,MATCH($I22,Материалы!$A$2:$A$9000,0))*(1+IFERROR(INDEX(Работы!$I$2:$I$6000,MATCH($C22,Работы!$A$2:$A$6000,0))/100,0))*(1-ДисконтТендер),0)) -> 0 | N22: =IF(AND($R22="да",$H22<>""),ROUND($H22*$L22,2),0) -> 0 | O22: =IF(AND($R22="да",$H22<>""),ROUND($H22*$M22,2),0) -> 0 | P22: =$N22+$O22 -> 0 | Q22: =IFERROR(INDEX(Работы!$J$2:$J$6000,MATCH($C22,Работы!$A$2:$A$6000,0)),"") -> нетиповая | R22: да | T22: =IF(AND($P22>0,$R22="да"),MAX($T$1:$T21)+1,"")
A23: =IFERROR(INDEX(Работы!$D$2:$D$6000,MATCH($C23,Работы!$A$2:$A$6000,0)),"") -> Р1 | B23: =IFERROR(INDEX(Работы!$F$2:$F$6000,MATCH($C23,Работы!$A$2:$A$6000,0)),"") -> 1 | C23: =IFERROR(INDEX(Работы!$A$2:$A$6000,22),"") -> РАБ.Р1.1.022 | D23: =IFERROR(INDEX(Работы!$B$2:$B$6000,MATCH($C23,Работы!$A$2:$A$6000,0)),"") -> Эскизный проект фасада и колористический паспорт с указанием ведомости отделки и проектным решением со спецификацией элементов (крыльцо, пандус, навесы, колонны и т.д.)(для фасадов… | E23: =IFERROR(INDEX(Работы!$C$2:$C$6000,MATCH($C23,Работы!$A$2:$A$6000,0)),"") -> кв.м.площади фасада | F23: =IFERROR(INDEX(Работы!$G$2:$G$6000,MATCH($C23,Работы!$A$2:$A$6000,0)),"") -> 0 | G23: =IFERROR(INDEX(Работы!$K$2:$K$6000,MATCH($C23,Работы!$A$2:$A$6000,0)),"") -> S_общая | J23: =IFERROR(INDEX(Материалы!$B$2:$B$9000,MATCH($I23,Материалы!$A$2:$A$9000,0)),"") | K23: =IF($I23="","",IF($F23=IFERROR(INDEX(Материалы!$G$2:$G$9000,MATCH($I23,Материалы!$A$2:$A$9000,0)),""),"OK","!! не та группа")) | L23: =IFERROR(INDEX(Работы!$H$2:$H$6000,MATCH($C23,Работы!$A$2:$A$6000,0))*(1-ДисконтТендер),0) -> 7822.5 | M23: =IF($I23="",0,IFERROR(INDEX(Материалы!$I$2:$I$9000,MATCH($I23,Материалы!$A$2:$A$9000,0))*IF(INDEX(Материалы!$J$2:$J$9000,MATCH($I23,Материалы!$A$2:$A$9000,0))="USD",КурсUSD,IF(INDEX(Материалы!$J$2:$J$9000,MATCH($I23,Материалы!$A$2:$A$9000,0))="EUR",КурсEUR,1))*INDEX(Материалы!$K$2:$K$9000,MATCH($I23,Материалы!$A$2:$A$9000,0))*(1+IFERROR(INDEX(Работы!$I$2:$I$6000,MATCH($C23,Работы!$A$2:$A$6000,0))/100,0))*(1-ДисконтТендер),0)) -> 0 | N23: =IF(AND($R23="да",$H23<>""),ROUND($H23*$L23,2),0) -> 0 | O23: =IF(AND($R23="да",$H23<>""),ROUND($H23*$M23,2),0) -> 0 | P23: =$N23+$O23 -> 0 | Q23: =IFERROR(INDEX(Работы!$J$2:$J$6000,MATCH($C23,Работы!$A$2:$A$6000,0)),"") -> нетиповая | R23: да | T23: =IF(AND($P23>0,$R23="да"),MAX($T$1:$T22)+1,"")
A24: =IFERROR(INDEX(Работы!$D$2:$D$6000,MATCH($C24,Работы!$A$2:$A$6000,0)),"") -> Р1 | B24: =IFERROR(INDEX(Работы!$F$2:$F$6000,MATCH($C24,Работы!$A$2:$A$6000,0)),"") -> 1 | C24: =IFERROR(INDEX(Работы!$A$2:$A$6000,23),"") -> РАБ.Р1.1.023 | D24: =IFERROR(INDEX(Работы!$B$2:$B$6000,MATCH($C24,Работы!$A$2:$A$6000,0)),"") -> Рабочая документация по усилению/устройству несущих конструкций ("КР"), включая пояснительную записку (для помещений менее 100 м.кв) | E24: =IFERROR(INDEX(Работы!$C$2:$C$6000,MATCH($C24,Работы!$A$2:$A$6000,0)),"") -> компл. | F24: =IFERROR(INDEX(Работы!$G$2:$G$6000,MATCH($C24,Работы!$A$2:$A$6000,0)),"") -> 0 | G24: =IFERROR(INDEX(Работы!$K$2:$K$6000,MATCH($C24,Работы!$A$2:$A$6000,0)),"") -> S_общая | J24: =IFERROR(INDEX(Материалы!$B$2:$B$9000,MATCH($I24,Материалы!$A$2:$A$9000,0)),"") | K24: =IF($I24="","",IF($F24=IFERROR(INDEX(Материалы!$G$2:$G$9000,MATCH($I24,Материалы!$A$2:$A$9000,0)),""),"OK","!! не та группа")) | L24: =IFERROR(INDEX(Работы!$H$2:$H$6000,MATCH($C24,Работы!$A$2:$A$6000,0))*(1-ДисконтТендер),0) -> 10500 | M24: =IF($I24="",0,IFERROR(INDEX(Материалы!$I$2:$I$9000,MATCH($I24,Материалы!$A$2:$A$9000,0))*IF(INDEX(Материалы!$J$2:$J$9000,MATCH($I24,Материалы!$A$2:$A$9000,0))="USD",КурсUSD,IF(INDEX(Материалы!$J$2:$J$9000,MATCH($I24,Материалы!$A$2:$A$9000,0))="EUR",КурсEUR,1))*INDEX(Материалы!$K$2:$K$9000,MATCH($I24,Материалы!$A$2:$A$9000,0))*(1+IFERROR(INDEX(Работы!$I$2:$I$6000,MATCH($C24,Работы!$A$2:$A$6000,0))/100,0))*(1-ДисконтТендер),0)) -> 0 | N24: =IF(AND($R24="да",$H24<>""),ROUND($H24*$L24,2),0) -> 0 | O24: =IF(AND($R24="да",$H24<>""),ROUND($H24*$M24,2),0) -> 0 | P24: =$N24+$O24 -> 0 | Q24: =IFERROR(INDEX(Работы!$J$2:$J$6000,MATCH($C24,Работы!$A$2:$A$6000,0)),"") -> нетиповая | R24: да | T24: =IF(AND($P24>0,$R24="да"),MAX($T$1:$T23)+1,"")
A25: =IFERROR(INDEX(Работы!$D$2:$D$6000,MATCH($C25,Работы!$A$2:$A$6000,0)),"") -> Р1 | B25: =IFERROR(INDEX(Работы!$F$2:$F$6000,MATCH($C25,Работы!$A$2:$A$6000,0)),"") -> 1 | C25: =IFERROR(INDEX(Работы!$A$2:$A$6000,24),"") -> РАБ.Р1.1.024 | D25: =IFERROR(INDEX(Работы!$B$2:$B$6000,MATCH($C25,Работы!$A$2:$A$6000,0)),"") -> Рабочая документация "Архитектурные решения" ("АР"), включая пояснительную записку (для помещений менее 100 м.кв) | E25: =IFERROR(INDEX(Работы!$C$2:$C$6000,MATCH($C25,Работы!$A$2:$A$6000,0)),"") -> компл. | F25: =IFERROR(INDEX(Работы!$G$2:$G$6000,MATCH($C25,Работы!$A$2:$A$6000,0)),"") -> 0 | G25: =IFERROR(INDEX(Работы!$K$2:$K$6000,MATCH($C25,Работы!$A$2:$A$6000,0)),"") -> S_общая | J25: =IFERROR(INDEX(Материалы!$B$2:$B$9000,MATCH($I25,Материалы!$A$2:$A$9000,0)),"") | K25: =IF($I25="","",IF($F25=IFERROR(INDEX(Материалы!$G$2:$G$9000,MATCH($I25,Материалы!$A$2:$A$9000,0)),""),"OK","!! не та группа")) | L25: =IFERROR(INDEX(Работы!$H$2:$H$6000,MATCH($C25,Работы!$A$2:$A$6000,0))*(1-ДисконтТендер),0) -> 20737.5 | M25: =IF($I25="",0,IFERROR(INDEX(Материалы!$I$2:$I$9000,MATCH($I25,Материалы!$A$2:$A$9000,0))*IF(INDEX(Материалы!$J$2:$J$9000,MATCH($I25,Материалы!$A$2:$A$9000,0))="USD",КурсUSD,IF(INDEX(Материалы!$J$2:$J$9000,MATCH($I25,Материалы!$A$2:$A$9000,0))="EUR",КурсEUR,1))*INDEX(Материалы!$K$2:$K$9000,MATCH($I25,Материалы!$A$2:$A$9000,0))*(1+IFERROR(INDEX(Работы!$I$2:$I$6000,MATCH($C25,Работы!$A$2:$A$6000,0))/100,0))*(1-ДисконтТендер),0)) -> 0 | N25: =IF(AND($R25="да",$H25<>""),ROUND($H25*$L25,2),0) -> 0 | O25: =IF(AND($R25="да",$H25<>""),ROUND($H25*$M25,2),0) -> 0 | P25: =$N25+$O25 -> 0 | Q25: =IFERROR(INDEX(Работы!$J$2:$J$6000,MATCH($C25,Работы!$A$2:$A$6000,0)),"") -> типовая | R25: да | T25: =IF(AND($P25>0,$R25="да"),MAX($T$1:$T24)+1,"")
A26: =IFERROR(INDEX(Работы!$D$2:$D$6000,MATCH($C26,Работы!$A$2:$A$6000,0)),"") -> Р1 | B26: =IFERROR(INDEX(Работы!$F$2:$F$6000,MATCH($C26,Работы!$A$2:$A$6000,0)),"") -> 1 | C26: =IFERROR(INDEX(Работы!$A$2:$A$6000,25),"") -> РАБ.Р1.1.025 | D26: =IFERROR(INDEX(Работы!$B$2:$B$6000,MATCH($C26,Работы!$A$2:$A$6000,0)),"") -> Рабочая документация по электроснабжению и электроосвещению ("ЭОМ"), включая пояснительную записку (для помещений менее 100 м.кв) | E26: =IFERROR(INDEX(Работы!$C$2:$C$6000,MATCH($C26,Работы!$A$2:$A$6000,0)),"") -> компл. | F26: =IFERROR(INDEX(Работы!$G$2:$G$6000,MATCH($C26,Работы!$A$2:$A$6000,0)),"") -> 0 | G26: =IFERROR(INDEX(Работы!$K$2:$K$6000,MATCH($C26,Работы!$A$2:$A$6000,0)),"") -> S_общая | J26: =IFERROR(INDEX(Материалы!$B$2:$B$9000,MATCH($I26,Материалы!$A$2:$A$9000,0)),"") | K26: =IF($I26="","",IF($F26=IFERROR(INDEX(Материалы!$G$2:$G$9000,MATCH($I26,Материалы!$A$2:$A$9000,0)),""),"OK","!! не та группа")) | L26: =IFERROR(INDEX(Работы!$H$2:$H$6000,MATCH($C26,Работы!$A$2:$A$6000,0))*(1-ДисконтТендер),0) -> 20737.5 | M26: =IF($I26="",0,IFERROR(INDEX(Материалы!$I$2:$I$9000,MATCH($I26,Материалы!$A$2:$A$9000,0))*IF(INDEX(Материалы!$J$2:$J$9000,MATCH($I26,Материалы!$A$2:$A$9000,0))="USD",КурсUSD,IF(INDEX(Материалы!$J$2:$J$9000,MATCH($I26,Материалы!$A$2:$A$9000,0))="EUR",КурсEUR,1))*INDEX(Материалы!$K$2:$K$9000,MATCH($I26,Материалы!$A$2:$A$9000,0))*(1+IFERROR(INDEX(Работы!$I$2:$I$6000,MATCH($C26,Работы!$A$2:$A$6000,0))/100,0))*(1-ДисконтТендер),0)) -> 0 | N26: =IF(AND($R26="да",$H26<>""),ROUND($H26*$L26,2),0) -> 0 | O26: =IF(AND($R26="да",$H26<>""),ROUND($H26*$M26,2),0) -> 0 | P26: =$N26+$O26 -> 0 | Q26: =IFERROR(INDEX(Работы!$J$2:$J$6000,MATCH($C26,Работы!$A$2:$A$6000,0)),"") -> типовая | R26: да | T26: =IF(AND($P26>0,$R26="да"),MAX($T$1:$T25)+1,"")
A27: =IFERROR(INDEX(Работы!$D$2:$D$6000,MATCH($C27,Работы!$A$2:$A$6000,0)),"") -> Р1 | B27: =IFERROR(INDEX(Работы!$F$2:$F$6000,MATCH($C27,Работы!$A$2:$A$6000,0)),"") -> 1 | C27: =IFERROR(INDEX(Работы!$A$2:$A$6000,26),"") -> РАБ.Р1.1.026 | D27: =IFERROR(INDEX(Работы!$B$2:$B$6000,MATCH($C27,Работы!$A$2:$A$6000,0)),"") -> Рабочая документация Системы вентиляции ("ОВиК-В"), включая пояснительную записку (для помещений менее 100 м.кв) | E27: =IFERROR(INDEX(Работы!$C$2:$C$6000,MATCH($C27,Работы!$A$2:$A$6000,0)),"") -> компл. | F27: =IFERROR(INDEX(Работы!$G$2:$G$6000,MATCH($C27,Работы!$A$2:$A$6000,0)),"") -> 0 | G27: =IFERROR(INDEX(Работы!$K$2:$K$6000,MATCH($C27,Работы!$A$2:$A$6000,0)),"") -> S_общая | J27: =IFERROR(INDEX(Материалы!$B$2:$B$9000,MATCH($I27,Материалы!$A$2:$A$9000,0)),"") | K27: =IF($I27="","",IF($F27=IFERROR(INDEX(Материалы!$G$2:$G$9000,MATCH($I27,Материалы!$A$2:$A$9000,0)),""),"OK","!! не та группа")) | L27: =IFERROR(INDEX(Работы!$H$2:$H$6000,MATCH($C27,Работы!$A$2:$A$6000,0))*(1-ДисконтТендер),0) -> 15592.5 | M27: =IF($I27="",0,IFERROR(INDEX(Материалы!$I$2:$I$9000,MATCH($I27,Материалы!$A$2:$A$9000,0))*IF(INDEX(Материалы!$J$2:$J$9000,MATCH($I27,Материалы!$A$2:$A$9000,0))="USD",КурсUSD,IF(INDEX(Материалы!$J$2:$J$9000,MATCH($I27,Материалы!$A$2:$A$9000,0))="EUR",КурсEUR,1))*INDEX(Материалы!$K$2:$K$9000,MATCH($I27,Материалы!$A$2:$A$9000,0))*(1+IFERROR(INDEX(Работы!$I$2:$I$6000,MATCH($C27,Работы!$A$2:$A$6000,0))/100,0))*(1-ДисконтТендер),0)) -> 0 | N27: =IF(AND($R27="да",$H27<>""),ROUND($H27*$L27,2),0) -> 0 | O27: =IF(AND($R27="да",$H27<>""),ROUND($H27*$M27,2),0) -> 0 | P27: =$N27+$O27 -> 0 | Q27: =IFERROR(INDEX(Работы!$J$2:$J$6000,MATCH($C27,Работы!$A$2:$A$6000,0)),"") -> типовая | R27: да | T27: =IF(AND($P27>0,$R27="да"),MAX($T$1:$T26)+1,"")
A28: =IFERROR(INDEX(Работы!$D$2:$D$6000,MATCH($C28,Работы!$A$2:$A$6000,0)),"") -> Р1 | B28: =IFERROR(INDEX(Работы!$F$2:$F$6000,MATCH($C28,Работы!$A$2:$A$6000,0)),"") -> 1 | C28: =IFERROR(INDEX(Работы!$A$2:$A$6000,27),"") -> РАБ.Р1.1.027 | D28: =IFERROR(INDEX(Работы!$B$2:$B$6000,MATCH($C28,Работы!$A$2:$A$6000,0)),"") -> Рабочая документация Системы кондиционирования ("ОВиК-К"), включая пояснительную записку (для помещений менее 100 м.кв) | E28: =IFERROR(INDEX(Работы!$C$2:$C$6000,MATCH($C28,Работы!$A$2:$A$6000,0)),"") -> компл. | F28: =IFERROR(INDEX(Работы!$G$2:$G$6000,MATCH($C28,Работы!$A$2:$A$6000,0)),"") -> 0 | G28: =IFERROR(INDEX(Работы!$K$2:$K$6000,MATCH($C28,Работы!$A$2:$A$6000,0)),"") -> S_общая | J28: =IFERROR(INDEX(Материалы!$B$2:$B$9000,MATCH($I28,Материалы!$A$2:$A$9000,0)),"") | K28: =IF($I28="","",IF($F28=IFERROR(INDEX(Материалы!$G$2:$G$9000,MATCH($I28,Материалы!$A$2:$A$9000,0)),""),"OK","!! не та группа")) | L28: =IFERROR(INDEX(Работы!$H$2:$H$6000,MATCH($C28,Работы!$A$2:$A$6000,0))*(1-ДисконтТендер),0) -> 10395 | M28: =IF($I28="",0,IFERROR(INDEX(Материалы!$I$2:$I$9000,MATCH($I28,Материалы!$A$2:$A$9000,0))*IF(INDEX(Материалы!$J$2:$J$9000,MATCH($I28,Материалы!$A$2:$A$9000,0))="USD",КурсUSD,IF(INDEX(Материалы!$J$2:$J$9000,MATCH($I28,Материалы!$A$2:$A$9000,0))="EUR",КурсEUR,1))*INDEX(Материалы!$K$2:$K$9000,MATCH($I28,Материалы!$A$2:$A$9000,0))*(1+IFERROR(INDEX(Работы!$I$2:$I$6000,MATCH($C28,Работы!$A$2:$A$6000,0))/100,0))*(1-ДисконтТендер),0)) -> 0 | N28: =IF(AND($R28="да",$H28<>""),ROUND($H28*$L28,2),0) -> 0 | O28: =IF(AND($R28="да",$H28<>""),ROUND($H28*$M28,2),0) -> 0 | P28: =$N28+$O28 -> 0 | Q28: =IFERROR(INDEX(Работы!$J$2:$J$6000,MATCH($C28,Работы!$A$2:$A$6000,0)),"") -> типовая | R28: да | T28: =IF(AND($P28>0,$R28="да"),MAX($T$1:$T27)+1,"")
A29: =IFERROR(INDEX(Работы!$D$2:$D$6000,MATCH($C29,Работы!$A$2:$A$6000,0)),"") -> Р1 | B29: =IFERROR(INDEX(Работы!$F$2:$F$6000,MATCH($C29,Работы!$A$2:$A$6000,0)),"") -> 1 | C29: =IFERROR(INDEX(Работы!$A$2:$A$6000,28),"") -> РАБ.Р1.1.028 | D29: =IFERROR(INDEX(Работы!$B$2:$B$6000,MATCH($C29,Работы!$A$2:$A$6000,0)),"") -> Рабочая документация Системы отопления ("ОВиК-О"), включая Пояснительную записку и Теплотехнический расчет (для помещений менее 100 м.кв) | E29: =IFERROR(INDEX(Работы!$C$2:$C$6000,MATCH($C29,Работы!$A$2:$A$6000,0)),"") -> компл. | F29: =IFERROR(INDEX(Работы!$G$2:$G$6000,MATCH($C29,Работы!$A$2:$A$6000,0)),"") -> 0 | G29: =IFERROR(INDEX(Работы!$K$2:$K$6000,MATCH($C29,Работы!$A$2:$A$6000,0)),"") -> S_общая | J29: =IFERROR(INDEX(Материалы!$B$2:$B$9000,MATCH($I29,Материалы!$A$2:$A$9000,0)),"") | K29: =IF($I29="","",IF($F29=IFERROR(INDEX(Материалы!$G$2:$G$9000,MATCH($I29,Материалы!$A$2:$A$9000,0)),""),"OK","!! не та группа")) | L29: =IFERROR(INDEX(Работы!$H$2:$H$6000,MATCH($C29,Работы!$A$2:$A$6000,0))*(1-ДисконтТендер),0) -> 10395 | M29: =IF($I29="",0,IFERROR(INDEX(Материалы!$I$2:$I$9000,MATCH($I29,Материалы!$A$2:$A$9000,0))*IF(INDEX(Материалы!$J$2:$J$9000,MATCH($I29,Материалы!$A$2:$A$9000,0))="USD",КурсUSD,IF(INDEX(Материалы!$J$2:$J$9000,MATCH($I29,Материалы!$A$2:$A$9000,0))="EUR",КурсEUR,1))*INDEX(Материалы!$K$2:$K$9000,MATCH($I29,Материалы!$A$2:$A$9000,0))*(1+IFERROR(INDEX(Работы!$I$2:$I$6000,MATCH($C29,Работы!$A$2:$A$6000,0))/100,0))*(1-ДисконтТендер),0)) -> 0 | N29: =IF(AND($R29="да",$H29<>""),ROUND($H29*$L29,2),0) -> 0 | O29: =IF(AND($R29="да",$H29<>""),ROUND($H29*$M29,2),0) -> 0 | P29: =$N29+$O29 -> 0 | Q29: =IFERROR(INDEX(Работы!$J$2:$J$6000,MATCH($C29,Работы!$A$2:$A$6000,0)),"") -> типовая | R29: да | T29: =IF(AND($P29>0,$R29="да"),MAX($T$1:$T28)+1,"")
A30: =IFERROR(INDEX(Работы!$D$2:$D$6000,MATCH($C30,Работы!$A$2:$A$6000,0)),"") -> Р1 | B30: =IFERROR(INDEX(Работы!$F$2:$F$6000,MATCH($C30,Работы!$A$2:$A$6000,0)),"") -> 1 | C30: =IFERROR(INDEX(Работы!$A$2:$A$6000,29),"") -> РАБ.Р1.1.029 | D30: =IFERROR(INDEX(Работы!$B$2:$B$6000,MATCH($C30,Работы!$A$2:$A$6000,0)),"") -> Рабочая документация Системы водоснабжения и канализации ("ВК"), включая пояснительную записку (для помещений менее 100 м.кв) | E30: =IFERROR(INDEX(Работы!$C$2:$C$6000,MATCH($C30,Работы!$A$2:$A$6000,0)),"") -> компл. | F30: =IFERROR(INDEX(Работы!$G$2:$G$6000,MATCH($C30,Работы!$A$2:$A$6000,0)),"") -> 0 | G30: =IFERROR(INDEX(Работы!$K$2:$K$6000,MATCH($C30,Работы!$A$2:$A$6000,0)),"") -> S_общая | J30: =IFERROR(INDEX(Материалы!$B$2:$B$9000,MATCH($I30,Материалы!$A$2:$A$9000,0)),"") | K30: =IF($I30="","",IF($F30=IFERROR(INDEX(Материалы!$G$2:$G$9000,MATCH($I30,Материалы!$A$2:$A$9000,0)),""),"OK","!! не та группа")) | L30: =IFERROR(INDEX(Работы!$H$2:$H$6000,MATCH($C30,Работы!$A$2:$A$6000,0))*(1-ДисконтТендер),0) -> 10395 | M30: =IF($I30="",0,IFERROR(INDEX(Материалы!$I$2:$I$9000,MATCH($I30,Материалы!$A$2:$A$9000,0))*IF(INDEX(Материалы!$J$2:$J$9000,MATCH($I30,Материалы!$A$2:$A$9000,0))="USD",КурсUSD,IF(INDEX(Материалы!$J$2:$J$9000,MATCH($I30,Материалы!$A$2:$A$9000,0))="EUR",КурсEUR,1))*INDEX(Материалы!$K$2:$K$9000,MATCH($I30,Материалы!$A$2:$A$9000,0))*(1+IFERROR(INDEX(Работы!$I$2:$I$6000,MATCH($C30,Работы!$A$2:$A$6000,0))/100,0))*(1-ДисконтТендер),0)) -> 0 | N30: =IF(AND($R30="да",$H30<>""),ROUND($H30*$L30,2),0) -> 0 | O30: =IF(AND($R30="да",$H30<>""),ROUND($H30*$M30,2),0) -> 0 | P30: =$N30+$O30 -> 0 | Q30: =IFERROR(INDEX(Работы!$J$2:$J$6000,MATCH($C30,Работы!$A$2:$A$6000,0)),"") -> типовая | R30: да | T30: =IF(AND($P30>0,$R30="да"),MAX($T$1:$T29)+1,"")
