Workbook
Name КодыРабот: спр_Работы!$A$2:$A$6000
Name ФорматОбъекта: Параметры!$B$5
Name Адрес: Параметры!$B$6
Name Срок: Параметры!$B$7
Name ДатаЦен: Параметры!$B$8
Name Подрядчик: Параметры!$B$11
Name ЮрАдрес: Параметры!$B$12
Name ЭлАдрес: Параметры!$B$13
Name КонтЛицо: Параметры!$B$14
Name КонтТел: Параметры!$B$15
Name Реквизиты: Параметры!$B$16
Name S_общая: Параметры!$B$19
Name S_пол: Параметры!$B$20
Name S_стены: Параметры!$B$21
Name S_потолок: Параметры!$B$22
Name S_поверхность: Параметры!$B$23
Name S_проёмы: Параметры!$B$24
Name S_фасад: Параметры!$B$25
Name Периметр_пола: Параметры!$B$26
Name РежимЦены: Параметры!$B$29
Name СтавкаНДС: Параметры!$B$30
Name ДисконтТендер: Параметры!$B$31
Name ПроцТранспорт: Параметры!$B$32
Name ПроцТакелаж: Параметры!$B$33
Name ПроцРезерв: Параметры!$B$34
Name КурсUSD: Параметры!$B$35
Name КурсEUR: Параметры!$B$36

Sheet О шаблоне
A1: Смета объекта — шаблон v0.4 (совместим с Excel 2019)
A3: ПОРЯДОК РАБОТЫ
A4: 1. «Параметры» — заполнить жёлтые ячейки: объект, подрядчик, площади, НДС, %% транспорта/такелажа/резерва, курсы.
A5: 2. «Конструктор» — предзаполнен ВСЕМИ работами справочника (колонка «Код_работы» — формула, правит сам себя).
A6: Для нужных строк: ввести «Объём» (подсказка «Драйвер»: S_пол / S_стены / спецификация / замер…),
A7: выбрать «Код_материала» (список — только материалы группы этой работы), при необходимости «Вкл.» = нет.
A8: 3. «Смета» — чистовой документ: шапка + расшифровка + итоги + сноска + подписи. Строится формулами ИНДЕКС/ПОИСКПОЗ.
A9: Изначально строки расшифровки СКРЫТЫ (данных нет). После ввода объёмов в «Конструкторе»:
A10: встать на любую ячейку таблицы расшифровки → Данные → «Применить повторно» (Ctrl+Alt+L).
A11: Заполненные позиции появятся, блок итогов встанет сразу под ними. Руками не трогать.
A12: 4. «Свод+ТЭП» — доли работ/материалов, ₽/м². «Контроль» — красное = ошибка.
A14: КАК ДОБАВЛЯТЬ НОВЫЕ РАБОТЫ И МАТЕРИАЛЫ
... A34: Сформировано: 2026-08-31. Справочники: версия 0.3. Работ предзаполнено: 911. Буфер Конструктора: 1211. Версия шаблона: 0.6.

Sheet Параметры
A1: ПАРАМЕТРЫ ОБЪЕКТА
A3: Параметр | B3: Значение | C3: Пояснение
A4: Объект
A5: Формат объекта | B5: ККО | C5: ККО / Инфраструктура
A6: Адрес объекта
A7: Срок проведения работ | B7: Согласно план-графику производства работ
A8: Дата цен | B8: 46265 | C8: на какую дату актуальны цены справочника
A10: Подрядчик
A11: ПОДРЯДЧИК (наименование)
A12: Юридический адрес
A13: Электронный адрес
A14: Контактное лицо (Ф.И.О.)
A15: Контактный телефон
A16: Реквизиты
A18: Площади, м²
A19: S_общая (площадь объекта) | B19: 0 | C19: для ТЭП и проектных расценок
A20: S_пол | B20: 0 | C20: драйвер S_пол
A21: S_стены | B21: 0 | C21: драйвер S_стены (развёртка)
A22: S_потолок | B22: 0 | C22: драйвер S_потолок
A23: S_поверхность | B23: 0 | C23: драйвер S_поверхность
A24: S_проёмы | B24: 0 | C24: драйвер S_проёмы
A25: S_фасад | B25: 0 | C25: драйвер S_фасад
A26: Периметр_пола, м.п. | B26: 0 | C26: драйвер Периметр_пола
A28: Финансы
A29: Режим цены | B29: с НДС в цене | C29: «с НДС в цене» — НДС извлекается; «без НДС» — начисляется сверху
A30: Ставка НДС, % | B30: 20 | C30: 5 / 7 / 20
A31: Дисконт по тендеру, доля | B31: 0 | C31: 0,05 = минус 5% к ЕР
A32: Транспортные, % от стоимости материалов | B32: 3
A33: Такелаж / верт. транспорт, % от (работы+материалы) | B33: 0 | C33: режим ТЦ/БЦ, ночные работы
A34: Резерв на непредвиденные, % от (работы+материалы) | B34: 0 | C34: 0 = не применять
A35: Курс USD | B35: 81 | C35: для валютных материалов
A36: Курс EUR | B36: 95

Sheet Конструктор
A1: Раздел | B1: Подраздел | C1: Код_работы | D1: Наименование работы | E1: Ед | F1: Группа_мат | G1: Драйвер | H1: Объём | I1: Код_материала | J1: Наименование материала | K1: Гр_ОK | L1: Цена работ, ₽ | M1: Цена мат, ₽ | N1: Стоим. работ, ₽ | O1: Стоим. мат, ₽ | P1: Всего, ₽ | Q1: Тип | R1: Вкл. | S1: Примечание | T1: _ранг
A2: =IFERROR(INDEX(спр_Работы!$D$2:$D$6000,MATCH($C2,спр_Работы!$A$2:$A$6000,0)),"") | B2: =IFERROR(INDEX(спр_Работы!$F$2:$F$6000,MATCH($C2,спр_Работы!$A$2:$A$6000,0)),"") | C2: =IFERROR(INDEX(спр_Работы!$A$2:$A$6000,1),"") | D2: =IFERROR(INDEX(спр_Работы!$B$2:$B$6000,MATCH($C2,спр_Работы!$A$2:$A$6000,0)),"") | E2: =IFERROR(INDEX(спр_Работы!$C$2:$C$6000,MATCH($C2,спр_Работы!$A$2:$A$6000,0)),"") | F2: =IFERROR(INDEX(спр_Работы!$G$2:$G$6000,MATCH($C2,спр_Работы!$A$2:$A$6000,0)),"") | G2: =IFERROR(INDEX(спр_Работы!$K$2:$K$6000,MATCH($C2,спр_Работы!$A$2:$A$6000,0)),"") | J2: =IFERROR(INDEX(спр_Материалы!$B$2:$B$9000,MATCH($I2,спр_Материалы!$A$2:$A$9000,0)),"") | K2: =IF($I2="","",IF($F2=IFERROR(INDEX(спр_Материалы!$G$2:$G$9000,MATCH($I2,спр_Материалы!$A$2:$A$9000,0)),""),"OK","!! не та группа")) | L2: =IFERROR(INDEX(спр_Работы!$H$2:$H$6000,MATCH($C2,спр_Работы!$A$2:$A$6000,0))*(1-ДисконтТендер),0) | M2: =IF($I2="",0,IFERROR(INDEX(спр_Материалы!$I$2:$I$9000,MATCH($I2,спр_Материалы!$A$2:$A$9000,0))*IF(INDEX(спр_Материалы!$J$2:$J$9000,MATCH($I2,спр_Материалы!$A$2:$A$9000,0))="USD",КурсUSD,IF(INDEX(спр_Материалы!$J$2:$J$9000,MATCH($I2,спр_Материалы!$A$2:$A$9000,0))="EUR",КурсEUR,1))*INDEX(спр_Материалы!$K$2:$K$9000,MATCH($I2,спр_Материалы!$A$2:$A$9000,0))*(1+IFERROR(INDEX(спр_Работы!$I$2:$I$6000,MATCH($C2,спр_Работы!$A$2:$A$6000,0))/100,0))*(1-ДисконтТендер),0)) | N2: =IF(AND($R2="да",$H2<>""),ROUND($H2*$L2,2),0) | O2: =IF(AND($R2="да",$H2<>""),ROUND($H2*$M2,2),0) | P2: =$N2+$O2 | Q2: =IFERROR(INDEX(спр_Работы!$J$2:$J$6000,MATCH($C2,спр_Работы!$A$2:$A$6000,0)),"") | R2: да | T2: =IF(AND($P2>0,$R2="да"),MAX($T$1:$T1)+1,"")
A3: =IFERROR(INDEX(спр_Работы!$D$2:$D$6000,MATCH($C3,спр_Работы!$A$2:$A$6000,0)),"") | B3: =IFERROR(INDEX(спр_Работы!$F$2:$F$6000,MATCH($C3,спр_Работы!$A$2:$A$6000,0)),"") | C3: =IFERROR(INDEX(спр_Работы!$A$2:$A$6000,2),"") | D3: =IFERROR(INDEX(спр_Работы!$B$2:$B$6000,MATCH($C3,спр_Работы!$A$2:$A$6000,0)),"") | E3: =IFERROR(INDEX(спр_Работы!$C$2:$C$6000,MATCH($C3,спр_Работы!$A$2:$A$6000,0)),"") | F3: =IFERROR(INDEX(спр_Работы!$G$2:$G$6000,MATCH($C3,спр_Работы!$A$2:$A$6000,0)),"") | G3: =IFERROR(INDEX(спр_Работы!$K$2:$K$6000,MATCH($C3,спр_Работы!$A$2:$A$6000,0)),"") | J3: =IFERROR(INDEX(спр_Материалы!$B$2:$B$9000,MATCH($I3,спр_Материалы!$A$2:$A$9000,0)),"") | K3: =IF($I3="","",IF($F3=IFERROR(INDEX(спр_Материалы!$G$2:$G$9000,MATCH($I3,спр_Материалы!$A$2:$A$9000,0)),""),"OK","!! не та группа")) | L3: =IFERROR(INDEX(спр_Работы!$H$2:$H$6000,MATCH($C3,спр_Работы!$A$2:$A$6000,0))*(1-ДисконтТендер),0) | M3: =IF($I3="",0,IFERROR(INDEX(спр_Материалы!$I$2:$I$9000,MATCH($I3,спр_Материалы!$A$2:$A$9000,0))*IF(INDEX(спр_Материалы!$J$2:$J$9000,MATCH($I3,спр_Материалы!$A$2:$A$9000,0))="USD",КурсUSD,IF(INDEX(спр_Материалы!$J$2:$J$9000,MATCH($I3,спр_Материалы!$A$2:$A$9000,0))="EUR",КурсEUR,1))*INDEX(спр_Материалы!$K$2:$K$9000,MATCH($I3,спр_Материалы!$A$2:$A$9000,0))*(1+IFERROR(INDEX(спр_Работы!$I$2:$I$6000,MATCH($C3,спр_Работы!$A$2:$A$6000,0))/100,0))*(1-ДисконтТендер),0)) | N3: =IF(AND($R3="да",$H3<>""),ROUND($H3*$L3,2),0) | O3: =IF(AND($R3="да",$H3<>""),ROUND($H3*$M3,2),0) | P3: =$N3+$O3 | Q3: =IFERROR(INDEX(спр_Работы!$J$2:$J$6000,MATCH($C3,спр_Работы!$A$2:$A$6000,0)),"") | R3: да | T3: =IF(AND($P3>0,$R3="да"),MAX($T$1:$T2)+1,"")
A4: =IFERROR(INDEX(спр_Работы!$D$2:$D$6000,MATCH($C4,спр_Работы!$A$2:$A$6000,0)),"") | B4: =IFERROR(INDEX(спр_Работы!$F$2:$F$6000,MATCH($C4,спр_Работы!$A$2:$A$6000,0)),"") | C4: =IFERROR(INDEX(спр_Работы!$A$2:$A$6000,3),"") | D4: =IFERROR(INDEX(спр_Работы!$B$2:$B$6000,MATCH($C4,спр_Работы!$A$2:$A$6000,0)),"") | E4: =IFERROR(INDEX(спр_Работы!$C$2:$C$6000,MATCH($C4,спр_Работы!$A$2:$A$6000,0)),"") | F4: =IFERROR(INDEX(спр_Работы!$G$2:$G$6000,MATCH($C4,спр_Работы!$A$2:$A$6000,0)),"") | G4: =IFERROR(INDEX(спр_Работы!$K$2:$K$6000,MATCH($C4,спр_Работы!$A$2:$A$6000,0)),"") | J4: =IFERROR(INDEX(спр_Материалы!$B$2:$B$9000,MATCH($I4,спр_Материалы!$A$2:$A$9000,0)),"") | K4: =IF($I4="","",IF($F4=IFERROR(INDEX(спр_Материалы!$G$2:$G$9000,MATCH($I4,спр_Материалы!$A$2:$A$9000,0)),""),"OK","!! не та группа")) | L4: =IFERROR(INDEX(спр_Работы!$H$2:$H$6000,MATCH($C4,спр_Работы!$A$2:$A$6000,0))*(1-ДисконтТендер),0) | M4: =IF($I4="",0,IFERROR(INDEX(спр_Материалы!$I$2:$I$9000,MATCH($I4,спр_Материалы!$A$2:$A$9000,0))*IF(INDEX(спр_Материалы!$J$2:$J$9000,MATCH($I4,спр_Материалы!$A$2:$A$9000,0))="USD",КурсUSD,IF(INDEX(спр_Материалы!$J$2:$J$9000,MATCH($I4,спр_Материалы!$A$2:$A$9000,0))="EUR",КурсEUR,1))*INDEX(спр_Материалы!$K$2:$K$9000,MATCH($I4,спр_Материалы!$A$2:$A$9000,0))*(1+IFERROR(INDEX(спр_Работы!$I$2:$I$6000,MATCH($C4,спр_Работы!$A$2:$A$6000,0))/100,0))*(1-ДисконтТендер),0)) | N4: =IF(AND($R4="да",$H4<>""),ROUND($H4*$L4,2),0) | O4: =IF(AND($R4="да",$H4<>""),ROUND($H4*$M4,2),0) | P4: =$N4+$O4 | Q4: =IFERROR(INDEX(спр_Работы!$J$2:$J$6000,MATCH($C4,спр_Работы!$A$2:$A$6000,0)),"") | R4: да | T4: =IF(AND($P4>0,$R4="да"),MAX($T$1:$T3)+1,"")
A5: =IFERROR(INDEX(спр_Работы!$D$2:$D$6000,MATCH($C5,спр_Работы!$A$2:$A$6000,0)),"") | B5: =IFERROR(INDEX(спр_Работы!$F$2:$F$6000,MATCH($C5,спр_Работы!$A$2:$A$6000,0)),"") | C5: =IFERROR(INDEX(спр_Работы!$A$2:$A$6000,4),"") | D5: =IFERROR(INDEX(спр_Работы!$B$2:$B$6000,MATCH($C5,спр_Работы!$A$2:$A$6000,0)),"") | E5: =IFERROR(INDEX(спр_Работы!$C$2:$C$6000,MATCH($C5,спр_Работы!$A$2:$A$6000,0)),"") | F5: =IFERROR(INDEX(спр_Работы!$G$2:$G$6000,MATCH($C5,спр_Работы!$A$2:$A$6000,0)),"") | G5: =IFERROR(INDEX(спр_Работы!$K$2:$K$6000,MATCH($C5,спр_Работы!$A$2:$A$6000,0)),"") | J5: =IFERROR(INDEX(спр_Материалы!$B$2:$B$9000,MATCH($I5,спр_Материалы!$A$2:$A$9000,0)),"") | K5: =IF($I5="","",IF($F5=IFERROR(INDEX(спр_Материалы!$G$2:$G$9000,MATCH($I5,спр_Материалы!$A$2:$A$9000,0)),""),"OK","!! не та группа")) | L5: =IFERROR(INDEX(спр_Работы!$H$2:$H$6000,MATCH($C5,спр_Работы!$A$2:$A$6000,0))*(1-ДисконтТендер),0) | M5: =IF($I5="",0,IFERROR(INDEX(спр_Материалы!$I$2:$I$9000,MATCH($I5,спр_Материалы!$A$2:$A$9000,0))*IF(INDEX(спр_Материалы!$J$2:$J$9000,MATCH($I5,спр_Материалы!$A$2:$A$9000,0))="USD",КурсUSD,IF(INDEX(спр_Материалы!$J$2:$J$9000,MATCH($I5,спр_Материалы!$A$2:$A$9000,0))="EUR",КурсEUR,1))*INDEX(спр_Материалы!$K$2:$K$9000,MATCH($I5,спр_Материалы!$A$2:$A$9000,0))*(1+IFERROR(INDEX(спр_Работы!$I$2:$I$6000,MATCH($C5,спр_Работы!$A$2:$A$6000,0))/100,0))*(1-ДисконтТендер),0)) | N5: =IF(AND($R5="да",$H5<>""),ROUND($H5*$L5,2),0) | O5: =IF(AND($R5="да",$H5<>""),ROUND($H5*$M5,2),0) | P5: =$N5+$O5 | Q5: =IFERROR(INDEX(спр_Работы!$J$2:$J$6000,MATCH($C5,спр_Работы!$A$2:$A$6000,0)),"") | R5: да | T5: =IF(AND($P5>0,$R5="да"),MAX($T$1:$T4)+1,"")
A6: =IFERROR(INDEX(спр_Работы!$D$2:$D$6000,MATCH($C6,спр_Работы!$A$2:$A$6000,0)),"") | B6: =IFERROR(INDEX(спр_Работы!$F$2:$F$6000,MATCH($C6,спр_Работы!$A$2:$A$6000,0)),"") | C6: =IFERROR(INDEX(спр_Работы!$A$2:$A$6000,5),"") | D6: =IFERROR(INDEX(спр_Работы!$B$2:$B$6000,MATCH($C6,спр_Работы!$A$2:$A$6000,0)),"") | E6: =IFERROR(INDEX(спр_Работы!$C$2:$C$6000,MATCH($C6,спр_Работы!$A$2:$A$6000,0)),"") | F6: =IFERROR(INDEX(спр_Работы!$G$2:$G$6000,MATCH($C6,спр_Работы!$A$2:$A$6000,0)),"") | G6: =IFERROR(INDEX(спр_Работы!$K$2:$K$6000,MATCH($C6,спр_Работы!$A$2:$A$6000,0)),"") | J6: =IFERROR(INDEX(спр_Материалы!$B$2:$B$9000,MATCH($I6,спр_Материалы!$A$2:$A$9000,0)),"") | K6: =IF($I6="","",IF($F6=IFERROR(INDEX(спр_Материалы!$G$2:$G$9000,MATCH($I6,спр_Материалы!$A$2:$A$9000,0)),""),"OK","!! не та группа")) | L6: =IFERROR(INDEX(спр_Работы!$H$2:$H$6000,MATCH($C6,спр_Работы!$A$2:$A$6000,0))*(1-ДисконтТендер),0) | M6: =IF($I6="",0,IFERROR(INDEX(спр_Материалы!$I$2:$I$9000,MATCH($I6,спр_Материалы!$A$2:$A$9000,0))*IF(INDEX(спр_Материалы!$J$2:$J$9000,MATCH($I6,спр_Материалы!$A$2:$A$9000,0))="USD",КурсUSD,IF(INDEX(спр_Материалы!$J$2:$J$9000,MATCH($I6,спр_Материалы!$A$2:$A$9000,0))="EUR",КурсEUR,1))*INDEX(спр_Материалы!$K$2:$K$9000,MATCH($I6,спр_Материалы!$A$2:$A$9000,0))*(1+IFERROR(INDEX(спр_Работы!$I$2:$I$6000,MATCH($C6,спр_Работы!$A$2:$A$6000,0))/100,0))*(1-ДисконтТендер),0)) | N6: =IF(AND($R6="да",$H6<>""),ROUND($H6*$L6,2),0) | O6: =IF(AND($R6="да",$H6<>""),ROUND($H6*$M6,2),0) | P6: =$N6+$O6 | Q6: =IFERROR(INDEX(спр_Работы!$J$2:$J$6000,MATCH($C6,спр_Работы!$A$2:$A$6000,0)),"") | R6: да | T6: =IF(AND($P6>0,$R6="да"),MAX($T$1:$T5)+1,"")
A7: =IFERROR(INDEX(спр_Работы!$D$2:$D$6000,MATCH($C7,спр_Работы!$A$2:$A$6000,0)),"") | B7: =IFERROR(INDEX(спр_Работы!$F$2:$F$6000,MATCH($C7,спр_Работы!$A$2:$A$6000,0)),"") | C7: =IFERROR(INDEX(спр_Работы!$A$2:$A$6000,6),"") | D7: =IFERROR(INDEX(спр_Работы!$B$2:$B$6000,MATCH($C7,спр_Работы!$A$2:$A$6000,0)),"") | E7: =IFERROR(INDEX(спр_Работы!$C$2:$C$6000,MATCH($C7,спр_Работы!$A$2:$A$6000,0)),"") | F7: =IFERROR(INDEX(спр_Работы!$G$2:$G$6000,MATCH($C7,спр_Работы!$A$2:$A$6000,0)),"") | G7: =IFERROR(INDEX(спр_Работы!$K$2:$K$6000,MATCH($C7,спр_Работы!$A$2:$A$6000,0)),"") | J7: =IFERROR(INDEX(спр_Материалы!$B$2:$B$9000,MATCH($I7,спр_Материалы!$A$2:$A$9000,0)),"") | K7: =IF($I7="","",IF($F7=IFERROR(INDEX(спр_Материалы!$G$2:$G$9000,MATCH($I7,спр_Материалы!$A$2:$A$9000,0)),""),"OK","!! не та группа")) | L7: =IFERROR(INDEX(спр_Работы!$H$2:$H$6000,MATCH($C7,спр_Работы!$A$2:$A$6000,0))*(1-ДисконтТендер),0) | M7: =IF($I7="",0,IFERROR(INDEX(спр_Материалы!$I$2:$I$9000,MATCH($I7,спр_Материалы!$A$2:$A$9000,0))*IF(INDEX(спр_Материалы!$J$2:$J$9000,MATCH($I7,спр_Материалы!$A$2:$A$9000,0))="USD",КурсUSD,IF(INDEX(спр_Материалы!$J$2:$J$9000,MATCH($I7,спр_Материалы!$A$2:$A$9000,0))="EUR",КурсEUR,1))*INDEX(спр_Материалы!$K$2:$K$9000,MATCH($I7,спр_Материалы!$A$2:$A$9000,0))*(1+IFERROR(INDEX(спр_Работы!$I$2:$I$6000,MATCH($C7,спр_Работы!$A$2:$A$6000,0))/100,0))*(1-ДисконтТендер),0)) | N7: =IF(AND($R7="да",$H7<>""),ROUND($H7*$L7,2),0) | O7: =IF(AND($R7="да",$H7<>""),ROUND($H7*$M7,2),0) | P7: =$N7+$O7 | Q7: =IFERROR(INDEX(спр_Работы!$J$2:$J$6000,MATCH($C7,спр_Работы!$A$2:$A$6000,0)),"") | R7: да | T7: =IF(AND($P7>0,$R7="да"),MAX($T$1:$T6)+1,"")
A8: =IFERROR(INDEX(спр_Работы!$D$2:$D$6000,MATCH($C8,спр_Работы!$A$2:$A$6000,0)),"") | B8: =IFERROR(INDEX(спр_Работы!$F$2:$F$6000,MATCH($C8,спр_Работы!$A$2:$A$6000,0)),"") | C8: =IFERROR(INDEX(спр_Работы!$A$2:$A$6000,7),"") | D8: =IFERROR(INDEX(спр_Работы!$B$2:$B$6000,MATCH($C8,спр_Работы!$A$2:$A$6000,0)),"") | E8: =IFERROR(INDEX(спр_Работы!$C$2:$C$6000,MATCH($C8,спр_Работы!$A$2:$A$6000,0)),"") | F8: =IFERROR(INDEX(спр_Работы!$G$2:$G$6000,MATCH($C8,спр_Работы!$A$2:$A$6000,0)),"") | G8: =IFERROR(INDEX(спр_Работы!$K$2:$K$6000,MATCH($C8,спр_Работы!$A$2:$A$6000,0)),"") | J8: =IFERROR(INDEX(спр_Материалы!$B$2:$B$9000,MATCH($I8,спр_Материалы!$A$2:$A$9000,0)),"") | K8: =IF($I8="","",IF($F8=IFERROR(INDEX(спр_Материалы!$G$2:$G$9000,MATCH($I8,спр_Материалы!$A$2:$A$9000,0)),""),"OK","!! не та группа")) | L8: =IFERROR(INDEX(спр_Работы!$H$2:$H$6000,MATCH($C8,спр_Работы!$A$2:$A$6000,0))*(1-ДисконтТендер),0) | M8: =IF($I8="",0,IFERROR(INDEX(спр_Материалы!$I$2:$I$9000,MATCH($I8,спр_Материалы!$A$2:$A$9000,0))*IF(INDEX(спр_Материалы!$J$2:$J$9000,MATCH($I8,спр_Материалы!$A$2:$A$9000,0))="USD",КурсUSD,IF(INDEX(спр_Материалы!$J$2:$J$9000,MATCH($I8,спр_Материалы!$A$2:$A$9000,0))="EUR",КурсEUR,1))*INDEX(спр_Материалы!$K$2:$K$9000,MATCH($I8,спр_Материалы!$A$2:$A$9000,0))*(1+IFERROR(INDEX(спр_Работы!$I$2:$I$6000,MATCH($C8,спр_Работы!$A$2:$A$6000,0))/100,0))*(1-ДисконтТендер),0)) | N8: =IF(AND($R8="да",$H8<>""),ROUND($H8*$L8,2),0) | O8: =IF(AND($R8="да",$H8<>""),ROUND($H8*$M8,2),0) | P8: =$N8+$O8 | Q8: =IFERROR(INDEX(спр_Работы!$J$2:$J$6000,MATCH($C8,спр_Работы!$A$2:$A$6000,0)),"") | R8: да | T8: =IF(AND($P8>0,$R8="да"),MAX($T$1:$T7)+1,"")
A9: =IFERROR(INDEX(спр_Работы!$D$2:$D$6000,MATCH($C9,спр_Работы!$A$2:$A$6000,0)),"") | B9: =IFERROR(INDEX(спр_Работы!$F$2:$F$6000,MATCH($C9,спр_Работы!$A$2:$A$6000,0)),"") | C9: =IFERROR(INDEX(спр_Работы!$A$2:$A$6000,8),"") | D9: =IFERROR(INDEX(спр_Работы!$B$2:$B$6000,MATCH($C9,спр_Работы!$A$2:$A$6000,0)),"") | E9: =IFERROR(INDEX(спр_Работы!$C$2:$C$6000,MATCH($C9,спр_Работы!$A$2:$A$6000,0)),"") | F9: =IFERROR(INDEX(спр_Работы!$G$2:$G$6000,MATCH($C9,спр_Работы!$A$2:$A$6000,0)),"") | G9: =IFERROR(INDEX(спр_Работы!$K$2:$K$6000,MATCH($C9,спр_Работы!$A$2:$A$6000,0)),"") | J9: =IFERROR(INDEX(спр_Материалы!$B$2:$B$9000,MATCH($I9,спр_Материалы!$A$2:$A$9000,0)),"") | K9: =IF($I9="","",IF($F9=IFERROR(INDEX(спр_Материалы!$G$2:$G$9000,MATCH($I9,спр_Материалы!$A$2:$A$9000,0)),""),"OK","!! не та группа")) | L9: =IFERROR(INDEX(спр_Работы!$H$2:$H$6000,MATCH($C9,спр_Работы!$A$2:$A$6000,0))*(1-ДисконтТендер),0) | M9: =IF($I9="",0,IFERROR(INDEX(спр_Материалы!$I$2:$I$9000,MATCH($I9,спр_Материалы!$A$2:$A$9000,0))*IF(INDEX(спр_Материалы!$J$2:$J$9000,MATCH($I9,спр_Материалы!$A$2:$A$9000,0))="USD",КурсUSD,IF(INDEX(спр_Материалы!$J$2:$J$9000,MATCH($I9,спр_Материалы!$A$2:$A$9000,0))="EUR",КурсEUR,1))*INDEX(спр_Материалы!$K$2:$K$9000,MATCH($I9,спр_Материалы!$A$2:$A$9000,0))*(1+IFERROR(INDEX(спр_Работы!$I$2:$I$6000,MATCH($C9,спр_Работы!$A$2:$A$6000,0))/100,0))*(1-ДисконтТендер),0)) | N9: =IF(AND($R9="да",$H9<>""),ROUND($H9*$L9,2),0) | O9: =IF(AND($R9="да",$H9<>""),ROUND($H9*$M9,2),0) | P9: =$N9+$O9 | Q9: =IFERROR(INDEX(спр_Работы!$J$2:$J$6000,MATCH($C9,спр_Работы!$A$2:$A$6000,0)),"") | R9: да | T9: =IF(AND($P9>0,$R9="да"),MAX($T$1:$T8)+1,"")
A10: =IFERROR(INDEX(спр_Работы!$D$2:$D$6000,MATCH($C10,спр_Работы!$A$2:$A$6000,0)),"") | B10: =IFERROR(INDEX(спр_Работы!$F$2:$F$6000,MATCH($C10,спр_Работы!$A$2:$A$6000,0)),"") | C10: =IFERROR(INDEX(спр_Работы!$A$2:$A$6000,9),"") | D10: =IFERROR(INDEX(спр_Работы!$B$2:$B$6000,MATCH($C10,спр_Работы!$A$2:$A$6000,0)),"") | E10: =IFERROR(INDEX(спр_Работы!$C$2:$C$6000,MATCH($C10,спр_Работы!$A$2:$A$6000,0)),"") | F10: =IFERROR(INDEX(спр_Работы!$G$2:$G$6000,MATCH($C10,спр_Работы!$A$2:$A$6000,0)),"") | G10: =IFERROR(INDEX(спр_Работы!$K$2:$K$6000,MATCH($C10,спр_Работы!$A$2:$A$6000,0)),"") | J10: =IFERROR(INDEX(спр_Материалы!$B$2:$B$9000,MATCH($I10,спр_Материалы!$A$2:$A$9000,0)),"") | K10: =IF($I10="","",IF($F10=IFERROR(INDEX(спр_Материалы!$G$2:$G$9000,MATCH($I10,спр_Материалы!$A$2:$A$9000,0)),""),"OK","!! не та группа")) | L10: =IFERROR(INDEX(спр_Работы!$H$2:$H$6000,MATCH($C10,спр_Работы!$A$2:$A$6000,0))*(1-ДисконтТендер),0) | M10: =IF($I10="",0,IFERROR(INDEX(спр_Материалы!$I$2:$I$9000,MATCH($I10,спр_Материалы!$A$2:$A$9000,0))*IF(INDEX(спр_Материалы!$J$2:$J$9000,MATCH($I10,спр_Материалы!$A$2:$A$9000,0))="USD",КурсUSD,IF(INDEX(спр_Материалы!$J$2:$J$9000,MATCH($I10,спр_Материалы!$A$2:$A$9000,0))="EUR",КурсEUR,1))*INDEX(спр_Материалы!$K$2:$K$9000,MATCH($I10,спр_Материалы!$A$2:$A$9000,0))*(1+IFERROR(INDEX(спр_Работы!$I$2:$I$6000,MATCH($C10,спр_Работы!$A$2:$A$6000,0))/100,0))*(1-ДисконтТендер),0)) | N10: =IF(AND($R10="да",$H10<>""),ROUND($H10*$L10,2),0) | O10: =IF(AND($R10="да",$H10<>""),ROUND($H10*$M10,2),0) | P10: =$N10+$O10 | Q10: =IFERROR(INDEX(спр_Работы!$J$2:$J$6000,MATCH($C10,спр_Работы!$A$2:$A$6000,0)),"") | R10: да | T10: =IF(AND($P10>0,$R10="да"),MAX($T$1:$T9)+1,"")
A11: =IFERROR(INDEX(спр_Работы!$D$2:$D$6000,MATCH($C11,спр_Работы!$A$2:$A$6000,0)),"") | B11: =IFERROR(INDEX(спр_Работы!$F$2:$F$6000,MATCH($C11,спр_Работы!$A$2:$A$6000,0)),"") | C11: =IFERROR(INDEX(спр_Работы!$A$2:$A$6000,10),"") | D11: =IFERROR(INDEX(спр_Работы!$B$2:$B$6000,MATCH($C11,спр_Работы!$A$2:$A$6000,0)),"") | E11: =IFERROR(INDEX(спр_Работы!$C$2:$C$6000,MATCH($C11,спр_Работы!$A$2:$A$6000,0)),"") | F11: =IFERROR(INDEX(спр_Работы!$G$2:$G$6000,MATCH($C11,спр_Работы!$A$2:$A$6000,0)),"") | G11: =IFERROR(INDEX(спр_Работы!$K$2:$K$6000,MATCH($C11,спр_Работы!$A$2:$A$6000,0)),"") | J11: =IFERROR(INDEX(спр_Материалы!$B$2:$B$9000,MATCH($I11,спр_Материалы!$A$2:$A$9000,0)),"") | K11: =IF($I11="","",IF($F11=IFERROR(INDEX(спр_Материалы!$G$2:$G$9000,MATCH($I11,спр_Материалы!$A$2:$A$9000,0)),""),"OK","!! не та группа")) | L11: =IFERROR(INDEX(спр_Работы!$H$2:$H$6000,MATCH($C11,спр_Работы!$A$2:$A$6000,0))*(1-ДисконтТендер),0) | M11: =IF($I11="",0,IFERROR(INDEX(спр_Материалы!$I$2:$I$9000,MATCH($I11,спр_Материалы!$A$2:$A$9000,0))*IF(INDEX(спр_Материалы!$J$2:$J$9000,MATCH($I11,спр_Материалы!$A$2:$A$9000,0))="USD",КурсUSD,IF(INDEX(спр_Материалы!$J$2:$J$9000,MATCH($I11,спр_Материалы!$A$2:$A$9000,0))="EUR",КурсEUR,1))*INDEX(спр_Материалы!$K$2:$K$9000,MATCH($I11,спр_Материалы!$A$2:$A$9000,0))*(1+IFERROR(INDEX(спр_Работы!$I$2:$I$6000,MATCH($C11,спр_Работы!$A$2:$A$6000,0))/100,0))*(1-ДисконтТендер),0)) | N11: =IF(AND($R11="да",$H11<>""),ROUND($H11*$L11,2),0) | O11: =IF(AND($R11="да",$H11<>""),ROUND($H11*$M11,2),0) | P11: =$N11+$O11 | Q11: =IFERROR(INDEX(спр_Работы!$J$2:$J$6000,MATCH($C11,спр_Работы!$A$2:$A$6000,0)),"") | R11: да | T11: =IF(AND($P11>0,$R11="да"),MAX($T$1:$T10)+1,"")
A12: =IFERROR(INDEX(спр_Работы!$D$2:$D$6000,MATCH($C12,спр_Работы!$A$2:$A$6000,0)),"") | B12: =IFERROR(INDEX(спр_Работы!$F$2:$F$6000,MATCH($C12,спр_Работы!$A$2:$A$6000,0)),"") | C12: =IFERROR(INDEX(спр_Работы!$A$2:$A$6000,11),"") | D12: =IFERROR(INDEX(спр_Работы!$B$2:$B$6000,MATCH($C12,спр_Работы!$A$2:$A$6000,0)),"") | E12: =IFERROR(INDEX(спр_Работы!$C$2:$C$6000,MATCH($C12,спр_Работы!$A$2:$A$6000,0)),"") | F12: =IFERROR(INDEX(спр_Работы!$G$2:$G$6000,MATCH($C12,спр_Работы!$A$2:$A$6000,0)),"") | G12: =IFERROR(INDEX(спр_Работы!$K$2:$K$6000,MATCH($C12,спр_Работы!$A$2:$A$6000,0)),"") | J12: =IFERROR(INDEX(спр_Материалы!$B$2:$B$9000,MATCH($I12,спр_Материалы!$A$2:$A$9000,0)),"") | K12: =IF($I12="","",IF($F12=IFERROR(INDEX(спр_Материалы!$G$2:$G$9000,MATCH($I12,спр_Материалы!$A$2:$A$9000,0)),""),"OK","!! не та группа")) | L12: =IFERROR(INDEX(спр_Работы!$H$2:$H$6000,MATCH($C12,спр_Работы!$A$2:$A$6000,0))*(1-ДисконтТендер),0) | M12: =IF($I12="",0,IFERROR(INDEX(спр_Материалы!$I$2:$I$9000,MATCH($I12,спр_Материалы!$A$2:$A$9000,0))*IF(INDEX(спр_Материалы!$J$2:$J$9000,MATCH($I12,спр_Материалы!$A$2:$A$9000,0))="USD",КурсUSD,IF(INDEX(спр_Материалы!$J$2:$J$9000,MATCH($I12,спр_Материалы!$A$2:$A$9000,0))="EUR",КурсEUR,1))*INDEX(спр_Материалы!$K$2:$K$9000,MATCH($I12,спр_Материалы!$A$2:$A$9000,0))*(1+IFERROR(INDEX(спр_Работы!$I$2:$I$6000,MATCH($C12,спр_Работы!$A$2:$A$6000,0))/100,0))*(1-ДисконтТендер),0)) | N12: =IF(AND($R12="да",$H12<>""),ROUND($H12*$L12,2),0) | O12: =IF(AND($R12="да",$H12<>""),ROUND($H12*$M12,2),0) | P12: =$N12+$O12 | Q12: =IFERROR(INDEX(спр_Работы!$J$2:$J$6000,MATCH($C12,спр_Работы!$A$2:$A$6000,0)),"") | R12: да | T12: =IF(AND($P12>0,$R12="да"),MAX($T$1:$T11)+1,"")
A13: =IFERROR(INDEX(спр_Работы!$D$2:$D$6000,MATCH($C13,спр_Работы!$A$2:$A$6000,0)),"") | B13: =IFERROR(INDEX(спр_Работы!$F$2:$F$6000,MATCH($C13,спр_Работы!$A$2:$A$6000,0)),"") | C13: =IFERROR(INDEX(спр_Работы!$A$2:$A$6000,12),"") | D13: =IFERROR(INDEX(спр_Работы!$B$2:$B$6000,MATCH($C13,спр_Работы!$A$2:$A$6000,0)),"") | E13: =IFERROR(INDEX(спр_Работы!$C$2:$C$6000,MATCH($C13,спр_Работы!$A$2:$A$6000,0)),"") | F13: =IFERROR(INDEX(спр_Работы!$G$2:$G$6000,MATCH($C13,спр_Работы!$A$2:$A$6000,0)),"") | G13: =IFERROR(INDEX(спр_Работы!$K$2:$K$6000,MATCH($C13,спр_Работы!$A$2:$A$6000,0)),"") | J13: =IFERROR(INDEX(спр_Материалы!$B$2:$B$9000,MATCH($I13,спр_Материалы!$A$2:$A$9000,0)),"") | K13: =IF($I13="","",IF($F13=IFERROR(INDEX(спр_Материалы!$G$2:$G$9000,MATCH($I13,спр_Материалы!$A$2:$A$9000,0)),""),"OK","!! не та группа")) | L13: =IFERROR(INDEX(спр_Работы!$H$2:$H$6000,MATCH($C13,спр_Работы!$A$2:$A$6000,0))*(1-ДисконтТендер),0) | M13: =IF($I13="",0,IFERROR(INDEX(спр_Материалы!$I$2:$I$9000,MATCH($I13,спр_Материалы!$A$2:$A$9000,0))*IF(INDEX(спр_Материалы!$J$2:$J$9000,MATCH($I13,спр_Материалы!$A$2:$A$9000,0))="USD",КурсUSD,IF(INDEX(спр_Материалы!$J$2:$J$9000,MATCH($I13,спр_Материалы!$A$2:$A$9000,0))="EUR",КурсEUR,1))*INDEX(спр_Материалы!$K$2:$K$9000,MATCH($I13,спр_Материалы!$A$2:$A$9000,0))*(1+IFERROR(INDEX(спр_Работы!$I$2:$I$6000,MATCH($C13,спр_Работы!$A$2:$A$6000,0))/100,0))*(1-ДисконтТендер),0)) | N13: =IF(AND($R13="да",$H13<>""),ROUND($H13*$L13,2),0) | O13: =IF(AND($R13="да",$H13<>""),ROUND($H13*$M13,2),0) | P13: =$N13+$O13 | Q13: =IFERROR(INDEX(спр_Работы!$J$2:$J$6000,MATCH($C13,спр_Работы!$A$2:$A$6000,0)),"") | R13: да | T13: =IF(AND($P13>0,$R13="да"),MAX($T$1:$T12)+1,"")
A14: =IFERROR(INDEX(спр_Работы!$D$2:$D$6000,MATCH($C14,спр_Работы!$A$2:$A$6000,0)),"") | B14: =IFERROR(INDEX(спр_Работы!$F$2:$F$6000,MATCH($C14,спр_Работы!$A$2:$A$6000,0)),"") | C14: =IFERROR(INDEX(спр_Работы!$A$2:$A$6000,13),"") | D14: =IFERROR(INDEX(спр_Работы!$B$2:$B$6000,MATCH($C14,спр_Работы!$A$2:$A$6000,0)),"") | E14: =IFERROR(INDEX(спр_Работы!$C$2:$C$6000,MATCH($C14,спр_Работы!$A$2:$A$6000,0)),"") | F14: =IFERROR(INDEX(спр_Работы!$G$2:$G$6000,MATCH($C14,спр_Работы!$A$2:$A$6000,0)),"") | G14: =IFERROR(INDEX(спр_Работы!$K$2:$K$6000,MATCH($C14,спр_Работы!$A$2:$A$6000,0)),"") | J14: =IFERROR(INDEX(спр_Материалы!$B$2:$B$9000,MATCH($I14,спр_Материалы!$A$2:$A$9000,0)),"") | K14: =IF($I14="","",IF($F14=IFERROR(INDEX(спр_Материалы!$G$2:$G$9000,MATCH($I14,спр_Материалы!$A$2:$A$9000,0)),""),"OK","!! не та группа")) | L14: =IFERROR(INDEX(спр_Работы!$H$2:$H$6000,MATCH($C14,спр_Работы!$A$2:$A$6000,0))*(1-ДисконтТендер),0) | M14: =IF($I14="",0,IFERROR(INDEX(спр_Материалы!$I$2:$I$9000,MATCH($I14,спр_Материалы!$A$2:$A$9000,0))*IF(INDEX(спр_Материалы!$J$2:$J$9000,MATCH($I14,спр_Материалы!$A$2:$A$9000,0))="USD",КурсUSD,IF(INDEX(спр_Материалы!$J$2:$J$9000,MATCH($I14,спр_Материалы!$A$2:$A$9000,0))="EUR",КурсEUR,1))*INDEX(спр_Материалы!$K$2:$K$9000,MATCH($I14,спр_Материалы!$A$2:$A$9000,0))*(1+IFERROR(INDEX(спр_Работы!$I$2:$I$6000,MATCH($C14,спр_Работы!$A$2:$A$6000,0))/100,0))*(1-ДисконтТендер),0)) | N14: =IF(AND($R14="да",$H14<>""),ROUND($H14*$L14,2),0) | O14: =IF(AND($R14="да",$H14<>""),ROUND($H14*$M14,2),0) | P14: =$N14+$O14 | Q14: =IFERROR(INDEX(спр_Работы!$J$2:$J$6000,MATCH($C14,спр_Работы!$A$2:$A$6000,0)),"") | R14: да | T14: =IF(AND($P14>0,$R14="да"),MAX($T$1:$T13)+1,"")
A15: =IFERROR(INDEX(спр_Работы!$D$2:$D$6000,MATCH($C15,спр_Работы!$A$2:$A$6000,0)),"") | B15: =IFERROR(INDEX(спр_Работы!$F$2:$F$6000,MATCH($C15,спр_Работы!$A$2:$A$6000,0)),"") | C15: =IFERROR(INDEX(спр_Работы!$A$2:$A$6000,14),"") | D15: =IFERROR(INDEX(спр_Работы!$B$2:$B$6000,MATCH($C15,спр_Работы!$A$2:$A$6000,0)),"") | E15: =IFERROR(INDEX(спр_Работы!$C$2:$C$6000,MATCH($C15,спр_Работы!$A$2:$A$6000,0)),"") | F15: =IFERROR(INDEX(спр_Работы!$G$2:$G$6000,MATCH($C15,спр_Работы!$A$2:$A$6000,0)),"") | G15: =IFERROR(INDEX(спр_Работы!$K$2:$K$6000,MATCH($C15,спр_Работы!$A$2:$A$6000,0)),"") | J15: =IFERROR(INDEX(спр_Материалы!$B$2:$B$9000,MATCH($I15,спр_Материалы!$A$2:$A$9000,0)),"") | K15: =IF($I15="","",IF($F15=IFERROR(INDEX(спр_Материалы!$G$2:$G$9000,MATCH($I15,спр_Материалы!$A$2:$A$9000,0)),""),"OK","!! не та группа")) | L15: =IFERROR(INDEX(спр_Работы!$H$2:$H$6000,MATCH($C15,спр_Работы!$A$2:$A$6000,0))*(1-ДисконтТендер),0) | M15: =IF($I15="",0,IFERROR(INDEX(спр_Материалы!$I$2:$I$9000,MATCH($I15,спр_Материалы!$A$2:$A$9000,0))*IF(INDEX(спр_Материалы!$J$2:$J$9000,MATCH($I15,спр_Материалы!$A$2:$A$9000,0))="USD",КурсUSD,IF(INDEX(спр_Материалы!$J$2:$J$9000,MATCH($I15,спр_Материалы!$A$2:$A$9000,0))="EUR",КурсEUR,1))*INDEX(спр_Материалы!$K$2:$K$9000,MATCH($I15,спр_Материалы!$A$2:$A$9000,0))*(1+IFERROR(INDEX(спр_Работы!$I$2:$I$6000,MATCH($C15,спр_Работы!$A$2:$A$6000,0))/100,0))*(1-ДисконтТендер),0)) | N15: =IF(AND($R15="да",$H15<>""),ROUND($H15*$L15,2),0) | O15: =IF(AND($R15="да",$H15<>""),ROUND($H15*$M15,2),0) | P15: =$N15+$O15 | Q15: =IFERROR(INDEX(спр_Работы!$J$2:$J$6000,MATCH($C15,спр_Работы!$A$2:$A$6000,0)),"") | R15: да | T15: =IF(AND($P15>0,$R15="да"),MAX($T$1:$T14)+1,"")
A16: =IFERROR(INDEX(спр_Работы!$D$2:$D$6000,MATCH($C16,спр_Работы!$A$2:$A$6000,0)),"") | B16: =IFERROR(INDEX(спр_Работы!$F$2:$F$6000,MATCH($C16,спр_Работы!$A$2:$A$6000,0)),"") | C16: =IFERROR(INDEX(спр_Работы!$A$2:$A$6000,15),"") | D16: =IFERROR(INDEX(спр_Работы!$B$2:$B$6000,MATCH($C16,спр_Работы!$A$2:$A$6000,0)),"") | E16: =IFERROR(INDEX(спр_Работы!$C$2:$C$6000,MATCH($C16,спр_Работы!$A$2:$A$6000,0)),"") | F16: =IFERROR(INDEX(спр_Работы!$G$2:$G$6000,MATCH($C16,спр_Работы!$A$2:$A$6000,0)),"") | G16: =IFERROR(INDEX(спр_Работы!$K$2:$K$6000,MATCH($C16,спр_Работы!$A$2:$A$6000,0)),"") | J16: =IFERROR(INDEX(спр_Материалы!$B$2:$B$9000,MATCH($I16,спр_Материалы!$A$2:$A$9000,0)),"") | K16: =IF($I16="","",IF($F16=IFERROR(INDEX(спр_Материалы!$G$2:$G$9000,MATCH($I16,спр_Материалы!$A$2:$A$9000,0)),""),"OK","!! не та группа")) | L16: =IFERROR(INDEX(спр_Работы!$H$2:$H$6000,MATCH($C16,спр_Работы!$A$2:$A$6000,0))*(1-ДисконтТендер),0) | M16: =IF($I16="",0,IFERROR(INDEX(спр_Материалы!$I$2:$I$9000,MATCH($I16,спр_Материалы!$A$2:$A$9000,0))*IF(INDEX(спр_Материалы!$J$2:$J$9000,MATCH($I16,спр_Материалы!$A$2:$A$9000,0))="USD",КурсUSD,IF(INDEX(спр_Материалы!$J$2:$J$9000,MATCH($I16,спр_Материалы!$A$2:$A$9000,0))="EUR",КурсEUR,1))*INDEX(спр_Материалы!$K$2:$K$9000,MATCH($I16,спр_Материалы!$A$2:$A$9000,0))*(1+IFERROR(INDEX(спр_Работы!$I$2:$I$6000,MATCH($C16,спр_Работы!$A$2:$A$6000,0))/100,0))*(1-ДисконтТендер),0)) | N16: =IF(AND($R16="да",$H16<>""),ROUND($H16*$L16,2),0) | O16: =IF(AND($R16="да",$H16<>""),ROUND($H16*$M16,2),0) | P16: =$N16+$O16 | Q16: =IFERROR(INDEX(спр_Работы!$J$2:$J$6000,MATCH($C16,спр_Работы!$A$2:$A$6000,0)),"") | R16: да | T16: =IF(AND($P16>0,$R16="да"),MAX($T$1:$T15)+1,"")
A17: =IFERROR(INDEX(спр_Работы!$D$2:$D$6000,MATCH($C17,спр_Работы!$A$2:$A$6000,0)),"") | B17: =IFERROR(INDEX(спр_Работы!$F$2:$F$6000,MATCH($C17,спр_Работы!$A$2:$A$6000,0)),"") | C17: =IFERROR(INDEX(спр_Работы!$A$2:$A$6000,16),"") | D17: =IFERROR(INDEX(спр_Работы!$B$2:$B$6000,MATCH($C17,спр_Работы!$A$2:$A$6000,0)),"") | E17: =IFERROR(INDEX(спр_Работы!$C$2:$C$6000,MATCH($C17,спр_Работы!$A$2:$A$6000,0)),"") | F17: =IFERROR(INDEX(спр_Работы!$G$2:$G$6000,MATCH($C17,спр_Работы!$A$2:$A$6000,0)),"") | G17: =IFERROR(INDEX(спр_Работы!$K$2:$K$6000,MATCH($C17,спр_Работы!$A$2:$A$6000,0)),"") | J17: =IFERROR(INDEX(спр_Материалы!$B$2:$B$9000,MATCH($I17,спр_Материалы!$A$2:$A$9000,0)),"") | K17: =IF($I17="","",IF($F17=IFERROR(INDEX(спр_Материалы!$G$2:$G$9000,MATCH($I17,спр_Материалы!$A$2:$A$9000,0)),""),"OK","!! не та группа")) | L17: =IFERROR(INDEX(спр_Работы!$H$2:$H$6000,MATCH($C17,спр_Работы!$A$2:$A$6000,0))*(1-ДисконтТендер),0) | M17: =IF($I17="",0,IFERROR(INDEX(спр_Материалы!$I$2:$I$9000,MATCH($I17,спр_Материалы!$A$2:$A$9000,0))*IF(INDEX(спр_Материалы!$J$2:$J$9000,MATCH($I17,спр_Материалы!$A$2:$A$9000,0))="USD",КурсUSD,IF(INDEX(спр_Материалы!$J$2:$J$9000,MATCH($I17,спр_Материалы!$A$2:$A$9000,0))="EUR",КурсEUR,1))*INDEX(спр_Материалы!$K$2:$K$9000,MATCH($I17,спр_Материалы!$A$2:$A$9000,0))*(1+IFERROR(INDEX(спр_Работы!$I$2:$I$6000,MATCH($C17,спр_Работы!$A$2:$A$6000,0))/100,0))*(1-ДисконтТендер),0)) | N17: =IF(AND($R17="да",$H17<>""),ROUND($H17*$L17,2),0) | O17: =IF(AND($R17="да",$H17<>""),ROUND($H17*$M17,2),0) | P17: =$N17+$O17 | Q17: =IFERROR(INDEX(спр_Работы!$J$2:$J$6000,MATCH($C17,спр_Работы!$A$2:$A$6000,0)),"") | R17: да | T17: =IF(AND($P17>0,$R17="да"),MAX($T$1:$T16)+1,"")
A18: =IFERROR(INDEX(спр_Работы!$D$2:$D$6000,MATCH($C18,спр_Работы!$A$2:$A$6000,0)),"") | B18: =IFERROR(INDEX(спр_Работы!$F$2:$F$6000,MATCH($C18,спр_Работы!$A$2:$A$6000,0)),"") | C18: =IFERROR(INDEX(спр_Работы!$A$2:$A$6000,17),"") | D18: =IFERROR(INDEX(спр_Работы!$B$2:$B$6000,MATCH($C18,спр_Работы!$A$2:$A$6000,0)),"") | E18: =IFERROR(INDEX(спр_Работы!$C$2:$C$6000,MATCH($C18,спр_Работы!$A$2:$A$6000,0)),"") | F18: =IFERROR(INDEX(спр_Работы!$G$2:$G$6000,MATCH($C18,спр_Работы!$A$2:$A$6000,0)),"") | G18: =IFERROR(INDEX(спр_Работы!$K$2:$K$6000,MATCH($C18,спр_Работы!$A$2:$A$6000,0)),"") | J18: =IFERROR(INDEX(спр_Материалы!$B$2:$B$9000,MATCH($I18,спр_Материалы!$A$2:$A$9000,0)),"") | K18: =IF($I18="","",IF($F18=IFERROR(INDEX(спр_Материалы!$G$2:$G$9000,MATCH($I18,спр_Материалы!$A$2:$A$9000,0)),""),"OK","!! не та группа")) | L18: =IFERROR(INDEX(спр_Работы!$H$2:$H$6000,MATCH($C18,спр_Работы!$A$2:$A$6000,0))*(1-ДисконтТендер),0) | M18: =IF($I18="",0,IFERROR(INDEX(спр_Материалы!$I$2:$I$9000,MATCH($I18,спр_Материалы!$A$2:$A$9000,0))*IF(INDEX(спр_Материалы!$J$2:$J$9000,MATCH($I18,спр_Материалы!$A$2:$A$9000,0))="USD",КурсUSD,IF(INDEX(спр_Материалы!$J$2:$J$9000,MATCH($I18,спр_Материалы!$A$2:$A$9000,0))="EUR",КурсEUR,1))*INDEX(спр_Материалы!$K$2:$K$9000,MATCH($I18,спр_Материалы!$A$2:$A$9000,0))*(1+IFERROR(INDEX(спр_Работы!$I$2:$I$6000,MATCH($C18,спр_Работы!$A$2:$A$6000,0))/100,0))*(1-ДисконтТендер),0)) | N18: =IF(AND($R18="да",$H18<>""),ROUND($H18*$L18,2),0) | O18: =IF(AND($R18="да",$H18<>""),ROUND($H18*$M18,2),0) | P18: =$N18+$O18 | Q18: =IFERROR(INDEX(спр_Работы!$J$2:$J$6000,MATCH($C18,спр_Работы!$A$2:$A$6000,0)),"") | R18: да | T18: =IF(AND($P18>0,$R18="да"),MAX($T$1:$T17)+1,"")
A19: =IFERROR(INDEX(спр_Работы!$D$2:$D$6000,MATCH($C19,спр_Работы!$A$2:$A$6000,0)),"") | B19: =IFERROR(INDEX(спр_Работы!$F$2:$F$6000,MATCH($C19,спр_Работы!$A$2:$A$6000,0)),"") | C19: =IFERROR(INDEX(спр_Работы!$A$2:$A$6000,18),"") | D19: =IFERROR(INDEX(спр_Работы!$B$2:$B$6000,MATCH($C19,спр_Работы!$A$2:$A$6000,0)),"") | E19: =IFERROR(INDEX(спр_Работы!$C$2:$C$6000,MATCH($C19,спр_Работы!$A$2:$A$6000,0)),"") | F19: =IFERROR(INDEX(спр_Работы!$G$2:$G$6000,MATCH($C19,спр_Работы!$A$2:$A$6000,0)),"") | G19: =IFERROR(INDEX(спр_Работы!$K$2:$K$6000,MATCH($C19,спр_Работы!$A$2:$A$6000,0)),"") | J19: =IFERROR(INDEX(спр_Материалы!$B$2:$B$9000,MATCH($I19,спр_Материалы!$A$2:$A$9000,0)),"") | K19: =IF($I19="","",IF($F19=IFERROR(INDEX(спр_Материалы!$G$2:$G$9000,MATCH($I19,спр_Материалы!$A$2:$A$9000,0)),""),"OK","!! не та группа")) | L19: =IFERROR(INDEX(спр_Работы!$H$2:$H$6000,MATCH($C19,спр_Работы!$A$2:$A$6000,0))*(1-ДисконтТендер),0) | M19: =IF($I19="",0,IFERROR(INDEX(спр_Материалы!$I$2:$I$9000,MATCH($I19,спр_Материалы!$A$2:$A$9000,0))*IF(INDEX(спр_Материалы!$J$2:$J$9000,MATCH($I19,спр_Материалы!$A$2:$A$9000,0))="USD",КурсUSD,IF(INDEX(спр_Материалы!$J$2:$J$9000,MATCH($I19,спр_Материалы!$A$2:$A$9000,0))="EUR",КурсEUR,1))*INDEX(спр_Материалы!$K$2:$K$9000,MATCH($I19,спр_Материалы!$A$2:$A$9000,0))*(1+IFERROR(INDEX(спр_Работы!$I$2:$I$6000,MATCH($C19,спр_Работы!$A$2:$A$6000,0))/100,0))*(1-ДисконтТендер),0)) | N19: =IF(AND($R19="да",$H19<>""),ROUND($H19*$L19,2),0) | O19: =IF(AND($R19="да",$H19<>""),ROUND($H19*$M19,2),0) | P19: =$N19+$O19 | Q19: =IFERROR(INDEX(спр_Работы!$J$2:$J$6000,MATCH($C19,спр_Работы!$A$2:$A$6000,0)),"") | R19: да | T19: =IF(AND($P19>0,$R19="да"),MAX($T$1:$T18)+1,"")
A20: =IFERROR(INDEX(спр_Работы!$D$2:$D$6000,MATCH($C20,спр_Работы!$A$2:$A$6000,0)),"") | B20: =IFERROR(INDEX(спр_Работы!$F$2:$F$6000,MATCH($C20,спр_Работы!$A$2:$A$6000,0)),"") | C20: =IFERROR(INDEX(спр_Работы!$A$2:$A$6000,19),"") | D20: =IFERROR(INDEX(спр_Работы!$B$2:$B$6000,MATCH($C20,спр_Работы!$A$2:$A$6000,0)),"") | E20: =IFERROR(INDEX(спр_Работы!$C$2:$C$6000,MATCH($C20,спр_Работы!$A$2:$A$6000,0)),"") | F20: =IFERROR(INDEX(спр_Работы!$G$2:$G$6000,MATCH($C20,спр_Работы!$A$2:$A$6000,0)),"") | G20: =IFERROR(INDEX(спр_Работы!$K$2:$K$6000,MATCH($C20,спр_Работы!$A$2:$A$6000,0)),"") | J20: =IFERROR(INDEX(спр_Материалы!$B$2:$B$9000,MATCH($I20,спр_Материалы!$A$2:$A$9000,0)),"") | K20: =IF($I20="","",IF($F20=IFERROR(INDEX(спр_Материалы!$G$2:$G$9000,MATCH($I20,спр_Материалы!$A$2:$A$9000,0)),""),"OK","!! не та группа")) | L20: =IFERROR(INDEX(спр_Работы!$H$2:$H$6000,MATCH($C20,спр_Работы!$A$2:$A$6000,0))*(1-ДисконтТендер),0) | M20: =IF($I20="",0,IFERROR(INDEX(спр_Материалы!$I$2:$I$9000,MATCH($I20,спр_Материалы!$A$2:$A$9000,0))*IF(INDEX(спр_Материалы!$J$2:$J$9000,MATCH($I20,спр_Материалы!$A$2:$A$9000,0))="USD",КурсUSD,IF(INDEX(спр_Материалы!$J$2:$J$9000,MATCH($I20,спр_Материалы!$A$2:$A$9000,0))="EUR",КурсEUR,1))*INDEX(спр_Материалы!$K$2:$K$9000,MATCH($I20,спр_Материалы!$A$2:$A$9000,0))*(1+IFERROR(INDEX(спр_Работы!$I$2:$I$6000,MATCH($C20,спр_Работы!$A$2:$A$6000,0))/100,0))*(1-ДисконтТендер),0)) | N20: =IF(AND($R20="да",$H20<>""),ROUND($H20*$L20,2),0) | O20: =IF(AND($R20="да",$H20<>""),ROUND($H20*$M20,2),0) | P20: =$N20+$O20 | Q20: =IFERROR(INDEX(спр_Работы!$J$2:$J$6000,MATCH($C20,спр_Работы!$A$2:$A$6000,0)),"") | R20: да | T20: =IF(AND($P20>0,$R20="да"),MAX($T$1:$T19)+1,"")
A21: =IFERROR(INDEX(спр_Работы!$D$2:$D$6000,MATCH($C21,спр_Работы!$A$2:$A$6000,0)),"") | B21: =IFERROR(INDEX(спр_Работы!$F$2:$F$6000,MATCH($C21,спр_Работы!$A$2:$A$6000,0)),"") | C21: =IFERROR(INDEX(спр_Работы!$A$2:$A$6000,20),"") | D21: =IFERROR(INDEX(спр_Работы!$B$2:$B$6000,MATCH($C21,спр_Работы!$A$2:$A$6000,0)),"") | E21: =IFERROR(INDEX(спр_Работы!$C$2:$C$6000,MATCH($C21,спр_Работы!$A$2:$A$6000,0)),"") | F21: =IFERROR(INDEX(спр_Работы!$G$2:$G$6000,MATCH($C21,спр_Работы!$A$2:$A$6000,0)),"") | G21: =IFERROR(INDEX(спр_Работы!$K$2:$K$6000,MATCH($C21,спр_Работы!$A$2:$A$6000,0)),"") | J21: =IFERROR(INDEX(спр_Материалы!$B$2:$B$9000,MATCH($I21,спр_Материалы!$A$2:$A$9000,0)),"") | K21: =IF($I21="","",IF($F21=IFERROR(INDEX(спр_Материалы!$G$2:$G$9000,MATCH($I21,спр_Материалы!$A$2:$A$9000,0)),""),"OK","!! не та группа")) | L21: =IFERROR(INDEX(спр_Работы!$H$2:$H$6000,MATCH($C21,спр_Работы!$A$2:$A$6000,0))*(1-ДисконтТендер),0) | M21: =IF($I21="",0,IFERROR(INDEX(спр_Материалы!$I$2:$I$9000,MATCH($I21,спр_Материалы!$A$2:$A$9000,0))*IF(INDEX(спр_Материалы!$J$2:$J$9000,MATCH($I21,спр_Материалы!$A$2:$A$9000,0))="USD",КурсUSD,IF(INDEX(спр_Материалы!$J$2:$J$9000,MATCH($I21,спр_Материалы!$A$2:$A$9000,0))="EUR",КурсEUR,1))*INDEX(спр_Материалы!$K$2:$K$9000,MATCH($I21,спр_Материалы!$A$2:$A$9000,0))*(1+IFERROR(INDEX(спр_Работы!$I$2:$I$6000,MATCH($C21,спр_Работы!$A$2:$A$6000,0))/100,0))*(1-ДисконтТендер),0)) | N21: =IF(AND($R21="да",$H21<>""),ROUND($H21*$L21,2),0) | O21: =IF(AND($R21="да",$H21<>""),ROUND($H21*$M21,2),0) | P21: =$N21+$O21 | Q21: =IFERROR(INDEX(спр_Работы!$J$2:$J$6000,MATCH($C21,спр_Работы!$A$2:$A$6000,0)),"") | R21: да | T21: =IF(AND($P21>0,$R21="да"),MAX($T$1:$T20)+1,"")
A22: =IFERROR(INDEX(спр_Работы!$D$2:$D$6000,MATCH($C22,спр_Работы!$A$2:$A$6000,0)),"") | B22: =IFERROR(INDEX(спр_Работы!$F$2:$F$6000,MATCH($C22,спр_Работы!$A$2:$A$6000,0)),"") | C22: =IFERROR(INDEX(спр_Работы!$A$2:$A$6000,21),"") | D22: =IFERROR(INDEX(спр_Работы!$B$2:$B$6000,MATCH($C22,спр_Работы!$A$2:$A$6000,0)),"") | E22: =IFERROR(INDEX(спр_Работы!$C$2:$C$6000,MATCH($C22,спр_Работы!$A$2:$A$6000,0)),"") | F22: =IFERROR(INDEX(спр_Работы!$G$2:$G$6000,MATCH($C22,спр_Работы!$A$2:$A$6000,0)),"") | G22: =IFERROR(INDEX(спр_Работы!$K$2:$K$6000,MATCH($C22,спр_Работы!$A$2:$A$6000,0)),"") | J22: =IFERROR(INDEX(спр_Материалы!$B$2:$B$9000,MATCH($I22,спр_Материалы!$A$2:$A$9000,0)),"") | K22: =IF($I22="","",IF($F22=IFERROR(INDEX(спр_Материалы!$G$2:$G$9000,MATCH($I22,спр_Материалы!$A$2:$A$9000,0)),""),"OK","!! не та группа")) | L22: =IFERROR(INDEX(спр_Работы!$H$2:$H$6000,MATCH($C22,спр_Работы!$A$2:$A$6000,0))*(1-ДисконтТендер),0) | M22: =IF($I22="",0,IFERROR(INDEX(спр_Материалы!$I$2:$I$9000,MATCH($I22,спр_Материалы!$A$2:$A$9000,0))*IF(INDEX(спр_Материалы!$J$2:$J$9000,MATCH($I22,спр_Материалы!$A$2:$A$9000,0))="USD",КурсUSD,IF(INDEX(спр_Материалы!$J$2:$J$9000,MATCH($I22,спр_Материалы!$A$2:$A$9000,0))="EUR",КурсEUR,1))*INDEX(спр_Материалы!$K$2:$K$9000,MATCH($I22,спр_Материалы!$A$2:$A$9000,0))*(1+IFERROR(INDEX(спр_Работы!$I$2:$I$6000,MATCH($C22,спр_Работы!$A$2:$A$6000,0))/100,0))*(1-ДисконтТендер),0)) | N22: =IF(AND($R22="да",$H22<>""),ROUND($H22*$L22,2),0) | O22: =IF(AND($R22="да",$H22<>""),ROUND($H22*$M22,2),0) | P22: =$N22+$O22 | Q22: =IFERROR(INDEX(спр_Работы!$J$2:$J$6000,MATCH($C22,спр_Работы!$A$2:$A$6000,0)),"") | R22: да | T22: =IF(AND($P22>0,$R22="да"),MAX($T$1:$T21)+1,"")
A23: =IFERROR(INDEX(спр_Работы!$D$2:$D$6000,MATCH($C23,спр_Работы!$A$2:$A$6000,0)),"") | B23: =IFERROR(INDEX(спр_Работы!$F$2:$F$6000,MATCH($C23,спр_Работы!$A$2:$A$6000,0)),"") | C23: =IFERROR(INDEX(спр_Работы!$A$2:$A$6000,22),"") | D23: =IFERROR(INDEX(спр_Работы!$B$2:$B$6000,MATCH($C23,спр_Работы!$A$2:$A$6000,0)),"") | E23: =IFERROR(INDEX(спр_Работы!$C$2:$C$6000,MATCH($C23,спр_Работы!$A$2:$A$6000,0)),"") | F23: =IFERROR(INDEX(спр_Работы!$G$2:$G$6000,MATCH($C23,спр_Работы!$A$2:$A$6000,0)),"") | G23: =IFERROR(INDEX(спр_Работы!$K$2:$K$6000,MATCH($C23,спр_Работы!$A$2:$A$6000,0)),"") | J23: =IFERROR(INDEX(спр_Материалы!$B$2:$B$9000,MATCH($I23,спр_Материалы!$A$2:$A$9000,0)),"") | K23: =IF($I23="","",IF($F23=IFERROR(INDEX(спр_Материалы!$G$2:$G$9000,MATCH($I23,спр_Материалы!$A$2:$A$9000,0)),""),"OK","!! не та группа")) | L23: =IFERROR(INDEX(спр_Работы!$H$2:$H$6000,MATCH($C23,спр_Работы!$A$2:$A$6000,0))*(1-ДисконтТендер),0) | M23: =IF($I23="",0,IFERROR(INDEX(спр_Материалы!$I$2:$I$9000,MATCH($I23,спр_Материалы!$A$2:$A$9000,0))*IF(INDEX(спр_Материалы!$J$2:$J$9000,MATCH($I23,спр_Материалы!$A$2:$A$9000,0))="USD",КурсUSD,IF(INDEX(спр_Материалы!$J$2:$J$9000,MATCH($I23,спр_Материалы!$A$2:$A$9000,0))="EUR",КурсEUR,1))*INDEX(спр_Материалы!$K$2:$K$9000,MATCH($I23,спр_Материалы!$A$2:$A$9000,0))*(1+IFERROR(INDEX(спр_Работы!$I$2:$I$6000,MATCH($C23,спр_Работы!$A$2:$A$6000,0))/100,0))*(1-ДисконтТендер),0)) | N23: =IF(AND($R23="да",$H23<>""),ROUND($H23*$L23,2),0) | O23: =IF(AND($R23="да",$H23<>""),ROUND($H23*$M23,2),0) | P23: =$N23+$O23 | Q23: =IFERROR(INDEX(спр_Работы!$J$2:$J$6000,MATCH($C23,спр_Работы!$A$2:$A$6000,0)),"") | R23: да | T23: =IF(AND($P23>0,$R23="да"),MAX($T$1:$T22)+1,"")
A24: =IFERROR(INDEX(спр_Работы!$D$2:$D$6000,MATCH($C24,спр_Работы!$A$2:$A$6000,0)),"") | B24: =IFERROR(INDEX(спр_Работы!$F$2:$F$6000,MATCH($C24,спр_Работы!$A$2:$A$6000,0)),"") | C24: =IFERROR(INDEX(спр_Работы!$A$2:$A$6000,23),"") | D24: =IFERROR(INDEX(спр_Работы!$B$2:$B$6000,MATCH($C24,спр_Работы!$A$2:$A$6000,0)),"") | E24: =IFERROR(INDEX(спр_Работы!$C$2:$C$6000,MATCH($C24,спр_Работы!$A$2:$A$6000,0)),"") | F24: =IFERROR(INDEX(спр_Работы!$G$2:$G$6000,MATCH($C24,спр_Работы!$A$2:$A$6000,0)),"") | G24: =IFERROR(INDEX(спр_Работы!$K$2:$K$6000,MATCH($C24,спр_Работы!$A$2:$A$6000,0)),"") | J24: =IFERROR(INDEX(спр_Материалы!$B$2:$B$9000,MATCH($I24,спр_Материалы!$A$2:$A$9000,0)),"") | K24: =IF($I24="","",IF($F24=IFERROR(INDEX(спр_Материалы!$G$2:$G$9000,MATCH($I24,спр_Материалы!$A$2:$A$9000,0)),""),"OK","!! не та группа")) | L24: =IFERROR(INDEX(спр_Работы!$H$2:$H$6000,MATCH($C24,спр_Работы!$A$2:$A$6000,0))*(1-ДисконтТендер),0) | M24: =IF($I24="",0,IFERROR(INDEX(спр_Материалы!$I$2:$I$9000,MATCH($I24,спр_Материалы!$A$2:$A$9000,0))*IF(INDEX(спр_Материалы!$J$2:$J$9000,MATCH($I24,спр_Материалы!$A$2:$A$9000,0))="USD",КурсUSD,IF(INDEX(спр_Материалы!$J$2:$J$9000,MATCH($I24,спр_Материалы!$A$2:$A$9000,0))="EUR",КурсEUR,1))*INDEX(спр_Материалы!$K$2:$K$9000,MATCH($I24,спр_Материалы!$A$2:$A$9000,0))*(1+IFERROR(INDEX(спр_Работы!$I$2:$I$6000,MATCH($C24,спр_Работы!$A$2:$A$6000,0))/100,0))*(1-ДисконтТендер),0)) | N24: =IF(AND($R24="да",$H24<>""),ROUND($H24*$L24,2),0) | O24: =IF(AND($R24="да",$H24<>""),ROUND($H24*$M24,2),0) | P24: =$N24+$O24 | Q24: =IFERROR(INDEX(спр_Работы!$J$2:$J$6000,MATCH($C24,спр_Работы!$A$2:$A$6000,0)),"") | R24: да | T24: =IF(AND($P24>0,$R24="да"),MAX($T$1:$T23)+1,"")
A25: =IFERROR(INDEX(спр_Работы!$D$2:$D$6000,MATCH($C25,спр_Работы!$A$2:$A$6000,0)),"") | B25: =IFERROR(INDEX(спр_Работы!$F$2:$F$6000,MATCH($C25,спр_Работы!$A$2:$A$6000,0)),"") | C25: =IFERROR(INDEX(спр_Работы!$A$2:$A$6000,24),"") | D25: =IFERROR(INDEX(спр_Работы!$B$2:$B$6000,MATCH($C25,спр_Работы!$A$2:$A$6000,0)),"") | E25: =IFERROR(INDEX(спр_Работы!$C$2:$C$6000,MATCH($C25,спр_Работы!$A$2:$A$6000,0)),"") | F25: =IFERROR(INDEX(спр_Работы!$G$2:$G$6000,MATCH($C25,спр_Работы!$A$2:$A$6000,0)),"") | G25: =IFERROR(INDEX(спр_Работы!$K$2:$K$6000,MATCH($C25,спр_Работы!$A$2:$A$6000,0)),"") | J25: =IFERROR(INDEX(спр_Материалы!$B$2:$B$9000,MATCH($I25,спр_Материалы!$A$2:$A$9000,0)),"") | K25: =IF($I25="","",IF($F25=IFERROR(INDEX(спр_Материалы!$G$2:$G$9000,MATCH($I25,спр_Материалы!$A$2:$A$9000,0)),""),"OK","!! не та группа")) | L25: =IFERROR(INDEX(спр_Работы!$H$2:$H$6000,MATCH($C25,спр_Работы!$A$2:$A$6000,0))*(1-ДисконтТендер),0) | M25: =IF($I25="",0,IFERROR(INDEX(спр_Материалы!$I$2:$I$9000,MATCH($I25,спр_Материалы!$A$2:$A$9000,0))*IF(INDEX(спр_Материалы!$J$2:$J$9000,MATCH($I25,спр_Материалы!$A$2:$A$9000,0))="USD",КурсUSD,IF(INDEX(спр_Материалы!$J$2:$J$9000,MATCH($I25,спр_Материалы!$A$2:$A$9000,0))="EUR",КурсEUR,1))*INDEX(спр_Материалы!$K$2:$K$9000,MATCH($I25,спр_Материалы!$A$2:$A$9000,0))*(1+IFERROR(INDEX(спр_Работы!$I$2:$I$6000,MATCH($C25,спр_Работы!$A$2:$A$6000,0))/100,0))*(1-ДисконтТендер),0)) | N25: =IF(AND($R25="да",$H25<>""),ROUND($H25*$L25,2),0) | O25: =IF(AND($R25="да",$H25<>""),ROUND($H25*$M25,2),0) | P25: =$N25+$O25 | Q25: =IFERROR(INDEX(спр_Работы!$J$2:$J$6000,MATCH($C25,спр_Работы!$A$2:$A$6000,0)),"") | R25: да | T25: =IF(AND($P25>0,$R25="да"),MAX($T$1:$T24)+1,"")
A26: =IFERROR(INDEX(спр_Работы!$D$2:$D$6000,MATCH($C26,спр_Работы!$A$2:$A$6000,0)),"") | B26: =IFERROR(INDEX(спр_Работы!$F$2:$F$6000,MATCH($C26,спр_Работы!$A$2:$A$6000,0)),"") | C26: =IFERROR(INDEX(спр_Работы!$A$2:$A$6000,25),"") | D26: =IFERROR(INDEX(спр_Работы!$B$2:$B$6000,MATCH($C26,спр_Работы!$A$2:$A$6000,0)),"") | E26: =IFERROR(INDEX(спр_Работы!$C$2:$C$6000,MATCH($C26,спр_Работы!$A$2:$A$6000,0)),"") | F26: =IFERROR(INDEX(спр_Работы!$G$2:$G$6000,MATCH($C26,спр_Работы!$A$2:$A$6000,0)),"") | G26: =IFERROR(INDEX(спр_Работы!$K$2:$K$6000,MATCH($C26,спр_Работы!$A$2:$A$6000,0)),"") | J26: =IFERROR(INDEX(спр_Материалы!$B$2:$B$9000,MATCH($I26,спр_Материалы!$A$2:$A$9000,0)),"") | K26: =IF($I26="","",IF($F26=IFERROR(INDEX(спр_Материалы!$G$2:$G$9000,MATCH($I26,спр_Материалы!$A$2:$A$9000,0)),""),"OK","!! не та группа")) | L26: =IFERROR(INDEX(спр_Работы!$H$2:$H$6000,MATCH($C26,спр_Работы!$A$2:$A$6000,0))*(1-ДисконтТендер),0) | M26: =IF($I26="",0,IFERROR(INDEX(спр_Материалы!$I$2:$I$9000,MATCH($I26,спр_Материалы!$A$2:$A$9000,0))*IF(INDEX(спр_Материалы!$J$2:$J$9000,MATCH($I26,спр_Материалы!$A$2:$A$9000,0))="USD",КурсUSD,IF(INDEX(спр_Материалы!$J$2:$J$9000,MATCH($I26,спр_Материалы!$A$2:$A$9000,0))="EUR",КурсEUR,1))*INDEX(спр_Материалы!$K$2:$K$9000,MATCH($I26,спр_Материалы!$A$2:$A$9000,0))*(1+IFERROR(INDEX(спр_Работы!$I$2:$I$6000,MATCH($C26,спр_Работы!$A$2:$A$6000,0))/100,0))*(1-ДисконтТендер),0)) | N26: =IF(AND($R26="да",$H26<>""),ROUND($H26*$L26,2),0) | O26: =IF(AND($R26="да",$H26<>""),ROUND($H26*$M26,2),0) | P26: =$N26+$O26 | Q26: =IFERROR(INDEX(спр_Работы!$J$2:$J$6000,MATCH($C26,спр_Работы!$A$2:$A$6000,0)),"") | R26: да | T26: =IF(AND($P26>0,$R26="да"),MAX($T$1:$T25)+1,"")
A27: =IFERROR(INDEX(спр_Работы!$D$2:$D$6000,MATCH($C27,спр_Работы!$A$2:$A$6000,0)),"") | B27: =IFERROR(INDEX(спр_Работы!$F$2:$F$6000,MATCH($C27,спр_Работы!$A$2:$A$6000,0)),"") | C27: =IFERROR(INDEX(спр_Работы!$A$2:$A$6000,26),"") | D27: =IFERROR(INDEX(спр_Работы!$B$2:$B$6000,MATCH($C27,спр_Работы!$A$2:$A$6000,0)),"") | E27: =IFERROR(INDEX(спр_Работы!$C$2:$C$6000,MATCH($C27,спр_Работы!$A$2:$A$6000,0)),"") | F27: =IFERROR(INDEX(спр_Работы!$G$2:$G$6000,MATCH($C27,спр_Работы!$A$2:$A$6000,0)),"") | G27: =IFERROR(INDEX(спр_Работы!$K$2:$K$6000,MATCH($C27,спр_Работы!$A$2:$A$6000,0)),"") | J27: =IFERROR(INDEX(спр_Материалы!$B$2:$B$9000,MATCH($I27,спр_Материалы!$A$2:$A$9000,0)),"") | K27: =IF($I27="","",IF($F27=IFERROR(INDEX(спр_Материалы!$G$2:$G$9000,MATCH($I27,спр_Материалы!$A$2:$A$9000,0)),""),"OK","!! не та группа")) | L27: =IFERROR(INDEX(спр_Работы!$H$2:$H$6000,MATCH($C27,спр_Работы!$A$2:$A$6000,0))*(1-ДисконтТендер),0) | M27: =IF($I27="",0,IFERROR(INDEX(спр_Материалы!$I$2:$I$9000,MATCH($I27,спр_Материалы!$A$2:$A$9000,0))*IF(INDEX(спр_Материалы!$J$2:$J$9000,MATCH($I27,спр_Материалы!$A$2:$A$9000,0))="USD",КурсUSD,IF(INDEX(спр_Материалы!$J$2:$J$9000,MATCH($I27,спр_Материалы!$A$2:$A$9000,0))="EUR",КурсEUR,1))*INDEX(спр_Материалы!$K$2:$K$9000,MATCH($I27,спр_Материалы!$A$2:$A$9000,0))*(1+IFERROR(INDEX(спр_Работы!$I$2:$I$6000,MATCH($C27,спр_Работы!$A$2:$A$6000,0))/100,0))*(1-ДисконтТендер),0)) | N27: =IF(AND($R27="да",$H27<>""),ROUND($H27*$L27,2),0) | O27: =IF(AND($R27="да",$H27<>""),ROUND($H27*$M27,2),0) | P27: =$N27+$O27 | Q27: =IFERROR(INDEX(спр_Работы!$J$2:$J$6000,MATCH($C27,спр_Работы!$A$2:$A$6000,0)),"") | R27: да | T27: =IF(AND($P27>0,$R27="да"),MAX($T$1:$T26)+1,"")
A28: =IFERROR(INDEX(спр_Работы!$D$2:$D$6000,MATCH($C28,спр_Работы!$A$2:$A$6000,0)),"") | B28: =IFERROR(INDEX(спр_Работы!$F$2:$F$6000,MATCH($C28,спр_Работы!$A$2:$A$6000,0)),"") | C28: =IFERROR(INDEX(спр_Работы!$A$2:$A$6000,27),"") | D28: =IFERROR(INDEX(спр_Работы!$B$2:$B$6000,MATCH($C28,спр_Работы!$A$2:$A$6000,0)),"") | E28: =IFERROR(INDEX(спр_Работы!$C$2:$C$6000,MATCH($C28,спр_Работы!$A$2:$A$6000,0)),"") | F28: =IFERROR(INDEX(спр_Работы!$G$2:$G$6000,MATCH($C28,спр_Работы!$A$2:$A$6000,0)),"") | G28: =IFERROR(INDEX(спр_Работы!$K$2:$K$6000,MATCH($C28,спр_Работы!$A$2:$A$6000,0)),"") | J28: =IFERROR(INDEX(спр_Материалы!$B$2:$B$9000,MATCH($I28,спр_Материалы!$A$2:$A$9000,0)),"") | K28: =IF($I28="","",IF($F28=IFERROR(INDEX(спр_Материалы!$G$2:$G$9000,MATCH($I28,спр_Материалы!$A$2:$A$9000,0)),""),"OK","!! не та группа")) | L28: =IFERROR(INDEX(спр_Работы!$H$2:$H$6000,MATCH($C28,спр_Работы!$A$2:$A$6000,0))*(1-ДисконтТендер),0) | M28: =IF($I28="",0,IFERROR(INDEX(спр_Материалы!$I$2:$I$9000,MATCH($I28,спр_Материалы!$A$2:$A$9000,0))*IF(INDEX(спр_Материалы!$J$2:$J$9000,MATCH($I28,спр_Материалы!$A$2:$A$9000,0))="USD",КурсUSD,IF(INDEX(спр_Материалы!$J$2:$J$9000,MATCH($I28,спр_Материалы!$A$2:$A$9000,0))="EUR",КурсEUR,1))*INDEX(спр_Материалы!$K$2:$K$9000,MATCH($I28,спр_Материалы!$A$2:$A$9000,0))*(1+IFERROR(INDEX(спр_Работы!$I$2:$I$6000,MATCH($C28,спр_Работы!$A$2:$A$6000,0))/100,0))*(1-ДисконтТендер),0)) | N28: =IF(AND($R28="да",$H28<>""),ROUND($H28*$L28,2),0) | O28: =IF(AND($R28="да",$H28<>""),ROUND($H28*$M28,2),0) | P28: =$N28+$O28 | Q28: =IFERROR(INDEX(спр_Работы!$J$2:$J$6000,MATCH($C28,спр_Работы!$A$2:$A$6000,0)),"") | R28: да | T28: =IF(AND($P28>0,$R28="да"),MAX($T$1:$T27)+1,"")
A29: =IFERROR(INDEX(спр_Работы!$D$2:$D$6000,MATCH($C29,спр_Работы!$A$2:$A$6000,0)),"") | B29: =IFERROR(INDEX(спр_Работы!$F$2:$F$6000,MATCH($C29,спр_Работы!$A$2:$A$6000,0)),"") | C29: =IFERROR(INDEX(спр_Работы!$A$2:$A$6000,28),"") | D29: =IFERROR(INDEX(спр_Работы!$B$2:$B$6000,MATCH($C29,спр_Работы!$A$2:$A$6000,0)),"") | E29: =IFERROR(INDEX(спр_Работы!$C$2:$C$6000,MATCH($C29,спр_Работы!$A$2:$A$6000,0)),"") | F29: =IFERROR(INDEX(спр_Работы!$G$2:$G$6000,MATCH($C29,спр_Работы!$A$2:$A$6000,0)),"") | G29: =IFERROR(INDEX(спр_Работы!$K$2:$K$6000,MATCH($C29,спр_Работы!$A$2:$A$6000,0)),"") | J29: =IFERROR(INDEX(спр_Материалы!$B$2:$B$9000,MATCH($I29,спр_Материалы!$A$2:$A$9000,0)),"") | K29: =IF($I29="","",IF($F29=IFERROR(INDEX(спр_Материалы!$G$2:$G$9000,MATCH($I29,спр_Материалы!$A$2:$A$9000,0)),""),"OK","!! не та группа")) | L29: =IFERROR(INDEX(спр_Работы!$H$2:$H$6000,MATCH($C29,спр_Работы!$A$2:$A$6000,0))*(1-ДисконтТендер),0) | M29: =IF($I29="",0,IFERROR(INDEX(спр_Материалы!$I$2:$I$9000,MATCH($I29,спр_Материалы!$A$2:$A$9000,0))*IF(INDEX(спр_Материалы!$J$2:$J$9000,MATCH($I29,спр_Материалы!$A$2:$A$9000,0))="USD",КурсUSD,IF(INDEX(спр_Материалы!$J$2:$J$9000,MATCH($I29,спр_Материалы!$A$2:$A$9000,0))="EUR",КурсEUR,1))*INDEX(спр_Материалы!$K$2:$K$9000,MATCH($I29,спр_Материалы!$A$2:$A$9000,0))*(1+IFERROR(INDEX(спр_Работы!$I$2:$I$6000,MATCH($C29,спр_Работы!$A$2:$A$6000,0))/100,0))*(1-ДисконтТендер),0)) | N29: =IF(AND($R29="да",$H29<>""),ROUND($H29*$L29,2),0) | O29: =IF(AND($R29="да",$H29<>""),ROUND($H29*$M29,2),0) | P29: =$N29+$O29 | Q29: =IFERROR(INDEX(спр_Работы!$J$2:$J$6000,MATCH($C29,спр_Работы!$A$2:$A$6000,0)),"") | R29: да | T29: =IF(AND($P29>0,$R29="да"),MAX($T$1:$T28)+1,"")
A30: =IFERROR(INDEX(спр_Работы!$D$2:$D$6000,MATCH($C30,спр_Работы!$A$2:$A$6000,0)),"") | B30: =IFERROR(INDEX(спр_Работы!$F$2:$F$6000,MATCH($C30,спр_Работы!$A$2:$A$6000,0)),"") | C30: =IFERROR(INDEX(спр_Работы!$A$2:$A$6000,29),"") | D30: =IFERROR(INDEX(спр_Работы!$B$2:$B$6000,MATCH($C30,спр_Работы!$A$2:$A$6000,0)),"") | E30: =IFERROR(INDEX(спр_Работы!$C$2:$C$6000,MATCH($C30,спр_Работы!$A$2:$A$6000,0)),"") | F30: =IFERROR(INDEX(спр_Работы!$G$2:$G$6000,MATCH($C30,спр_Работы!$A$2:$A$6000,0)),"") | G30: =IFERROR(INDEX(спр_Работы!$K$2:$K$6000,MATCH($C30,спр_Работы!$A$2:$A$6000,0)),"") | J30: =IFERROR(INDEX(спр_Материалы!$B$2:$B$9000,MATCH($I30,спр_Материалы!$A$2:$A$9000,0)),"") | K30: =IF($I30="","",IF($F30=IFERROR(INDEX(спр_Материалы!$G$2:$G$9000,MATCH($I30,спр_Материалы!$A$2:$A$9000,0)),""),"OK","!! не та группа")) | L30: =IFERROR(INDEX(спр_Работы!$H$2:$H$6000,MATCH($C30,спр_Работы!$A$2:$A$6000,0))*(1-ДисконтТендер),0) | M30: =IF($I30="",0,IFERROR(INDEX(спр_Материалы!$I$2:$I$9000,MATCH($I30,спр_Материалы!$A$2:$A$9000,0))*IF(INDEX(спр_Материалы!$J$2:$J$9000,MATCH($I30,спр_Материалы!$A$2:$A$9000,0))="USD",КурсUSD,IF(INDEX(спр_Материалы!$J$2:$J$9000,MATCH($I30,спр_Материалы!$A$2:$A$9000,0))="EUR",КурсEUR,1))*INDEX(спр_Материалы!$K$2:$K$9000,MATCH($I30,спр_Материалы!$A$2:$A$9000,0))*(1+IFERROR(INDEX(спр_Работы!$I$2:$I$6000,MATCH($C30,спр_Работы!$A$2:$A$6000,0))/100,0))*(1-ДисконтТендер),0)) | N30: =IF(AND($R30="да",$H30<>""),ROUND($H30*$L30,2),0) | O30: =IF(AND($R30="да",$H30<>""),ROUND($H30*$M30,2),0) | P30: =$N30+$O30 | Q30: =IFERROR(INDEX(спр_Работы!$J$2:$J$6000,MATCH($C30,спр_Работы!$A$2:$A$6000,0)),"") | R30: да | T30: =IF(AND($P30>0,$R30="да"),MAX($T$1:$T29)+1,"")
A31: =IFERROR(INDEX(спр_Работы!$D$2:$D$6000,MATCH($C31,спр_Работы!$A$2:$A$6000,0)),"") | B31: =IFERROR(INDEX(спр_Работы!$F$2:$F$6000,MATCH($C31,спр_Работы!$A$2:$A$6000,0)),"") | C31: =IFERROR(INDEX(спр_Работы!$A$2:$A$6000,30),"") | D31: =IFERROR(INDEX(спр_Работы!$B$2:$B$6000,MATCH($C31,спр_Работы!$A$2:$A$6000,0)),"") | E31: =IFERROR(INDEX(спр_Работы!$C$2:$C$6000,MATCH($C31,спр_Работы!$A$2:$A$6000,0)),"") | F31: =IFERROR(INDEX(спр_Работы!$G$2:$G$6000,MATCH($C31,спр_Работы!$A$2:$A$6000,0)),"") | G31: =IFERROR(INDEX(спр_Работы!$K$2:$K$6000,MATCH($C31,спр_Работы!$A$2:$A$6000,0)),"") | J31: =IFERROR(INDEX(спр_Материалы!$B$2:$B$9000,MATCH($I31,спр_Материалы!$A$2:$A$9000,0)),"") | K31: =IF($I31="","",IF($F31=IFERROR(INDEX(спр_Материалы!$G$2:$G$9000,MATCH($I31,спр_Материалы!$A$2:$A$9000,0)),""),"OK","!! не та группа")) | L31: =IFERROR(INDEX(спр_Работы!$H$2:$H$6000,MATCH($C31,спр_Работы!$A$2:$A$6000,0))*(1-ДисконтТендер),0) | M31: =IF($I31="",0,IFERROR(INDEX(спр_Материалы!$I$2:$I$9000,MATCH($I31,спр_Материалы!$A$2:$A$9000,0))*IF(INDEX(спр_Материалы!$J$2:$J$9000,MATCH($I31,спр_Материалы!$A$2:$A$9000,0))="USD",КурсUSD,IF(INDEX(спр_Материалы!$J$2:$J$9000,MATCH($I31,спр_Материалы!$A$2:$A$9000,0))="EUR",КурсEUR,1))*INDEX(спр_Материалы!$K$2:$K$9000,MATCH($I31,спр_Материалы!$A$2:$A$9000,0))*(1+IFERROR(INDEX(спр_Работы!$I$2:$I$6000,MATCH($C31,спр_Работы!$A$2:$A$6000,0))/100,0))*(1-ДисконтТендер),0)) | N31: =IF(AND($R31="да",$H31<>""),ROUND($H31*$L31,2),0) | O31: =IF(AND($R31="да",$H31<>""),ROUND($H31*$M31,2),0) | P31: =$N31+$O31 | Q31: =IFERROR(INDEX(спр_Работы!$J$2:$J$6000,MATCH($C31,спр_Работы!$A$2:$A$6000,0)),"") | R31: да | T31: =IF(AND($P31>0,$R31="да"),MAX($T$1:$T30)+1,"")
A32: =IFERROR(INDEX(спр_Работы!$D$2:$D$6000,MATCH($C32,спр_Работы!$A$2:$A$6000,0)),"") | B32: =IFERROR(INDEX(спр_Работы!$F$2:$F$6000,MATCH($C32,спр_Работы!$A$2:$A$6000,0)),"") | C32: =IFERROR(INDEX(спр_Работы!$A$2:$A$6000,31),"") | D32: =IFERROR(INDEX(спр_Работы!$B$2:$B$6000,MATCH($C32,спр_Работы!$A$2:$A$6000,0)),"") | E32: =IFERROR(INDEX(спр_Работы!$C$2:$C$6000,MATCH($C32,спр_Работы!$A$2:$A$6000,0)),"") | F32: =IFERROR(INDEX(спр_Работы!$G$2:$G$6000,MATCH($C32,спр_Работы!$A$2:$A$6000,0)),"") | G32: =IFERROR(INDEX(спр_Работы!$K$2:$K$6000,MATCH($C32,спр_Работы!$A$2:$A$6000,0)),"") | J32: =IFERROR(INDEX(спр_Материалы!$B$2:$B$9000,MATCH($I32,спр_Материалы!$A$2:$A$9000,0)),"") | K32: =IF($I32="","",IF($F32=IFERROR(INDEX(спр_Материалы!$G$2:$G$9000,MATCH($I32,спр_Материалы!$A$2:$A$9000,0)),""),"OK","!! не та группа")) | L32: =IFERROR(INDEX(спр_Работы!$H$2:$H$6000,MATCH($C32,спр_Работы!$A$2:$A$6000,0))*(1-ДисконтТендер),0) | M32: =IF($I32="",0,IFERROR(INDEX(спр_Материалы!$I$2:$I$9000,MATCH($I32,спр_Материалы!$A$2:$A$9000,0))*IF(INDEX(спр_Материалы!$J$2:$J$9000,MATCH($I32,спр_Материалы!$A$2:$A$9000,0))="USD",КурсUSD,IF(INDEX(спр_Материалы!$J$2:$J$9000,MATCH($I32,спр_Материалы!$A$2:$A$9000,0))="EUR",КурсEUR,1))*INDEX(спр_Материалы!$K$2:$K$9000,MATCH($I32,спр_Материалы!$A$2:$A$9000,0))*(1+IFERROR(INDEX(спр_Работы!$I$2:$I$6000,MATCH($C32,спр_Работы!$A$2:$A$6000,0))/100,0))*(1-ДисконтТендер),0)) | N32: =IF(AND($R32="да",$H32<>""),ROUND($H32*$L32,2),0) | O32: =IF(AND($R32="да",$H32<>""),ROUND($H32*$M32,2),0) | P32: =$N32+$O32 | Q32: =IFERROR(INDEX(спр_Работы!$J$2:$J$6000,MATCH($C32,спр_Работы!$A$2:$A$6000,0)),"") | R32: да | T32: =IF(AND($P32>0,$R32="да"),MAX($T$1:$T31)+1,"")
A33: =IFERROR(INDEX(спр_Работы!$D$2:$D$6000,MATCH($C33,спр_Работы!$A$2:$A$6000,0)),"") | B33: =IFERROR(INDEX(спр_Работы!$F$2:$F$6000,MATCH($C33,спр_Работы!$A$2:$A$6000,0)),"") | C33: =IFERROR(INDEX(спр_Работы!$A$2:$A$6000,32),"") | D33: =IFERROR(INDEX(спр_Работы!$B$2:$B$6000,MATCH($C33,спр_Работы!$A$2:$A$6000,0)),"") | E33: =IFERROR(INDEX(спр_Работы!$C$2:$C$6000,MATCH($C33,спр_Работы!$A$2:$A$6000,0)),"") | F33: =IFERROR(INDEX(спр_Работы!$G$2:$G$6000,MATCH($C33,спр_Работы!$A$2:$A$6000,0)),"") | G33: =IFERROR(INDEX(спр_Работы!$K$2:$K$6000,MATCH($C33,спр_Работы!$A$2:$A$6000,0)),"") | J33: =IFERROR(INDEX(спр_Материалы!$B$2:$B$9000,MATCH($I33,спр_Материалы!$A$2:$A$9000,0)),"") | K33: =IF($I33="","",IF($F33=IFERROR(INDEX(спр_Материалы!$G$2:$G$9000,MATCH($I33,спр_Материалы!$A$2:$A$9000,0)),""),"OK","!! не та группа")) | L33: =IFERROR(INDEX(спр_Работы!$H$2:$H$6000,MATCH($C33,спр_Работы!$A$2:$A$6000,0))*(1-ДисконтТендер),0) | M33: =IF($I33="",0,IFERROR(INDEX(спр_Материалы!$I$2:$I$9000,MATCH($I33,спр_Материалы!$A$2:$A$9000,0))*IF(INDEX(спр_Материалы!$J$2:$J$9000,MATCH($I33,спр_Материалы!$A$2:$A$9000,0))="USD",КурсUSD,IF(INDEX(спр_Материалы!$J$2:$J$9000,MATCH($I33,спр_Материалы!$A$2:$A$9000,0))="EUR",КурсEUR,1))*INDEX(спр_Материалы!$K$2:$K$9000,MATCH($I33,спр_Материалы!$A$2:$A$9000,0))*(1+IFERROR(INDEX(спр_Работы!$I$2:$I$6000,MATCH($C33,спр_Работы!$A$2:$A$6000,0))/100,0))*(1-ДисконтТендер),0)) | N33: =IF(AND($R33="да",$H33<>""),ROUND($H33*$L33,2),0) | O33: =IF(AND($R33="да",$H33<>""),ROUND($H33*$M33,2),0) | P33: =$N33+$O33 | Q33: =IFERROR(INDEX(спр_Работы!$J$2:$J$6000,MATCH($C33,спр_Работы!$A$2:$A$6000,0)),"") | R33: да | T33: =IF(AND($P33>0,$R33="да"),MAX($T$1:$T32)+1,"")
A34: =IFERROR(INDEX(спр_Работы!$D$2:$D$6000,MATCH($C34,спр_Работы!$A$2:$A$6000,0)),"") | B34: =IFERROR(INDEX(спр_Работы!$F$2:$F$6000,MATCH($C34,спр_Работы!$A$2:$A$6000,0)),"") | C34: =IFERROR(INDEX(спр_Работы!$A$2:$A$6000,33),"") | D34: =IFERROR(INDEX(спр_Работы!$B$2:$B$6000,MATCH($C34,спр_Работы!$A$2:$A$6000,0)),"") | E34: =IFERROR(INDEX(спр_Работы!$C$2:$C$6000,MATCH($C34,спр_Работы!$A$2:$A$6000,0)),"") | F34: =IFERROR(INDEX(спр_Работы!$G$2:$G$6000,MATCH($C34,спр_Работы!$A$2:$A$6000,0)),"") | G34: =IFERROR(INDEX(спр_Работы!$K$2:$K$6000,MATCH($C34,спр_Работы!$A$2:$A$6000,0)),"") | J34: =IFERROR(INDEX(спр_Материалы!$B$2:$B$9000,MATCH($I34,спр_Материалы!$A$2:$A$9000,0)),"") | K34: =IF($I34="","",IF($F34=IFERROR(INDEX(спр_Материалы!$G$2:$G$9000,MATCH($I34,спр_Материалы!$A$2:$A$9000,0)),""),"OK","!! не та группа")) | L34: =IFERROR(INDEX(спр_Работы!$H$2:$H$6000,MATCH($C34,спр_Работы!$A$2:$A$6000,0))*(1-ДисконтТендер),0) | M34: =IF($I34="",0,IFERROR(INDEX(спр_Материалы!$I$2:$I$9000,MATCH($I34,спр_Материалы!$A$2:$A$9000,0))*IF(INDEX(спр_Материалы!$J$2:$J$9000,MATCH($I34,спр_Материалы!$A$2:$A$9000,0))="USD",КурсUSD,IF(INDEX(спр_Материалы!$J$2:$J$9000,MATCH($I34,спр_Материалы!$A$2:$A$9000,0))="EUR",КурсEUR,1))*INDEX(спр_Материалы!$K$2:$K$9000,MATCH($I34,спр_Материалы!$A$2:$A$9000,0))*(1+IFERROR(INDEX(спр_Работы!$I$2:$I$6000,MATCH($C34,спр_Работы!$A$2:$A$6000,0))/100,0))*(1-ДисконтТендер),0)) | N34: =IF(AND($R34="да",$H34<>""),ROUND($H34*$L34,2),0) | O34: =IF(AND($R34="да",$H34<>""),ROUND($H34*$M34,2),0) | P34: =$N34+$O34 | Q34: =IFERROR(INDEX(спр_Работы!$J$2:$J$6000,MATCH($C34,спр_Работы!$A$2:$A$6000,0)),"") | R34: да | T34: =IF(AND($P34>0,$R34="да"),MAX($T$1:$T33)+1,"")
