Workbook
Name ДисконтТендер: Смета!$C$18
Name КурсCNY: Смета!$C$17
Name КурсEUR: Смета!$C$16
Name КурсUSD: Смета!$C$15
Name мат_VRF_ВНУТ: МАТЕРИАЛЫ!$L$2:$L$259
Name мат_VRF_НАР: МАТЕРИАЛЫ!$L$260:$L$360
Name мат_БРОНЯ: МАТЕРИАЛЫ!$L$361:$L$382
Name мат_ДВ: МАТЕРИАЛЫ!$L$383:$L$393
Name мат_ДВ_АЛ: МАТЕРИАЛЫ!$L$394:$L$399
Name мат_ДВ_ДЕР: МАТЕРИАЛЫ!$L$400:$L$405
Name мат_ДВ_СТ: МАТЕРИАЛЫ!$L$406:$L$410
Name мат_ДОК_ИД: Документация!$F$38:$F$57
Name мат_ДОК_РД: Документация!$F$2:$F$37
Name мат_ЗАВЕСА: МАТЕРИАЛЫ!$L$411:$L$414
Name мат_ЛЮЧОК: МАТЕРИАЛЫ!$L$415:$L$415
Name мат_ПВУ: МАТЕРИАЛЫ!$L$416:$L$431
Name мат_ПЕРЕГ_СТ: МАТЕРИАЛЫ!$L$432:$L$432
Name мат_ПЕРЕГ_ТР: МАТЕРИАЛЫ!$L$433:$L$442
Name мат_ПОЛ_КГ: МАТЕРИАЛЫ!$L$443:$L$450
Name мат_ПОЛ_МОД: МАТЕРИАЛЫ!$L$451:$L$455
Name мат_ПОТОЛОК: МАТЕРИАЛЫ!$L$456:$L$460
Name мат_РАД: МАТЕРИАЛЫ!$L$461:$L$597
Name мат_РАД_КОМПЛ: МАТЕРИАЛЫ!$L$598:$L$612
Name мат_СВЕТ: МАТЕРИАЛЫ!$L$613:$L$925
Name мат_СВЕТ_АВАР: МАТЕРИАЛЫ!$L$926:$L$1035
Name мат_СПЛИТ: МАТЕРИАЛЫ!$L$1036:$L$1151
Name мат_СТЕН_ПЛ: МАТЕРИАЛЫ!$L$1152:$L$1154
Name мат_СТП_РАК: МАТЕРИАЛЫ!$L$1155:$L$1167
Name мат_СТП_СМЕС: МАТЕРИАЛЫ!$L$1168:$L$1180
Name мат_СТП_УНИТ: МАТЕРИАЛЫ!$L$1181:$L$1188
Name мат_ФАЛЬШПОЛ: МАТЕРИАЛЫ!$L$1189:$L$1197
Name мат_ЭУИ_ВЫКЛ: МАТЕРИАЛЫ!$L$1198:$L$1199
Name мат_ЭУИ_РОЗ: МАТЕРИАЛЫ!$L$1200:$L$1208
Name мат_ЭЩ: МАТЕРИАЛЫ!$L$1209:$L$1219
Name спрРазделы: Разделы!$A$2:$B$13

Sheet О файле
A1: ТС ЕР — раздельно. Справочник расценок + сборка смет (Excel 2019+)
A3: КАК РАБОТАТЬ
A4: Этот файл — МАСТЕР (справочник). Смету на объект делай в КОПИИ:
A5: 1. Файл → Сохранить как → «Смета <объект> <дата>.xlsx».
A6: 2. Лист РАБОТЫ. По нужным работам поставь «в смету» = да, впиши «Объём».
A7: Если работа с материалом — выбери «Материал» из списка (список = материалы группы работы).
A8: Нет списка или своего материала — впиши «Цена мат (ручн.), ₽».
A9: Строки «Рабочая/Исполнительная документация» (раздел 1): в «Материал» выбери раздел проекта —
A10: цена подставится с листа «Документация». Для нескольких разделов — вставь копию строки.
A11: Розовая ячейка объёма = работа отмечена, а объём не введён.
A12: 3. Лист «Смета» — печатная форма. Данные → «Применить повторно» (Ctrl+Alt+L): останутся
A13: только отмеченные строки, по разделам, с итогом. Заполни шапку объекта.
... A25: Сформировано: 2026-09-01. Работ: 857. Материалов: 1218. Вариантов документации: 56. Запас строк РАБОТЫ: 1057.

Sheet РАБОТЫ
A1: Код | B1: Раздел | C1: Подраздел | D1: Наименование работы | E1: Ед | F1: Цена работы, ₽ | G1: Группа мат. | H1: Вспом. мат., % | I1: Источник | J1: Дата изм. цены | K1: Кто изменил | L1: в смету | M1: Объём | N1: Материал | O1: Цена мат (ручн.), ₽ | P1: Стоим. работ, ₽ | Q1: Стоим. мат, ₽ | R1: Всего, ₽ | S1: _цр | T1: _цм | U1: _ранг | V1: _рзд | W1: _перв | X1: _строка | Y1: _имя | Z1: _разд_имя
A2: РАБ.Р1.1.001 | B2: Р1 | C2: 1 | D2: Техническое обследование состояния несущих конструкций помещения с подготовкой рекомендаций по усилению (Техничесекое заключение о конструктиве - "ТЗК") (для помещений от 100 до 45… | E2: м2 | F2: 3675 | H2: 0 | I2: ТС ЕР | P2: =IF($L2="да",ROUND(N($M2)*$S2,2),"") | Q2: =IF($L2="да",ROUND(N($M2)*$T2,2),"") | R2: =IF($L2="да",N($P2)+N($Q2),"") | S2: =IF($A2="","",IF(AND(LEFT($G2,3)="ДОК",$N2<>""),IFERROR(INDEX(Документация!$E$2:$E$57,MATCH($N2,Документация!$F$2:$F$57,0)),0),N($F2))*(1-MEDIAN(0,N(ДисконтТендер),1))) -> 3675 | T2: =IF($A2="","",IF(AND(LEFT($G2,3)="ДОК",$N2<>""),0,IF(AND(LEFT($G2,3)<>"ДОК",$N2<>""),IFERROR(INDEX(МАТЕРИАЛЫ!$H$2:$H$9000,MATCH($N2,МАТЕРИАЛЫ!$L$2:$L$9000,0))*IF(INDEX(МАТЕРИАЛЫ!$I$2:$I$9000,MATCH($N2,МАТЕРИАЛЫ!$L$2:$L$9000,0))="USD",КурсUSD,IF(INDEX(МАТЕРИАЛЫ!$I$2:$I$9000,MATCH($N2,МАТЕРИАЛЫ!$L$2:$L$9000,0))="EUR",КурсEUR,IF(INDEX(МАТЕРИАЛЫ!$I$2:$I$9000,MATCH($N2,МАТЕРИАЛЫ!$L$2:$L$9000,0))="CNY",КурсCNY,1)))*(1+N($H2)/100),0),N($O2))*(1-MEDIAN(0,N(ДисконтТендер),1)))) -> 0 | U2: =IF($L2="да",MAX($U$1:$U1)+1,"") | V2: =IF($A2="","",$B2) -> Р1 | W2: =IF($U2="","",IF($U2=1,1,IF($V2<>IFERROR(INDEX($V$2:$V$1058,MATCH($U2-1,$U$2:$U$1058,0)),"~"),1,0))) | X2: =IF($U2="","",$U2+SUMIFS($W$2:$W$1058,$U$2:$U$1058,"<="&$U2)) | Y2: =IF($A2="","",IF(AND(LEFT($G2,3)="ДОК",$N2<>""),IFERROR(INDEX(Документация!$G$2:$G$57,MATCH($N2,Документация!$F$2:$F$57,0)),$D2),$D2&IF(AND(LEFT($G2,3)<>"ДОК",$N2<>"")," — "&IFERROR(INDEX(МАТЕРИАЛЫ!$C$2:$C$9000,MATCH($N2,МАТЕРИАЛЫ!$L$2:$L$9000,0)),""),""))) -> Техническое обследование состояния несущих конструкций помещения с подготовкой рекомендаций по усилению (Техничесекое заключение о конструктиве - "ТЗК") (для помещений от 100 до 45… | Z2: =IF($B2="","",$B2&" · "&IFERROR(VLOOKUP($B2,спрРазделы,2,0),"")) -> Р1 · Проектные работы и согласования
A3: РАБ.Р1.1.002 | B3: Р1 | C3: 1 | D3: Эскизный проект фасада и Колористический паспорт с указанием ведомости отделки и проектным решением со спецификацией элементов (крыльцо, пандус, навесы, колонны и т.д.)(для фасадов… | E3: м2 | F3: 7822.5 | H3: 0 | I3: ТС ЕР | P3: =IF($L3="да",ROUND(N($M3)*$S3,2),"") | Q3: =IF($L3="да",ROUND(N($M3)*$T3,2),"") | R3: =IF($L3="да",N($P3)+N($Q3),"") | S3: =IF($A3="","",IF(AND(LEFT($G3,3)="ДОК",$N3<>""),IFERROR(INDEX(Документация!$E$2:$E$57,MATCH($N3,Документация!$F$2:$F$57,0)),0),N($F3))*(1-MEDIAN(0,N(ДисконтТендер),1))) -> 7822.5 | T3: =IF($A3="","",IF(AND(LEFT($G3,3)="ДОК",$N3<>""),0,IF(AND(LEFT($G3,3)<>"ДОК",$N3<>""),IFERROR(INDEX(МАТЕРИАЛЫ!$H$2:$H$9000,MATCH($N3,МАТЕРИАЛЫ!$L$2:$L$9000,0))*IF(INDEX(МАТЕРИАЛЫ!$I$2:$I$9000,MATCH($N3,МАТЕРИАЛЫ!$L$2:$L$9000,0))="USD",КурсUSD,IF(INDEX(МАТЕРИАЛЫ!$I$2:$I$9000,MATCH($N3,МАТЕРИАЛЫ!$L$2:$L$9000,0))="EUR",КурсEUR,IF(INDEX(МАТЕРИАЛЫ!$I$2:$I$9000,MATCH($N3,МАТЕРИАЛЫ!$L$2:$L$9000,0))="CNY",КурсCNY,1)))*(1+N($H3)/100),0),N($O3))*(1-MEDIAN(0,N(ДисконтТендер),1)))) -> 0 | U3: =IF($L3="да",MAX($U$1:$U2)+1,"") | V3: =IF($A3="","",$B3) -> Р1 | W3: =IF($U3="","",IF($U3=1,1,IF($V3<>IFERROR(INDEX($V$2:$V$1058,MATCH($U3-1,$U$2:$U$1058,0)),"~"),1,0))) | X3: =IF($U3="","",$U3+SUMIFS($W$2:$W$1058,$U$2:$U$1058,"<="&$U3)) | Y3: =IF($A3="","",IF(AND(LEFT($G3,3)="ДОК",$N3<>""),IFERROR(INDEX(Документация!$G$2:$G$57,MATCH($N3,Документация!$F$2:$F$57,0)),$D3),$D3&IF(AND(LEFT($G3,3)<>"ДОК",$N3<>"")," — "&IFERROR(INDEX(МАТЕРИАЛЫ!$C$2:$C$9000,MATCH($N3,МАТЕРИАЛЫ!$L$2:$L$9000,0)),""),""))) -> Эскизный проект фасада и Колористический паспорт с указанием ведомости отделки и проектным решением со спецификацией элементов (крыльцо, пандус, навесы, колонны и т.д.)(для фасадов… | Z3: =IF($B3="","",$B3&" · "&IFERROR(VLOOKUP($B3,спрРазделы,2,0),"")) -> Р1 · Проектные работы и согласования
A4: РАБ.Р1.1.901 | B4: Р1 | C4: 1 | D4: Рабочая документация (раздел проекта — выбрать) | E4: =IF($N4="","—",IFERROR(INDEX(Документация!$D$2:$D$57,MATCH($N4,Документация!$F$2:$F$57,0)),"—")) -> — | F4: 0 | G4: ДОК.РД | H4: 0 | I4: ТС ЕР | P4: =IF($L4="да",ROUND(N($M4)*$S4,2),"") | Q4: =IF($L4="да",ROUND(N($M4)*$T4,2),"") | R4: =IF($L4="да",N($P4)+N($Q4),"") | S4: =IF($A4="","",IF(AND(LEFT($G4,3)="ДОК",$N4<>""),IFERROR(INDEX(Документация!$E$2:$E$57,MATCH($N4,Документация!$F$2:$F$57,0)),0),N($F4))*(1-MEDIAN(0,N(ДисконтТендер),1))) -> 0 | T4: =IF($A4="","",IF(AND(LEFT($G4,3)="ДОК",$N4<>""),0,IF(AND(LEFT($G4,3)<>"ДОК",$N4<>""),IFERROR(INDEX(МАТЕРИАЛЫ!$H$2:$H$9000,MATCH($N4,МАТЕРИАЛЫ!$L$2:$L$9000,0))*IF(INDEX(МАТЕРИАЛЫ!$I$2:$I$9000,MATCH($N4,МАТЕРИАЛЫ!$L$2:$L$9000,0))="USD",КурсUSD,IF(INDEX(МАТЕРИАЛЫ!$I$2:$I$9000,MATCH($N4,МАТЕРИАЛЫ!$L$2:$L$9000,0))="EUR",КурсEUR,IF(INDEX(МАТЕРИАЛЫ!$I$2:$I$9000,MATCH($N4,МАТЕРИАЛЫ!$L$2:$L$9000,0))="CNY",КурсCNY,1)))*(1+N($H4)/100),0),N($O4))*(1-MEDIAN(0,N(ДисконтТендер),1)))) -> 0 | U4: =IF($L4="да",MAX($U$1:$U3)+1,"") | V4: =IF($A4="","",$B4) -> Р1 | W4: =IF($U4="","",IF($U4=1,1,IF($V4<>IFERROR(INDEX($V$2:$V$1058,MATCH($U4-1,$U$2:$U$1058,0)),"~"),1,0))) | X4: =IF($U4="","",$U4+SUMIFS($W$2:$W$1058,$U$2:$U$1058,"<="&$U4)) | Y4: =IF($A4="","",IF(AND(LEFT($G4,3)="ДОК",$N4<>""),IFERROR(INDEX(Документация!$G$2:$G$57,MATCH($N4,Документация!$F$2:$F$57,0)),$D4),$D4&IF(AND(LEFT($G4,3)<>"ДОК",$N4<>"")," — "&IFERROR(INDEX(МАТЕРИАЛЫ!$C$2:$C$9000,MATCH($N4,МАТЕРИАЛЫ!$L$2:$L$9000,0)),""),""))) -> Рабочая документация (раздел проекта — выбрать) | Z4: =IF($B4="","",$B4&" · "&IFERROR(VLOOKUP($B4,спрРазделы,2,0),"")) -> Р1 · Проектные работы и согласования
A5: РАБ.Р1.1.961 | B5: Р1 | C5: 1 | D5: Исполнительная документация (раздел проекта — выбрать) | E5: =IF($N5="","—",IFERROR(INDEX(Документация!$D$2:$D$57,MATCH($N5,Документация!$F$2:$F$57,0)),"—")) -> — | F5: 0 | G5: ДОК.ИД | H5: 0 | I5: ТС ЕР | P5: =IF($L5="да",ROUND(N($M5)*$S5,2),"") | Q5: =IF($L5="да",ROUND(N($M5)*$T5,2),"") | R5: =IF($L5="да",N($P5)+N($Q5),"") | S5: =IF($A5="","",IF(AND(LEFT($G5,3)="ДОК",$N5<>""),IFERROR(INDEX(Документация!$E$2:$E$57,MATCH($N5,Документация!$F$2:$F$57,0)),0),N($F5))*(1-MEDIAN(0,N(ДисконтТендер),1))) -> 0 | T5: =IF($A5="","",IF(AND(LEFT($G5,3)="ДОК",$N5<>""),0,IF(AND(LEFT($G5,3)<>"ДОК",$N5<>""),IFERROR(INDEX(МАТЕРИАЛЫ!$H$2:$H$9000,MATCH($N5,МАТЕРИАЛЫ!$L$2:$L$9000,0))*IF(INDEX(МАТЕРИАЛЫ!$I$2:$I$9000,MATCH($N5,МАТЕРИАЛЫ!$L$2:$L$9000,0))="USD",КурсUSD,IF(INDEX(МАТЕРИАЛЫ!$I$2:$I$9000,MATCH($N5,МАТЕРИАЛЫ!$L$2:$L$9000,0))="EUR",КурсEUR,IF(INDEX(МАТЕРИАЛЫ!$I$2:$I$9000,MATCH($N5,МАТЕРИАЛЫ!$L$2:$L$9000,0))="CNY",КурсCNY,1)))*(1+N($H5)/100),0),N($O5))*(1-MEDIAN(0,N(ДисконтТендер),1)))) -> 0 | U5: =IF($L5="да",MAX($U$1:$U4)+1,"") | V5: =IF($A5="","",$B5) -> Р1 | W5: =IF($U5="","",IF($U5=1,1,IF($V5<>IFERROR(INDEX($V$2:$V$1058,MATCH($U5-1,$U$2:$U$1058,0)),"~"),1,0))) | X5: =IF($U5="","",$U5+SUMIFS($W$2:$W$1058,$U$2:$U$1058,"<="&$U5)) | Y5: =IF($A5="","",IF(AND(LEFT($G5,3)="ДОК",$N5<>""),IFERROR(INDEX(Документация!$G$2:$G$57,MATCH($N5,Документация!$F$2:$F$57,0)),$D5),$D5&IF(AND(LEFT($G5,3)<>"ДОК",$N5<>"")," — "&IFERROR(INDEX(МАТЕРИАЛЫ!$C$2:$C$9000,MATCH($N5,МАТЕРИАЛЫ!$L$2:$L$9000,0)),""),""))) -> Исполнительная документация (раздел проекта — выбрать) | Z5: =IF($B5="","",$B5&" · "&IFERROR(VLOOKUP($B5,спрРазделы,2,0),"")) -> Р1 · Проектные работы и согласования
A6: РАБ.Р1.1.021 | B6: Р1 | C6: 1 | D6: Техническое обследование состояния несущих конструкций помещения с подготовкой рекомендаций по усилению в зоне расположения депозитария, кассового узла и банкоматов (Техничесекое з… | E6: м2 | F6: 3675 | H6: 0 | I6: ТС ЕР | P6: =IF($L6="да",ROUND(N($M6)*$S6,2),"") | Q6: =IF($L6="да",ROUND(N($M6)*$T6,2),"") | R6: =IF($L6="да",N($P6)+N($Q6),"") | S6: =IF($A6="","",IF(AND(LEFT($G6,3)="ДОК",$N6<>""),IFERROR(INDEX(Документация!$E$2:$E$57,MATCH($N6,Документация!$F$2:$F$57,0)),0),N($F6))*(1-MEDIAN(0,N(ДисконтТендер),1))) -> 3675 | T6: =IF($A6="","",IF(AND(LEFT($G6,3)="ДОК",$N6<>""),0,IF(AND(LEFT($G6,3)<>"ДОК",$N6<>""),IFERROR(INDEX(МАТЕРИАЛЫ!$H$2:$H$9000,MATCH($N6,МАТЕРИАЛЫ!$L$2:$L$9000,0))*IF(INDEX(МАТЕРИАЛЫ!$I$2:$I$9000,MATCH($N6,МАТЕРИАЛЫ!$L$2:$L$9000,0))="USD",КурсUSD,IF(INDEX(МАТЕРИАЛЫ!$I$2:$I$9000,MATCH($N6,МАТЕРИАЛЫ!$L$2:$L$9000,0))="EUR",КурсEUR,IF(INDEX(МАТЕРИАЛЫ!$I$2:$I$9000,MATCH($N6,МАТЕРИАЛЫ!$L$2:$L$9000,0))="CNY",КурсCNY,1)))*(1+N($H6)/100),0),N($O6))*(1-MEDIAN(0,N(ДисконтТендер),1)))) -> 0 | U6: =IF($L6="да",MAX($U$1:$U5)+1,"") | V6: =IF($A6="","",$B6) -> Р1 | W6: =IF($U6="","",IF($U6=1,1,IF($V6<>IFERROR(INDEX($V$2:$V$1058,MATCH($U6-1,$U$2:$U$1058,0)),"~"),1,0))) | X6: =IF($U6="","",$U6+SUMIFS($W$2:$W$1058,$U$2:$U$1058,"<="&$U6)) | Y6: =IF($A6="","",IF(AND(LEFT($G6,3)="ДОК",$N6<>""),IFERROR(INDEX(Документация!$G$2:$G$57,MATCH($N6,Документация!$F$2:$F$57,0)),$D6),$D6&IF(AND(LEFT($G6,3)<>"ДОК",$N6<>"")," — "&IFERROR(INDEX(МАТЕРИАЛЫ!$C$2:$C$9000,MATCH($N6,МАТЕРИАЛЫ!$L$2:$L$9000,0)),""),""))) -> Техническое обследование состояния несущих конструкций помещения с подготовкой рекомендаций по усилению в зоне расположения депозитария, кассового узла и банкоматов (Техничесекое з… | Z6: =IF($B6="","",$B6&" · "&IFERROR(VLOOKUP($B6,спрРазделы,2,0),"")) -> Р1 · Проектные работы и согласования
A7: РАБ.Р1.1.022 | B7: Р1 | C7: 1 | D7: Эскизный проект фасада и колористический паспорт с указанием ведомости отделки и проектным решением со спецификацией элементов (крыльцо, пандус, навесы, колонны и т.д.)(для фасадов… | E7: кв.м.площади фасада | F7: 7822.5 | H7: 0 | I7: ТС ЕР | P7: =IF($L7="да",ROUND(N($M7)*$S7,2),"") | Q7: =IF($L7="да",ROUND(N($M7)*$T7,2),"") | R7: =IF($L7="да",N($P7)+N($Q7),"") | S7: =IF($A7="","",IF(AND(LEFT($G7,3)="ДОК",$N7<>""),IFERROR(INDEX(Документация!$E$2:$E$57,MATCH($N7,Документация!$F$2:$F$57,0)),0),N($F7))*(1-MEDIAN(0,N(ДисконтТендер),1))) -> 7822.5 | T7: =IF($A7="","",IF(AND(LEFT($G7,3)="ДОК",$N7<>""),0,IF(AND(LEFT($G7,3)<>"ДОК",$N7<>""),IFERROR(INDEX(МАТЕРИАЛЫ!$H$2:$H$9000,MATCH($N7,МАТЕРИАЛЫ!$L$2:$L$9000,0))*IF(INDEX(МАТЕРИАЛЫ!$I$2:$I$9000,MATCH($N7,МАТЕРИАЛЫ!$L$2:$L$9000,0))="USD",КурсUSD,IF(INDEX(МАТЕРИАЛЫ!$I$2:$I$9000,MATCH($N7,МАТЕРИАЛЫ!$L$2:$L$9000,0))="EUR",КурсEUR,IF(INDEX(МАТЕРИАЛЫ!$I$2:$I$9000,MATCH($N7,МАТЕРИАЛЫ!$L$2:$L$9000,0))="CNY",КурсCNY,1)))*(1+N($H7)/100),0),N($O7))*(1-MEDIAN(0,N(ДисконтТендер),1)))) -> 0 | U7: =IF($L7="да",MAX($U$1:$U6)+1,"") | V7: =IF($A7="","",$B7) -> Р1 | W7: =IF($U7="","",IF($U7=1,1,IF($V7<>IFERROR(INDEX($V$2:$V$1058,MATCH($U7-1,$U$2:$U$1058,0)),"~"),1,0))) | X7: =IF($U7="","",$U7+SUMIFS($W$2:$W$1058,$U$2:$U$1058,"<="&$U7)) | Y7: =IF($A7="","",IF(AND(LEFT($G7,3)="ДОК",$N7<>""),IFERROR(INDEX(Документация!$G$2:$G$57,MATCH($N7,Документация!$F$2:$F$57,0)),$D7),$D7&IF(AND(LEFT($G7,3)<>"ДОК",$N7<>"")," — "&IFERROR(INDEX(МАТЕРИАЛЫ!$C$2:$C$9000,MATCH($N7,МАТЕРИАЛЫ!$L$2:$L$9000,0)),""),""))) -> Эскизный проект фасада и колористический паспорт с указанием ведомости отделки и проектным решением со спецификацией элементов (крыльцо, пандус, навесы, колонны и т.д.)(для фасадов… | Z7: =IF($B7="","",$B7&" · "&IFERROR(VLOOKUP($B7,спрРазделы,2,0),"")) -> Р1 · Проектные работы и согласования
A8: РАБ.Р1.1.061 | B8: Р1 | C8: 1 | D8: Стоимость согласования проекта перепланировки/реставрации объекта культурного наследия в соответствии с нормативными актами г.______________. | E8: м2 | F8: 0 | H8: 0 | I8: ТС ЕР | P8: =IF($L8="да",ROUND(N($M8)*$S8,2),"") | Q8: =IF($L8="да",ROUND(N($M8)*$T8,2),"") | R8: =IF($L8="да",N($P8)+N($Q8),"") | S8: =IF($A8="","",IF(AND(LEFT($G8,3)="ДОК",$N8<>""),IFERROR(INDEX(Документация!$E$2:$E$57,MATCH($N8,Документация!$F$2:$F$57,0)),0),N($F8))*(1-MEDIAN(0,N(ДисконтТендер),1))) -> 0 | T8: =IF($A8="","",IF(AND(LEFT($G8,3)="ДОК",$N8<>""),0,IF(AND(LEFT($G8,3)<>"ДОК",$N8<>""),IFERROR(INDEX(МАТЕРИАЛЫ!$H$2:$H$9000,MATCH($N8,МАТЕРИАЛЫ!$L$2:$L$9000,0))*IF(INDEX(МАТЕРИАЛЫ!$I$2:$I$9000,MATCH($N8,МАТЕРИАЛЫ!$L$2:$L$9000,0))="USD",КурсUSD,IF(INDEX(МАТЕРИАЛЫ!$I$2:$I$9000,MATCH($N8,МАТЕРИАЛЫ!$L$2:$L$9000,0))="EUR",КурсEUR,IF(INDEX(МАТЕРИАЛЫ!$I$2:$I$9000,MATCH($N8,МАТЕРИАЛЫ!$L$2:$L$9000,0))="CNY",КурсCNY,1)))*(1+N($H8)/100),0),N($O8))*(1-MEDIAN(0,N(ДисконтТендер),1)))) -> 0 | U8: =IF($L8="да",MAX($U$1:$U7)+1,"") | V8: =IF($A8="","",$B8) -> Р1 | W8: =IF($U8="","",IF($U8=1,1,IF($V8<>IFERROR(INDEX($V$2:$V$1058,MATCH($U8-1,$U$2:$U$1058,0)),"~"),1,0))) | X8: =IF($U8="","",$U8+SUMIFS($W$2:$W$1058,$U$2:$U$1058,"<="&$U8)) | Y8: =IF($A8="","",IF(AND(LEFT($G8,3)="ДОК",$N8<>""),IFERROR(INDEX(Документация!$G$2:$G$57,MATCH($N8,Документация!$F$2:$F$57,0)),$D8),$D8&IF(AND(LEFT($G8,3)<>"ДОК",$N8<>"")," — "&IFERROR(INDEX(МАТЕРИАЛЫ!$C$2:$C$9000,MATCH($N8,МАТЕРИАЛЫ!$L$2:$L$9000,0)),""),""))) -> Стоимость согласования проекта перепланировки/реставрации объекта культурного наследия в соответствии с нормативными актами г.______________. | Z8: =IF($B8="","",$B8&" · "&IFERROR(VLOOKUP($B8,спрРазделы,2,0),"")) -> Р1 · Проектные работы и согласования
A9: РАБ.Р1.1.062 | B9: Р1 | C9: 1 | D9: Стоимость согласования проекта перепланировки/реконструкции объекта в соответствии с нормативными актами г.______________. | E9: м2 | F9: 0 | H9: 0 | I9: ТС ЕР | P9: =IF($L9="да",ROUND(N($M9)*$S9,2),"") | Q9: =IF($L9="да",ROUND(N($M9)*$T9,2),"") | R9: =IF($L9="да",N($P9)+N($Q9),"") | S9: =IF($A9="","",IF(AND(LEFT($G9,3)="ДОК",$N9<>""),IFERROR(INDEX(Документация!$E$2:$E$57,MATCH($N9,Документация!$F$2:$F$57,0)),0),N($F9))*(1-MEDIAN(0,N(ДисконтТендер),1))) -> 0 | T9: =IF($A9="","",IF(AND(LEFT($G9,3)="ДОК",$N9<>""),0,IF(AND(LEFT($G9,3)<>"ДОК",$N9<>""),IFERROR(INDEX(МАТЕРИАЛЫ!$H$2:$H$9000,MATCH($N9,МАТЕРИАЛЫ!$L$2:$L$9000,0))*IF(INDEX(МАТЕРИАЛЫ!$I$2:$I$9000,MATCH($N9,МАТЕРИАЛЫ!$L$2:$L$9000,0))="USD",КурсUSD,IF(INDEX(МАТЕРИАЛЫ!$I$2:$I$9000,MATCH($N9,МАТЕРИАЛЫ!$L$2:$L$9000,0))="EUR",КурсEUR,IF(INDEX(МАТЕРИАЛЫ!$I$2:$I$9000,MATCH($N9,МАТЕРИАЛЫ!$L$2:$L$9000,0))="CNY",КурсCNY,1)))*(1+N($H9)/100),0),N($O9))*(1-MEDIAN(0,N(ДисконтТендер),1)))) -> 0 | U9: =IF($L9="да",MAX($U$1:$U8)+1,"") | V9: =IF($A9="","",$B9) -> Р1 | W9: =IF($U9="","",IF($U9=1,1,IF($V9<>IFERROR(INDEX($V$2:$V$1058,MATCH($U9-1,$U$2:$U$1058,0)),"~"),1,0))) | X9: =IF($U9="","",$U9+SUMIFS($W$2:$W$1058,$U$2:$U$1058,"<="&$U9)) | Y9: =IF($A9="","",IF(AND(LEFT($G9,3)="ДОК",$N9<>""),IFERROR(INDEX(Документация!$G$2:$G$57,MATCH($N9,Документация!$F$2:$F$57,0)),$D9),$D9&IF(AND(LEFT($G9,3)<>"ДОК",$N9<>"")," — "&IFERROR(INDEX(МАТЕРИАЛЫ!$C$2:$C$9000,MATCH($N9,МАТЕРИАЛЫ!$L$2:$L$9000,0)),""),""))) -> Стоимость согласования проекта перепланировки/реконструкции объекта в соответствии с нормативными актами г.______________. | Z9: =IF($B9="","",$B9&" · "&IFERROR(VLOOKUP($B9,спрРазделы,2,0),"")) -> Р1 · Проектные работы и согласования
A10: РАБ.Р1.1.063 | B10: Р1 | C10: 1 | D10: Получение паспорта БТИ (в черных линиях) | E10: м2 | F10: 0 | H10: 0 | I10: ТС ЕР | P10: =IF($L10="да",ROUND(N($M10)*$S10,2),"") | Q10: =IF($L10="да",ROUND(N($M10)*$T10,2),"") | R10: =IF($L10="да",N($P10)+N($Q10),"") | S10: =IF($A10="","",IF(AND(LEFT($G10,3)="ДОК",$N10<>""),IFERROR(INDEX(Документация!$E$2:$E$57,MATCH($N10,Документация!$F$2:$F$57,0)),0),N($F10))*(1-MEDIAN(0,N(ДисконтТендер),1))) -> 0 | T10: =IF($A10="","",IF(AND(LEFT($G10,3)="ДОК",$N10<>""),0,IF(AND(LEFT($G10,3)<>"ДОК",$N10<>""),IFERROR(INDEX(МАТЕРИАЛЫ!$H$2:$H$9000,MATCH($N10,МАТЕРИАЛЫ!$L$2:$L$9000,0))*IF(INDEX(МАТЕРИАЛЫ!$I$2:$I$9000,MATCH($N10,МАТЕРИАЛЫ!$L$2:$L$9000,0))="USD",КурсUSD,IF(INDEX(МАТЕРИАЛЫ!$I$2:$I$9000,MATCH($N10,МАТЕРИАЛЫ!$L$2:$L$9000,0))="EUR",КурсEUR,IF(INDEX(МАТЕРИАЛЫ!$I$2:$I$9000,MATCH($N10,МАТЕРИАЛЫ!$L$2:$L$9000,0))="CNY",КурсCNY,1)))*(1+N($H10)/100),0),N($O10))*(1-MEDIAN(0,N(ДисконтТендер),1)))) -> 0 | U10: =IF($L10="да",MAX($U$1:$U9)+1,"") | V10: =IF($A10="","",$B10) -> Р1 | W10: =IF($U10="","",IF($U10=1,1,IF($V10<>IFERROR(INDEX($V$2:$V$1058,MATCH($U10-1,$U$2:$U$1058,0)),"~"),1,0))) | X10: =IF($U10="","",$U10+SUMIFS($W$2:$W$1058,$U$2:$U$1058,"<="&$U10)) | Y10: =IF($A10="","",IF(AND(LEFT($G10,3)="ДОК",$N10<>""),IFERROR(INDEX(Документация!$G$2:$G$57,MATCH($N10,Документация!$F$2:$F$57,0)),$D10),$D10&IF(AND(LEFT($G10,3)<>"ДОК",$N10<>"")," — "&IFERROR(INDEX(МАТЕРИАЛЫ!$C$2:$C$9000,MATCH($N10,МАТЕРИАЛЫ!$L$2:$L$9000,0)),""),""))) -> Получение паспорта БТИ (в черных линиях) | Z10: =IF($B10="","",$B10&" · "&IFERROR(VLOOKUP($B10,спрРазделы,2,0),"")) -> Р1 · Проектные работы и согласования
A11: РАБ.Р1.1.064 | B11: Р1 | C11: 1 | D11: Сертификация помещения для совершения операций с ценностями, хранение ценностей по (2) классу вломостойкости и (3) классу пулестойкости | E11: м2 | F11: 88.99 | H11: 0 | I11: ТС ЕР | P11: =IF($L11="да",ROUND(N($M11)*$S11,2),"") | Q11: =IF($L11="да",ROUND(N($M11)*$T11,2),"") | R11: =IF($L11="да",N($P11)+N($Q11),"") | S11: =IF($A11="","",IF(AND(LEFT($G11,3)="ДОК",$N11<>""),IFERROR(INDEX(Документация!$E$2:$E$57,MATCH($N11,Документация!$F$2:$F$57,0)),0),N($F11))*(1-MEDIAN(0,N(ДисконтТендер),1))) -> 88.99 | T11: =IF($A11="","",IF(AND(LEFT($G11,3)="ДОК",$N11<>""),0,IF(AND(LEFT($G11,3)<>"ДОК",$N11<>""),IFERROR(INDEX(МАТЕРИАЛЫ!$H$2:$H$9000,MATCH($N11,МАТЕРИАЛЫ!$L$2:$L$9000,0))*IF(INDEX(МАТЕРИАЛЫ!$I$2:$I$9000,MATCH($N11,МАТЕРИАЛЫ!$L$2:$L$9000,0))="USD",КурсUSD,IF(INDEX(МАТЕРИАЛЫ!$I$2:$I$9000,MATCH($N11,МАТЕРИАЛЫ!$L$2:$L$9000,0))="EUR",КурсEUR,IF(INDEX(МАТЕРИАЛЫ!$I$2:$I$9000,MATCH($N11,МАТЕРИАЛЫ!$L$2:$L$9000,0))="CNY",КурсCNY,1)))*(1+N($H11)/100),0),N($O11))*(1-MEDIAN(0,N(ДисконтТендер),1)))) -> 0 | U11: =IF($L11="да",MAX($U$1:$U10)+1,"") | V11: =IF($A11="","",$B11) -> Р1 | W11: =IF($U11="","",IF($U11=1,1,IF($V11<>IFERROR(INDEX($V$2:$V$1058,MATCH($U11-1,$U$2:$U$1058,0)),"~"),1,0))) | X11: =IF($U11="","",$U11+SUMIFS($W$2:$W$1058,$U$2:$U$1058,"<="&$U11)) | Y11: =IF($A11="","",IF(AND(LEFT($G11,3)="ДОК",$N11<>""),IFERROR(INDEX(Документация!$G$2:$G$57,MATCH($N11,Документация!$F$2:$F$57,0)),$D11),$D11&IF(AND(LEFT($G11,3)<>"ДОК",$N11<>"")," — "&IFERROR(INDEX(МАТЕРИАЛЫ!$C$2:$C$9000,MATCH($N11,МАТЕРИАЛЫ!$L$2:$L$9000,0)),""),""))) -> Сертификация помещения для совершения операций с ценностями, хранение ценностей по (2) классу вломостойкости и (3) классу пулестойкости | Z11: =IF($B11="","",$B11&" · "&IFERROR(VLOOKUP($B11,спрРазделы,2,0),"")) -> Р1 · Проектные работы и согласования
A12: РАБ.Р1.1.065 | B12: Р1 | C12: 1 | D12: Сертификация помещения для совершения операций с ценностями, хранение ценностей по 3 классу вломостойкости и 3 классу пулестойкости | E12: м2 | F12: 149.82 | H12: 0 | I12: ТС ЕР | P12: =IF($L12="да",ROUND(N($M12)*$S12,2),"") | Q12: =IF($L12="да",ROUND(N($M12)*$T12,2),"") | R12: =IF($L12="да",N($P12)+N($Q12),"") | S12: =IF($A12="","",IF(AND(LEFT($G12,3)="ДОК",$N12<>""),IFERROR(INDEX(Документация!$E$2:$E$57,MATCH($N12,Документация!$F$2:$F$57,0)),0),N($F12))*(1-MEDIAN(0,N(ДисконтТендер),1))) -> 149.82 | T12: =IF($A12="","",IF(AND(LEFT($G12,3)="ДОК",$N12<>""),0,IF(AND(LEFT($G12,3)<>"ДОК",$N12<>""),IFERROR(INDEX(МАТЕРИАЛЫ!$H$2:$H$9000,MATCH($N12,МАТЕРИАЛЫ!$L$2:$L$9000,0))*IF(INDEX(МАТЕРИАЛЫ!$I$2:$I$9000,MATCH($N12,МАТЕРИАЛЫ!$L$2:$L$9000,0))="USD",КурсUSD,IF(INDEX(МАТЕРИАЛЫ!$I$2:$I$9000,MATCH($N12,МАТЕРИАЛЫ!$L$2:$L$9000,0))="EUR",КурсEUR,IF(INDEX(МАТЕРИАЛЫ!$I$2:$I$9000,MATCH($N12,МАТЕРИАЛЫ!$L$2:$L$9000,0))="CNY",КурсCNY,1)))*(1+N($H12)/100),0),N($O12))*(1-MEDIAN(0,N(ДисконтТендер),1)))) -> 0 | U12: =IF($L12="да",MAX($U$1:$U11)+1,"") | V12: =IF($A12="","",$B12) -> Р1 | W12: =IF($U12="","",IF($U12=1,1,IF($V12<>IFERROR(INDEX($V$2:$V$1058,MATCH($U12-1,$U$2:$U$1058,0)),"~"),1,0))) | X12: =IF($U12="","",$U12+SUMIFS($W$2:$W$1058,$U$2:$U$1058,"<="&$U12)) | Y12: =IF($A12="","",IF(AND(LEFT($G12,3)="ДОК",$N12<>""),IFERROR(INDEX(Документация!$G$2:$G$57,MATCH($N12,Документация!$F$2:$F$57,0)),$D12),$D12&IF(AND(LEFT($G12,3)<>"ДОК",$N12<>"")," — "&IFERROR(INDEX(МАТЕРИАЛЫ!$C$2:$C$9000,MATCH($N12,МАТЕРИАЛЫ!$L$2:$L$9000,0)),""),""))) -> Сертификация помещения для совершения операций с ценностями, хранение ценностей по 3 классу вломостойкости и 3 классу пулестойкости | Z12: =IF($B12="","",$B12&" · "&IFERROR(VLOOKUP($B12,спрРазделы,2,0),"")) -> Р1 · Проектные работы и согласования
A13: РАБ.Р1.1.066 | B13: Р1 | C13: 1 | D13: Сертификация помещения для совершения операций с ценностями, хранение ценностей по (5) классу вломостойкости | E13: м2 | F13: 96.48 | H13: 0 | I13: ТС ЕР | P13: =IF($L13="да",ROUND(N($M13)*$S13,2),"") | Q13: =IF($L13="да",ROUND(N($M13)*$T13,2),"") | R13: =IF($L13="да",N($P13)+N($Q13),"") | S13: =IF($A13="","",IF(AND(LEFT($G13,3)="ДОК",$N13<>""),IFERROR(INDEX(Документация!$E$2:$E$57,MATCH($N13,Документация!$F$2:$F$57,0)),0),N($F13))*(1-MEDIAN(0,N(ДисконтТендер),1))) -> 96.48 | T13: =IF($A13="","",IF(AND(LEFT($G13,3)="ДОК",$N13<>""),0,IF(AND(LEFT($G13,3)<>"ДОК",$N13<>""),IFERROR(INDEX(МАТЕРИАЛЫ!$H$2:$H$9000,MATCH($N13,МАТЕРИАЛЫ!$L$2:$L$9000,0))*IF(INDEX(МАТЕРИАЛЫ!$I$2:$I$9000,MATCH($N13,МАТЕРИАЛЫ!$L$2:$L$9000,0))="USD",КурсUSD,IF(INDEX(МАТЕРИАЛЫ!$I$2:$I$9000,MATCH($N13,МАТЕРИАЛЫ!$L$2:$L$9000,0))="EUR",КурсEUR,IF(INDEX(МАТЕРИАЛЫ!$I$2:$I$9000,MATCH($N13,МАТЕРИАЛЫ!$L$2:$L$9000,0))="CNY",КурсCNY,1)))*(1+N($H13)/100),0),N($O13))*(1-MEDIAN(0,N(ДисконтТендер),1)))) -> 0 | U13: =IF($L13="да",MAX($U$1:$U12)+1,"") | V13: =IF($A13="","",$B13) -> Р1 | W13: =IF($U13="","",IF($U13=1,1,IF($V13<>IFERROR(INDEX($V$2:$V$1058,MATCH($U13-1,$U$2:$U$1058,0)),"~"),1,0))) | X13: =IF($U13="","",$U13+SUMIFS($W$2:$W$1058,$U$2:$U$1058,"<="&$U13)) | Y13: =IF($A13="","",IF(AND(LEFT($G13,3)="ДОК",$N13<>""),IFERROR(INDEX(Документация!$G$2:$G$57,MATCH($N13,Документация!$F$2:$F$57,0)),$D13),$D13&IF(AND(LEFT($G13,3)<>"ДОК",$N13<>"")," — "&IFERROR(INDEX(МАТЕРИАЛЫ!$C$2:$C$9000,MATCH($N13,МАТЕРИАЛЫ!$L$2:$L$9000,0)),""),""))) -> Сертификация помещения для совершения операций с ценностями, хранение ценностей по (5) классу вломостойкости | Z13: =IF($B13="","",$B13&" · "&IFERROR(VLOOKUP($B13,спрРазделы,2,0),"")) -> Р1 · Проектные работы и согласования
A14: РАБ.Р1.1.067 | B14: Р1 | C14: 1 | D14: Технический отчет электролаборатории для помещений более 100 м.кв. | E14: м2 | F14: 123.58 | H14: 0 | I14: ТС ЕР | P14: =IF($L14="да",ROUND(N($M14)*$S14,2),"") | Q14: =IF($L14="да",ROUND(N($M14)*$T14,2),"") | R14: =IF($L14="да",N($P14)+N($Q14),"") | S14: =IF($A14="","",IF(AND(LEFT($G14,3)="ДОК",$N14<>""),IFERROR(INDEX(Документация!$E$2:$E$57,MATCH($N14,Документация!$F$2:$F$57,0)),0),N($F14))*(1-MEDIAN(0,N(ДисконтТендер),1))) -> 123.58 | T14: =IF($A14="","",IF(AND(LEFT($G14,3)="ДОК",$N14<>""),0,IF(AND(LEFT($G14,3)<>"ДОК",$N14<>""),IFERROR(INDEX(МАТЕРИАЛЫ!$H$2:$H$9000,MATCH($N14,МАТЕРИАЛЫ!$L$2:$L$9000,0))*IF(INDEX(МАТЕРИАЛЫ!$I$2:$I$9000,MATCH($N14,МАТЕРИАЛЫ!$L$2:$L$9000,0))="USD",КурсUSD,IF(INDEX(МАТЕРИАЛЫ!$I$2:$I$9000,MATCH($N14,МАТЕРИАЛЫ!$L$2:$L$9000,0))="EUR",КурсEUR,IF(INDEX(МАТЕРИАЛЫ!$I$2:$I$9000,MATCH($N14,МАТЕРИАЛЫ!$L$2:$L$9000,0))="CNY",КурсCNY,1)))*(1+N($H14)/100),0),N($O14))*(1-MEDIAN(0,N(ДисконтТендер),1)))) -> 0 | U14: =IF($L14="да",MAX($U$1:$U13)+1,"") | V14: =IF($A14="","",$B14) -> Р1 | W14: =IF($U14="","",IF($U14=1,1,IF($V14<>IFERROR(INDEX($V$2:$V$1058,MATCH($U14-1,$U$2:$U$1058,0)),"~"),1,0))) | X14: =IF($U14="","",$U14+SUMIFS($W$2:$W$1058,$U$2:$U$1058,"<="&$U14)) | Y14: =IF($A14="","",IF(AND(LEFT($G14,3)="ДОК",$N14<>""),IFERROR(INDEX(Документация!$G$2:$G$57,MATCH($N14,Документация!$F$2:$F$57,0)),$D14),$D14&IF(AND(LEFT($G14,3)<>"ДОК",$N14<>"")," — "&IFERROR(INDEX(МАТЕРИАЛЫ!$C$2:$C$9000,MATCH($N14,МАТЕРИАЛЫ!$L$2:$L$9000,0)),""),""))) -> Технический отчет электролаборатории для помещений более 100 м.кв. | Z14: =IF($B14="","",$B14&" · "&IFERROR(VLOOKUP($B14,спрРазделы,2,0),"")) -> Р1 · Проектные работы и согласования
A15: РАБ.Р1.1.068 | B15: Р1 | C15: 1 | D15: Технический отчет электролаборатории для помещений менее 100 м.кв. | E15: компл. | F15: 13074.35 | H15: 0 | I15: ТС ЕР | P15: =IF($L15="да",ROUND(N($M15)*$S15,2),"") | Q15: =IF($L15="да",ROUND(N($M15)*$T15,2),"") | R15: =IF($L15="да",N($P15)+N($Q15),"") | S15: =IF($A15="","",IF(AND(LEFT($G15,3)="ДОК",$N15<>""),IFERROR(INDEX(Документация!$E$2:$E$57,MATCH($N15,Документация!$F$2:$F$57,0)),0),N($F15))*(1-MEDIAN(0,N(ДисконтТендер),1))) -> 13074.35 | T15: =IF($A15="","",IF(AND(LEFT($G15,3)="ДОК",$N15<>""),0,IF(AND(LEFT($G15,3)<>"ДОК",$N15<>""),IFERROR(INDEX(МАТЕРИАЛЫ!$H$2:$H$9000,MATCH($N15,МАТЕРИАЛЫ!$L$2:$L$9000,0))*IF(INDEX(МАТЕРИАЛЫ!$I$2:$I$9000,MATCH($N15,МАТЕРИАЛЫ!$L$2:$L$9000,0))="USD",КурсUSD,IF(INDEX(МАТЕРИАЛЫ!$I$2:$I$9000,MATCH($N15,МАТЕРИАЛЫ!$L$2:$L$9000,0))="EUR",КурсEUR,IF(INDEX(МАТЕРИАЛЫ!$I$2:$I$9000,MATCH($N15,МАТЕРИАЛЫ!$L$2:$L$9000,0))="CNY",КурсCNY,1)))*(1+N($H15)/100),0),N($O15))*(1-MEDIAN(0,N(ДисконтТендер),1)))) -> 0 | U15: =IF($L15="да",MAX($U$1:$U14)+1,"") | V15: =IF($A15="","",$B15) -> Р1 | W15: =IF($U15="","",IF($U15=1,1,IF($V15<>IFERROR(INDEX($V$2:$V$1058,MATCH($U15-1,$U$2:$U$1058,0)),"~"),1,0))) | X15: =IF($U15="","",$U15+SUMIFS($W$2:$W$1058,$U$2:$U$1058,"<="&$U15)) | Y15: =IF($A15="","",IF(AND(LEFT($G15,3)="ДОК",$N15<>""),IFERROR(INDEX(Документация!$G$2:$G$57,MATCH($N15,Документация!$F$2:$F$57,0)),$D15),$D15&IF(AND(LEFT($G15,3)<>"ДОК",$N15<>"")," — "&IFERROR(INDEX(МАТЕРИАЛЫ!$C$2:$C$9000,MATCH($N15,МАТЕРИАЛЫ!$L$2:$L$9000,0)),""),""))) -> Технический отчет электролаборатории для помещений менее 100 м.кв. | Z15: =IF($B15="","",$B15&" · "&IFERROR(VLOOKUP($B15,спрРазделы,2,0),"")) -> Р1 · Проектные работы и согласования
A16: РАБ.Р1.1.069 | B16: Р1 | C16: 1 | D16: Стоимость согласования проекта изменения фасада согласно нормативных и законодательных актов г. ___________ и РФ. | E16: м2 | F16: 190.9 | H16: 0 | I16: ТС ЕР | P16: =IF($L16="да",ROUND(N($M16)*$S16,2),"") | Q16: =IF($L16="да",ROUND(N($M16)*$T16,2),"") | R16: =IF($L16="да",N($P16)+N($Q16),"") | S16: =IF($A16="","",IF(AND(LEFT($G16,3)="ДОК",$N16<>""),IFERROR(INDEX(Документация!$E$2:$E$57,MATCH($N16,Документация!$F$2:$F$57,0)),0),N($F16))*(1-MEDIAN(0,N(ДисконтТендер),1))) -> 190.9 | T16: =IF($A16="","",IF(AND(LEFT($G16,3)="ДОК",$N16<>""),0,IF(AND(LEFT($G16,3)<>"ДОК",$N16<>""),IFERROR(INDEX(МАТЕРИАЛЫ!$H$2:$H$9000,MATCH($N16,МАТЕРИАЛЫ!$L$2:$L$9000,0))*IF(INDEX(МАТЕРИАЛЫ!$I$2:$I$9000,MATCH($N16,МАТЕРИАЛЫ!$L$2:$L$9000,0))="USD",КурсUSD,IF(INDEX(МАТЕРИАЛЫ!$I$2:$I$9000,MATCH($N16,МАТЕРИАЛЫ!$L$2:$L$9000,0))="EUR",КурсEUR,IF(INDEX(МАТЕРИАЛЫ!$I$2:$I$9000,MATCH($N16,МАТЕРИАЛЫ!$L$2:$L$9000,0))="CNY",КурсCNY,1)))*(1+N($H16)/100),0),N($O16))*(1-MEDIAN(0,N(ДисконтТендер),1)))) -> 0 | U16: =IF($L16="да",MAX($U$1:$U15)+1,"") | V16: =IF($A16="","",$B16) -> Р1 | W16: =IF($U16="","",IF($U16=1,1,IF($V16<>IFERROR(INDEX($V$2:$V$1058,MATCH($U16-1,$U$2:$U$1058,0)),"~"),1,0))) | X16: =IF($U16="","",$U16+SUMIFS($W$2:$W$1058,$U$2:$U$1058,"<="&$U16)) | Y16: =IF($A16="","",IF(AND(LEFT($G16,3)="ДОК",$N16<>""),IFERROR(INDEX(Документация!$G$2:$G$57,MATCH($N16,Документация!$F$2:$F$57,0)),$D16),$D16&IF(AND(LEFT($G16,3)<>"ДОК",$N16<>"")," — "&IFERROR(INDEX(МАТЕРИАЛЫ!$C$2:$C$9000,MATCH($N16,МАТЕРИАЛЫ!$L$2:$L$9000,0)),""),""))) -> Стоимость согласования проекта изменения фасада согласно нормативных и законодательных актов г. ___________ и РФ. | Z16: =IF($B16="","",$B16&" · "&IFERROR(VLOOKUP($B16,спрРазделы,2,0),"")) -> Р1 · Проектные работы и согласования
A17: РАБ.Р1.1.070 | B17: Р1 | C17: 1 | D17: Разработка дизайн-проекта интерьера | E17: м2 | F17: 0 | H17: 0 | I17: ТС ЕР | P17: =IF($L17="да",ROUND(N($M17)*$S17,2),"") | Q17: =IF($L17="да",ROUND(N($M17)*$T17,2),"") | R17: =IF($L17="да",N($P17)+N($Q17),"") | S17: =IF($A17="","",IF(AND(LEFT($G17,3)="ДОК",$N17<>""),IFERROR(INDEX(Документация!$E$2:$E$57,MATCH($N17,Документация!$F$2:$F$57,0)),0),N($F17))*(1-MEDIAN(0,N(ДисконтТендер),1))) -> 0 | T17: =IF($A17="","",IF(AND(LEFT($G17,3)="ДОК",$N17<>""),0,IF(AND(LEFT($G17,3)<>"ДОК",$N17<>""),IFERROR(INDEX(МАТЕРИАЛЫ!$H$2:$H$9000,MATCH($N17,МАТЕРИАЛЫ!$L$2:$L$9000,0))*IF(INDEX(МАТЕРИАЛЫ!$I$2:$I$9000,MATCH($N17,МАТЕРИАЛЫ!$L$2:$L$9000,0))="USD",КурсUSD,IF(INDEX(МАТЕРИАЛЫ!$I$2:$I$9000,MATCH($N17,МАТЕРИАЛЫ!$L$2:$L$9000,0))="EUR",КурсEUR,IF(INDEX(МАТЕРИАЛЫ!$I$2:$I$9000,MATCH($N17,МАТЕРИАЛЫ!$L$2:$L$9000,0))="CNY",КурсCNY,1)))*(1+N($H17)/100),0),N($O17))*(1-MEDIAN(0,N(ДисконтТендер),1)))) -> 0 | U17: =IF($L17="да",MAX($U$1:$U16)+1,"") | V17: =IF($A17="","",$B17) -> Р1 | W17: =IF($U17="","",IF($U17=1,1,IF($V17<>IFERROR(INDEX($V$2:$V$1058,MATCH($U17-1,$U$2:$U$1058,0)),"~"),1,0))) | X17: =IF($U17="","",$U17+SUMIFS($W$2:$W$1058,$U$2:$U$1058,"<="&$U17)) | Y17: =IF($A17="","",IF(AND(LEFT($G17,3)="ДОК",$N17<>""),IFERROR(INDEX(Документация!$G$2:$G$57,MATCH($N17,Документация!$F$2:$F$57,0)),$D17),$D17&IF(AND(LEFT($G17,3)<>"ДОК",$N17<>"")," — "&IFERROR(INDEX(МАТЕРИАЛЫ!$C$2:$C$9000,MATCH($N17,МАТЕРИАЛЫ!$L$2:$L$9000,0)),""),""))) -> Разработка дизайн-проекта интерьера | Z17: =IF($B17="","",$B17&" · "&IFERROR(VLOOKUP($B17,спрРазделы,2,0),"")) -> Р1 · Проектные работы и согласования
... A161: РАБ.Р2.13.001 | B161: Р2 | C161: 13 | D161: Демонтажные работы до состояния shell-and-core | E161: м2 | F161: 2133.33 | H161: 0 | I161: ТС ЕР | P161: =IF($L161="да",ROUND(N($M161)*$S161,2),"") | Q161: =IF($L161="да",ROUND(N($M161)*$T161,2),"") | R161: =IF($L161="да",N($P161)+N($Q161),"") | S161: =IF($A161="","",IF(AND(LEFT($G161,3)="ДОК",$N161<>""),IFERROR(INDEX(Документация!$E$2:$E$57,MATCH($N161,Документация!$F$2:$F$57,0)),0),N($F161))*(1-MEDIAN(0,N(ДисконтТендер),1))) -> 2133.33 | T161: =IF($A161="","",IF(AND(LEFT($G161,3)="ДОК",$N161<>""),0,IF(AND(LEFT($G161,3)<>"ДОК",$N161<>""),IFERROR(INDEX(МАТЕРИАЛЫ!$H$2:$H$9000,MATCH($N161,МАТЕРИАЛЫ!$L$2:$L$9000,0))*IF(INDEX(МАТЕРИАЛЫ!$I$2:$I$9000,MATCH($N161,МАТЕРИАЛЫ!$L$2:$L$9000,0))="USD",КурсUSD,IF(INDEX(МАТЕРИАЛЫ!$I$2:$I$9000,MATCH($N161,МАТЕРИАЛЫ!$L$2:$L$9000,0))="EUR",КурсEUR,IF(INDEX(МАТЕРИАЛЫ!$I$2:$I$9000,MATCH($N161,МАТЕРИАЛЫ!$L$2:$L$9000,0))="CNY",КурсCNY,1)))*(1+N($H161)/100),0),N($O161))*(1-MEDIAN(0,N(ДисконтТендер),1)))) -> 0 | U161: =IF($L161="да",MAX($U$1:$U160)+1,"") | V161: =IF($A161="","",$B161) -> Р2 | W161: =IF($U161="","",IF($U161=1,1,IF($V161<>IFERROR(INDEX($V$2:$V$1058,MATCH($U161-1,$U$2:$U$1058,0)),"~"),1,0))) | X161: =IF($U161="","",$U161+SUMIFS($W$2:$W$1058,$U$2:$U$1058,"<="&$U161)) | Y161: =IF($A161="","",IF(AND(LEFT($G161,3)="ДОК",$N161<>""),IFERROR(INDEX(Документация!$G$2:$G$57,MATCH($N161,Документация!$F$2:$F$57,0)),$D161),$D161&IF(AND(LEFT($G161,3)<>"ДОК",$N161<>"")," — "&IFERROR(INDEX(МАТЕРИАЛЫ!$C$2:$C$9000,MATCH($N161,МАТЕРИАЛЫ!$L$2:$L$9000,0)),""),""))) -> Демонтажные работы до состояния shell-and-core | Z161: =IF($B161="","",$B161&" · "&IFERROR(VLOOKUP($B161,спрРазделы,2,0),"")) -> Р2 · Демонтажные работы
A162: РАБ.Р3.1.001 | B162: Р3 | C162: 1 | D162: Кладка перегородок толщиной в 1/2 кирпича | E162: м2 | F162: 2392.5 | G162: КЛАДКА | H162: 5 | I162: ТС ЕР | P162: =IF($L162="да",ROUND(N($M162)*$S162,2),"") | Q162: =IF($L162="да",ROUND(N($M162)*$T162,2),"") | R162: =IF($L162="да",N($P162)+N($Q162),"") | S162: =IF($A162="","",IF(AND(LEFT($G162,3)="ДОК",$N162<>""),IFERROR(INDEX(Документация!$E$2:$E$57,MATCH($N162,Документация!$F$2:$F$57,0)),0),N($F162))*(1-MEDIAN(0,N(ДисконтТендер),1))) -> 2392.5 | T162: =IF($A162="","",IF(AND(LEFT($G162,3)="ДОК",$N162<>""),0,IF(AND(LEFT($G162,3)<>"ДОК",$N162<>""),IFERROR(INDEX(МАТЕРИАЛЫ!$H$2:$H$9000,MATCH($N162,МАТЕРИАЛЫ!$L$2:$L$9000,0))*IF(INDEX(МАТЕРИАЛЫ!$I$2:$I$9000,MATCH($N162,МАТЕРИАЛЫ!$L$2:$L$9000,0))="USD",КурсUSD,IF(INDEX(МАТЕРИАЛЫ!$I$2:$I$9000,MATCH($N162,МАТЕРИАЛЫ!$L$2:$L$9000,0))="EUR",КурсEUR,IF(INDEX(МАТЕРИАЛЫ!$I$2:$I$9000,MATCH($N162,МАТЕРИАЛЫ!$L$2:$L$9000,0))="CNY",КурсCNY,1)))*(1+N($H162)/100),0),N($O162))*(1-MEDIAN(0,N(ДисконтТендер),1)))) -> 0 | U162: =IF($L162="да",MAX($U$1:$U161)+1,"") | V162: =IF($A162="","",$B162) -> Р3 | W162: =IF($U162="","",IF($U162=1,1,IF($V162<>IFERROR(INDEX($V$2:$V$1058,MATCH($U162-1,$U$2:$U$1058,0)),"~"),1,0))) | X162: =IF($U162="","",$U162+SUMIFS($W$2:$W$1058,$U$2:$U$1058,"<="&$U162)) | Y162: =IF($A162="","",IF(AND(LEFT($G162,3)="ДОК",$N162<>""),IFERROR(INDEX(Документация!$G$2:$G$57,MATCH($N162,Документация!$F$2:$F$57,0)),$D162),$D162&IF(AND(LEFT($G162,3)<>"ДОК",$N162<>"")," — "&IFERROR(INDEX(МАТЕРИАЛЫ!$C$2:$C$9000,MATCH($N162,МАТЕРИАЛЫ!$L$2:$L$9000,0)),""),""))) -> Кладка перегородок толщиной в 1/2 кирпича | Z162: =IF($B162="","",$B162&" · "&IFERROR(VLOOKUP($B162,спрРазделы,2,0),"")) -> Р3 · Внутренние строительные работы
A163: РАБ.Р3.1.002 | B163: Р3 | C163: 1 | D163: Кладка перегородок армированных толщиной в 1 кирпич | E163: м2 | F163: 2704.48 | G163: КЛАДКА | H163: 5 | I163: ТС ЕР | P163: =IF($L163="да",ROUND(N($M163)*$S163,2),"") | Q163: =IF($L163="да",ROUND(N($M163)*$T163,2),"") | R163: =IF($L163="да",N($P163)+N($Q163),"") | S163: =IF($A163="","",IF(AND(LEFT($G163,3)="ДОК",$N163<>""),IFERROR(INDEX(Документация!$E$2:$E$57,MATCH($N163,Документация!$F$2:$F$57,0)),0),N($F163))*(1-MEDIAN(0,N(ДисконтТендер),1))) -> 2704.48 | T163: =IF($A163="","",IF(AND(LEFT($G163,3)="ДОК",$N163<>""),0,IF(AND(LEFT($G163,3)<>"ДОК",$N163<>""),IFERROR(INDEX(МАТЕРИАЛЫ!$H$2:$H$9000,MATCH($N163,МАТЕРИАЛЫ!$L$2:$L$9000,0))*IF(INDEX(МАТЕРИАЛЫ!$I$2:$I$9000,MATCH($N163,МАТЕРИАЛЫ!$L$2:$L$9000,0))="USD",КурсUSD,IF(INDEX(МАТЕРИАЛЫ!$I$2:$I$9000,MATCH($N163,МАТЕРИАЛЫ!$L$2:$L$9000,0))="EUR",КурсEUR,IF(INDEX(МАТЕРИАЛЫ!$I$2:$I$9000,MATCH($N163,МАТЕРИАЛЫ!$L$2:$L$9000,0))="CNY",КурсCNY,1)))*(1+N($H163)/100),0),N($O163))*(1-MEDIAN(0,N(ДисконтТендер),1)))) -> 0 | U163: =IF($L163="да",MAX($U$1:$U162)+1,"") | V163: =IF($A163="","",$B163) -> Р3 | W163: =IF($U163="","",IF($U163=1,1,IF($V163<>IFERROR(INDEX($V$2:$V$1058,MATCH($U163-1,$U$2:$U$1058,0)),"~"),1,0))) | X163: =IF($U163="","",$U163+SUMIFS($W$2:$W$1058,$U$2:$U$1058,"<="&$U163)) | Y163: =IF($A163="","",IF(AND(LEFT($G163,3)="ДОК",$N163<>""),IFERROR(INDEX(Документация!$G$2:$G$57,MATCH($N163,Документация!$F$2:$F$57,0)),$D163),$D163&IF(AND(LEFT($G163,3)<>"ДОК",$N163<>"")," — "&IFERROR(INDEX(МАТЕРИАЛЫ!$C$2:$C$9000,MATCH($N163,МАТЕРИАЛЫ!$L$2:$L$9000,0)),""),""))) -> Кладка перегородок армированных толщиной в 1 кирпич | Z163: =IF($B163="","",$B163&" · "&IFERROR(VLOOKUP($B163,спрРазделы,2,0),"")) -> Р3 · Внутренние строительные работы
A164: РАБ.Р3.1.003 | B164: Р3 | C164: 1 | D164: Кладка перегородок из пеноблоков (600*300*200) | E164: м2 | F164: 2035.8 | G164: КЛАДКА | H164: 5 | I164: ТС ЕР | P164: =IF($L164="да",ROUND(N($M164)*$S164,2),"") | Q164: =IF($L164="да",ROUND(N($M164)*$T164,2),"") | R164: =IF($L164="да",N($P164)+N($Q164),"") | S164: =IF($A164="","",IF(AND(LEFT($G164,3)="ДОК",$N164<>""),IFERROR(INDEX(Документация!$E$2:$E$57,MATCH($N164,Документация!$F$2:$F$57,0)),0),N($F164))*(1-MEDIAN(0,N(ДисконтТендер),1))) -> 2035.8 | T164: =IF($A164="","",IF(AND(LEFT($G164,3)="ДОК",$N164<>""),0,IF(AND(LEFT($G164,3)<>"ДОК",$N164<>""),IFERROR(INDEX(МАТЕРИАЛЫ!$H$2:$H$9000,MATCH($N164,МАТЕРИАЛЫ!$L$2:$L$9000,0))*IF(INDEX(МАТЕРИАЛЫ!$I$2:$I$9000,MATCH($N164,МАТЕРИАЛЫ!$L$2:$L$9000,0))="USD",КурсUSD,IF(INDEX(МАТЕРИАЛЫ!$I$2:$I$9000,MATCH($N164,МАТЕРИАЛЫ!$L$2:$L$9000,0))="EUR",КурсEUR,IF(INDEX(МАТЕРИАЛЫ!$I$2:$I$9000,MATCH($N164,МАТЕРИАЛЫ!$L$2:$L$9000,0))="CNY",КурсCNY,1)))*(1+N($H164)/100),0),N($O164))*(1-MEDIAN(0,N(ДисконтТендер),1)))) -> 0 | U164: =IF($L164="да",MAX($U$1:$U163)+1,"") | V164: =IF($A164="","",$B164) -> Р3 | W164: =IF($U164="","",IF($U164=1,1,IF($V164<>IFERROR(INDEX($V$2:$V$1058,MATCH($U164-1,$U$2:$U$1058,0)),"~"),1,0))) | X164: =IF($U164="","",$U164+SUMIFS($W$2:$W$1058,$U$2:$U$1058,"<="&$U164)) | Y164: =IF($A164="","",IF(AND(LEFT($G164,3)="ДОК",$N164<>""),IFERROR(INDEX(Документация!$G$2:$G$57,MATCH($N164,Документация!$F$2:$F$57,0)),$D164),$D164&IF(AND(LEFT($G164,3)<>"ДОК",$N164<>"")," — "&IFERROR(INDEX(МАТЕРИАЛЫ!$C$2:$C$9000,MATCH($N164,МАТЕРИАЛЫ!$L$2:$L$9000,0)),""),""))) -> Кладка перегородок из пеноблоков (600*300*200) | Z164: =IF($B164="","",$B164&" · "&IFERROR(VLOOKUP($B164,спрРазделы,2,0),"")) -> Р3 · Внутренние строительные работы
A165: РАБ.Р3.1.004 | B165: Р3 | C165: 1 | D165: Заделка проемов в кирпичных стенах | E165: м3 | F165: 9787.5 | G165: КЛАДКА | H165: 5 | I165: ТС ЕР | P165: =IF($L165="да",ROUND(N($M165)*$S165,2),"") | Q165: =IF($L165="да",ROUND(N($M165)*$T165,2),"") | R165: =IF($L165="да",N($P165)+N($Q165),"") | S165: =IF($A165="","",IF(AND(LEFT($G165,3)="ДОК",$N165<>""),IFERROR(INDEX(Документация!$E$2:$E$57,MATCH($N165,Документация!$F$2:$F$57,0)),0),N($F165))*(1-MEDIAN(0,N(ДисконтТендер),1))) -> 9787.5 | T165: =IF($A165="","",IF(AND(LEFT($G165,3)="ДОК",$N165<>""),0,IF(AND(LEFT($G165,3)<>"ДОК",$N165<>""),IFERROR(INDEX(МАТЕРИАЛЫ!$H$2:$H$9000,MATCH($N165,МАТЕРИАЛЫ!$L$2:$L$9000,0))*IF(INDEX(МАТЕРИАЛЫ!$I$2:$I$9000,MATCH($N165,МАТЕРИАЛЫ!$L$2:$L$9000,0))="USD",КурсUSD,IF(INDEX(МАТЕРИАЛЫ!$I$2:$I$9000,MATCH($N165,МАТЕРИАЛЫ!$L$2:$L$9000,0))="EUR",КурсEUR,IF(INDEX(МАТЕРИАЛЫ!$I$2:$I$9000,MATCH($N165,МАТЕРИАЛЫ!$L$2:$L$9000,0))="CNY",КурсCNY,1)))*(1+N($H165)/100),0),N($O165))*(1-MEDIAN(0,N(ДисконтТендер),1)))) -> 0 | U165: =IF($L165="да",MAX($U$1:$U164)+1,"") | V165: =IF($A165="","",$B165) -> Р3 | W165: =IF($U165="","",IF($U165=1,1,IF($V165<>IFERROR(INDEX($V$2:$V$1058,MATCH($U165-1,$U$2:$U$1058,0)),"~"),1,0))) | X165: =IF($U165="","",$U165+SUMIFS($W$2:$W$1058,$U$2:$U$1058,"<="&$U165)) | Y165: =IF($A165="","",IF(AND(LEFT($G165,3)="ДОК",$N165<>""),IFERROR(INDEX(Документация!$G$2:$G$57,MATCH($N165,Документация!$F$2:$F$57,0)),$D165),$D165&IF(AND(LEFT($G165,3)<>"ДОК",$N165<>"")," — "&IFERROR(INDEX(МАТЕРИАЛЫ!$C$2:$C$9000,MATCH($N165,МАТЕРИАЛЫ!$L$2:$L$9000,0)),""),""))) -> Заделка проемов в кирпичных стенах | Z165: =IF($B165="","",$B165&" · "&IFERROR(VLOOKUP($B165,спрРазделы,2,0),"")) -> Р3 · Внутренние строительные работы
A166: РАБ.Р3.1.005 | B166: Р3 | C166: 1 | D166: Усиление проемов металлическим профилем из уголка 50*3 | E166: м.п. | F166: 1045 | H166: 0 | I166: ТС ЕР | P166: =IF($L166="да",ROUND(N($M166)*$S166,2),"") | Q166: =IF($L166="да",ROUND(N($M166)*$T166,2),"") | R166: =IF($L166="да",N($P166)+N($Q166),"") | S166: =IF($A166="","",IF(AND(LEFT($G166,3)="ДОК",$N166<>""),IFERROR(INDEX(Документация!$E$2:$E$57,MATCH($N166,Документация!$F$2:$F$57,0)),0),N($F166))*(1-MEDIAN(0,N(ДисконтТендер),1))) -> 1045 | T166: =IF($A166="","",IF(AND(LEFT($G166,3)="ДОК",$N166<>""),0,IF(AND(LEFT($G166,3)<>"ДОК",$N166<>""),IFERROR(INDEX(МАТЕРИАЛЫ!$H$2:$H$9000,MATCH($N166,МАТЕРИАЛЫ!$L$2:$L$9000,0))*IF(INDEX(МАТЕРИАЛЫ!$I$2:$I$9000,MATCH($N166,МАТЕРИАЛЫ!$L$2:$L$9000,0))="USD",КурсUSD,IF(INDEX(МАТЕРИАЛЫ!$I$2:$I$9000,MATCH($N166,МАТЕРИАЛЫ!$L$2:$L$9000,0))="EUR",КурсEUR,IF(INDEX(МАТЕРИАЛЫ!$I$2:$I$9000,MATCH($N166,МАТЕРИАЛЫ!$L$2:$L$9000,0))="CNY",КурсCNY,1)))*(1+N($H166)/100),0),N($O166))*(1-MEDIAN(0,N(ДисконтТендер),1)))) -> 0 | U166: =IF($L166="да",MAX($U$1:$U165)+1,"") | V166: =IF($A166="","",$B166) -> Р3 | W166: =IF($U166="","",IF($U166=1,1,IF($V166<>IFERROR(INDEX($V$2:$V$1058,MATCH($U166-1,$U$2:$U$1058,0)),"~"),1,0))) | X166: =IF($U166="","",$U166+SUMIFS($W$2:$W$1058,$U$2:$U$1058,"<="&$U166)) | Y166: =IF($A166="","",IF(AND(LEFT($G166,3)="ДОК",$N166<>""),IFERROR(INDEX(Документация!$G$2:$G$57,MATCH($N166,Документация!$F$2:$F$57,0)),$D166),$D166&IF(AND(LEFT($G166,3)<>"ДОК",$N166<>"")," — "&IFERROR(INDEX(МАТЕРИАЛЫ!$C$2:$C$9000,MATCH($N166,МАТЕРИАЛЫ!$L$2:$L$9000,0)),""),""))) -> Усиление проемов металлическим профилем из уголка 50*3 | Z166: =IF($B166="","",$B166&" · "&IFERROR(VLOOKUP($B166,спрРазделы,2,0),"")) -> Р3 · Внутренние строительные работы
A167: РАБ.Р3.1.006 | B167: Р3 | C167: 1 | D167: Усиление проемов металлическим профилем из уголка 100*100*10 | E167: м.п. | F167: 2090 | H167: 0 | I167: ТС ЕР | P167: =IF($L167="да",ROUND(N($M167)*$S167,2),"") | Q167: =IF($L167="да",ROUND(N($M167)*$T167,2),"") | R167: =IF($L167="да",N($P167)+N($Q167),"") | S167: =IF($A167="","",IF(AND(LEFT($G167,3)="ДОК",$N167<>""),IFERROR(INDEX(Документация!$E$2:$E$57,MATCH($N167,Документация!$F$2:$F$57,0)),0),N($F167))*(1-MEDIAN(0,N(ДисконтТендер),1))) -> 2090 | T167: =IF($A167="","",IF(AND(LEFT($G167,3)="ДОК",$N167<>""),0,IF(AND(LEFT($G167,3)<>"ДОК",$N167<>""),IFERROR(INDEX(МАТЕРИАЛЫ!$H$2:$H$9000,MATCH($N167,МАТЕРИАЛЫ!$L$2:$L$9000,0))*IF(INDEX(МАТЕРИАЛЫ!$I$2:$I$9000,MATCH($N167,МАТЕРИАЛЫ!$L$2:$L$9000,0))="USD",КурсUSD,IF(INDEX(МАТЕРИАЛЫ!$I$2:$I$9000,MATCH($N167,МАТЕРИАЛЫ!$L$2:$L$9000,0))="EUR",КурсEUR,IF(INDEX(МАТЕРИАЛЫ!$I$2:$I$9000,MATCH($N167,МАТЕРИАЛЫ!$L$2:$L$9000,0))="CNY",КурсCNY,1)))*(1+N($H167)/100),0),N($O167))*(1-MEDIAN(0,N(ДисконтТендер),1)))) -> 0 | U167: =IF($L167="да",MAX($U$1:$U166)+1,"") | V167: =IF($A167="","",$B167) -> Р3 | W167: =IF($U167="","",IF($U167=1,1,IF($V167<>IFERROR(INDEX($V$2:$V$1058,MATCH($U167-1,$U$2:$U$1058,0)),"~"),1,0))) | X167: =IF($U167="","",$U167+SUMIFS($W$2:$W$1058,$U$2:$U$1058,"<="&$U167)) | Y167: =IF($A167="","",IF(AND(LEFT($G167,3)="ДОК",$N167<>""),IFERROR(INDEX(Документация!$G$2:$G$57,MATCH($N167,Документация!$F$2:$F$57,0)),$D167),$D167&IF(AND(LEFT($G167,3)<>"ДОК",$N167<>"")," — "&IFERROR(INDEX(МАТЕРИАЛЫ!$C$2:$C$9000,MATCH($N167,МАТЕРИАЛЫ!$L$2:$L$9000,0)),""),""))) -> Усиление проемов металлическим профилем из уголка 100*100*10 | Z167: =IF($B167="","",$B167&" · "&IFERROR(VLOOKUP($B167,спрРазделы,2,0),"")) -> Р3 · Внутренние строительные работы
A168: РАБ.Р3.1.007 | B168: Р3 | C168: 1 | D168: Устройство перегородок из ГКЛ толщ. 12 мм. "Кнауф" с одинарным металлическим каркасом и однослойной обшивкой с обеих сторон (включая перфорированные уголки на внешние углы) | E168: м2 | F168: 1722.6 | G168: ГКЛ | H168: 5 | I168: ТС ЕР | P168: =IF($L168="да",ROUND(N($M168)*$S168,2),"") | Q168: =IF($L168="да",ROUND(N($M168)*$T168,2),"") | R168: =IF($L168="да",N($P168)+N($Q168),"") | S168: =IF($A168="","",IF(AND(LEFT($G168,3)="ДОК",$N168<>""),IFERROR(INDEX(Документация!$E$2:$E$57,MATCH($N168,Документация!$F$2:$F$57,0)),0),N($F168))*(1-MEDIAN(0,N(ДисконтТендер),1))) -> 1722.6 | T168: =IF($A168="","",IF(AND(LEFT($G168,3)="ДОК",$N168<>""),0,IF(AND(LEFT($G168,3)<>"ДОК",$N168<>""),IFERROR(INDEX(МАТЕРИАЛЫ!$H$2:$H$9000,MATCH($N168,МАТЕРИАЛЫ!$L$2:$L$9000,0))*IF(INDEX(МАТЕРИАЛЫ!$I$2:$I$9000,MATCH($N168,МАТЕРИАЛЫ!$L$2:$L$9000,0))="USD",КурсUSD,IF(INDEX(МАТЕРИАЛЫ!$I$2:$I$9000,MATCH($N168,МАТЕРИАЛЫ!$L$2:$L$9000,0))="EUR",КурсEUR,IF(INDEX(МАТЕРИАЛЫ!$I$2:$I$9000,MATCH($N168,МАТЕРИАЛЫ!$L$2:$L$9000,0))="CNY",КурсCNY,1)))*(1+N($H168)/100),0),N($O168))*(1-MEDIAN(0,N(ДисконтТендер),1)))) -> 0 | U168: =IF($L168="да",MAX($U$1:$U167)+1,"") | V168: =IF($A168="","",$B168) -> Р3 | W168: =IF($U168="","",IF($U168=1,1,IF($V168<>IFERROR(INDEX($V$2:$V$1058,MATCH($U168-1,$U$2:$U$1058,0)),"~"),1,0))) | X168: =IF($U168="","",$U168+SUMIFS($W$2:$W$1058,$U$2:$U$1058,"<="&$U168)) | Y168: =IF($A168="","",IF(AND(LEFT($G168,3)="ДОК",$N168<>""),IFERROR(INDEX(Документация!$G$2:$G$57,MATCH($N168,Документация!$F$2:$F$57,0)),$D168),$D168&IF(AND(LEFT($G168,3)<>"ДОК",$N168<>"")," — "&IFERROR(INDEX(МАТЕРИАЛЫ!$C$2:$C$9000,MATCH($N168,МАТЕРИАЛЫ!$L$2:$L$9000,0)),""),""))) -> Устройство перегородок из ГКЛ толщ. 12 мм. "Кнауф" с одинарным металлическим каркасом и однослойной обшивкой с обеих сторон (включая перфорированные уголки на внешние углы) | Z168: =IF($B168="","",$B168&" · "&IFERROR(VLOOKUP($B168,спрРазделы,2,0),"")) -> Р3 · Внутренние строительные работы
A169: РАБ.Р3.1.008 | B169: Р3 | C169: 1 | D169: Устройство перегородок из ГКЛ толщ. 12 мм. "Кнауф" с одинарным металлическим каркасом и двухслойной обшивкой с обеих сторон (включая перфорированные уголки на внешние углы) | E169: м2 | F169: 1894.86 | G169: ГКЛ | H169: 5 | I169: ТС ЕР | P169: =IF($L169="да",ROUND(N($M169)*$S169,2),"") | Q169: =IF($L169="да",ROUND(N($M169)*$T169,2),"") | R169: =IF($L169="да",N($P169)+N($Q169),"") | S169: =IF($A169="","",IF(AND(LEFT($G169,3)="ДОК",$N169<>""),IFERROR(INDEX(Документация!$E$2:$E$57,MATCH($N169,Документация!$F$2:$F$57,0)),0),N($F169))*(1-MEDIAN(0,N(ДисконтТендер),1))) -> 1894.86 | T169: =IF($A169="","",IF(AND(LEFT($G169,3)="ДОК",$N169<>""),0,IF(AND(LEFT($G169,3)<>"ДОК",$N169<>""),IFERROR(INDEX(МАТЕРИАЛЫ!$H$2:$H$9000,MATCH($N169,МАТЕРИАЛЫ!$L$2:$L$9000,0))*IF(INDEX(МАТЕРИАЛЫ!$I$2:$I$9000,MATCH($N169,МАТЕРИАЛЫ!$L$2:$L$9000,0))="USD",КурсUSD,IF(INDEX(МАТЕРИАЛЫ!$I$2:$I$9000,MATCH($N169,МАТЕРИАЛЫ!$L$2:$L$9000,0))="EUR",КурсEUR,IF(INDEX(МАТЕРИАЛЫ!$I$2:$I$9000,MATCH($N169,МАТЕРИАЛЫ!$L$2:$L$9000,0))="CNY",КурсCNY,1)))*(1+N($H169)/100),0),N($O169))*(1-MEDIAN(0,N(ДисконтТендер),1)))) -> 0 | U169: =IF($L169="да",MAX($U$1:$U168)+1,"") | V169: =IF($A169="","",$B169) -> Р3 | W169: =IF($U169="","",IF($U169=1,1,IF($V169<>IFERROR(INDEX($V$2:$V$1058,MATCH($U169-1,$U$2:$U$1058,0)),"~"),1,0))) | X169: =IF($U169="","",$U169+SUMIFS($W$2:$W$1058,$U$2:$U$1058,"<="&$U169)) | Y169: =IF($A169="","",IF(AND(LEFT($G169,3)="ДОК",$N169<>""),IFERROR(INDEX(Документация!$G$2:$G$57,MATCH($N169,Документация!$F$2:$F$57,0)),$D169),$D169&IF(AND(LEFT($G169,3)<>"ДОК",$N169<>"")," — "&IFERROR(INDEX(МАТЕРИАЛЫ!$C$2:$C$9000,MATCH($N169,МАТЕРИАЛЫ!$L$2:$L$9000,0)),""),""))) -> Устройство перегородок из ГКЛ толщ. 12 мм. "Кнауф" с одинарным металлическим каркасом и двухслойной обшивкой с обеих сторон (включая перфорированные уголки на внешние углы) | Z169: =IF($B169="","",$B169&" · "&IFERROR(VLOOKUP($B169,спрРазделы,2,0),"")) -> Р3 · Внутренние строительные работы
A170: РАБ.Р3.1.009 | B170: Р3 | C170: 1 | D170: Устройство перегородки / облицовки из ГКЛ | E170: м2 | F170: 1305.22 | G170: ГКЛ | H170: 5 | I170: ТС ЕР | P170: =IF($L170="да",ROUND(N($M170)*$S170,2),"") | Q170: =IF($L170="да",ROUND(N($M170)*$T170,2),"") | R170: =IF($L170="да",N($P170)+N($Q170),"") | S170: =IF($A170="","",IF(AND(LEFT($G170,3)="ДОК",$N170<>""),IFERROR(INDEX(Документация!$E$2:$E$57,MATCH($N170,Документация!$F$2:$F$57,0)),0),N($F170))*(1-MEDIAN(0,N(ДисконтТендер),1))) -> 1305.22 | T170: =IF($A170="","",IF(AND(LEFT($G170,3)="ДОК",$N170<>""),0,IF(AND(LEFT($G170,3)<>"ДОК",$N170<>""),IFERROR(INDEX(МАТЕРИАЛЫ!$H$2:$H$9000,MATCH($N170,МАТЕРИАЛЫ!$L$2:$L$9000,0))*IF(INDEX(МАТЕРИАЛЫ!$I$2:$I$9000,MATCH($N170,МАТЕРИАЛЫ!$L$2:$L$9000,0))="USD",КурсUSD,IF(INDEX(МАТЕРИАЛЫ!$I$2:$I$9000,MATCH($N170,МАТЕРИАЛЫ!$L$2:$L$9000,0))="EUR",КурсEUR,IF(INDEX(МАТЕРИАЛЫ!$I$2:$I$9000,MATCH($N170,МАТЕРИАЛЫ!$L$2:$L$9000,0))="CNY",КурсCNY,1)))*(1+N($H170)/100),0),N($O170))*(1-MEDIAN(0,N(ДисконтТендер),1)))) -> 0 | U170: =IF($L170="да",MAX($U$1:$U169)+1,"") | V170: =IF($A170="","",$B170) -> Р3 | W170: =IF($U170="","",IF($U170=1,1,IF($V170<>IFERROR(INDEX($V$2:$V$1058,MATCH($U170-1,$U$2:$U$1058,0)),"~"),1,0))) | X170: =IF($U170="","",$U170+SUMIFS($W$2:$W$1058,$U$2:$U$1058,"<="&$U170)) | Y170: =IF($A170="","",IF(AND(LEFT($G170,3)="ДОК",$N170<>""),IFERROR(INDEX(Документация!$G$2:$G$57,MATCH($N170,Документация!$F$2:$F$57,0)),$D170),$D170&IF(AND(LEFT($G170,3)<>"ДОК",$N170<>"")," — "&IFERROR(INDEX(МАТЕРИАЛЫ!$C$2:$C$9000,MATCH($N170,МАТЕРИАЛЫ!$L$2:$L$9000,0)),""),""))) -> Устройство перегородки / облицовки из ГКЛ | Z170: =IF($B170="","",$B170&" · "&IFERROR(VLOOKUP($B170,спрРазделы,2,0),"")) -> Р3 · Внутренние строительные работы
A171: РАБ.Р3.1.010 | B171: Р3 | C171: 1 | D171: Устройство перегородки / облицовки из ГКЛ | E171: м2 | F171: 1515.98 | G171: ГКЛ | H171: 5 | I171: ТС ЕР | P171: =IF($L171="да",ROUND(N($M171)*$S171,2),"") | Q171: =IF($L171="да",ROUND(N($M171)*$T171,2),"") | R171: =IF($L171="да",N($P171)+N($Q171),"") | S171: =IF($A171="","",IF(AND(LEFT($G171,3)="ДОК",$N171<>""),IFERROR(INDEX(Документация!$E$2:$E$57,MATCH($N171,Документация!$F$2:$F$57,0)),0),N($F171))*(1-MEDIAN(0,N(ДисконтТендер),1))) -> 1515.98 | T171: =IF($A171="","",IF(AND(LEFT($G171,3)="ДОК",$N171<>""),0,IF(AND(LEFT($G171,3)<>"ДОК",$N171<>""),IFERROR(INDEX(МАТЕРИАЛЫ!$H$2:$H$9000,MATCH($N171,МАТЕРИАЛЫ!$L$2:$L$9000,0))*IF(INDEX(МАТЕРИАЛЫ!$I$2:$I$9000,MATCH($N171,МАТЕРИАЛЫ!$L$2:$L$9000,0))="USD",КурсUSD,IF(INDEX(МАТЕРИАЛЫ!$I$2:$I$9000,MATCH($N171,МАТЕРИАЛЫ!$L$2:$L$9000,0))="EUR",КурсEUR,IF(INDEX(МАТЕРИАЛЫ!$I$2:$I$9000,MATCH($N171,МАТЕРИАЛЫ!$L$2:$L$9000,0))="CNY",КурсCNY,1)))*(1+N($H171)/100),0),N($O171))*(1-MEDIAN(0,N(ДисконтТендер),1)))) -> 0 | U171: =IF($L171="да",MAX($U$1:$U170)+1,"") | V171: =IF($A171="","",$B171) -> Р3 | W171: =IF($U171="","",IF($U171=1,1,IF($V171<>IFERROR(INDEX($V$2:$V$1058,MATCH($U171-1,$U$2:$U$1058,0)),"~"),1,0))) | X171: =IF($U171="","",$U171+SUMIFS($W$2:$W$1058,$U$2:$U$1058,"<="&$U171)) | Y171: =IF($A171="","",IF(AND(LEFT($G171,3)="ДОК",$N171<>""),IFERROR(INDEX(Документация!$G$2:$G$57,MATCH($N171,Документация!$F$2:$F$57,0)),$D171),$D171&IF(AND(LEFT($G171,3)<>"ДОК",$N171<>"")," — "&IFERROR(INDEX(МАТЕРИАЛЫ!$C$2:$C$9000,MATCH($N171,МАТЕРИАЛЫ!$L$2:$L$9000,0)),""),""))) -> Устройство перегородки / облицовки из ГКЛ | Z171: =IF($B171="","",$B171&" · "&IFERROR(VLOOKUP($B171,спрРазделы,2,0),"")) -> Р3 · Внутренние строительные работы
A172: РАБ.Р3.1.011 | B172: Р3 | C172: 1 | D172: Облицовка стен гипсокартонными листами (ГКЛ) "Кнауф" в один слой на клее (включая перфорированные уголки на внешние углы) | E172: м2 | F172: 1357.2 | G172: ГКЛ | H172: 5 | I172: ТС ЕР | P172: =IF($L172="да",ROUND(N($M172)*$S172,2),"") | Q172: =IF($L172="да",ROUND(N($M172)*$T172,2),"") | R172: =IF($L172="да",N($P172)+N($Q172),"") | S172: =IF($A172="","",IF(AND(LEFT($G172,3)="ДОК",$N172<>""),IFERROR(INDEX(Документация!$E$2:$E$57,MATCH($N172,Документация!$F$2:$F$57,0)),0),N($F172))*(1-MEDIAN(0,N(ДисконтТендер),1))) -> 1357.2 | T172: =IF($A172="","",IF(AND(LEFT($G172,3)="ДОК",$N172<>""),0,IF(AND(LEFT($G172,3)<>"ДОК",$N172<>""),IFERROR(INDEX(МАТЕРИАЛЫ!$H$2:$H$9000,MATCH($N172,МАТЕРИАЛЫ!$L$2:$L$9000,0))*IF(INDEX(МАТЕРИАЛЫ!$I$2:$I$9000,MATCH($N172,МАТЕРИАЛЫ!$L$2:$L$9000,0))="USD",КурсUSD,IF(INDEX(МАТЕРИАЛЫ!$I$2:$I$9000,MATCH($N172,МАТЕРИАЛЫ!$L$2:$L$9000,0))="EUR",КурсEUR,IF(INDEX(МАТЕРИАЛЫ!$I$2:$I$9000,MATCH($N172,МАТЕРИАЛЫ!$L$2:$L$9000,0))="CNY",КурсCNY,1)))*(1+N($H172)/100),0),N($O172))*(1-MEDIAN(0,N(ДисконтТендер),1)))) -> 0 | U172: =IF($L172="да",MAX($U$1:$U171)+1,"") | V172: =IF($A172="","",$B172) -> Р3 | W172: =IF($U172="","",IF($U172=1,1,IF($V172<>IFERROR(INDEX($V$2:$V$1058,MATCH($U172-1,$U$2:$U$1058,0)),"~"),1,0))) | X172: =IF($U172="","",$U172+SUMIFS($W$2:$W$1058,$U$2:$U$1058,"<="&$U172)) | Y172: =IF($A172="","",IF(AND(LEFT($G172,3)="ДОК",$N172<>""),IFERROR(INDEX(Документация!$G$2:$G$57,MATCH($N172,Документация!$F$2:$F$57,0)),$D172),$D172&IF(AND(LEFT($G172,3)<>"ДОК",$N172<>"")," — "&IFERROR(INDEX(МАТЕРИАЛЫ!$C$2:$C$9000,MATCH($N172,МАТЕРИАЛЫ!$L$2:$L$9000,0)),""),""))) -> Облицовка стен гипсокартонными листами (ГКЛ) "Кнауф" в один слой на клее (включая перфорированные уголки на внешние углы) | Z172: =IF($B172="","",$B172&" · "&IFERROR(VLOOKUP($B172,спрРазделы,2,0),"")) -> Р3 · Внутренние строительные работы
A173: РАБ.Р3.1.012 | B173: Р3 | C173: 1 | D173: Устройство оконных откосов из ГКЛВ толщ. 12 мм. | E173: м2 | F173: 1305 | G173: ГКЛ | H173: 5 | I173: ТС ЕР | P173: =IF($L173="да",ROUND(N($M173)*$S173,2),"") | Q173: =IF($L173="да",ROUND(N($M173)*$T173,2),"") | R173: =IF($L173="да",N($P173)+N($Q173),"") | S173: =IF($A173="","",IF(AND(LEFT($G173,3)="ДОК",$N173<>""),IFERROR(INDEX(Документация!$E$2:$E$57,MATCH($N173,Документация!$F$2:$F$57,0)),0),N($F173))*(1-MEDIAN(0,N(ДисконтТендер),1))) -> 1305 | T173: =IF($A173="","",IF(AND(LEFT($G173,3)="ДОК",$N173<>""),0,IF(AND(LEFT($G173,3)<>"ДОК",$N173<>""),IFERROR(INDEX(МАТЕРИАЛЫ!$H$2:$H$9000,MATCH($N173,МАТЕРИАЛЫ!$L$2:$L$9000,0))*IF(INDEX(МАТЕРИАЛЫ!$I$2:$I$9000,MATCH($N173,МАТЕРИАЛЫ!$L$2:$L$9000,0))="USD",КурсUSD,IF(INDEX(МАТЕРИАЛЫ!$I$2:$I$9000,MATCH($N173,МАТЕРИАЛЫ!$L$2:$L$9000,0))="EUR",КурсEUR,IF(INDEX(МАТЕРИАЛЫ!$I$2:$I$9000,MATCH($N173,МАТЕРИАЛЫ!$L$2:$L$9000,0))="CNY",КурсCNY,1)))*(1+N($H173)/100),0),N($O173))*(1-MEDIAN(0,N(ДисконтТендер),1)))) -> 0 | U173: =IF($L173="да",MAX($U$1:$U172)+1,"") | V173: =IF($A173="","",$B173) -> Р3 | W173: =IF($U173="","",IF($U173=1,1,IF($V173<>IFERROR(INDEX($V$2:$V$1058,MATCH($U173-1,$U$2:$U$1058,0)),"~"),1,0))) | X173: =IF($U173="","",$U173+SUMIFS($W$2:$W$1058,$U$2:$U$1058,"<="&$U173)) | Y173: =IF($A173="","",IF(AND(LEFT($G173,3)="ДОК",$N173<>""),IFERROR(INDEX(Документация!$G$2:$G$57,MATCH($N173,Документация!$F$2:$F$57,0)),$D173),$D173&IF(AND(LEFT($G173,3)<>"ДОК",$N173<>"")," — "&IFERROR(INDEX(МАТЕРИАЛЫ!$C$2:$C$9000,MATCH($N173,МАТЕРИАЛЫ!$L$2:$L$9000,0)),""),""))) -> Устройство оконных откосов из ГКЛВ толщ. 12 мм. | Z173: =IF($B173="","",$B173&" · "&IFERROR(VLOOKUP($B173,спрРазделы,2,0),"")) -> Р3 · Внутренние строительные работы
A174: РАБ.Р3.1.013 | B174: Р3 | C174: 1 | D174: Тепло- и звукоизоляция стен из минеральных материалов | E174: м2 | F174: 106.14 | G174: ИЗОЛ | H174: 5 | I174: ТС ЕР | P174: =IF($L174="да",ROUND(N($M174)*$S174,2),"") | Q174: =IF($L174="да",ROUND(N($M174)*$T174,2),"") | R174: =IF($L174="да",N($P174)+N($Q174),"") | S174: =IF($A174="","",IF(AND(LEFT($G174,3)="ДОК",$N174<>""),IFERROR(INDEX(Документация!$E$2:$E$57,MATCH($N174,Документация!$F$2:$F$57,0)),0),N($F174))*(1-MEDIAN(0,N(ДисконтТендер),1))) -> 106.14 | T174: =IF($A174="","",IF(AND(LEFT($G174,3)="ДОК",$N174<>""),0,IF(AND(LEFT($G174,3)<>"ДОК",$N174<>""),IFERROR(INDEX(МАТЕРИАЛЫ!$H$2:$H$9000,MATCH($N174,МАТЕРИАЛЫ!$L$2:$L$9000,0))*IF(INDEX(МАТЕРИАЛЫ!$I$2:$I$9000,MATCH($N174,МАТЕРИАЛЫ!$L$2:$L$9000,0))="USD",КурсUSD,IF(INDEX(МАТЕРИАЛЫ!$I$2:$I$9000,MATCH($N174,МАТЕРИАЛЫ!$L$2:$L$9000,0))="EUR",КурсEUR,IF(INDEX(МАТЕРИАЛЫ!$I$2:$I$9000,MATCH($N174,МАТЕРИАЛЫ!$L$2:$L$9000,0))="CNY",КурсCNY,1)))*(1+N($H174)/100),0),N($O174))*(1-MEDIAN(0,N(ДисконтТендер),1)))) -> 0 | U174: =IF($L174="да",MAX($U$1:$U173)+1,"") | V174: =IF($A174="","",$B174) -> Р3 | W174: =IF($U174="","",IF($U174=1,1,IF($V174<>IFERROR(INDEX($V$2:$V$1058,MATCH($U174-1,$U$2:$U$1058,0)),"~"),1,0))) | X174: =IF($U174="","",$U174+SUMIFS($W$2:$W$1058,$U$2:$U$1058,"<="&$U174)) | Y174: =IF($A174="","",IF(AND(LEFT($G174,3)="ДОК",$N174<>""),IFERROR(INDEX(Документация!$G$2:$G$57,MATCH($N174,Документация!$F$2:$F$57,0)),$D174),$D174&IF(AND(LEFT($G174,3)<>"ДОК",$N174<>"")," — "&IFERROR(INDEX(МАТЕРИАЛЫ!$C$2:$C$9000,MATCH($N174,МАТЕРИАЛЫ!$L$2:$L$9000,0)),""),""))) -> Тепло- и звукоизоляция стен из минеральных материалов | Z174: =IF($B174="","",$B174&" · "&IFERROR(VLOOKUP($B174,спрРазделы,2,0),"")) -> Р3 · Внутренние строительные работы
A175: РАБ.Р3.1.014 | B175: Р3 | C175: 1 | D175: Штукатурка стен | E175: м2 | F175: 977.08 | H175: 0 | I175: ТС ЕР | P175: =IF($L175="да",ROUND(N($M175)*$S175,2),"") | Q175: =IF($L175="да",ROUND(N($M175)*$T175,2),"") | R175: =IF($L175="да",N($P175)+N($Q175),"") | S175: =IF($A175="","",IF(AND(LEFT($G175,3)="ДОК",$N175<>""),IFERROR(INDEX(Документация!$E$2:$E$57,MATCH($N175,Документация!$F$2:$F$57,0)),0),N($F175))*(1-MEDIAN(0,N(ДисконтТендер),1))) -> 977.08 | T175: =IF($A175="","",IF(AND(LEFT($G175,3)="ДОК",$N175<>""),0,IF(AND(LEFT($G175,3)<>"ДОК",$N175<>""),IFERROR(INDEX(МАТЕРИАЛЫ!$H$2:$H$9000,MATCH($N175,МАТЕРИАЛЫ!$L$2:$L$9000,0))*IF(INDEX(МАТЕРИАЛЫ!$I$2:$I$9000,MATCH($N175,МАТЕРИАЛЫ!$L$2:$L$9000,0))="USD",КурсUSD,IF(INDEX(МАТЕРИАЛЫ!$I$2:$I$9000,MATCH($N175,МАТЕРИАЛЫ!$L$2:$L$9000,0))="EUR",КурсEUR,IF(INDEX(МАТЕРИАЛЫ!$I$2:$I$9000,MATCH($N175,МАТЕРИАЛЫ!$L$2:$L$9000,0))="CNY",КурсCNY,1)))*(1+N($H175)/100),0),N($O175))*(1-MEDIAN(0,N(ДисконтТендер),1)))) -> 0 | U175: =IF($L175="да",MAX($U$1:$U174)+1,"") | V175: =IF($A175="","",$B175) -> Р3 | W175: =IF($U175="","",IF($U175=1,1,IF($V175<>IFERROR(INDEX($V$2:$V$1058,MATCH($U175-1,$U$2:$U$1058,0)),"~"),1,0))) | X175: =IF($U175="","",$U175+SUMIFS($W$2:$W$1058,$U$2:$U$1058,"<="&$U175)) | Y175: =IF($A175="","",IF(AND(LEFT($G175,3)="ДОК",$N175<>""),IFERROR(INDEX(Документация!$G$2:$G$57,MATCH($N175,Документация!$F$2:$F$57,0)),$D175),$D175&IF(AND(LEFT($G175,3)<>"ДОК",$N175<>"")," — "&IFERROR(INDEX(МАТЕРИАЛЫ!$C$2:$C$9000,MATCH($N175,МАТЕРИАЛЫ!$L$2:$L$9000,0)),""),""))) -> Штукатурка стен | Z175: =IF($B175="","",$B175&" · "&IFERROR(VLOOKUP($B175,спрРазделы,2,0),"")) -> Р3 · Внутренние строительные работы
A176: РАБ.Р3.1.015 | B176: Р3 | C176: 1 | D176: Устройство штроб в кирпичных стенах | E176: м.п. | F176: 616.1 | G176: КЛАДКА | H176: 5 | I176: ТС ЕР | P176: =IF($L176="да",ROUND(N($M176)*$S176,2),"") | Q176: =IF($L176="да",ROUND(N($M176)*$T176,2),"") | R176: =IF($L176="да",N($P176)+N($Q176),"") | S176: =IF($A176="","",IF(AND(LEFT($G176,3)="ДОК",$N176<>""),IFERROR(INDEX(Документация!$E$2:$E$57,MATCH($N176,Документация!$F$2:$F$57,0)),0),N($F176))*(1-MEDIAN(0,N(ДисконтТендер),1))) -> 616.1 | T176: =IF($A176="","",IF(AND(LEFT($G176,3)="ДОК",$N176<>""),0,IF(AND(LEFT($G176,3)<>"ДОК",$N176<>""),IFERROR(INDEX(МАТЕРИАЛЫ!$H$2:$H$9000,MATCH($N176,МАТЕРИАЛЫ!$L$2:$L$9000,0))*IF(INDEX(МАТЕРИАЛЫ!$I$2:$I$9000,MATCH($N176,МАТЕРИАЛЫ!$L$2:$L$9000,0))="USD",КурсUSD,IF(INDEX(МАТЕРИАЛЫ!$I$2:$I$9000,MATCH($N176,МАТЕРИАЛЫ!$L$2:$L$9000,0))="EUR",КурсEUR,IF(INDEX(МАТЕРИАЛЫ!$I$2:$I$9000,MATCH($N176,МАТЕРИАЛЫ!$L$2:$L$9000,0))="CNY",КурсCNY,1)))*(1+N($H176)/100),0),N($O176))*(1-MEDIAN(0,N(ДисконтТендер),1)))) -> 0 | U176: =IF($L176="да",MAX($U$1:$U175)+1,"") | V176: =IF($A176="","",$B176) -> Р3 | W176: =IF($U176="","",IF($U176=1,1,IF($V176<>IFERROR(INDEX($V$2:$V$1058,MATCH($U176-1,$U$2:$U$1058,0)),"~"),1,0))) | X176: =IF($U176="","",$U176+SUMIFS($W$2:$W$1058,$U$2:$U$1058,"<="&$U176)) | Y176: =IF($A176="","",IF(AND(LEFT($G176,3)="ДОК",$N176<>""),IFERROR(INDEX(Документация!$G$2:$G$57,MATCH($N176,Документация!$F$2:$F$57,0)),$D176),$D176&IF(AND(LEFT($G176,3)<>"ДОК",$N176<>"")," — "&IFERROR(INDEX(МАТЕРИАЛЫ!$C$2:$C$9000,MATCH($N176,МАТЕРИАЛЫ!$L$2:$L$9000,0)),""),""))) -> Устройство штроб в кирпичных стенах | Z176: =IF($B176="","",$B176&" · "&IFERROR(VLOOKUP($B176,спрРазделы,2,0),"")) -> Р3 · Внутренние строительные работы
