Workbook

Sheet Смета ЕР (общ) 
F1: Формат объекта | M1: ККО | U1: курс $ | V1: 81
F2: дверной | L2: Адрес объекта: | M2: СПб, улюЛьва Толстого д..9 | U2: курс Евро | V2: 95
F3: Плoщадь объекта (м.кв.): | L3: Плащадь объекта: | M3: 1900 | U3: Дисконт по тендеру | V3: 0
F4: Срок проведения работ | L4: Срок проведения работ | M4: Согласно план-графику производства работ | U4: курс Юань | V4: 10.94
F5: ПОДРЯДЧИК: | L5: ПОДРЯДЧИК:
F6: Юридический адрес: | L6: Юридический адрес:
F7: Электронный адрес: | L7: Электронный адрес:
F8: Контактное лицо (Ф.И.О.) : | L8: Контактное лицо (Ф.И.О.) :
F9: Контактный телефон: | L9: Контактный телефон:
F10: Реквизиты: | L10: Реквизиты:
F11: Сумма по смете: | L11: Сумма по смете:
A14: Раздел | B14: Подраздел | C14: Подраздел подраздела | D14: Пункт подраздела | E14: Новый номенклатурный номер | F14: № | L14: Наименование работ и затрат | M14: Един. изм. | N14: Кол - во. (объем) | O14: ЕР цена работ, руб.* | P14: ЕР цена материалов и оборудования, руб.* | Q14: Цена работ, руб. * | R14: Цена материалов и оборудования, руб. * | S14: Стоимость работ, руб. * | T14: Стоимость материалов и оборудования руб. * | U14: Примечание | Y14: Кол - во. (объем)
A15: Р1 | B15: 0 | D15: 0 | E15: =CONCATENATE('Смета ЕР (общ) '!$A15,".",'Смета ЕР (общ) '!$B15,".",'Смета ЕР (общ) '!$D15) -> Р1.0.0 | F15: 1 | L15: Раздел №1. Проектные работы и согласования | N15: =N16 -> 0 | S15: =ROUND(S16,2) -> 0 | T15: =ROUND(T16,2) -> 0 | Y15: 1498
A16: Р1 | B16: 1 | D16: 0 | E16: =CONCATENATE('Смета ЕР (общ) '!$A16,".",'Смета ЕР (общ) '!$B16,".",'Смета ЕР (общ) '!$D16) -> Р1.1.0 | F16: =IF(N16>0,F15+1,F15) -> 1 | G16: Раздел №1. Проектные работы и согласования | H16: 1.1.0 Проектные работы и согласования | L16: 1.1.0 Проектные работы и согласования | N16: =SUM(N17:N108) -> 0 | S16: =SUM(S17:S108) -> 0 | T16: =SUM(T17:T108) -> 0 | Y16: 1498
A17: Р1 | B17: 1 | D17: 1 | E17: =CONCATENATE('Смета ЕР (общ) '!$A17,".",'Смета ЕР (общ) '!$B17,".",'Смета ЕР (общ) '!$D17) -> Р1.1.1 | F17: =IF(N17>0,F16+1,F16) -> 1 | G17: Раздел №1. Проектные работы и согласования | H17: 1.1.0 Проектные работы и согласования | J17: Техническое обследование состояния несущих конструкций помещения с подготовкой рекомендаций по усилению (Техничесекое заключение о конструктиве - "ТЗК") | K17: (для помещений от 100 до 450 м.кв) | L17: Техническое обследование состояния несущих конструкций помещения с подготовкой рекомендаций по усилению (Техничесекое заключение о конструктиве - "ТЗК") (для помещений от 100 до 450 м.кв) | M17: м2 | O17: ='[1]Проектирование 100-450'!E36*1.05 -> 3675 | P17: 0 | Q17: =ROUND(O17-O17*$V$3,2) -> 3675 | R17: =ROUND(P17-P17*$V$3,2) -> 0 | S17: =ROUND('Смета ЕР (общ) '!$N17*'Смета ЕР (общ) '!$Q17,2) -> 0 | T17: =ROUND('Смета ЕР (общ) '!$N17*'Смета ЕР (общ) '!$R17,2) -> 0
A18: Р1 | B18: 1 | D18: 44 | E18: =CONCATENATE('Смета ЕР (общ) '!$A18,".",'Смета ЕР (общ) '!$B18,".",'Смета ЕР (общ) '!$D18) -> Р1.1.44 | F18: =IF(N18>0,F17+1,F17) -> 1 | G18: Раздел №1. Проектные работы и согласования | H18: 1.1.0 Проектные работы и согласования | J18: Эскизный проект фасада и Колористический паспорт с указанием ведомости отделки и проектным решением со спецификацией элементов (крыльцо, пандус, навесы, колонны и т.д.) | K18: (для фасадов от 100 до 450 м.кв) | L18: Эскизный проект фасада и Колористический паспорт с указанием ведомости отделки и проектным решением со спецификацией элементов (крыльцо, пандус, навесы, колонны и т.д.)(для фасадов от 100 до 450 м.кв) | M18: м2 | O18: ='[1]Проектирование 100-450'!E37*1.05 -> 7822.5 | P18: 0 | Q18: =ROUND(O18-O18*$V$3,2) -> 7822.5 | R18: =ROUND(P18-P18*$V$3,2) -> 0 | S18: =ROUND('Смета ЕР (общ) '!$N18*'Смета ЕР (общ) '!$Q18,2) -> 0 | T18: =ROUND('Смета ЕР (общ) '!$N18*'Смета ЕР (общ) '!$R18,2) -> 0
A19: Р1 | B19: 1 | D19: 2 | E19: =CONCATENATE('Смета ЕР (общ) '!$A19,".",'Смета ЕР (общ) '!$B19,".",'Смета ЕР (общ) '!$D19) -> Р1.1.2 | F19: =IF(N19>0,F18+1,F18) -> 1 | G19: Раздел №1. Проектные работы и согласования | H19: 1.1.0 Проектные работы и согласования | I19: Рабочая документация | J19: Рабочая документация по усилению/устройству несущих конструкций ("КР"), включая пояснительную записку | K19: (для помещений от 100 до 450 м.кв) | L19: Рабочая документация по усилению/устройству несущих конструкций ("КР"), включая пояснительную записку (для помещений от 100 до 450 м.кв) | M19: м2 | O19: ='[1]Проектирование 100-450'!E18*1.05 -> 135.45 | P19: 0 | Q19: =ROUND(O19-O19*$V$3,2) -> 135.45 | R19: =ROUND(P19-P19*$V$3,2) -> 0 | S19: =ROUND('Смета ЕР (общ) '!$N19*'Смета ЕР (общ) '!$Q19,2) -> 0 | T19: =ROUND('Смета ЕР (общ) '!$N19*'Смета ЕР (общ) '!$R19,2) -> 0
A20: Р1 | B20: 1 | D20: 3 | E20: =CONCATENATE('Смета ЕР (общ) '!$A20,".",'Смета ЕР (общ) '!$B20,".",'Смета ЕР (общ) '!$D20) -> Р1.1.3 | F20: =IF(N20>0,F19+1,F19) -> 1 | G20: Раздел №1. Проектные работы и согласования | H20: 1.1.0 Проектные работы и согласования | I20: Рабочая документация | J20: Рабочая документация "Архитектурные решения" ("АР"), включая пояснительную записку | K20: (для помещений от 100 до 450 м.кв) | L20: Рабочая документация "Архитектурные решения" ("АР"), включая пояснительную записку (для помещений от 100 до 450 м.кв) | M20: м2 | O20: ='[1]Проектирование 100-450'!E19*1.05 -> 389.55 | P20: 0 | Q20: =ROUND(O20-O20*$V$3,2) -> 389.55 | R20: =ROUND(P20-P20*$V$3,2) -> 0 | S20: =ROUND('Смета ЕР (общ) '!$N20*'Смета ЕР (общ) '!$Q20,2) -> 0 | T20: =ROUND('Смета ЕР (общ) '!$N20*'Смета ЕР (общ) '!$R20,2) -> 0 | Y20: 214
A21: Р1 | B21: 1 | D21: 4 | E21: =CONCATENATE('Смета ЕР (общ) '!$A21,".",'Смета ЕР (общ) '!$B21,".",'Смета ЕР (общ) '!$D21) -> Р1.1.4 | F21: =IF(N21>0,F20+1,F20) -> 1 | G21: Раздел №1. Проектные работы и согласования | H21: 1.1.0 Проектные работы и согласования | I21: Рабочая документация | J21: Рабочая документация по электроснабжению и электроосвещению ("ЭОМ"), включая пояснительную записку | K21: (для помещений от 100 до 450 м.кв) | L21: Рабочая документация по электроснабжению и электроосвещению ("ЭОМ"), включая пояснительную записку (для помещений от 100 до 450 м.кв) | M21: м2 | O21: ='[1]Проектирование 100-450'!E20*1.05 -> 258.3 | P21: 0 | Q21: =ROUND(O21-O21*$V$3,2) -> 258.3 | R21: =ROUND(P21-P21*$V$3,2) -> 0 | S21: =ROUND('Смета ЕР (общ) '!$N21*'Смета ЕР (общ) '!$Q21,2) -> 0 | T21: =ROUND('Смета ЕР (общ) '!$N21*'Смета ЕР (общ) '!$R21,2) -> 0 | Y21: 214
A22: Р1 | B22: 1 | D22: 5 | E22: =CONCATENATE('Смета ЕР (общ) '!$A22,".",'Смета ЕР (общ) '!$B22,".",'Смета ЕР (общ) '!$D22) -> Р1.1.5 | F22: =IF(N22>0,F21+1,F21) -> 1 | G22: Раздел №1. Проектные работы и согласования | H22: 1.1.0 Проектные работы и согласования | I22: Рабочая документация | J22: Рабочая документация Системы вентиляции ("ОВиК-В"), включая пояснительную записку | K22: (для помещений от 100 до 450 м.кв) | L22: Рабочая документация Системы вентиляции ("ОВиК-В"), включая пояснительную записку (для помещений от 100 до 450 м.кв) | M22: м2 | O22: ='[1]Проектирование 100-450'!E21*1.05 -> 202.65 | P22: 0 | Q22: =ROUND(O22-O22*$V$3,2) -> 202.65 | R22: =ROUND(P22-P22*$V$3,2) -> 0 | S22: =ROUND('Смета ЕР (общ) '!$N22*'Смета ЕР (общ) '!$Q22,2) -> 0 | T22: =ROUND('Смета ЕР (общ) '!$N22*'Смета ЕР (общ) '!$R22,2) -> 0 | Y22: 214
A23: Р1 | B23: 1 | D23: 6 | E23: =CONCATENATE('Смета ЕР (общ) '!$A23,".",'Смета ЕР (общ) '!$B23,".",'Смета ЕР (общ) '!$D23) -> Р1.1.6 | F23: =IF(N23>0,F22+1,F22) -> 1 | G23: Раздел №1. Проектные работы и согласования | H23: 1.1.0 Проектные работы и согласования | I23: Рабочая документация | J23: Рабочая документация Системы кондиционирования ("ОВиК-К"), включая пояснительную записку | K23: (для помещений от 100 до 450 м.кв) | L23: Рабочая документация Системы кондиционирования ("ОВиК-К"), включая пояснительную записку (для помещений от 100 до 450 м.кв) | M23: м2 | O23: ='[1]Проектирование 100-450'!E22*1.05 -> 159.4845 | P23: 0 | Q23: =ROUND(O23-O23*$V$3,2) -> 159.48 | R23: =ROUND(P23-P23*$V$3,2) -> 0 | S23: =ROUND('Смета ЕР (общ) '!$N23*'Смета ЕР (общ) '!$Q23,2) -> 0 | T23: =ROUND('Смета ЕР (общ) '!$N23*'Смета ЕР (общ) '!$R23,2) -> 0 | Y23: 214
A24: Р1 | B24: 1 | D24: 7 | E24: =CONCATENATE('Смета ЕР (общ) '!$A24,".",'Смета ЕР (общ) '!$B24,".",'Смета ЕР (общ) '!$D24) -> Р1.1.7 | F24: =IF(N24>0,F23+1,F23) -> 1 | G24: Раздел №1. Проектные работы и согласования | H24: 1.1.0 Проектные работы и согласования | I24: Рабочая документация | J24: Рабочая документация Системы отопления ("ОВиК-О"), включая Пояснительную записку и Теплотехнический расчет | K24: (для помещений от 100 до 450 м.кв) | L24: Рабочая документация Системы отопления ("ОВиК-О"), включая Пояснительную записку и Теплотехнический расчет (для помещений от 100 до 450 м.кв) | M24: м2 | O24: ='[1]Проектирование 100-450'!E23*1.05 -> 123.9 | P24: 0 | Q24: =ROUND(O24-O24*$V$3,2) -> 123.9 | R24: =ROUND(P24-P24*$V$3,2) -> 0 | S24: =ROUND('Смета ЕР (общ) '!$N24*'Смета ЕР (общ) '!$Q24,2) -> 0 | T24: =ROUND('Смета ЕР (общ) '!$N24*'Смета ЕР (общ) '!$R24,2) -> 0 | Y24: 214
A25: Р1 | B25: 1 | D25: 8 | E25: =CONCATENATE('Смета ЕР (общ) '!$A25,".",'Смета ЕР (общ) '!$B25,".",'Смета ЕР (общ) '!$D25) -> Р1.1.8 | F25: =IF(N25>0,F24+1,F24) -> 1 | G25: Раздел №1. Проектные работы и согласования | H25: 1.1.0 Проектные работы и согласования | I25: Рабочая документация | J25: Рабочая документация Системы водоснабжения и канализации ("ВК"), включая пояснительную записку | K25: (для помещений от 100 до 450 м.кв) | L25: Рабочая документация Системы водоснабжения и канализации ("ВК"), включая пояснительную записку (для помещений от 100 до 450 м.кв) | M25: м2 | O25: ='[1]Проектирование 100-450'!E24*1.05 -> 130.2 | P25: 0 | Q25: =ROUND(O25-O25*$V$3,2) -> 130.2 | R25: =ROUND(P25-P25*$V$3,2) -> 0 | S25: =ROUND('Смета ЕР (общ) '!$N25*'Смета ЕР (общ) '!$Q25,2) -> 0 | T25: =ROUND('Смета ЕР (общ) '!$N25*'Смета ЕР (общ) '!$R25,2) -> 0 | Y25: 214
A26: Р1 | B26: 1 | D26: 9 | E26: =CONCATENATE('Смета ЕР (общ) '!$A26,".",'Смета ЕР (общ) '!$B26,".",'Смета ЕР (общ) '!$D26) -> Р1.1.9 | F26: =IF(N26>0,F25+1,F25) -> 1 | G26: Раздел №1. Проектные работы и согласования | H26: 1.1.0 Проектные работы и согласования | I26: Рабочая документация | J26: Рабочая документация Системы автоматической установки водяного пожаротушения ("АУВПТ"), (спринкерная, дренчерная, модульная система), включая пояснительную записку | K26: (для помещений от 100 до 450 м.кв) | L26: Рабочая документация Системы автоматической установки водяного пожаротушения ("АУВПТ"), (спринкерная, дренчерная, модульная система), включая пояснительную записку (для помещений от 100 до 450 м.кв) | M26: м2 | O26: ='[1]Проектирование 100-450'!E25*1.05 -> 91.6755 | P26: 0 | Q26: =ROUND(O26-O26*$V$3,2) -> 91.68 | R26: =ROUND(P26-P26*$V$3,2) -> 0 | S26: =ROUND('Смета ЕР (общ) '!$N26*'Смета ЕР (общ) '!$Q26,2) -> 0 | T26: =ROUND('Смета ЕР (общ) '!$N26*'Смета ЕР (общ) '!$R26,2) -> 0
A27: Р1 | B27: 1 | D27: 43 | E27: =CONCATENATE('Смета ЕР (общ) '!$A27,".",'Смета ЕР (общ) '!$B27,".",'Смета ЕР (общ) '!$D27) -> Р1.1.43 | F27: =IF(N27>0,F26+1,F26) -> 1 | G27: Раздел №1. Проектные работы и согласования | H27: 1.1.0 Проектные работы и согласования | I27: Рабочая документация | J27: Рабочая документация Системы Внутреннего противопожарного водопровода ("ВПВ"), включая пояснительную записку | K27: (для помещений от 100 до 450 м.кв) | L27: Рабочая документация Системы Внутреннего противопожарного водопровода ("ВПВ"), включая пояснительную записку (для помещений от 100 до 450 м.кв) | M27: м2 | O27: ='[1]Проектирование 100-450'!E26*1.05 -> 91.6755 | P27: 0 | Q27: =ROUND(O27-O27*$V$3,2) -> 91.68 | R27: =ROUND(P27-P27*$V$3,2) -> 0 | S27: =ROUND('Смета ЕР (общ) '!$N27*'Смета ЕР (общ) '!$Q27,2) -> 0 | T27: =ROUND('Смета ЕР (общ) '!$N27*'Смета ЕР (общ) '!$R27,2) -> 0
A28: Р1 | B28: 1 | D28: 10 | E28: =CONCATENATE('Смета ЕР (общ) '!$A28,".",'Смета ЕР (общ) '!$B28,".",'Смета ЕР (общ) '!$D28) -> Р1.1.10 | F28: =IF(N28>0,F27+1,F27) -> 1 | G28: Раздел №1. Проектные работы и согласования | H28: 1.1.0 Проектные работы и согласования | I28: Рабочая документация | J28: Рабочая документация Системы дымоудаления ("ДУ"), включая пояснительную записку | K28: (для помещений от 100 до 450 м.кв) | L28: Рабочая документация Системы дымоудаления ("ДУ"), включая пояснительную записку (для помещений от 100 до 450 м.кв) | M28: м2 | O28: ='[1]Проектирование 100-450'!E27*1.05 -> 103.95 | P28: 0 | Q28: =ROUND(O28-O28*$V$3,2) -> 103.95 | R28: =ROUND(P28-P28*$V$3,2) -> 0 | S28: =ROUND('Смета ЕР (общ) '!$N28*'Смета ЕР (общ) '!$Q28,2) -> 0 | T28: =ROUND('Смета ЕР (общ) '!$N28*'Смета ЕР (общ) '!$R28,2) -> 0
A29: Р1 | B29: 1 | D29: 11 | E29: =CONCATENATE('Смета ЕР (общ) '!$A29,".",'Смета ЕР (общ) '!$B29,".",'Смета ЕР (общ) '!$D29) -> Р1.1.11 | F29: =IF(N29>0,F28+1,F28) -> 1 | G29: Раздел №1. Проектные работы и согласования | H29: 1.1.0 Проектные работы и согласования | I29: Рабочая документация | J29: Рабочая документация "Автоматическая пожарная сигнализация" (АПС) | L29: Рабочая документация "Автоматическая пожарная сигнализация" (АПС) | M29: м2 | O29: ='[1]АПС, СОУЭ, ППА'!F13*1.05*0.1 -> 7.035 | P29: 0 | Q29: =ROUND(O29-O29*$V$3,2) -> 7.04 | R29: =ROUND(P29-P29*$V$3,2) -> 0 | S29: =ROUND('Смета ЕР (общ) '!$N29*'Смета ЕР (общ) '!$Q29,2) -> 0 | T29: =ROUND('Смета ЕР (общ) '!$N29*'Смета ЕР (общ) '!$R29,2) -> 0
A30: Р1 | B30: 1 | D30: 25 | E30: =CONCATENATE('Смета ЕР (общ) '!$A30,".",'Смета ЕР (общ) '!$B30,".",'Смета ЕР (общ) '!$D30) -> Р1.1.25 | F30: =IF(N30>0,F29+1,F29) -> 1 | G30: Раздел №1. Проектные работы и согласования | H30: 1.1.0 Проектные работы и согласования | I30: Рабочая документация | J30: Рабочая документация "Система оповещения и управления эвакуацией людей при пожаре" (СОУЭ) | L30: Рабочая документация "Система оповещения и управления эвакуацией людей при пожаре" (СОУЭ) | M30: м2 | O30: ='[1]АПС, СОУЭ, ППА'!F14*1.05*0.1 -> 4.095 | P30: 0 | Q30: =ROUND(O30-O30*$V$3,2) -> 4.1 | R30: =ROUND(P30-P30*$V$3,2) -> 0 | S30: =ROUND('Смета ЕР (общ) '!$N30*'Смета ЕР (общ) '!$Q30,2) -> 0 | T30: =ROUND('Смета ЕР (общ) '!$N30*'Смета ЕР (общ) '!$R30,2) -> 0
A31: Р1 | B31: 1 | D31: 26 | E31: =CONCATENATE('Смета ЕР (общ) '!$A31,".",'Смета ЕР (общ) '!$B31,".",'Смета ЕР (общ) '!$D31) -> Р1.1.26 | F31: =IF(N31>0,F30+1,F30) -> 1 | G31: Раздел №1. Проектные работы и согласования | H31: 1.1.0 Проектные работы и согласования | I31: Рабочая документация | J31: Рабочая документация "Автоматизация системы внутреннего противопожарного водопровода (ВПВ) | L31: Рабочая документация "Автоматизация системы внутреннего противопожарного водопровода (ВПВ) | M31: м2 | O31: ='[1]АПС, СОУЭ, ППА'!F16*1.05*0.1 -> 0.84 | P31: 0 | Q31: =ROUND(O31-O31*$V$3,2) -> 0.84 | R31: =ROUND(P31-P31*$V$3,2) -> 0 | S31: =ROUND('Смета ЕР (общ) '!$N31*'Смета ЕР (общ) '!$Q31,2) -> 0 | T31: =ROUND('Смета ЕР (общ) '!$N31*'Смета ЕР (общ) '!$R31,2) -> 0
A32: Р1 | B32: 1 | D32: 29 | E32: =CONCATENATE('Смета ЕР (общ) '!$A32,".",'Смета ЕР (общ) '!$B32,".",'Смета ЕР (общ) '!$D32) -> Р1.1.29 | F32: =IF(N32>0,F31+1,F31) -> 1 | G32: Раздел №1. Проектные работы и согласования | H32: 1.1.0 Проектные работы и согласования | I32: Рабочая документация | J32: Рабочая документация "Автоматизация системы противодымной вентиляции (ПДВ")" | L32: Рабочая документация "Автоматизация системы противодымной вентиляции (ПДВ")" | M32: м2 | O32: ='[1]АПС, СОУЭ, ППА'!F17*1.05*0.1 -> 2.625 | P32: 0 | Q32: =ROUND(O32-O32*$V$3,2) -> 2.63 | R32: =ROUND(P32-P32*$V$3,2) -> 0 | S32: =ROUND('Смета ЕР (общ) '!$N32*'Смета ЕР (общ) '!$Q32,2) -> 0 | T32: =ROUND('Смета ЕР (общ) '!$N32*'Смета ЕР (общ) '!$R32,2) -> 0
A33: Р1 | B33: 1 | D33: 30 | E33: =CONCATENATE('Смета ЕР (общ) '!$A33,".",'Смета ЕР (общ) '!$B33,".",'Смета ЕР (общ) '!$D33) -> Р1.1.30 | F33: =IF(N33>0,F32+1,F32) -> 1 | G33: Раздел №1. Проектные работы и согласования | H33: 1.1.0 Проектные работы и согласования | I33: Рабочая документация | J33: Рабочая документация "Автоматизация Системы отопления, вентиляции и кондиционирования (ОВиК)" | L33: Рабочая документация "Автоматизация Системы отопления, вентиляции и кондиционирования (ОВиК)" | M33: м2 | O33: ='[1]АПС, СОУЭ, ППА'!F18*1.05*0.1 -> 0.315 | P33: 0 | Q33: =ROUND(O33-O33*$V$3,2) -> 0.32 | R33: =ROUND(P33-P33*$V$3,2) -> 0 | S33: =ROUND('Смета ЕР (общ) '!$N33*'Смета ЕР (общ) '!$Q33,2) -> 0 | T33: =ROUND('Смета ЕР (общ) '!$N33*'Смета ЕР (общ) '!$R33,2) -> 0
A34: Р1 | B34: 1 | D34: 31 | E34: =CONCATENATE('Смета ЕР (общ) '!$A34,".",'Смета ЕР (общ) '!$B34,".",'Смета ЕР (общ) '!$D34) -> Р1.1.31 | F34: =IF(N34>0,F33+1,F33) -> 1 | G34: Раздел №1. Проектные работы и согласования | H34: 1.1.0 Проектные работы и согласования | I34: Рабочая документация | J34: Рабочая документация "Автоматизация Системы аварийного освещения (АО)" | L34: Рабочая документация "Автоматизация Системы аварийного освещения (АО)" | M34: м2 | O34: ='[1]АПС, СОУЭ, ППА'!F19*1.05*0.1 -> 0.105 | P34: 0 | Q34: =ROUND(O34-O34*$V$3,2) -> 0.11 | R34: =ROUND(P34-P34*$V$3,2) -> 0 | S34: =ROUND('Смета ЕР (общ) '!$N34*'Смета ЕР (общ) '!$Q34,2) -> 0 | T34: =ROUND('Смета ЕР (общ) '!$N34*'Смета ЕР (общ) '!$R34,2) -> 0
A35: Р1 | B35: 1 | D35: 33 | E35: =CONCATENATE('Смета ЕР (общ) '!$A35,".",'Смета ЕР (общ) '!$B35,".",'Смета ЕР (общ) '!$D35) -> Р1.1.33 | F35: =IF(N35>0,F34+1,F34) -> 1 | G35: Раздел №1. Проектные работы и согласования | H35: 1.1.0 Проектные работы и согласования | I35: Рабочая документация | J35: Рабочая документация "Автоматизации лифтовового хозяйства" | L35: Рабочая документация "Автоматизации лифтовового хозяйства" | M35: м2 | O35: ='[1]АПС, СОУЭ, ППА'!F20*1.05*0.1 -> 0.105 | P35: 0 | Q35: =ROUND(O35-O35*$V$3,2) -> 0.11 | R35: =ROUND(P35-P35*$V$3,2) -> 0 | S35: =ROUND('Смета ЕР (общ) '!$N35*'Смета ЕР (общ) '!$Q35,2) -> 0 | T35: =ROUND('Смета ЕР (общ) '!$N35*'Смета ЕР (общ) '!$R35,2) -> 0
A36: Р1 | B36: 1 | D36: 36 | E36: =CONCATENATE('Смета ЕР (общ) '!$A36,".",'Смета ЕР (общ) '!$B36,".",'Смета ЕР (общ) '!$D36) -> Р1.1.36 | F36: =IF(N36>0,F35+1,F35) -> 1 | G36: Раздел №1. Проектные работы и согласования | H36: 1.1.0 Проектные работы и согласования | I36: Рабочая документация | J36: Рабочая документация "Автоматизации Системы контроля управления доступом (СКУД)" | L36: Рабочая документация "Автоматизации Системы контроля управления доступом (СКУД)" | M36: м2 | O36: ='[1]АПС, СОУЭ, ППА'!F21*1.05*0.1 -> 0.105 | P36: 0 | Q36: =ROUND(O36-O36*$V$3,2) -> 0.11 | R36: =ROUND(P36-P36*$V$3,2) -> 0 | S36: =ROUND('Смета ЕР (общ) '!$N36*'Смета ЕР (общ) '!$Q36,2) -> 0 | T36: =ROUND('Смета ЕР (общ) '!$N36*'Смета ЕР (общ) '!$R36,2) -> 0
A37: Р1 | B37: 1 | D37: 37 | E37: =CONCATENATE('Смета ЕР (общ) '!$A37,".",'Смета ЕР (общ) '!$B37,".",'Смета ЕР (общ) '!$D37) -> Р1.1.37 | F37: =IF(N37>0,F36+1,F36) -> 1 | G37: Раздел №1. Проектные работы и согласования | H37: 1.1.0 Проектные работы и согласования | J37: Техническое обследование состояния несущих конструкций помещения с подготовкой рекомендаций по усилению в зоне расположения депозитария, кассового узла и банкоматов (Техничесекое заключение о конструктиве - "ТЗК") | K37: (для помещений менее 100 м.кв) | L37: Техническое обследование состояния несущих конструкций помещения с подготовкой рекомендаций по усилению в зоне расположения депозитария, кассового узла и банкоматов (Техничесекое заключение о конструктиве - "ТЗК")(для помещений менее 100 м.кв) | M37: м2 | O37: ='[1]Проектирование до 100'!E35*1.05 -> 3675 | P37: 0 | Q37: =ROUND(O37-O37*$V$3,2) -> 3675 | R37: =ROUND(P37-P37*$V$3,2) -> 0 | S37: =ROUND('Смета ЕР (общ) '!$N37*'Смета ЕР (общ) '!$Q37,2) -> 0 | T37: =ROUND('Смета ЕР (общ) '!$N37*'Смета ЕР (общ) '!$R37,2) -> 0
A38: Р1 | B38: 1 | D38: 45 | E38: =CONCATENATE('Смета ЕР (общ) '!$A38,".",'Смета ЕР (общ) '!$B38,".",'Смета ЕР (общ) '!$D38) -> Р1.1.45 | F38: =IF(N38>0,F37+1,F37) -> 1 | G38: Раздел №1. Проектные работы и согласования | H38: 1.1.0 Проектные работы и согласования | J38: Эскизный проект фасада и колористический паспорт с указанием ведомости отделки и проектным решением со спецификацией элементов (крыльцо, пандус, навесы, колонны и т.д.) | K38: (для фасадов менее 100 м.кв) | L38: Эскизный проект фасада и колористический паспорт с указанием ведомости отделки и проектным решением со спецификацией элементов (крыльцо, пандус, навесы, колонны и т.д.)(для фасадов менее 100 м.кв) | M38: кв.м.площади фасада | O38: ='[1]Проектирование до 100'!E36*1.05 -> 7822.5 | P38: 0 | Q38: =ROUND(O38-O38*$V$3,2) -> 7822.5 | R38: =ROUND(P38-P38*$V$3,2) -> 0 | S38: =ROUND('Смета ЕР (общ) '!$N38*'Смета ЕР (общ) '!$Q38,2) -> 0 | T38: =ROUND('Смета ЕР (общ) '!$N38*'Смета ЕР (общ) '!$R38,2) -> 0
A39: Р1 | B39: 1 | D39: 46 | E39: =CONCATENATE('Смета ЕР (общ) '!$A39,".",'Смета ЕР (общ) '!$B39,".",'Смета ЕР (общ) '!$D39) -> Р1.1.46 | F39: =IF(N39>0,F38+1,F38) -> 1 | G39: Раздел №1. Проектные работы и согласования | H39: 1.1.0 Проектные работы и согласования | I39: Рабочая документация | J39: Рабочая документация по усилению/устройству несущих конструкций ("КР"), включая пояснительную записку | K39: (для помещений менее 100 м.кв) | L39: Рабочая документация по усилению/устройству несущих конструкций ("КР"), включая пояснительную записку (для помещений менее 100 м.кв) | M39: компл. | O39: ='[1]Проектирование до 100'!E17*1.05 -> 10500 | P39: 0 | Q39: =ROUND(O39-O39*$V$3,2) -> 10500 | R39: =ROUND(P39-P39*$V$3,2) -> 0 | S39: =ROUND('Смета ЕР (общ) '!$N39*'Смета ЕР (общ) '!$Q39,2) -> 0 | T39: =ROUND('Смета ЕР (общ) '!$N39*'Смета ЕР (общ) '!$R39,2) -> 0
A40: Р1 | B40: 1 | D40: 47 | E40: =CONCATENATE('Смета ЕР (общ) '!$A40,".",'Смета ЕР (общ) '!$B40,".",'Смета ЕР (общ) '!$D40) -> Р1.1.47 | F40: =IF(N40>0,F39+1,F39) -> 1 | G40: Раздел №1. Проектные работы и согласования | H40: 1.1.0 Проектные работы и согласования | I40: Рабочая документация | J40: Рабочая документация "Архитектурные решения" ("АР"), включая пояснительную записку | K40: (для помещений менее 100 м.кв) | L40: Рабочая документация "Архитектурные решения" ("АР"), включая пояснительную записку (для помещений менее 100 м.кв) | M40: компл. | O40: ='[1]Проектирование до 100'!E18*1.05 -> 20737.5 | P40: 0 | Q40: =ROUND(O40-O40*$V$3,2) -> 20737.5 | R40: =ROUND(P40-P40*$V$3,2) -> 0 | S40: =ROUND('Смета ЕР (общ) '!$N40*'Смета ЕР (общ) '!$Q40,2) -> 0 | T40: =ROUND('Смета ЕР (общ) '!$N40*'Смета ЕР (общ) '!$R40,2) -> 0
A41: Р1 | B41: 1 | D41: 48 | E41: =CONCATENATE('Смета ЕР (общ) '!$A41,".",'Смета ЕР (общ) '!$B41,".",'Смета ЕР (общ) '!$D41) -> Р1.1.48 | F41: =IF(N41>0,F40+1,F40) -> 1 | G41: Раздел №1. Проектные работы и согласования | H41: 1.1.0 Проектные работы и согласования | I41: Рабочая документация | J41: Рабочая документация по электроснабжению и электроосвещению ("ЭОМ"), включая пояснительную записку | K41: (для помещений менее 100 м.кв) | L41: Рабочая документация по электроснабжению и электроосвещению ("ЭОМ"), включая пояснительную записку (для помещений менее 100 м.кв) | M41: компл. | O41: ='[1]Проектирование до 100'!E19*1.05 -> 20737.5 | P41: 0 | Q41: =ROUND(O41-O41*$V$3,2) -> 20737.5 | R41: =ROUND(P41-P41*$V$3,2) -> 0 | S41: =ROUND('Смета ЕР (общ) '!$N41*'Смета ЕР (общ) '!$Q41,2) -> 0 | T41: =ROUND('Смета ЕР (общ) '!$N41*'Смета ЕР (общ) '!$R41,2) -> 0
A42: Р1 | B42: 1 | D42: 49 | E42: =CONCATENATE('Смета ЕР (общ) '!$A42,".",'Смета ЕР (общ) '!$B42,".",'Смета ЕР (общ) '!$D42) -> Р1.1.49 | F42: =IF(N42>0,F41+1,F41) -> 1 | G42: Раздел №1. Проектные работы и согласования | H42: 1.1.0 Проектные работы и согласования | I42: Рабочая документация | J42: Рабочая документация Системы вентиляции ("ОВиК-В"), включая пояснительную записку | K42: (для помещений менее 100 м.кв) | L42: Рабочая документация Системы вентиляции ("ОВиК-В"), включая пояснительную записку (для помещений менее 100 м.кв) | M42: компл. | O42: ='[1]Проектирование до 100'!E20*1.05 -> 15592.5 | P42: 0 | Q42: =ROUND(O42-O42*$V$3,2) -> 15592.5 | R42: =ROUND(P42-P42*$V$3,2) -> 0 | S42: =ROUND('Смета ЕР (общ) '!$N42*'Смета ЕР (общ) '!$Q42,2) -> 0 | T42: =ROUND('Смета ЕР (общ) '!$N42*'Смета ЕР (общ) '!$R42,2) -> 0
...
