Workbook
Name ДисконтТендер: Смета!$C$17
Name КурсEUR: Смета!$C$16
Name КурсUSD: Смета!$C$15
Name мат_VRF_ВНУТ: Материалы!$M$2:$M$259
Name мат_VRF_НАР: Материалы!$M$260:$M$360
Name мат_БРОНЯ: Материалы!$M$361:$M$382
Name мат_ДВ: Материалы!$M$383:$M$393
Name мат_ДВ_АЛ: Материалы!$M$394:$M$399
Name мат_ДВ_ДЕР: Материалы!$M$400:$M$405
Name мат_ДВ_СТ: Материалы!$M$406:$M$410
Name мат_ДОК_ИД: Документация!$F$38:$F$57
Name мат_ДОК_РД: Документация!$F$2:$F$37
Name мат_ЗАВЕСА: Материалы!$M$411:$M$414
Name мат_ЛЮЧОК: Материалы!$M$415:$M$415
Name мат_ПВУ: Материалы!$M$416:$M$431
Name мат_ПЕРЕГ_СТ: Материалы!$M$432:$M$432
Name мат_ПЕРЕГ_ТР: Материалы!$M$433:$M$442
Name мат_ПОЛ_КГ: Материалы!$M$443:$M$450
Name мат_ПОЛ_МОД: Материалы!$M$451:$M$455
Name мат_ПОТОЛОК: Материалы!$M$456:$M$460
Name мат_РАД: Материалы!$M$461:$M$597
Name мат_РАД_КОМПЛ: Материалы!$M$598:$M$612
Name мат_СВЕТ: Материалы!$M$613:$M$925
Name мат_СВЕТ_АВАР: Материалы!$M$926:$M$1035
Name мат_СПЛИТ: Материалы!$M$1036:$M$1151
Name мат_СТЕН_ПЛ: Материалы!$M$1152:$M$1154
Name мат_СТП_РАК: Материалы!$M$1155:$M$1167
Name мат_СТП_СМЕС: Материалы!$M$1168:$M$1180
Name мат_СТП_УНИТ: Материалы!$M$1181:$M$1188
Name мат_ФАЛЬШПОЛ: Материалы!$M$1189:$M$1197
Name мат_ЭУИ_ВЫКЛ: Материалы!$M$1198:$M$1199
Name мат_ЭУИ_РОЗ: Материалы!$M$1200:$M$1208
Name мат_ЭЩ: Материалы!$M$1209:$M$1219
Name раб_Р1: Работы!$N$2:$N$39
Name раб_Р10: Работы!$N$821:$N$832
Name раб_Р11: Работы!$N$833:$N$841
Name раб_Р12: Работы!$N$842:$N$858
Name раб_Р2: Работы!$N$40:$N$161
Name раб_Р3: Работы!$N$162:$N$371
Name раб_Р4: Работы!$N$372:$N$429
Name раб_Р5: Работы!$N$430:$N$475
Name раб_Р6: Работы!$N$476:$N$522
Name раб_Р7: Работы!$N$523:$N$556
Name раб_Р8: Работы!$N$557:$N$581
Name раб_Р9: Работы!$N$582:$N$820

Sheet О шаблоне
A1: Шаблон сметы — РУЧНАЯ СБОРКА перечня (Excel 2019+)
A3: КАК РАБОТАТЬ
A4: 1. Лист «Сборка» — пустой. Для каждой нужной работы заполни строку:
A5: • Раздел — выбери Р1…Р12 из списка;
A6: • Работа (Код — Наименование) — выбери из списка (в нём только работы этого раздела);
A7: • Объём — впиши число;
A8: • Материал / раздел документации — если работа с материалом, выбери из списка;
A9: для строк «Рабочая/Исполнительная документация» (раздел 1) в этом же столбце выбирается
A10: раздел проекта — цена подставится с листа «Документация».
A11: Наименование, ед. изм. и цены подставляются сами. Порядок строк — любой.
A12: 2. Лист «Смета» — готовый документ. После сборки встань на таблицу расшифровки и нажми
A13: Ctrl+Alt+L (Данные → «Применить повторно»): останутся только строки с объёмом, разбитые
... A21: Сформировано: 2026-09-01. Работ в справочнике: 857. Материалов: 1218. Вариантов документации: 56. Пустых строк «Сборки»: 500.

Sheet Сборка
A1: Раздел | B1: Работа (Код — Наименование) | C1: _код | D1: Наименование работы | E1: Ед | F1: Группа_мат | G1: Объём | H1: Материал / раздел документации | I1: Наим. материала | J1: Цена работ, ₽ | K1: Цена мат, ₽ | L1: Стоим. работ, ₽ | M1: Стоим. мат, ₽ | N1: Всего, ₽ | O1: _ранг | P1: _рзд | Q1: _перв | R1: _строка | S1: _разд_имя
C2: =IF($B2="","",IFERROR(LEFT($B2,FIND(" — ",$B2)-1),$B2)) | D2: =IF($C2="","",IF(AND(LEFT($F2,3)="ДОК",$H2<>""),IFERROR(INDEX(Документация!$G$2:$G$57,MATCH($H2,Документация!$F$2:$F$57,0)),"— вариант не найден —"),IFERROR(INDEX(Работы!$B$2:$B$6000,MATCH($C2,Работы!$A$2:$A$6000,0)),"— нет такого кода —"))) | E2: =IF($C2="","",IF(AND(LEFT($F2,3)="ДОК",$H2<>""),IFERROR(INDEX(Документация!$D$2:$D$57,MATCH($H2,Документация!$F$2:$F$57,0)),""),IFERROR(INDEX(Работы!$C$2:$C$6000,MATCH($C2,Работы!$A$2:$A$6000,0)),""))) | F2: =IF($C2="","",IFERROR(INDEX(Работы!$G$2:$G$6000,MATCH($C2,Работы!$A$2:$A$6000,0))&"","")) | I2: =IF((LEFT($F2,3)="ДОК"),"",IF($H2="","",IFERROR(INDEX(Материалы!$B$2:$B$9000,MATCH($H2,Материалы!$M$2:$M$9000,0)),""))) | J2: =IF(AND(LEFT($F2,3)="ДОК",$H2<>""),IFERROR(INDEX(Документация!$E$2:$E$57,MATCH($H2,Документация!$F$2:$F$57,0)),0),IFERROR(INDEX(Работы!$H$2:$H$6000,MATCH($C2,Работы!$A$2:$A$6000,0)),0))*(1-MEDIAN(0,N(ДисконтТендер),1)) -> 0 | K2: =IF(OR((LEFT($F2,3)="ДОК"),$H2=""),0,IFERROR(INDEX(Материалы!$H$2:$H$9000,MATCH($H2,Материалы!$M$2:$M$9000,0))*IF(INDEX(Материалы!$I$2:$I$9000,MATCH($H2,Материалы!$M$2:$M$9000,0))="USD",КурсUSD,IF(INDEX(Материалы!$I$2:$I$9000,MATCH($H2,Материалы!$M$2:$M$9000,0))="EUR",КурсEUR,1))*(1+IFERROR(INDEX(Работы!$I$2:$I$6000,MATCH($C2,Работы!$A$2:$A$6000,0))/100,0))*(1-MEDIAN(0,N(ДисконтТендер),1)),0)) -> 0 | L2: =IF($G2<>"",ROUND($G2*$J2,2),0) -> 0 | M2: =IF($G2<>"",ROUND($G2*$K2,2),0) -> 0 | N2: =$L2+$M2 -> 0 | O2: =IF($N2>0,MAX($O$1:$O1)+1,"") | P2: =IF($C2="","",IFERROR(INDEX(Работы!$D$2:$D$6000,MATCH($C2,Работы!$A$2:$A$6000,0)),"")) | Q2: =IF($O2="","",IF($O2=1,1,IF($P2<>IFERROR(INDEX($P$2:$P$501,MATCH($O2-1,$O$2:$O$501,0)),"~"),1,0))) | R2: =IF($O2="","",$O2+SUMIFS($Q$2:$Q$501,$O$2:$O$501,"<="&$O2)) | S2: =IF($P2="","",$P2&" · "&IFERROR(INDEX(Работы!$E$2:$E$6000,MATCH($C2,Работы!$A$2:$A$6000,0)),""))
C3: =IF($B3="","",IFERROR(LEFT($B3,FIND(" — ",$B3)-1),$B3)) | D3: =IF($C3="","",IF(AND(LEFT($F3,3)="ДОК",$H3<>""),IFERROR(INDEX(Документация!$G$2:$G$57,MATCH($H3,Документация!$F$2:$F$57,0)),"— вариант не найден —"),IFERROR(INDEX(Работы!$B$2:$B$6000,MATCH($C3,Работы!$A$2:$A$6000,0)),"— нет такого кода —"))) | E3: =IF($C3="","",IF(AND(LEFT($F3,3)="ДОК",$H3<>""),IFERROR(INDEX(Документация!$D$2:$D$57,MATCH($H3,Документация!$F$2:$F$57,0)),""),IFERROR(INDEX(Работы!$C$2:$C$6000,MATCH($C3,Работы!$A$2:$A$6000,0)),""))) | F3: =IF($C3="","",IFERROR(INDEX(Работы!$G$2:$G$6000,MATCH($C3,Работы!$A$2:$A$6000,0))&"","")) | I3: =IF((LEFT($F3,3)="ДОК"),"",IF($H3="","",IFERROR(INDEX(Материалы!$B$2:$B$9000,MATCH($H3,Материалы!$M$2:$M$9000,0)),""))) | J3: =IF(AND(LEFT($F3,3)="ДОК",$H3<>""),IFERROR(INDEX(Документация!$E$2:$E$57,MATCH($H3,Документация!$F$2:$F$57,0)),0),IFERROR(INDEX(Работы!$H$2:$H$6000,MATCH($C3,Работы!$A$2:$A$6000,0)),0))*(1-MEDIAN(0,N(ДисконтТендер),1)) -> 0 | K3: =IF(OR((LEFT($F3,3)="ДОК"),$H3=""),0,IFERROR(INDEX(Материалы!$H$2:$H$9000,MATCH($H3,Материалы!$M$2:$M$9000,0))*IF(INDEX(Материалы!$I$2:$I$9000,MATCH($H3,Материалы!$M$2:$M$9000,0))="USD",КурсUSD,IF(INDEX(Материалы!$I$2:$I$9000,MATCH($H3,Материалы!$M$2:$M$9000,0))="EUR",КурсEUR,1))*(1+IFERROR(INDEX(Работы!$I$2:$I$6000,MATCH($C3,Работы!$A$2:$A$6000,0))/100,0))*(1-MEDIAN(0,N(ДисконтТендер),1)),0)) -> 0 | L3: =IF($G3<>"",ROUND($G3*$J3,2),0) -> 0 | M3: =IF($G3<>"",ROUND($G3*$K3,2),0) -> 0 | N3: =$L3+$M3 -> 0 | O3: =IF($N3>0,MAX($O$1:$O2)+1,"") | P3: =IF($C3="","",IFERROR(INDEX(Работы!$D$2:$D$6000,MATCH($C3,Работы!$A$2:$A$6000,0)),"")) | Q3: =IF($O3="","",IF($O3=1,1,IF($P3<>IFERROR(INDEX($P$2:$P$501,MATCH($O3-1,$O$2:$O$501,0)),"~"),1,0))) | R3: =IF($O3="","",$O3+SUMIFS($Q$2:$Q$501,$O$2:$O$501,"<="&$O3)) | S3: =IF($P3="","",$P3&" · "&IFERROR(INDEX(Работы!$E$2:$E$6000,MATCH($C3,Работы!$A$2:$A$6000,0)),""))
C4: =IF($B4="","",IFERROR(LEFT($B4,FIND(" — ",$B4)-1),$B4)) | D4: =IF($C4="","",IF(AND(LEFT($F4,3)="ДОК",$H4<>""),IFERROR(INDEX(Документация!$G$2:$G$57,MATCH($H4,Документация!$F$2:$F$57,0)),"— вариант не найден —"),IFERROR(INDEX(Работы!$B$2:$B$6000,MATCH($C4,Работы!$A$2:$A$6000,0)),"— нет такого кода —"))) | E4: =IF($C4="","",IF(AND(LEFT($F4,3)="ДОК",$H4<>""),IFERROR(INDEX(Документация!$D$2:$D$57,MATCH($H4,Документация!$F$2:$F$57,0)),""),IFERROR(INDEX(Работы!$C$2:$C$6000,MATCH($C4,Работы!$A$2:$A$6000,0)),""))) | F4: =IF($C4="","",IFERROR(INDEX(Работы!$G$2:$G$6000,MATCH($C4,Работы!$A$2:$A$6000,0))&"","")) | I4: =IF((LEFT($F4,3)="ДОК"),"",IF($H4="","",IFERROR(INDEX(Материалы!$B$2:$B$9000,MATCH($H4,Материалы!$M$2:$M$9000,0)),""))) | J4: =IF(AND(LEFT($F4,3)="ДОК",$H4<>""),IFERROR(INDEX(Документация!$E$2:$E$57,MATCH($H4,Документация!$F$2:$F$57,0)),0),IFERROR(INDEX(Работы!$H$2:$H$6000,MATCH($C4,Работы!$A$2:$A$6000,0)),0))*(1-MEDIAN(0,N(ДисконтТендер),1)) -> 0 | K4: =IF(OR((LEFT($F4,3)="ДОК"),$H4=""),0,IFERROR(INDEX(Материалы!$H$2:$H$9000,MATCH($H4,Материалы!$M$2:$M$9000,0))*IF(INDEX(Материалы!$I$2:$I$9000,MATCH($H4,Материалы!$M$2:$M$9000,0))="USD",КурсUSD,IF(INDEX(Материалы!$I$2:$I$9000,MATCH($H4,Материалы!$M$2:$M$9000,0))="EUR",КурсEUR,1))*(1+IFERROR(INDEX(Работы!$I$2:$I$6000,MATCH($C4,Работы!$A$2:$A$6000,0))/100,0))*(1-MEDIAN(0,N(ДисконтТендер),1)),0)) -> 0 | L4: =IF($G4<>"",ROUND($G4*$J4,2),0) -> 0 | M4: =IF($G4<>"",ROUND($G4*$K4,2),0) -> 0 | N4: =$L4+$M4 -> 0 | O4: =IF($N4>0,MAX($O$1:$O3)+1,"") | P4: =IF($C4="","",IFERROR(INDEX(Работы!$D$2:$D$6000,MATCH($C4,Работы!$A$2:$A$6000,0)),"")) | Q4: =IF($O4="","",IF($O4=1,1,IF($P4<>IFERROR(INDEX($P$2:$P$501,MATCH($O4-1,$O$2:$O$501,0)),"~"),1,0))) | R4: =IF($O4="","",$O4+SUMIFS($Q$2:$Q$501,$O$2:$O$501,"<="&$O4)) | S4: =IF($P4="","",$P4&" · "&IFERROR(INDEX(Работы!$E$2:$E$6000,MATCH($C4,Работы!$A$2:$A$6000,0)),""))
C5: =IF($B5="","",IFERROR(LEFT($B5,FIND(" — ",$B5)-1),$B5)) | D5: =IF($C5="","",IF(AND(LEFT($F5,3)="ДОК",$H5<>""),IFERROR(INDEX(Документация!$G$2:$G$57,MATCH($H5,Документация!$F$2:$F$57,0)),"— вариант не найден —"),IFERROR(INDEX(Работы!$B$2:$B$6000,MATCH($C5,Работы!$A$2:$A$6000,0)),"— нет такого кода —"))) | E5: =IF($C5="","",IF(AND(LEFT($F5,3)="ДОК",$H5<>""),IFERROR(INDEX(Документация!$D$2:$D$57,MATCH($H5,Документация!$F$2:$F$57,0)),""),IFERROR(INDEX(Работы!$C$2:$C$6000,MATCH($C5,Работы!$A$2:$A$6000,0)),""))) | F5: =IF($C5="","",IFERROR(INDEX(Работы!$G$2:$G$6000,MATCH($C5,Работы!$A$2:$A$6000,0))&"","")) | I5: =IF((LEFT($F5,3)="ДОК"),"",IF($H5="","",IFERROR(INDEX(Материалы!$B$2:$B$9000,MATCH($H5,Материалы!$M$2:$M$9000,0)),""))) | J5: =IF(AND(LEFT($F5,3)="ДОК",$H5<>""),IFERROR(INDEX(Документация!$E$2:$E$57,MATCH($H5,Документация!$F$2:$F$57,0)),0),IFERROR(INDEX(Работы!$H$2:$H$6000,MATCH($C5,Работы!$A$2:$A$6000,0)),0))*(1-MEDIAN(0,N(ДисконтТендер),1)) -> 0 | K5: =IF(OR((LEFT($F5,3)="ДОК"),$H5=""),0,IFERROR(INDEX(Материалы!$H$2:$H$9000,MATCH($H5,Материалы!$M$2:$M$9000,0))*IF(INDEX(Материалы!$I$2:$I$9000,MATCH($H5,Материалы!$M$2:$M$9000,0))="USD",КурсUSD,IF(INDEX(Материалы!$I$2:$I$9000,MATCH($H5,Материалы!$M$2:$M$9000,0))="EUR",КурсEUR,1))*(1+IFERROR(INDEX(Работы!$I$2:$I$6000,MATCH($C5,Работы!$A$2:$A$6000,0))/100,0))*(1-MEDIAN(0,N(ДисконтТендер),1)),0)) -> 0 | L5: =IF($G5<>"",ROUND($G5*$J5,2),0) -> 0 | M5: =IF($G5<>"",ROUND($G5*$K5,2),0) -> 0 | N5: =$L5+$M5 -> 0 | O5: =IF($N5>0,MAX($O$1:$O4)+1,"") | P5: =IF($C5="","",IFERROR(INDEX(Работы!$D$2:$D$6000,MATCH($C5,Работы!$A$2:$A$6000,0)),"")) | Q5: =IF($O5="","",IF($O5=1,1,IF($P5<>IFERROR(INDEX($P$2:$P$501,MATCH($O5-1,$O$2:$O$501,0)),"~"),1,0))) | R5: =IF($O5="","",$O5+SUMIFS($Q$2:$Q$501,$O$2:$O$501,"<="&$O5)) | S5: =IF($P5="","",$P5&" · "&IFERROR(INDEX(Работы!$E$2:$E$6000,MATCH($C5,Работы!$A$2:$A$6000,0)),""))
C6: =IF($B6="","",IFERROR(LEFT($B6,FIND(" — ",$B6)-1),$B6)) | D6: =IF($C6="","",IF(AND(LEFT($F6,3)="ДОК",$H6<>""),IFERROR(INDEX(Документация!$G$2:$G$57,MATCH($H6,Документация!$F$2:$F$57,0)),"— вариант не найден —"),IFERROR(INDEX(Работы!$B$2:$B$6000,MATCH($C6,Работы!$A$2:$A$6000,0)),"— нет такого кода —"))) | E6: =IF($C6="","",IF(AND(LEFT($F6,3)="ДОК",$H6<>""),IFERROR(INDEX(Документация!$D$2:$D$57,MATCH($H6,Документация!$F$2:$F$57,0)),""),IFERROR(INDEX(Работы!$C$2:$C$6000,MATCH($C6,Работы!$A$2:$A$6000,0)),""))) | F6: =IF($C6="","",IFERROR(INDEX(Работы!$G$2:$G$6000,MATCH($C6,Работы!$A$2:$A$6000,0))&"","")) | I6: =IF((LEFT($F6,3)="ДОК"),"",IF($H6="","",IFERROR(INDEX(Материалы!$B$2:$B$9000,MATCH($H6,Материалы!$M$2:$M$9000,0)),""))) | J6: =IF(AND(LEFT($F6,3)="ДОК",$H6<>""),IFERROR(INDEX(Документация!$E$2:$E$57,MATCH($H6,Документация!$F$2:$F$57,0)),0),IFERROR(INDEX(Работы!$H$2:$H$6000,MATCH($C6,Работы!$A$2:$A$6000,0)),0))*(1-MEDIAN(0,N(ДисконтТендер),1)) -> 0 | K6: =IF(OR((LEFT($F6,3)="ДОК"),$H6=""),0,IFERROR(INDEX(Материалы!$H$2:$H$9000,MATCH($H6,Материалы!$M$2:$M$9000,0))*IF(INDEX(Материалы!$I$2:$I$9000,MATCH($H6,Материалы!$M$2:$M$9000,0))="USD",КурсUSD,IF(INDEX(Материалы!$I$2:$I$9000,MATCH($H6,Материалы!$M$2:$M$9000,0))="EUR",КурсEUR,1))*(1+IFERROR(INDEX(Работы!$I$2:$I$6000,MATCH($C6,Работы!$A$2:$A$6000,0))/100,0))*(1-MEDIAN(0,N(ДисконтТендер),1)),0)) -> 0 | L6: =IF($G6<>"",ROUND($G6*$J6,2),0) -> 0 | M6: =IF($G6<>"",ROUND($G6*$K6,2),0) -> 0 | N6: =$L6+$M6 -> 0 | O6: =IF($N6>0,MAX($O$1:$O5)+1,"") | P6: =IF($C6="","",IFERROR(INDEX(Работы!$D$2:$D$6000,MATCH($C6,Работы!$A$2:$A$6000,0)),"")) | Q6: =IF($O6="","",IF($O6=1,1,IF($P6<>IFERROR(INDEX($P$2:$P$501,MATCH($O6-1,$O$2:$O$501,0)),"~"),1,0))) | R6: =IF($O6="","",$O6+SUMIFS($Q$2:$Q$501,$O$2:$O$501,"<="&$O6)) | S6: =IF($P6="","",$P6&" · "&IFERROR(INDEX(Работы!$E$2:$E$6000,MATCH($C6,Работы!$A$2:$A$6000,0)),""))
C7: =IF($B7="","",IFERROR(LEFT($B7,FIND(" — ",$B7)-1),$B7)) | D7: =IF($C7="","",IF(AND(LEFT($F7,3)="ДОК",$H7<>""),IFERROR(INDEX(Документация!$G$2:$G$57,MATCH($H7,Документация!$F$2:$F$57,0)),"— вариант не найден —"),IFERROR(INDEX(Работы!$B$2:$B$6000,MATCH($C7,Работы!$A$2:$A$6000,0)),"— нет такого кода —"))) | E7: =IF($C7="","",IF(AND(LEFT($F7,3)="ДОК",$H7<>""),IFERROR(INDEX(Документация!$D$2:$D$57,MATCH($H7,Документация!$F$2:$F$57,0)),""),IFERROR(INDEX(Работы!$C$2:$C$6000,MATCH($C7,Работы!$A$2:$A$6000,0)),""))) | F7: =IF($C7="","",IFERROR(INDEX(Работы!$G$2:$G$6000,MATCH($C7,Работы!$A$2:$A$6000,0))&"","")) | I7: =IF((LEFT($F7,3)="ДОК"),"",IF($H7="","",IFERROR(INDEX(Материалы!$B$2:$B$9000,MATCH($H7,Материалы!$M$2:$M$9000,0)),""))) | J7: =IF(AND(LEFT($F7,3)="ДОК",$H7<>""),IFERROR(INDEX(Документация!$E$2:$E$57,MATCH($H7,Документация!$F$2:$F$57,0)),0),IFERROR(INDEX(Работы!$H$2:$H$6000,MATCH($C7,Работы!$A$2:$A$6000,0)),0))*(1-MEDIAN(0,N(ДисконтТендер),1)) -> 0 | K7: =IF(OR((LEFT($F7,3)="ДОК"),$H7=""),0,IFERROR(INDEX(Материалы!$H$2:$H$9000,MATCH($H7,Материалы!$M$2:$M$9000,0))*IF(INDEX(Материалы!$I$2:$I$9000,MATCH($H7,Материалы!$M$2:$M$9000,0))="USD",КурсUSD,IF(INDEX(Материалы!$I$2:$I$9000,MATCH($H7,Материалы!$M$2:$M$9000,0))="EUR",КурсEUR,1))*(1+IFERROR(INDEX(Работы!$I$2:$I$6000,MATCH($C7,Работы!$A$2:$A$6000,0))/100,0))*(1-MEDIAN(0,N(ДисконтТендер),1)),0)) -> 0 | L7: =IF($G7<>"",ROUND($G7*$J7,2),0) -> 0 | M7: =IF($G7<>"",ROUND($G7*$K7,2),0) -> 0 | N7: =$L7+$M7 -> 0 | O7: =IF($N7>0,MAX($O$1:$O6)+1,"") | P7: =IF($C7="","",IFERROR(INDEX(Работы!$D$2:$D$6000,MATCH($C7,Работы!$A$2:$A$6000,0)),"")) | Q7: =IF($O7="","",IF($O7=1,1,IF($P7<>IFERROR(INDEX($P$2:$P$501,MATCH($O7-1,$O$2:$O$501,0)),"~"),1,0))) | R7: =IF($O7="","",$O7+SUMIFS($Q$2:$Q$501,$O$2:$O$501,"<="&$O7)) | S7: =IF($P7="","",$P7&" · "&IFERROR(INDEX(Работы!$E$2:$E$6000,MATCH($C7,Работы!$A$2:$A$6000,0)),""))
C8: =IF($B8="","",IFERROR(LEFT($B8,FIND(" — ",$B8)-1),$B8)) | D8: =IF($C8="","",IF(AND(LEFT($F8,3)="ДОК",$H8<>""),IFERROR(INDEX(Документация!$G$2:$G$57,MATCH($H8,Документация!$F$2:$F$57,0)),"— вариант не найден —"),IFERROR(INDEX(Работы!$B$2:$B$6000,MATCH($C8,Работы!$A$2:$A$6000,0)),"— нет такого кода —"))) | E8: =IF($C8="","",IF(AND(LEFT($F8,3)="ДОК",$H8<>""),IFERROR(INDEX(Документация!$D$2:$D$57,MATCH($H8,Документация!$F$2:$F$57,0)),""),IFERROR(INDEX(Работы!$C$2:$C$6000,MATCH($C8,Работы!$A$2:$A$6000,0)),""))) | F8: =IF($C8="","",IFERROR(INDEX(Работы!$G$2:$G$6000,MATCH($C8,Работы!$A$2:$A$6000,0))&"","")) | I8: =IF((LEFT($F8,3)="ДОК"),"",IF($H8="","",IFERROR(INDEX(Материалы!$B$2:$B$9000,MATCH($H8,Материалы!$M$2:$M$9000,0)),""))) | J8: =IF(AND(LEFT($F8,3)="ДОК",$H8<>""),IFERROR(INDEX(Документация!$E$2:$E$57,MATCH($H8,Документация!$F$2:$F$57,0)),0),IFERROR(INDEX(Работы!$H$2:$H$6000,MATCH($C8,Работы!$A$2:$A$6000,0)),0))*(1-MEDIAN(0,N(ДисконтТендер),1)) -> 0 | K8: =IF(OR((LEFT($F8,3)="ДОК"),$H8=""),0,IFERROR(INDEX(Материалы!$H$2:$H$9000,MATCH($H8,Материалы!$M$2:$M$9000,0))*IF(INDEX(Материалы!$I$2:$I$9000,MATCH($H8,Материалы!$M$2:$M$9000,0))="USD",КурсUSD,IF(INDEX(Материалы!$I$2:$I$9000,MATCH($H8,Материалы!$M$2:$M$9000,0))="EUR",КурсEUR,1))*(1+IFERROR(INDEX(Работы!$I$2:$I$6000,MATCH($C8,Работы!$A$2:$A$6000,0))/100,0))*(1-MEDIAN(0,N(ДисконтТендер),1)),0)) -> 0 | L8: =IF($G8<>"",ROUND($G8*$J8,2),0) -> 0 | M8: =IF($G8<>"",ROUND($G8*$K8,2),0) -> 0 | N8: =$L8+$M8 -> 0 | O8: =IF($N8>0,MAX($O$1:$O7)+1,"") | P8: =IF($C8="","",IFERROR(INDEX(Работы!$D$2:$D$6000,MATCH($C8,Работы!$A$2:$A$6000,0)),"")) | Q8: =IF($O8="","",IF($O8=1,1,IF($P8<>IFERROR(INDEX($P$2:$P$501,MATCH($O8-1,$O$2:$O$501,0)),"~"),1,0))) | R8: =IF($O8="","",$O8+SUMIFS($Q$2:$Q$501,$O$2:$O$501,"<="&$O8)) | S8: =IF($P8="","",$P8&" · "&IFERROR(INDEX(Работы!$E$2:$E$6000,MATCH($C8,Работы!$A$2:$A$6000,0)),""))
C9: =IF($B9="","",IFERROR(LEFT($B9,FIND(" — ",$B9)-1),$B9)) | D9: =IF($C9="","",IF(AND(LEFT($F9,3)="ДОК",$H9<>""),IFERROR(INDEX(Документация!$G$2:$G$57,MATCH($H9,Документация!$F$2:$F$57,0)),"— вариант не найден —"),IFERROR(INDEX(Работы!$B$2:$B$6000,MATCH($C9,Работы!$A$2:$A$6000,0)),"— нет такого кода —"))) | E9: =IF($C9="","",IF(AND(LEFT($F9,3)="ДОК",$H9<>""),IFERROR(INDEX(Документация!$D$2:$D$57,MATCH($H9,Документация!$F$2:$F$57,0)),""),IFERROR(INDEX(Работы!$C$2:$C$6000,MATCH($C9,Работы!$A$2:$A$6000,0)),""))) | F9: =IF($C9="","",IFERROR(INDEX(Работы!$G$2:$G$6000,MATCH($C9,Работы!$A$2:$A$6000,0))&"","")) | I9: =IF((LEFT($F9,3)="ДОК"),"",IF($H9="","",IFERROR(INDEX(Материалы!$B$2:$B$9000,MATCH($H9,Материалы!$M$2:$M$9000,0)),""))) | J9: =IF(AND(LEFT($F9,3)="ДОК",$H9<>""),IFERROR(INDEX(Документация!$E$2:$E$57,MATCH($H9,Документация!$F$2:$F$57,0)),0),IFERROR(INDEX(Работы!$H$2:$H$6000,MATCH($C9,Работы!$A$2:$A$6000,0)),0))*(1-MEDIAN(0,N(ДисконтТендер),1)) -> 0 | K9: =IF(OR((LEFT($F9,3)="ДОК"),$H9=""),0,IFERROR(INDEX(Материалы!$H$2:$H$9000,MATCH($H9,Материалы!$M$2:$M$9000,0))*IF(INDEX(Материалы!$I$2:$I$9000,MATCH($H9,Материалы!$M$2:$M$9000,0))="USD",КурсUSD,IF(INDEX(Материалы!$I$2:$I$9000,MATCH($H9,Материалы!$M$2:$M$9000,0))="EUR",КурсEUR,1))*(1+IFERROR(INDEX(Работы!$I$2:$I$6000,MATCH($C9,Работы!$A$2:$A$6000,0))/100,0))*(1-MEDIAN(0,N(ДисконтТендер),1)),0)) -> 0 | L9: =IF($G9<>"",ROUND($G9*$J9,2),0) -> 0 | M9: =IF($G9<>"",ROUND($G9*$K9,2),0) -> 0 | N9: =$L9+$M9 -> 0 | O9: =IF($N9>0,MAX($O$1:$O8)+1,"") | P9: =IF($C9="","",IFERROR(INDEX(Работы!$D$2:$D$6000,MATCH($C9,Работы!$A$2:$A$6000,0)),"")) | Q9: =IF($O9="","",IF($O9=1,1,IF($P9<>IFERROR(INDEX($P$2:$P$501,MATCH($O9-1,$O$2:$O$501,0)),"~"),1,0))) | R9: =IF($O9="","",$O9+SUMIFS($Q$2:$Q$501,$O$2:$O$501,"<="&$O9)) | S9: =IF($P9="","",$P9&" · "&IFERROR(INDEX(Работы!$E$2:$E$6000,MATCH($C9,Работы!$A$2:$A$6000,0)),""))
C10: =IF($B10="","",IFERROR(LEFT($B10,FIND(" — ",$B10)-1),$B10)) | D10: =IF($C10="","",IF(AND(LEFT($F10,3)="ДОК",$H10<>""),IFERROR(INDEX(Документация!$G$2:$G$57,MATCH($H10,Документация!$F$2:$F$57,0)),"— вариант не найден —"),IFERROR(INDEX(Работы!$B$2:$B$6000,MATCH($C10,Работы!$A$2:$A$6000,0)),"— нет такого кода —"))) | E10: =IF($C10="","",IF(AND(LEFT($F10,3)="ДОК",$H10<>""),IFERROR(INDEX(Документация!$D$2:$D$57,MATCH($H10,Документация!$F$2:$F$57,0)),""),IFERROR(INDEX(Работы!$C$2:$C$6000,MATCH($C10,Работы!$A$2:$A$6000,0)),""))) | F10: =IF($C10="","",IFERROR(INDEX(Работы!$G$2:$G$6000,MATCH($C10,Работы!$A$2:$A$6000,0))&"","")) | I10: =IF((LEFT($F10,3)="ДОК"),"",IF($H10="","",IFERROR(INDEX(Материалы!$B$2:$B$9000,MATCH($H10,Материалы!$M$2:$M$9000,0)),""))) | J10: =IF(AND(LEFT($F10,3)="ДОК",$H10<>""),IFERROR(INDEX(Документация!$E$2:$E$57,MATCH($H10,Документация!$F$2:$F$57,0)),0),IFERROR(INDEX(Работы!$H$2:$H$6000,MATCH($C10,Работы!$A$2:$A$6000,0)),0))*(1-MEDIAN(0,N(ДисконтТендер),1)) -> 0 | K10: =IF(OR((LEFT($F10,3)="ДОК"),$H10=""),0,IFERROR(INDEX(Материалы!$H$2:$H$9000,MATCH($H10,Материалы!$M$2:$M$9000,0))*IF(INDEX(Материалы!$I$2:$I$9000,MATCH($H10,Материалы!$M$2:$M$9000,0))="USD",КурсUSD,IF(INDEX(Материалы!$I$2:$I$9000,MATCH($H10,Материалы!$M$2:$M$9000,0))="EUR",КурсEUR,1))*(1+IFERROR(INDEX(Работы!$I$2:$I$6000,MATCH($C10,Работы!$A$2:$A$6000,0))/100,0))*(1-MEDIAN(0,N(ДисконтТендер),1)),0)) -> 0 | L10: =IF($G10<>"",ROUND($G10*$J10,2),0) -> 0 | M10: =IF($G10<>"",ROUND($G10*$K10,2),0) -> 0 | N10: =$L10+$M10 -> 0 | O10: =IF($N10>0,MAX($O$1:$O9)+1,"") | P10: =IF($C10="","",IFERROR(INDEX(Работы!$D$2:$D$6000,MATCH($C10,Работы!$A$2:$A$6000,0)),"")) | Q10: =IF($O10="","",IF($O10=1,1,IF($P10<>IFERROR(INDEX($P$2:$P$501,MATCH($O10-1,$O$2:$O$501,0)),"~"),1,0))) | R10: =IF($O10="","",$O10+SUMIFS($Q$2:$Q$501,$O$2:$O$501,"<="&$O10)) | S10: =IF($P10="","",$P10&" · "&IFERROR(INDEX(Работы!$E$2:$E$6000,MATCH($C10,Работы!$A$2:$A$6000,0)),""))
C11: =IF($B11="","",IFERROR(LEFT($B11,FIND(" — ",$B11)-1),$B11)) | D11: =IF($C11="","",IF(AND(LEFT($F11,3)="ДОК",$H11<>""),IFERROR(INDEX(Документация!$G$2:$G$57,MATCH($H11,Документация!$F$2:$F$57,0)),"— вариант не найден —"),IFERROR(INDEX(Работы!$B$2:$B$6000,MATCH($C11,Работы!$A$2:$A$6000,0)),"— нет такого кода —"))) | E11: =IF($C11="","",IF(AND(LEFT($F11,3)="ДОК",$H11<>""),IFERROR(INDEX(Документация!$D$2:$D$57,MATCH($H11,Документация!$F$2:$F$57,0)),""),IFERROR(INDEX(Работы!$C$2:$C$6000,MATCH($C11,Работы!$A$2:$A$6000,0)),""))) | F11: =IF($C11="","",IFERROR(INDEX(Работы!$G$2:$G$6000,MATCH($C11,Работы!$A$2:$A$6000,0))&"","")) | I11: =IF((LEFT($F11,3)="ДОК"),"",IF($H11="","",IFERROR(INDEX(Материалы!$B$2:$B$9000,MATCH($H11,Материалы!$M$2:$M$9000,0)),""))) | J11: =IF(AND(LEFT($F11,3)="ДОК",$H11<>""),IFERROR(INDEX(Документация!$E$2:$E$57,MATCH($H11,Документация!$F$2:$F$57,0)),0),IFERROR(INDEX(Работы!$H$2:$H$6000,MATCH($C11,Работы!$A$2:$A$6000,0)),0))*(1-MEDIAN(0,N(ДисконтТендер),1)) -> 0 | K11: =IF(OR((LEFT($F11,3)="ДОК"),$H11=""),0,IFERROR(INDEX(Материалы!$H$2:$H$9000,MATCH($H11,Материалы!$M$2:$M$9000,0))*IF(INDEX(Материалы!$I$2:$I$9000,MATCH($H11,Материалы!$M$2:$M$9000,0))="USD",КурсUSD,IF(INDEX(Материалы!$I$2:$I$9000,MATCH($H11,Материалы!$M$2:$M$9000,0))="EUR",КурсEUR,1))*(1+IFERROR(INDEX(Работы!$I$2:$I$6000,MATCH($C11,Работы!$A$2:$A$6000,0))/100,0))*(1-MEDIAN(0,N(ДисконтТендер),1)),0)) -> 0 | L11: =IF($G11<>"",ROUND($G11*$J11,2),0) -> 0 | M11: =IF($G11<>"",ROUND($G11*$K11,2),0) -> 0 | N11: =$L11+$M11 -> 0 | O11: =IF($N11>0,MAX($O$1:$O10)+1,"") | P11: =IF($C11="","",IFERROR(INDEX(Работы!$D$2:$D$6000,MATCH($C11,Работы!$A$2:$A$6000,0)),"")) | Q11: =IF($O11="","",IF($O11=1,1,IF($P11<>IFERROR(INDEX($P$2:$P$501,MATCH($O11-1,$O$2:$O$501,0)),"~"),1,0))) | R11: =IF($O11="","",$O11+SUMIFS($Q$2:$Q$501,$O$2:$O$501,"<="&$O11)) | S11: =IF($P11="","",$P11&" · "&IFERROR(INDEX(Работы!$E$2:$E$6000,MATCH($C11,Работы!$A$2:$A$6000,0)),""))
C12: =IF($B12="","",IFERROR(LEFT($B12,FIND(" — ",$B12)-1),$B12)) | D12: =IF($C12="","",IF(AND(LEFT($F12,3)="ДОК",$H12<>""),IFERROR(INDEX(Документация!$G$2:$G$57,MATCH($H12,Документация!$F$2:$F$57,0)),"— вариант не найден —"),IFERROR(INDEX(Работы!$B$2:$B$6000,MATCH($C12,Работы!$A$2:$A$6000,0)),"— нет такого кода —"))) | E12: =IF($C12="","",IF(AND(LEFT($F12,3)="ДОК",$H12<>""),IFERROR(INDEX(Документация!$D$2:$D$57,MATCH($H12,Документация!$F$2:$F$57,0)),""),IFERROR(INDEX(Работы!$C$2:$C$6000,MATCH($C12,Работы!$A$2:$A$6000,0)),""))) | F12: =IF($C12="","",IFERROR(INDEX(Работы!$G$2:$G$6000,MATCH($C12,Работы!$A$2:$A$6000,0))&"","")) | I12: =IF((LEFT($F12,3)="ДОК"),"",IF($H12="","",IFERROR(INDEX(Материалы!$B$2:$B$9000,MATCH($H12,Материалы!$M$2:$M$9000,0)),""))) | J12: =IF(AND(LEFT($F12,3)="ДОК",$H12<>""),IFERROR(INDEX(Документация!$E$2:$E$57,MATCH($H12,Документация!$F$2:$F$57,0)),0),IFERROR(INDEX(Работы!$H$2:$H$6000,MATCH($C12,Работы!$A$2:$A$6000,0)),0))*(1-MEDIAN(0,N(ДисконтТендер),1)) -> 0 | K12: =IF(OR((LEFT($F12,3)="ДОК"),$H12=""),0,IFERROR(INDEX(Материалы!$H$2:$H$9000,MATCH($H12,Материалы!$M$2:$M$9000,0))*IF(INDEX(Материалы!$I$2:$I$9000,MATCH($H12,Материалы!$M$2:$M$9000,0))="USD",КурсUSD,IF(INDEX(Материалы!$I$2:$I$9000,MATCH($H12,Материалы!$M$2:$M$9000,0))="EUR",КурсEUR,1))*(1+IFERROR(INDEX(Работы!$I$2:$I$6000,MATCH($C12,Работы!$A$2:$A$6000,0))/100,0))*(1-MEDIAN(0,N(ДисконтТендер),1)),0)) -> 0 | L12: =IF($G12<>"",ROUND($G12*$J12,2),0) -> 0 | M12: =IF($G12<>"",ROUND($G12*$K12,2),0) -> 0 | N12: =$L12+$M12 -> 0 | O12: =IF($N12>0,MAX($O$1:$O11)+1,"") | P12: =IF($C12="","",IFERROR(INDEX(Работы!$D$2:$D$6000,MATCH($C12,Работы!$A$2:$A$6000,0)),"")) | Q12: =IF($O12="","",IF($O12=1,1,IF($P12<>IFERROR(INDEX($P$2:$P$501,MATCH($O12-1,$O$2:$O$501,0)),"~"),1,0))) | R12: =IF($O12="","",$O12+SUMIFS($Q$2:$Q$501,$O$2:$O$501,"<="&$O12)) | S12: =IF($P12="","",$P12&" · "&IFERROR(INDEX(Работы!$E$2:$E$6000,MATCH($C12,Работы!$A$2:$A$6000,0)),""))
C13: =IF($B13="","",IFERROR(LEFT($B13,FIND(" — ",$B13)-1),$B13)) | D13: =IF($C13="","",IF(AND(LEFT($F13,3)="ДОК",$H13<>""),IFERROR(INDEX(Документация!$G$2:$G$57,MATCH($H13,Документация!$F$2:$F$57,0)),"— вариант не найден —"),IFERROR(INDEX(Работы!$B$2:$B$6000,MATCH($C13,Работы!$A$2:$A$6000,0)),"— нет такого кода —"))) | E13: =IF($C13="","",IF(AND(LEFT($F13,3)="ДОК",$H13<>""),IFERROR(INDEX(Документация!$D$2:$D$57,MATCH($H13,Документация!$F$2:$F$57,0)),""),IFERROR(INDEX(Работы!$C$2:$C$6000,MATCH($C13,Работы!$A$2:$A$6000,0)),""))) | F13: =IF($C13="","",IFERROR(INDEX(Работы!$G$2:$G$6000,MATCH($C13,Работы!$A$2:$A$6000,0))&"","")) | I13: =IF((LEFT($F13,3)="ДОК"),"",IF($H13="","",IFERROR(INDEX(Материалы!$B$2:$B$9000,MATCH($H13,Материалы!$M$2:$M$9000,0)),""))) | J13: =IF(AND(LEFT($F13,3)="ДОК",$H13<>""),IFERROR(INDEX(Документация!$E$2:$E$57,MATCH($H13,Документация!$F$2:$F$57,0)),0),IFERROR(INDEX(Работы!$H$2:$H$6000,MATCH($C13,Работы!$A$2:$A$6000,0)),0))*(1-MEDIAN(0,N(ДисконтТендер),1)) -> 0 | K13: =IF(OR((LEFT($F13,3)="ДОК"),$H13=""),0,IFERROR(INDEX(Материалы!$H$2:$H$9000,MATCH($H13,Материалы!$M$2:$M$9000,0))*IF(INDEX(Материалы!$I$2:$I$9000,MATCH($H13,Материалы!$M$2:$M$9000,0))="USD",КурсUSD,IF(INDEX(Материалы!$I$2:$I$9000,MATCH($H13,Материалы!$M$2:$M$9000,0))="EUR",КурсEUR,1))*(1+IFERROR(INDEX(Работы!$I$2:$I$6000,MATCH($C13,Работы!$A$2:$A$6000,0))/100,0))*(1-MEDIAN(0,N(ДисконтТендер),1)),0)) -> 0 | L13: =IF($G13<>"",ROUND($G13*$J13,2),0) -> 0 | M13: =IF($G13<>"",ROUND($G13*$K13,2),0) -> 0 | N13: =$L13+$M13 -> 0 | O13: =IF($N13>0,MAX($O$1:$O12)+1,"") | P13: =IF($C13="","",IFERROR(INDEX(Работы!$D$2:$D$6000,MATCH($C13,Работы!$A$2:$A$6000,0)),"")) | Q13: =IF($O13="","",IF($O13=1,1,IF($P13<>IFERROR(INDEX($P$2:$P$501,MATCH($O13-1,$O$2:$O$501,0)),"~"),1,0))) | R13: =IF($O13="","",$O13+SUMIFS($Q$2:$Q$501,$O$2:$O$501,"<="&$O13)) | S13: =IF($P13="","",$P13&" · "&IFERROR(INDEX(Работы!$E$2:$E$6000,MATCH($C13,Работы!$A$2:$A$6000,0)),""))
... C501: =IF($B501="","",IFERROR(LEFT($B501,FIND(" — ",$B501)-1),$B501)) | D501: =IF($C501="","",IF(AND(LEFT($F501,3)="ДОК",$H501<>""),IFERROR(INDEX(Документация!$G$2:$G$57,MATCH($H501,Документация!$F$2:$F$57,0)),"— вариант не найден —"),IFERROR(INDEX(Работы!$B$2:$B$6000,MATCH($C501,Работы!$A$2:$A$6000,0)),"— нет такого кода —"))) | E501: =IF($C501="","",IF(AND(LEFT($F501,3)="ДОК",$H501<>""),IFERROR(INDEX(Документация!$D$2:$D$57,MATCH($H501,Документация!$F$2:$F$57,0)),""),IFERROR(INDEX(Работы!$C$2:$C$6000,MATCH($C501,Работы!$A$2:$A$6000,0)),""))) | F501: =IF($C501="","",IFERROR(INDEX(Работы!$G$2:$G$6000,MATCH($C501,Работы!$A$2:$A$6000,0))&"","")) | I501: =IF((LEFT($F501,3)="ДОК"),"",IF($H501="","",IFERROR(INDEX(Материалы!$B$2:$B$9000,MATCH($H501,Материалы!$M$2:$M$9000,0)),""))) | J501: =IF(AND(LEFT($F501,3)="ДОК",$H501<>""),IFERROR(INDEX(Документация!$E$2:$E$57,MATCH($H501,Документация!$F$2:$F$57,0)),0),IFERROR(INDEX(Работы!$H$2:$H$6000,MATCH($C501,Работы!$A$2:$A$6000,0)),0))*(1-MEDIAN(0,N(ДисконтТендер),1)) -> 0 | K501: =IF(OR((LEFT($F501,3)="ДОК"),$H501=""),0,IFERROR(INDEX(Материалы!$H$2:$H$9000,MATCH($H501,Материалы!$M$2:$M$9000,0))*IF(INDEX(Материалы!$I$2:$I$9000,MATCH($H501,Материалы!$M$2:$M$9000,0))="USD",КурсUSD,IF(INDEX(Материалы!$I$2:$I$9000,MATCH($H501,Материалы!$M$2:$M$9000,0))="EUR",КурсEUR,1))*(1+IFERROR(INDEX(Работы!$I$2:$I$6000,MATCH($C501,Работы!$A$2:$A$6000,0))/100,0))*(1-MEDIAN(0,N(ДисконтТендер),1)),0)) -> 0 | L501: =IF($G501<>"",ROUND($G501*$J501,2),0) -> 0 | M501: =IF($G501<>"",ROUND($G501*$K501,2),0) -> 0 | N501: =$L501+$M501 -> 0 | O501: =IF($N501>0,MAX($O$1:$O500)+1,"") | P501: =IF($C501="","",IFERROR(INDEX(Работы!$D$2:$D$6000,MATCH($C501,Работы!$A$2:$A$6000,0)),"")) | Q501: =IF($O501="","",IF($O501=1,1,IF($P501<>IFERROR(INDEX($P$2:$P$501,MATCH($O501-1,$O$2:$O$501,0)),"~"),1,0))) | R501: =IF($O501="","",$O501+SUMIFS($Q$2:$Q$501,$O$2:$O$501,"<="&$O501)) | S501: =IF($P501="","",$P501&" · "&IFERROR(INDEX(Работы!$E$2:$E$6000,MATCH($C501,Работы!$A$2:$A$6000,0)),""))

Sheet Смета
A1: СМЕТА
A2: Формат объекта:
A3: Адрес объекта:
A4: Площадь объекта (м.кв.):
A5: Срок проведения работ:
A6: ПОДРЯДЧИК:
A7: Юридический адрес:
A8: Электронный адрес:
A9: Контактное лицо (Ф.И.О.):
A10: Контактный телефон:
A11: Реквизиты:
A12: Сумма по смете, ₽: | C12: =$J$541 -> 0
A13: Цены на дату:
A15: Курс USD: | C15: 81
A16: Курс EUR: | C16: 95
A17: Дисконт по тендеру, доля: | C17: 0
A19: РАСШИФРОВКА РАБОТ И ЗАТРАТ. После сборки перечня: встать на таблицу → Данные → «Применить повторно» (Ctrl+Alt+L). Перед отправкой фильтровать по «Кол-ву».
A20: № | B20: Код | C20: Наименование работ и затрат | D20: Ед. изм. | E20: Кол-во | F20: Цена ед. работ, ₽ | G20: Цена ед. материалов/оборуд., ₽ | H20: Стоимость работ, ₽ | I20: Стоимость материалов/оборуд., ₽ | J20: Всего, ₽ | K20: _w | L20: _hdr | M20: _показать
A21: =IF(ISNUMBER($K21),INDEX(Сборка!$O$2:$O$501,$K21),"") | B21: =IF(ISNUMBER($K21),INDEX(Сборка!$C$2:$C$501,$K21),"") | C21: =IF($L21<>"",INDEX(Сборка!$S$2:$S$501,MATCH($L21,Сборка!$P$2:$P$501,0)),IF(ISNUMBER($K21),INDEX(Сборка!$D$2:$D$501,$K21)&IF(INDEX(Сборка!$I$2:$I$501,$K21)<>""," — "&INDEX(Сборка!$I$2:$I$501,$K21),""),"")) | D21: =IF(ISNUMBER($K21),INDEX(Сборка!$E$2:$E$501,$K21),"") | E21: =IF(ISNUMBER($K21),INDEX(Сборка!$G$2:$G$501,$K21),"") | F21: =IF(ISNUMBER($K21),INDEX(Сборка!$J$2:$J$501,$K21),"") | G21: =IF(ISNUMBER($K21),INDEX(Сборка!$K$2:$K$501,$K21),"") | H21: =IF(ISNUMBER($K21),ROUND($E21*$F21,2),"") | I21: =IF(ISNUMBER($K21),ROUND($E21*$G21,2),"") | J21: =IF(ISNUMBER($K21),$H21+$I21,"") | K21: =IFERROR(MATCH(1,Сборка!$R$2:$R$501,0),"") | L21: =IFERROR(IF(INDEX(Сборка!$Q$2:$Q$501,MATCH(1+1,Сборка!$R$2:$R$501,0))=1,INDEX(Сборка!$P$2:$P$501,MATCH(1+1,Сборка!$R$2:$R$501,0)),""),"") | M21: =IF(OR(ISNUMBER($K21),$L21<>""),"показать","")
A22: =IF(ISNUMBER($K22),INDEX(Сборка!$O$2:$O$501,$K22),"") | B22: =IF(ISNUMBER($K22),INDEX(Сборка!$C$2:$C$501,$K22),"") | C22: =IF($L22<>"",INDEX(Сборка!$S$2:$S$501,MATCH($L22,Сборка!$P$2:$P$501,0)),IF(ISNUMBER($K22),INDEX(Сборка!$D$2:$D$501,$K22)&IF(INDEX(Сборка!$I$2:$I$501,$K22)<>""," — "&INDEX(Сборка!$I$2:$I$501,$K22),""),"")) | D22: =IF(ISNUMBER($K22),INDEX(Сборка!$E$2:$E$501,$K22),"") | E22: =IF(ISNUMBER($K22),INDEX(Сборка!$G$2:$G$501,$K22),"") | F22: =IF(ISNUMBER($K22),INDEX(Сборка!$J$2:$J$501,$K22),"") | G22: =IF(ISNUMBER($K22),INDEX(Сборка!$K$2:$K$501,$K22),"") | H22: =IF(ISNUMBER($K22),ROUND($E22*$F22,2),"") | I22: =IF(ISNUMBER($K22),ROUND($E22*$G22,2),"") | J22: =IF(ISNUMBER($K22),$H22+$I22,"") | K22: =IFERROR(MATCH(2,Сборка!$R$2:$R$501,0),"") | L22: =IFERROR(IF(INDEX(Сборка!$Q$2:$Q$501,MATCH(2+1,Сборка!$R$2:$R$501,0))=1,INDEX(Сборка!$P$2:$P$501,MATCH(2+1,Сборка!$R$2:$R$501,0)),""),"") | M22: =IF(OR(ISNUMBER($K22),$L22<>""),"показать","")
A23: =IF(ISNUMBER($K23),INDEX(Сборка!$O$2:$O$501,$K23),"") | B23: =IF(ISNUMBER($K23),INDEX(Сборка!$C$2:$C$501,$K23),"") | C23: =IF($L23<>"",INDEX(Сборка!$S$2:$S$501,MATCH($L23,Сборка!$P$2:$P$501,0)),IF(ISNUMBER($K23),INDEX(Сборка!$D$2:$D$501,$K23)&IF(INDEX(Сборка!$I$2:$I$501,$K23)<>""," — "&INDEX(Сборка!$I$2:$I$501,$K23),""),"")) | D23: =IF(ISNUMBER($K23),INDEX(Сборка!$E$2:$E$501,$K23),"") | E23: =IF(ISNUMBER($K23),INDEX(Сборка!$G$2:$G$501,$K23),"") | F23: =IF(ISNUMBER($K23),INDEX(Сборка!$J$2:$J$501,$K23),"") | G23: =IF(ISNUMBER($K23),INDEX(Сборка!$K$2:$K$501,$K23),"") | H23: =IF(ISNUMBER($K23),ROUND($E23*$F23,2),"") | I23: =IF(ISNUMBER($K23),ROUND($E23*$G23,2),"") | J23: =IF(ISNUMBER($K23),$H23+$I23,"") | K23: =IFERROR(MATCH(3,Сборка!$R$2:$R$501,0),"") | L23: =IFERROR(IF(INDEX(Сборка!$Q$2:$Q$501,MATCH(3+1,Сборка!$R$2:$R$501,0))=1,INDEX(Сборка!$P$2:$P$501,MATCH(3+1,Сборка!$R$2:$R$501,0)),""),"") | M23: =IF(OR(ISNUMBER($K23),$L23<>""),"показать","")
A24: =IF(ISNUMBER($K24),INDEX(Сборка!$O$2:$O$501,$K24),"") | B24: =IF(ISNUMBER($K24),INDEX(Сборка!$C$2:$C$501,$K24),"") | C24: =IF($L24<>"",INDEX(Сборка!$S$2:$S$501,MATCH($L24,Сборка!$P$2:$P$501,0)),IF(ISNUMBER($K24),INDEX(Сборка!$D$2:$D$501,$K24)&IF(INDEX(Сборка!$I$2:$I$501,$K24)<>""," — "&INDEX(Сборка!$I$2:$I$501,$K24),""),"")) | D24: =IF(ISNUMBER($K24),INDEX(Сборка!$E$2:$E$501,$K24),"") | E24: =IF(ISNUMBER($K24),INDEX(Сборка!$G$2:$G$501,$K24),"") | F24: =IF(ISNUMBER($K24),INDEX(Сборка!$J$2:$J$501,$K24),"") | G24: =IF(ISNUMBER($K24),INDEX(Сборка!$K$2:$K$501,$K24),"") | H24: =IF(ISNUMBER($K24),ROUND($E24*$F24,2),"") | I24: =IF(ISNUMBER($K24),ROUND($E24*$G24,2),"") | J24: =IF(ISNUMBER($K24),$H24+$I24,"") | K24: =IFERROR(MATCH(4,Сборка!$R$2:$R$501,0),"") | L24: =IFERROR(IF(INDEX(Сборка!$Q$2:$Q$501,MATCH(4+1,Сборка!$R$2:$R$501,0))=1,INDEX(Сборка!$P$2:$P$501,MATCH(4+1,Сборка!$R$2:$R$501,0)),""),"") | M24: =IF(OR(ISNUMBER($K24),$L24<>""),"показать","")
A25: =IF(ISNUMBER($K25),INDEX(Сборка!$O$2:$O$501,$K25),"") | B25: =IF(ISNUMBER($K25),INDEX(Сборка!$C$2:$C$501,$K25),"") | C25: =IF($L25<>"",INDEX(Сборка!$S$2:$S$501,MATCH($L25,Сборка!$P$2:$P$501,0)),IF(ISNUMBER($K25),INDEX(Сборка!$D$2:$D$501,$K25)&IF(INDEX(Сборка!$I$2:$I$501,$K25)<>""," — "&INDEX(Сборка!$I$2:$I$501,$K25),""),"")) | D25: =IF(ISNUMBER($K25),INDEX(Сборка!$E$2:$E$501,$K25),"") | E25: =IF(ISNUMBER($K25),INDEX(Сборка!$G$2:$G$501,$K25),"") | F25: =IF(ISNUMBER($K25),INDEX(Сборка!$J$2:$J$501,$K25),"") | G25: =IF(ISNUMBER($K25),INDEX(Сборка!$K$2:$K$501,$K25),"") | H25: =IF(ISNUMBER($K25),ROUND($E25*$F25,2),"") | I25: =IF(ISNUMBER($K25),ROUND($E25*$G25,2),"") | J25: =IF(ISNUMBER($K25),$H25+$I25,"") | K25: =IFERROR(MATCH(5,Сборка!$R$2:$R$501,0),"") | L25: =IFERROR(IF(INDEX(Сборка!$Q$2:$Q$501,MATCH(5+1,Сборка!$R$2:$R$501,0))=1,INDEX(Сборка!$P$2:$P$501,MATCH(5+1,Сборка!$R$2:$R$501,0)),""),"") | M25: =IF(OR(ISNUMBER($K25),$L25<>""),"показать","")
A26: =IF(ISNUMBER($K26),INDEX(Сборка!$O$2:$O$501,$K26),"") | B26: =IF(ISNUMBER($K26),INDEX(Сборка!$C$2:$C$501,$K26),"") | C26: =IF($L26<>"",INDEX(Сборка!$S$2:$S$501,MATCH($L26,Сборка!$P$2:$P$501,0)),IF(ISNUMBER($K26),INDEX(Сборка!$D$2:$D$501,$K26)&IF(INDEX(Сборка!$I$2:$I$501,$K26)<>""," — "&INDEX(Сборка!$I$2:$I$501,$K26),""),"")) | D26: =IF(ISNUMBER($K26),INDEX(Сборка!$E$2:$E$501,$K26),"") | E26: =IF(ISNUMBER($K26),INDEX(Сборка!$G$2:$G$501,$K26),"") | F26: =IF(ISNUMBER($K26),INDEX(Сборка!$J$2:$J$501,$K26),"") | G26: =IF(ISNUMBER($K26),INDEX(Сборка!$K$2:$K$501,$K26),"") | H26: =IF(ISNUMBER($K26),ROUND($E26*$F26,2),"") | I26: =IF(ISNUMBER($K26),ROUND($E26*$G26,2),"") | J26: =IF(ISNUMBER($K26),$H26+$I26,"") | K26: =IFERROR(MATCH(6,Сборка!$R$2:$R$501,0),"") | L26: =IFERROR(IF(INDEX(Сборка!$Q$2:$Q$501,MATCH(6+1,Сборка!$R$2:$R$501,0))=1,INDEX(Сборка!$P$2:$P$501,MATCH(6+1,Сборка!$R$2:$R$501,0)),""),"") | M26: =IF(OR(ISNUMBER($K26),$L26<>""),"показать","")
A27: =IF(ISNUMBER($K27),INDEX(Сборка!$O$2:$O$501,$K27),"") | B27: =IF(ISNUMBER($K27),INDEX(Сборка!$C$2:$C$501,$K27),"") | C27: =IF($L27<>"",INDEX(Сборка!$S$2:$S$501,MATCH($L27,Сборка!$P$2:$P$501,0)),IF(ISNUMBER($K27),INDEX(Сборка!$D$2:$D$501,$K27)&IF(INDEX(Сборка!$I$2:$I$501,$K27)<>""," — "&INDEX(Сборка!$I$2:$I$501,$K27),""),"")) | D27: =IF(ISNUMBER($K27),INDEX(Сборка!$E$2:$E$501,$K27),"") | E27: =IF(ISNUMBER($K27),INDEX(Сборка!$G$2:$G$501,$K27),"") | F27: =IF(ISNUMBER($K27),INDEX(Сборка!$J$2:$J$501,$K27),"") | G27: =IF(ISNUMBER($K27),INDEX(Сборка!$K$2:$K$501,$K27),"") | H27: =IF(ISNUMBER($K27),ROUND($E27*$F27,2),"") | I27: =IF(ISNUMBER($K27),ROUND($E27*$G27,2),"") | J27: =IF(ISNUMBER($K27),$H27+$I27,"") | K27: =IFERROR(MATCH(7,Сборка!$R$2:$R$501,0),"") | L27: =IFERROR(IF(INDEX(Сборка!$Q$2:$Q$501,MATCH(7+1,Сборка!$R$2:$R$501,0))=1,INDEX(Сборка!$P$2:$P$501,MATCH(7+1,Сборка!$R$2:$R$501,0)),""),"") | M27: =IF(OR(ISNUMBER($K27),$L27<>""),"показать","")
A28: =IF(ISNUMBER($K28),INDEX(Сборка!$O$2:$O$501,$K28),"") | B28: =IF(ISNUMBER($K28),INDEX(Сборка!$C$2:$C$501,$K28),"") | C28: =IF($L28<>"",INDEX(Сборка!$S$2:$S$501,MATCH($L28,Сборка!$P$2:$P$501,0)),IF(ISNUMBER($K28),INDEX(Сборка!$D$2:$D$501,$K28)&IF(INDEX(Сборка!$I$2:$I$501,$K28)<>""," — "&INDEX(Сборка!$I$2:$I$501,$K28),""),"")) | D28: =IF(ISNUMBER($K28),INDEX(Сборка!$E$2:$E$501,$K28),"") | E28: =IF(ISNUMBER($K28),INDEX(Сборка!$G$2:$G$501,$K28),"") | F28: =IF(ISNUMBER($K28),INDEX(Сборка!$J$2:$J$501,$K28),"") | G28: =IF(ISNUMBER($K28),INDEX(Сборка!$K$2:$K$501,$K28),"") | H28: =IF(ISNUMBER($K28),ROUND($E28*$F28,2),"") | I28: =IF(ISNUMBER($K28),ROUND($E28*$G28,2),"") | J28: =IF(ISNUMBER($K28),$H28+$I28,"") | K28: =IFERROR(MATCH(8,Сборка!$R$2:$R$501,0),"") | L28: =IFERROR(IF(INDEX(Сборка!$Q$2:$Q$501,MATCH(8+1,Сборка!$R$2:$R$501,0))=1,INDEX(Сборка!$P$2:$P$501,MATCH(8+1,Сборка!$R$2:$R$501,0)),""),"") | M28: =IF(OR(ISNUMBER($K28),$L28<>""),"показать","")
A29: =IF(ISNUMBER($K29),INDEX(Сборка!$O$2:$O$501,$K29),"") | B29: =IF(ISNUMBER($K29),INDEX(Сборка!$C$2:$C$501,$K29),"") | C29: =IF($L29<>"",INDEX(Сборка!$S$2:$S$501,MATCH($L29,Сборка!$P$2:$P$501,0)),IF(ISNUMBER($K29),INDEX(Сборка!$D$2:$D$501,$K29)&IF(INDEX(Сборка!$I$2:$I$501,$K29)<>""," — "&INDEX(Сборка!$I$2:$I$501,$K29),""),"")) | D29: =IF(ISNUMBER($K29),INDEX(Сборка!$E$2:$E$501,$K29),"") | E29: =IF(ISNUMBER($K29),INDEX(Сборка!$G$2:$G$501,$K29),"") | F29: =IF(ISNUMBER($K29),INDEX(Сборка!$J$2:$J$501,$K29),"") | G29: =IF(ISNUMBER($K29),INDEX(Сборка!$K$2:$K$501,$K29),"") | H29: =IF(ISNUMBER($K29),ROUND($E29*$F29,2),"") | I29: =IF(ISNUMBER($K29),ROUND($E29*$G29,2),"") | J29: =IF(ISNUMBER($K29),$H29+$I29,"") | K29: =IFERROR(MATCH(9,Сборка!$R$2:$R$501,0),"") | L29: =IFERROR(IF(INDEX(Сборка!$Q$2:$Q$501,MATCH(9+1,Сборка!$R$2:$R$501,0))=1,INDEX(Сборка!$P$2:$P$501,MATCH(9+1,Сборка!$R$2:$R$501,0)),""),"") | M29: =IF(OR(ISNUMBER($K29),$L29<>""),"показать","")
A30: =IF(ISNUMBER($K30),INDEX(Сборка!$O$2:$O$501,$K30),"") | B30: =IF(ISNUMBER($K30),INDEX(Сборка!$C$2:$C$501,$K30),"") | C30: =IF($L30<>"",INDEX(Сборка!$S$2:$S$501,MATCH($L30,Сборка!$P$2:$P$501,0)),IF(ISNUMBER($K30),INDEX(Сборка!$D$2:$D$501,$K30)&IF(INDEX(Сборка!$I$2:$I$501,$K30)<>""," — "&INDEX(Сборка!$I$2:$I$501,$K30),""),"")) | D30: =IF(ISNUMBER($K30),INDEX(Сборка!$E$2:$E$501,$K30),"") | E30: =IF(ISNUMBER($K30),INDEX(Сборка!$G$2:$G$501,$K30),"") | F30: =IF(ISNUMBER($K30),INDEX(Сборка!$J$2:$J$501,$K30),"") | G30: =IF(ISNUMBER($K30),INDEX(Сборка!$K$2:$K$501,$K30),"") | H30: =IF(ISNUMBER($K30),ROUND($E30*$F30,2),"") | I30: =IF(ISNUMBER($K30),ROUND($E30*$G30,2),"") | J30: =IF(ISNUMBER($K30),$H30+$I30,"") | K30: =IFERROR(MATCH(10,Сборка!$R$2:$R$501,0),"") | L30: =IFERROR(IF(INDEX(Сборка!$Q$2:$Q$501,MATCH(10+1,Сборка!$R$2:$R$501,0))=1,INDEX(Сборка!$P$2:$P$501,MATCH(10+1,Сборка!$R$2:$R$501,0)),""),"") | M30: =IF(OR(ISNUMBER($K30),$L30<>""),"показать","")
A31: =IF(ISNUMBER($K31),INDEX(Сборка!$O$2:$O$501,$K31),"") | B31: =IF(ISNUMBER($K31),INDEX(Сборка!$C$2:$C$501,$K31),"") | C31: =IF($L31<>"",INDEX(Сборка!$S$2:$S$501,MATCH($L31,Сборка!$P$2:$P$501,0)),IF(ISNUMBER($K31),INDEX(Сборка!$D$2:$D$501,$K31)&IF(INDEX(Сборка!$I$2:$I$501,$K31)<>""," — "&INDEX(Сборка!$I$2:$I$501,$K31),""),"")) | D31: =IF(ISNUMBER($K31),INDEX(Сборка!$E$2:$E$501,$K31),"") | E31: =IF(ISNUMBER($K31),INDEX(Сборка!$G$2:$G$501,$K31),"") | F31: =IF(ISNUMBER($K31),INDEX(Сборка!$J$2:$J$501,$K31),"") | G31: =IF(ISNUMBER($K31),INDEX(Сборка!$K$2:$K$501,$K31),"") | H31: =IF(ISNUMBER($K31),ROUND($E31*$F31,2),"") | I31: =IF(ISNUMBER($K31),ROUND($E31*$G31,2),"") | J31: =IF(ISNUMBER($K31),$H31+$I31,"") | K31: =IFERROR(MATCH(11,Сборка!$R$2:$R$501,0),"") | L31: =IFERROR(IF(INDEX(Сборка!$Q$2:$Q$501,MATCH(11+1,Сборка!$R$2:$R$501,0))=1,INDEX(Сборка!$P$2:$P$501,MATCH(11+1,Сборка!$R$2:$R$501,0)),""),"") | M31: =IF(OR(ISNUMBER($K31),$L31<>""),"показать","")
A32: =IF(ISNUMBER($K32),INDEX(Сборка!$O$2:$O$501,$K32),"") | B32: =IF(ISNUMBER($K32),INDEX(Сборка!$C$2:$C$501,$K32),"") | C32: =IF($L32<>"",INDEX(Сборка!$S$2:$S$501,MATCH($L32,Сборка!$P$2:$P$501,0)),IF(ISNUMBER($K32),INDEX(Сборка!$D$2:$D$501,$K32)&IF(INDEX(Сборка!$I$2:$I$501,$K32)<>""," — "&INDEX(Сборка!$I$2:$I$501,$K32),""),"")) | D32: =IF(ISNUMBER($K32),INDEX(Сборка!$E$2:$E$501,$K32),"") | E32: =IF(ISNUMBER($K32),INDEX(Сборка!$G$2:$G$501,$K32),"") | F32: =IF(ISNUMBER($K32),INDEX(Сборка!$J$2:$J$501,$K32),"") | G32: =IF(ISNUMBER($K32),INDEX(Сборка!$K$2:$K$501,$K32),"") | H32: =IF(ISNUMBER($K32),ROUND($E32*$F32,2),"") | I32: =IF(ISNUMBER($K32),ROUND($E32*$G32,2),"") | J32: =IF(ISNUMBER($K32),$H32+$I32,"") | K32: =IFERROR(MATCH(12,Сборка!$R$2:$R$501,0),"") | L32: =IFERROR(IF(INDEX(Сборка!$Q$2:$Q$501,MATCH(12+1,Сборка!$R$2:$R$501,0))=1,INDEX(Сборка!$P$2:$P$501,MATCH(12+1,Сборка!$R$2:$R$501,0)),""),"") | M32: =IF(OR(ISNUMBER($K32),$L32<>""),"показать","")
A33: =IF(ISNUMBER($K33),INDEX(Сборка!$O$2:$O$501,$K33),"") | B33: =IF(ISNUMBER($K33),INDEX(Сборка!$C$2:$C$501,$K33),"") | C33: =IF($L33<>"",INDEX(Сборка!$S$2:$S$501,MATCH($L33,Сборка!$P$2:$P$501,0)),IF(ISNUMBER($K33),INDEX(Сборка!$D$2:$D$501,$K33)&IF(INDEX(Сборка!$I$2:$I$501,$K33)<>""," — "&INDEX(Сборка!$I$2:$I$501,$K33),""),"")) | D33: =IF(ISNUMBER($K33),INDEX(Сборка!$E$2:$E$501,$K33),"") | E33: =IF(ISNUMBER($K33),INDEX(Сборка!$G$2:$G$501,$K33),"") | F33: =IF(ISNUMBER($K33),INDEX(Сборка!$J$2:$J$501,$K33),"") | G33: =IF(ISNUMBER($K33),INDEX(Сборка!$K$2:$K$501,$K33),"") | H33: =IF(ISNUMBER($K33),ROUND($E33*$F33,2),"") | I33: =IF(ISNUMBER($K33),ROUND($E33*$G33,2),"") | J33: =IF(ISNUMBER($K33),$H33+$I33,"") | K33: =IFERROR(MATCH(13,Сборка!$R$2:$R$501,0),"") | L33: =IFERROR(IF(INDEX(Сборка!$Q$2:$Q$501,MATCH(13+1,Сборка!$R$2:$R$501,0))=1,INDEX(Сборка!$P$2:$P$501,MATCH(13+1,Сборка!$R$2:$R$501,0)),""),"") | M33: =IF(OR(ISNUMBER($K33),$L33<>""),"показать","")
A34: =IF(ISNUMBER($K34),INDEX(Сборка!$O$2:$O$501,$K34),"") | B34: =IF(ISNUMBER($K34),INDEX(Сборка!$C$2:$C$501,$K34),"") | C34: =IF($L34<>"",INDEX(Сборка!$S$2:$S$501,MATCH($L34,Сборка!$P$2:$P$501,0)),IF(ISNUMBER($K34),INDEX(Сборка!$D$2:$D$501,$K34)&IF(INDEX(Сборка!$I$2:$I$501,$K34)<>""," — "&INDEX(Сборка!$I$2:$I$501,$K34),""),"")) | D34: =IF(ISNUMBER($K34),INDEX(Сборка!$E$2:$E$501,$K34),"") | E34: =IF(ISNUMBER($K34),INDEX(Сборка!$G$2:$G$501,$K34),"") | F34: =IF(ISNUMBER($K34),INDEX(Сборка!$J$2:$J$501,$K34),"") | G34: =IF(ISNUMBER($K34),INDEX(Сборка!$K$2:$K$501,$K34),"") | H34: =IF(ISNUMBER($K34),ROUND($E34*$F34,2),"") | I34: =IF(ISNUMBER($K34),ROUND($E34*$G34,2),"") | J34: =IF(ISNUMBER($K34),$H34+$I34,"") | K34: =IFERROR(MATCH(14,Сборка!$R$2:$R$501,0),"") | L34: =IFERROR(IF(INDEX(Сборка!$Q$2:$Q$501,MATCH(14+1,Сборка!$R$2:$R$501,0))=1,INDEX(Сборка!$P$2:$P$501,MATCH(14+1,Сборка!$R$2:$R$501,0)),""),"") | M34: =IF(OR(ISNUMBER($K34),$L34<>""),"показать","")
A35: =IF(ISNUMBER($K35),INDEX(Сборка!$O$2:$O$501,$K35),"") | B35: =IF(ISNUMBER($K35),INDEX(Сборка!$C$2:$C$501,$K35),"") | C35: =IF($L35<>"",INDEX(Сборка!$S$2:$S$501,MATCH($L35,Сборка!$P$2:$P$501,0)),IF(ISNUMBER($K35),INDEX(Сборка!$D$2:$D$501,$K35)&IF(INDEX(Сборка!$I$2:$I$501,$K35)<>""," — "&INDEX(Сборка!$I$2:$I$501,$K35),""),"")) | D35: =IF(ISNUMBER($K35),INDEX(Сборка!$E$2:$E$501,$K35),"") | E35: =IF(ISNUMBER($K35),INDEX(Сборка!$G$2:$G$501,$K35),"") | F35: =IF(ISNUMBER($K35),INDEX(Сборка!$J$2:$J$501,$K35),"") | G35: =IF(ISNUMBER($K35),INDEX(Сборка!$K$2:$K$501,$K35),"") | H35: =IF(ISNUMBER($K35),ROUND($E35*$F35,2),"") | I35: =IF(ISNUMBER($K35),ROUND($E35*$G35,2),"") | J35: =IF(ISNUMBER($K35),$H35+$I35,"") | K35: =IFERROR(MATCH(15,Сборка!$R$2:$R$501,0),"") | L35: =IFERROR(IF(INDEX(Сборка!$Q$2:$Q$501,MATCH(15+1,Сборка!$R$2:$R$501,0))=1,INDEX(Сборка!$P$2:$P$501,MATCH(15+1,Сборка!$R$2:$R$501,0)),""),"") | M35: =IF(OR(ISNUMBER($K35),$L35<>""),"показать","")
A36: =IF(ISNUMBER($K36),INDEX(Сборка!$O$2:$O$501,$K36),"") | B36: =IF(ISNUMBER($K36),INDEX(Сборка!$C$2:$C$501,$K36),"") | C36: =IF($L36<>"",INDEX(Сборка!$S$2:$S$501,MATCH($L36,Сборка!$P$2:$P$501,0)),IF(ISNUMBER($K36),INDEX(Сборка!$D$2:$D$501,$K36)&IF(INDEX(Сборка!$I$2:$I$501,$K36)<>""," — "&INDEX(Сборка!$I$2:$I$501,$K36),""),"")) | D36: =IF(ISNUMBER($K36),INDEX(Сборка!$E$2:$E$501,$K36),"") | E36: =IF(ISNUMBER($K36),INDEX(Сборка!$G$2:$G$501,$K36),"") | F36: =IF(ISNUMBER($K36),INDEX(Сборка!$J$2:$J$501,$K36),"") | G36: =IF(ISNUMBER($K36),INDEX(Сборка!$K$2:$K$501,$K36),"") | H36: =IF(ISNUMBER($K36),ROUND($E36*$F36,2),"") | I36: =IF(ISNUMBER($K36),ROUND($E36*$G36,2),"") | J36: =IF(ISNUMBER($K36),$H36+$I36,"") | K36: =IFERROR(MATCH(16,Сборка!$R$2:$R$501,0),"") | L36: =IFERROR(IF(INDEX(Сборка!$Q$2:$Q$501,MATCH(16+1,Сборка!$R$2:$R$501,0))=1,INDEX(Сборка!$P$2:$P$501,MATCH(16+1,Сборка!$R$2:$R$501,0)),""),"") | M36: =IF(OR(ISNUMBER($K36),$L36<>""),"показать","")
A37: =IF(ISNUMBER($K37),INDEX(Сборка!$O$2:$O$501,$K37),"") | B37: =IF(ISNUMBER($K37),INDEX(Сборка!$C$2:$C$501,$K37),"") | C37: =IF($L37<>"",INDEX(Сборка!$S$2:$S$501,MATCH($L37,Сборка!$P$2:$P$501,0)),IF(ISNUMBER($K37),INDEX(Сборка!$D$2:$D$501,$K37)&IF(INDEX(Сборка!$I$2:$I$501,$K37)<>""," — "&INDEX(Сборка!$I$2:$I$501,$K37),""),"")) | D37: =IF(ISNUMBER($K37),INDEX(Сборка!$E$2:$E$501,$K37),"") | E37: =IF(ISNUMBER($K37),INDEX(Сборка!$G$2:$G$501,$K37),"") | F37: =IF(ISNUMBER($K37),INDEX(Сборка!$J$2:$J$501,$K37),"") | G37: =IF(ISNUMBER($K37),INDEX(Сборка!$K$2:$K$501,$K37),"") | H37: =IF(ISNUMBER($K37),ROUND($E37*$F37,2),"") | I37: =IF(ISNUMBER($K37),ROUND($E37*$G37,2),"") | J37: =IF(ISNUMBER($K37),$H37+$I37,"") | K37: =IFERROR(MATCH(17,Сборка!$R$2:$R$501,0),"") | L37: =IFERROR(IF(INDEX(Сборка!$Q$2:$Q$501,MATCH(17+1,Сборка!$R$2:$R$501,0))=1,INDEX(Сборка!$P$2:$P$501,MATCH(17+1,Сборка!$R$2:$R$501,0)),""),"") | M37: =IF(OR(ISNUMBER($K37),$L37<>""),"показать","")
A38: =IF(ISNUMBER($K38),INDEX(Сборка!$O$2:$O$501,$K38),"") | B38: =IF(ISNUMBER($K38),INDEX(Сборка!$C$2:$C$501,$K38),"") | C38: =IF($L38<>"",INDEX(Сборка!$S$2:$S$501,MATCH($L38,Сборка!$P$2:$P$501,0)),IF(ISNUMBER($K38),INDEX(Сборка!$D$2:$D$501,$K38)&IF(INDEX(Сборка!$I$2:$I$501,$K38)<>""," — "&INDEX(Сборка!$I$2:$I$501,$K38),""),"")) | D38: =IF(ISNUMBER($K38),INDEX(Сборка!$E$2:$E$501,$K38),"") | E38: =IF(ISNUMBER($K38),INDEX(Сборка!$G$2:$G$501,$K38),"") | F38: =IF(ISNUMBER($K38),INDEX(Сборка!$J$2:$J$501,$K38),"") | G38: =IF(ISNUMBER($K38),INDEX(Сборка!$K$2:$K$501,$K38),"") | H38: =IF(ISNUMBER($K38),ROUND($E38*$F38,2),"") | I38: =IF(ISNUMBER($K38),ROUND($E38*$G38,2),"") | J38: =IF(ISNUMBER($K38),$H38+$I38,"") | K38: =IFERROR(MATCH(18,Сборка!$R$2:$R$501,0),"") | L38: =IFERROR(IF(INDEX(Сборка!$Q$2:$Q$501,MATCH(18+1,Сборка!$R$2:$R$501,0))=1,INDEX(Сборка!$P$2:$P$501,MATCH(18+1,Сборка!$R$2:$R$501,0)),""),"") | M38: =IF(OR(ISNUMBER($K38),$L38<>""),"показать","")
A39: =IF(ISNUMBER($K39),INDEX(Сборка!$O$2:$O$501,$K39),"") | B39: =IF(ISNUMBER($K39),INDEX(Сборка!$C$2:$C$501,$K39),"") | C39: =IF($L39<>"",INDEX(Сборка!$S$2:$S$501,MATCH($L39,Сборка!$P$2:$P$501,0)),IF(ISNUMBER($K39),INDEX(Сборка!$D$2:$D$501,$K39)&IF(INDEX(Сборка!$I$2:$I$501,$K39)<>""," — "&INDEX(Сборка!$I$2:$I$501,$K39),""),"")) | D39: =IF(ISNUMBER($K39),INDEX(Сборка!$E$2:$E$501,$K39),"") | E39: =IF(ISNUMBER($K39),INDEX(Сборка!$G$2:$G$501,$K39),"") | F39: =IF(ISNUMBER($K39),INDEX(Сборка!$J$2:$J$501,$K39),"") | G39: =IF(ISNUMBER($K39),INDEX(Сборка!$K$2:$K$501,$K39),"") | H39: =IF(ISNUMBER($K39),ROUND($E39*$F39,2),"") | I39: =IF(ISNUMBER($K39),ROUND($E39*$G39,2),"") | J39: =IF(ISNUMBER($K39),$H39+$I39,"") | K39: =IFERROR(MATCH(19,Сборка!$R$2:$R$501,0),"") | L39: =IFERROR(IF(INDEX(Сборка!$Q$2:$Q$501,MATCH(19+1,Сборка!$R$2:$R$501,0))=1,INDEX(Сборка!$P$2:$P$501,MATCH(19+1,Сборка!$R$2:$R$501,0)),""),"") | M39: =IF(OR(ISNUMBER($K39),$L39<>""),"показать","")
A40: =IF(ISNUMBER($K40),INDEX(Сборка!$O$2:$O$501,$K40),"") | B40: =IF(ISNUMBER($K40),INDEX(Сборка!$C$2:$C$501,$K40),"") | C40: =IF($L40<>"",INDEX(Сборка!$S$2:$S$501,MATCH($L40,Сборка!$P$2:$P$501,0)),IF(ISNUMBER($K40),INDEX(Сборка!$D$2:$D$501,$K40)&IF(INDEX(Сборка!$I$2:$I$501,$K40)<>""," — "&INDEX(Сборка!$I$2:$I$501,$K40),""),"")) | D40: =IF(ISNUMBER($K40),INDEX(Сборка!$E$2:$E$501,$K40),"") | E40: =IF(ISNUMBER($K40),INDEX(Сборка!$G$2:$G$501,$K40),"") | F40: =IF(ISNUMBER($K40),INDEX(Сборка!$J$2:$J$501,$K40),"") | G40: =IF(ISNUMBER($K40),INDEX(Сборка!$K$2:$K$501,$K40),"") | H40: =IF(ISNUMBER($K40),ROUND($E40*$F40,2),"") | I40: =IF(ISNUMBER($K40),ROUND($E40*$G40,2),"") | J40: =IF(ISNUMBER($K40),$H40+$I40,"") | K40: =IFERROR(MATCH(20,Сборка!$R$2:$R$501,0),"") | L40: =IFERROR(IF(INDEX(Сборка!$Q$2:$Q$501,MATCH(20+1,Сборка!$R$2:$R$501,0))=1,INDEX(Сборка!$P$2:$P$501,MATCH(20+1,Сборка!$R$2:$R$501,0)),""),"") | M40: =IF(OR(ISNUMBER($K40),$L40<>""),"показать","")
A41: =IF(ISNUMBER($K41),INDEX(Сборка!$O$2:$O$501,$K41),"") | B41: =IF(ISNUMBER($K41),INDEX(Сборка!$C$2:$C$501,$K41),"") | C41: =IF($L41<>"",INDEX(Сборка!$S$2:$S$501,MATCH($L41,Сборка!$P$2:$P$501,0)),IF(ISNUMBER($K41),INDEX(Сборка!$D$2:$D$501,$K41)&IF(INDEX(Сборка!$I$2:$I$501,$K41)<>""," — "&INDEX(Сборка!$I$2:$I$501,$K41),""),"")) | D41: =IF(ISNUMBER($K41),INDEX(Сборка!$E$2:$E$501,$K41),"") | E41: =IF(ISNUMBER($K41),INDEX(Сборка!$G$2:$G$501,$K41),"") | F41: =IF(ISNUMBER($K41),INDEX(Сборка!$J$2:$J$501,$K41),"") | G41: =IF(ISNUMBER($K41),INDEX(Сборка!$K$2:$K$501,$K41),"") | H41: =IF(ISNUMBER($K41),ROUND($E41*$F41,2),"") | I41: =IF(ISNUMBER($K41),ROUND($E41*$G41,2),"") | J41: =IF(ISNUMBER($K41),$H41+$I41,"") | K41: =IFERROR(MATCH(21,Сборка!$R$2:$R$501,0),"") | L41: =IFERROR(IF(INDEX(Сборка!$Q$2:$Q$501,MATCH(21+1,Сборка!$R$2:$R$501,0))=1,INDEX(Сборка!$P$2:$P$501,MATCH(21+1,Сборка!$R$2:$R$501,0)),""),"") | M41: =IF(OR(ISNUMBER($K41),$L41<>""),"показать","")
A42: =IF(ISNUMBER($K42),INDEX(Сборка!$O$2:$O$501,$K42),"") | B42: =IF(ISNUMBER($K42),INDEX(Сборка!$C$2:$C$501,$K42),"") | C42: =IF($L42<>"",INDEX(Сборка!$S$2:$S$501,MATCH($L42,Сборка!$P$2:$P$501,0)),IF(ISNUMBER($K42),INDEX(Сборка!$D$2:$D$501,$K42)&IF(INDEX(Сборка!$I$2:$I$501,$K42)<>""," — "&INDEX(Сборка!$I$2:$I$501,$K42),""),"")) | D42: =IF(ISNUMBER($K42),INDEX(Сборка!$E$2:$E$501,$K42),"") | E42: =IF(ISNUMBER($K42),INDEX(Сборка!$G$2:$G$501,$K42),"") | F42: =IF(ISNUMBER($K42),INDEX(Сборка!$J$2:$J$501,$K42),"") | G42: =IF(ISNUMBER($K42),INDEX(Сборка!$K$2:$K$501,$K42),"") | H42: =IF(ISNUMBER($K42),ROUND($E42*$F42,2),"") | I42: =IF(ISNUMBER($K42),ROUND($E42*$G42,2),"") | J42: =IF(ISNUMBER($K42),$H42+$I42,"") | K42: =IFERROR(MATCH(22,Сборка!$R$2:$R$501,0),"") | L42: =IFERROR(IF(INDEX(Сборка!$Q$2:$Q$501,MATCH(22+1,Сборка!$R$2:$R$501,0))=1,INDEX(Сборка!$P$2:$P$501,MATCH(22+1,Сборка!$R$2:$R$501,0)),""),"") | M42: =IF(OR(ISNUMBER($K42),$L42<>""),"показать","")
...

Sheet Работы
A1: Код_работы | B1: Наименование_работы | C1: Ед_изм | D1: Раздел | E1: Раздел_наимен | F1: Подраздел | G1: Группа_материалов | H1: Цена_работ_ЕР | I1: Вспом_материалы_% | J1: Тип | K1: Примечание | L1: Дата изм. цены | M1: Кто изменил / обоснование | N1: Код — Наименование (для списка)
A2: РАБ.Р1.1.001 | B2: Техническое обследование состояния несущих конструкций помещения с подготовкой рекомендаций по усилению (Техничесекое заключение о конструктиве - "ТЗК") (для помещений от 100 до 45… | C2: м2 | D2: Р1 | E2: Проектные работы и согласования | F2: 1 | H2: 3675 | I2: 0 | J2: нетиповая | N2: РАБ.Р1.1.001 — Техническое обследование состояния несущих конструкций помещения с подготовкой рекомендаций по усилению (Техничесекое заключение о конструктиве - "ТЗК") (для помещений от 100 до 45…
A3: РАБ.Р1.1.002 | B3: Эскизный проект фасада и Колористический паспорт с указанием ведомости отделки и проектным решением со спецификацией элементов (крыльцо, пандус, навесы, колонны и т.д.)(для фасадов… | C3: м2 | D3: Р1 | E3: Проектные работы и согласования | F3: 1 | H3: 7822.5 | I3: 0 | J3: нетиповая | N3: РАБ.Р1.1.002 — Эскизный проект фасада и Колористический паспорт с указанием ведомости отделки и проектным решением со спецификацией элементов (крыльцо, пандус, навесы, колонны и т.д.)(для фасадов…
A4: РАБ.Р1.1.901 | B4: Рабочая документация (раздел проекта — выбрать в «Сборке») | C4: — | D4: Р1 | E4: Проектные работы и согласования | F4: 1 | G4: ДОК.РД | H4: 0 | I4: 0 | J4: нетиповая | N4: РАБ.Р1.1.901 — Рабочая документация (раздел проекта — выбрать в «Сборке»)
A5: РАБ.Р1.1.961 | B5: Исполнительная документация (раздел проекта — выбрать в «Сборке») | C5: — | D5: Р1 | E5: Проектные работы и согласования | F5: 1 | G5: ДОК.ИД | H5: 0 | I5: 0 | J5: нетиповая | N5: РАБ.Р1.1.961 — Исполнительная документация (раздел проекта — выбрать в «Сборке»)
A6: РАБ.Р1.1.021 | B6: Техническое обследование состояния несущих конструкций помещения с подготовкой рекомендаций по усилению в зоне расположения депозитария, кассового узла и банкоматов (Техничесекое з… | C6: м2 | D6: Р1 | E6: Проектные работы и согласования | F6: 1 | H6: 3675 | I6: 0 | J6: нетиповая | N6: РАБ.Р1.1.021 — Техническое обследование состояния несущих конструкций помещения с подготовкой рекомендаций по усилению в зоне расположения депозитария, кассового узла и банкоматов (Техничесекое з…
A7: РАБ.Р1.1.022 | B7: Эскизный проект фасада и колористический паспорт с указанием ведомости отделки и проектным решением со спецификацией элементов (крыльцо, пандус, навесы, колонны и т.д.)(для фасадов… | C7: кв.м.площади фасада | D7: Р1 | E7: Проектные работы и согласования | F7: 1 | H7: 7822.5 | I7: 0 | J7: нетиповая | N7: РАБ.Р1.1.022 — Эскизный проект фасада и колористический паспорт с указанием ведомости отделки и проектным решением со спецификацией элементов (крыльцо, пандус, навесы, колонны и т.д.)(для фасадов…
A8: РАБ.Р1.1.061 | B8: Стоимость согласования проекта перепланировки/реставрации объекта культурного наследия в соответствии с нормативными актами г.______________. | C8: м2 | D8: Р1 | E8: Проектные работы и согласования | F8: 1 | H8: 0 | I8: 0 | J8: типовая | N8: РАБ.Р1.1.061 — Стоимость согласования проекта перепланировки/реставрации объекта культурного наследия в соответствии с нормативными актами г.______________.
A9: РАБ.Р1.1.062 | B9: Стоимость согласования проекта перепланировки/реконструкции объекта в соответствии с нормативными актами г.______________. | C9: м2 | D9: Р1 | E9: Проектные работы и согласования | F9: 1 | H9: 0 | I9: 0 | J9: типовая | N9: РАБ.Р1.1.062 — Стоимость согласования проекта перепланировки/реконструкции объекта в соответствии с нормативными актами г.______________.
A10: РАБ.Р1.1.063 | B10: Получение паспорта БТИ (в черных линиях) | C10: м2 | D10: Р1 | E10: Проектные работы и согласования | F10: 1 | H10: 0 | I10: 0 | J10: типовая | N10: РАБ.Р1.1.063 — Получение паспорта БТИ (в черных линиях)
A11: РАБ.Р1.1.064 | B11: Сертификация помещения для совершения операций с ценностями, хранение ценностей по (2) классу вломостойкости и (3) классу пулестойкости | C11: м2 | D11: Р1 | E11: Проектные работы и согласования | F11: 1 | H11: 88.99 | I11: 0 | J11: типовая | N11: РАБ.Р1.1.064 — Сертификация помещения для совершения операций с ценностями, хранение ценностей по (2) классу вломостойкости и (3) классу пулестойкости
A12: РАБ.Р1.1.065 | B12: Сертификация помещения для совершения операций с ценностями, хранение ценностей по 3 классу вломостойкости и 3 классу пулестойкости | C12: м2 | D12: Р1 | E12: Проектные работы и согласования | F12: 1 | H12: 149.82 | I12: 0 | J12: типовая | N12: РАБ.Р1.1.065 — Сертификация помещения для совершения операций с ценностями, хранение ценностей по 3 классу вломостойкости и 3 классу пулестойкости
A13: РАБ.Р1.1.066 | B13: Сертификация помещения для совершения операций с ценностями, хранение ценностей по (5) классу вломостойкости | C13: м2 | D13: Р1 | E13: Проектные работы и согласования | F13: 1 | H13: 96.48 | I13: 0 | J13: типовая | N13: РАБ.Р1.1.066 — Сертификация помещения для совершения операций с ценностями, хранение ценностей по (5) классу вломостойкости
A14: РАБ.Р1.1.067 | B14: Технический отчет электролаборатории для помещений более 100 м.кв. | C14: м2 | D14: Р1 | E14: Проектные работы и согласования | F14: 1 | H14: 123.58 | I14: 0 | J14: типовая | N14: РАБ.Р1.1.067 — Технический отчет электролаборатории для помещений более 100 м.кв.
A15: РАБ.Р1.1.068 | B15: Технический отчет электролаборатории для помещений менее 100 м.кв. | C15: компл. | D15: Р1 | E15: Проектные работы и согласования | F15: 1 | H15: 13074.35 | I15: 0 | J15: типовая | N15: РАБ.Р1.1.068 — Технический отчет электролаборатории для помещений менее 100 м.кв.
A16: РАБ.Р1.1.069 | B16: Стоимость согласования проекта изменения фасада согласно нормативных и законодательных актов г. ___________ и РФ. | C16: м2 | D16: Р1 | E16: Проектные работы и согласования | F16: 1 | H16: 190.9 | I16: 0 | J16: нетиповая | N16: РАБ.Р1.1.069 — Стоимость согласования проекта изменения фасада согласно нормативных и законодательных актов г. ___________ и РФ.
A17: РАБ.Р1.1.070 | B17: Разработка дизайн-проекта интерьера | C17: м2 | D17: Р1 | E17: Проектные работы и согласования | F17: 1 | H17: 0 | I17: 0 | J17: типовая | N17: РАБ.Р1.1.070 — Разработка дизайн-проекта интерьера
... A161: РАБ.Р2.13.001 | B161: Демонтажные работы до состояния shell-and-core | C161: м2 | D161: Р2 | E161: Демонтажные работы | F161: 13 | H161: 2133.33 | I161: 0 | J161: типовая | N161: РАБ.Р2.13.001 — Демонтажные работы до состояния shell-and-core
A162: РАБ.Р3.1.001 | B162: Кладка перегородок толщиной в 1/2 кирпича | C162: м2 | D162: Р3 | E162: Внутренние строительные работы | F162: 1 | G162: КЛАДКА | H162: 2392.5 | I162: 5 | J162: типовая | N162: РАБ.Р3.1.001 — Кладка перегородок толщиной в 1/2 кирпича
A163: РАБ.Р3.1.002 | B163: Кладка перегородок армированных толщиной в 1 кирпич | C163: м2 | D163: Р3 | E163: Внутренние строительные работы | F163: 1 | G163: КЛАДКА | H163: 2704.48 | I163: 5 | J163: типовая | N163: РАБ.Р3.1.002 — Кладка перегородок армированных толщиной в 1 кирпич
A164: РАБ.Р3.1.003 | B164: Кладка перегородок из пеноблоков (600*300*200) | C164: м2 | D164: Р3 | E164: Внутренние строительные работы | F164: 1 | G164: КЛАДКА | H164: 2035.8 | I164: 5 | J164: типовая | N164: РАБ.Р3.1.003 — Кладка перегородок из пеноблоков (600*300*200)
A165: РАБ.Р3.1.004 | B165: Заделка проемов в кирпичных стенах | C165: м3 | D165: Р3 | E165: Внутренние строительные работы | F165: 1 | G165: КЛАДКА | H165: 9787.5 | I165: 5 | J165: типовая | N165: РАБ.Р3.1.004 — Заделка проемов в кирпичных стенах
A166: РАБ.Р3.1.005 | B166: Усиление проемов металлическим профилем из уголка 50*3 | C166: м.п. | D166: Р3 | E166: Внутренние строительные работы | F166: 1 | H166: 1045 | I166: 0 | J166: нетиповая | N166: РАБ.Р3.1.005 — Усиление проемов металлическим профилем из уголка 50*3
A167: РАБ.Р3.1.006 | B167: Усиление проемов металлическим профилем из уголка 100*100*10 | C167: м.п. | D167: Р3 | E167: Внутренние строительные работы | F167: 1 | H167: 2090 | I167: 0 | J167: нетиповая | N167: РАБ.Р3.1.006 — Усиление проемов металлическим профилем из уголка 100*100*10
A168: РАБ.Р3.1.007 | B168: Устройство перегородок из ГКЛ толщ. 12 мм. "Кнауф" с одинарным металлическим каркасом и однослойной обшивкой с обеих сторон (включая перфорированные уголки на внешние углы) | C168: м2 | D168: Р3 | E168: Внутренние строительные работы | F168: 1 | G168: ГКЛ | H168: 1722.6 | I168: 5 | J168: типовая | N168: РАБ.Р3.1.007 — Устройство перегородок из ГКЛ толщ. 12 мм. "Кнауф" с одинарным металлическим каркасом и однослойной обшивкой с обеих сторон (включая перфорированные уголки на внешние углы)
A169: РАБ.Р3.1.008 | B169: Устройство перегородок из ГКЛ толщ. 12 мм. "Кнауф" с одинарным металлическим каркасом и двухслойной обшивкой с обеих сторон (включая перфорированные уголки на внешние углы) | C169: м2 | D169: Р3 | E169: Внутренние строительные работы | F169: 1 | G169: ГКЛ | H169: 1894.86 | I169: 5 | J169: типовая | N169: РАБ.Р3.1.008 — Устройство перегородок из ГКЛ толщ. 12 мм. "Кнауф" с одинарным металлическим каркасом и двухслойной обшивкой с обеих сторон (включая перфорированные уголки на внешние углы)
A170: РАБ.Р3.1.009 | B170: Устройство перегородки / облицовки из ГКЛ | C170: м2 | D170: Р3 | E170: Внутренние строительные работы | F170: 1 | G170: ГКЛ | H170: 1305.22 | I170: 5 | J170: типовая | N170: РАБ.Р3.1.009 — Устройство перегородки / облицовки из ГКЛ
A171: РАБ.Р3.1.010 | B171: Устройство перегородки / облицовки из ГКЛ | C171: м2 | D171: Р3 | E171: Внутренние строительные работы | F171: 1 | G171: ГКЛ | H171: 1515.98 | I171: 5 | J171: типовая | N171: РАБ.Р3.1.010 — Устройство перегородки / облицовки из ГКЛ
